Workbook

Sheet Raw Data
A1: Exported from Tally | I1: Dala Sales & Deliveries | Q1: External Deliveries | Y1: Forwarding From Client | AG1: Client Restock | AO1: Dala Restock | AW1: Unique Locations
A2: item name | B2: Date | C2: Particulars | D2: Vch Type | E2: Vch No. | F2: Quantity | G2: Value | I2: item name | J2: Date | K2: Particulars | L2: Vch Type | M2: Vch No. | N2: Quantity | O2: Value | P2: Total Value | Q2: item name | R2: Date | S2: Particulars | T2: Vch Type | U2: Vch No. | V2: Quantity | W2: Value | Y2: item name | Z2: Date | AA2: Particulars | AB2: Vch Type | AC2: Vch No. | AD2: Quantity | AE2: Value | AG2: item name | AH2: Date | AI2: Particulars | AJ2: Vch Type | AK2: Vch No. | AL2: Quantity | AM2: Value | AO2: item name | AP2: Date | AQ2: Particulars | AR2: Vch Type | AS2: Vch No. | AT2: Quantity | AU2: Value | AW2: {=counta(unique(C:C))-2} -> 16
A3: Atun 120g Peppersoup Spice (12x) | B3: 46044 | C3: Atun Foods | D3: Inventory Pickup by Dala | E3: 22 | F3: 17.92 | G3: 600111.59 | I3: =IFERROR(__xludf.DUMMYFUNCTION("IFERROR( FILTER($A$3:$G1844, LEN($A$3:$A1844), LOWER(TRIM($D$3:$D1844))=""sales""), )"),"Atun 120g Peppersoup Spice (12x)") -> Atun 120g Peppersoup Spice (12x) | J3: =IFERROR(__xludf.DUMMYFUNCTION("""COMPUTED_VALUE"""),46027.0) -> 46027 | K3: =IFERROR(__xludf.DUMMYFUNCTION("""COMPUTED_VALUE"""),"Jendol Supermarket, EGBEDA") -> Jendol Supermarket, EGBEDA | L3: =IFERROR(__xludf.DUMMYFUNCTION("""COMPUTED_VALUE"""),"Sales") -> Sales | M3: =IFERROR(__xludf.DUMMYFUNCTION("""COMPUTED_VALUE"""),"DT:000018") -> DT:000018 | N3: =IFERROR(__xludf.DUMMYFUNCTION("""COMPUTED_VALUE"""),1.0) -> 1 | O3: =IFERROR(__xludf.DUMMYFUNCTION("""COMPUTED_VALUE"""),33488.37) -> 33488.37 | P3: =sumif(M:M,M3,O:O) -> 33488.37 | Q3: =IFERROR(__xludf.DUMMYFUNCTION("IFERROR( FILTER($A$3:$G1844, LEN($A$3:$A1844), REGEXMATCH(LOWER(TRIM($D$3:$D1844)), ""\bjournal\b"")), ) "),"") | AG3: =IFERROR(__xludf.DUMMYFUNCTION("IFERROR(FILTER($A$3:$G1844, LEN($A$3:$A1844), LOWER(TRIM($D$3:$D1844))=""Inventory Supplied by Brands""),)"),"") | AO3: =IFERROR(__xludf.DUMMYFUNCTION("IFERROR(FILTER($A$3:$G1844, LEN($A$3:$A1844), LOWER(TRIM($D$3:$D1844))=""Inventory Pickup by Dala""),) "),"Atun 120g Peppersoup Spice (12x)") -> Atun 120g Peppersoup Spice (12x) | AP3: =IFERROR(__xludf.DUMMYFUNCTION("""COMPUTED_VALUE"""),46044.0) -> 46044 | AQ3: =IFERROR(__xludf.DUMMYFUNCTION("""COMPUTED_VALUE"""),"Atun Foods") -> Atun Foods | AR3: =IFERROR(__xludf.DUMMYFUNCTION("""COMPUTED_VALUE"""),"Inventory Pickup by Dala") -> Inventory Pickup by Dala | AS3: =IFERROR(__xludf.DUMMYFUNCTION("""COMPUTED_VALUE"""),22.0) -> 22 | AT3: =IFERROR(__xludf.DUMMYFUNCTION("""COMPUTED_VALUE"""),17.92) -> 17.92 | AU3: =IFERROR(__xludf.DUMMYFUNCTION("""COMPUTED_VALUE"""),600111.59) -> 600111.59
A4: Atun 120g Peppersoup Spice (12x) | B4: 46027 | C4: Jendol Supermarket, EGBEDA | D4: Sales | E4: DT:000018 | F4: 1 | G4: 33488.37 | I4: =IFERROR(__xludf.DUMMYFUNCTION("""COMPUTED_VALUE"""),"Atun 120g Peppersoup Spice (12x)") -> Atun 120g Peppersoup Spice (12x) | J4: =IFERROR(__xludf.DUMMYFUNCTION("""COMPUTED_VALUE"""),46030.0) -> 46030 | K4: =IFERROR(__xludf.DUMMYFUNCTION("""COMPUTED_VALUE"""),"Renees Supermarket, LEKKI CENTRAL MOSQUE") -> Renees Supermarket, LEKKI CENTRAL MOSQUE | L4: =IFERROR(__xludf.DUMMYFUNCTION("""COMPUTED_VALUE"""),"Sales") -> Sales | M4: =IFERROR(__xludf.DUMMYFUNCTION("""COMPUTED_VALUE"""),"DT:000077") -> DT:000077 | N4: =IFERROR(__xludf.DUMMYFUNCTION("""COMPUTED_VALUE"""),1.0) -> 1 | O4: =IFERROR(__xludf.DUMMYFUNCTION("""COMPUTED_VALUE"""),33488.37) -> 33488.37 | P4: =sumif(M:M,M4,O:O) -> 33488.37
A5: Atun 120g Peppersoup Spice (12x) | B5: 46030 | C5: Renees Supermarket, LEKKI CENTRAL MOSQUE | D5: Sales | E5: DT:000077 | F5: 1 | G5: 33488.37 | I5: =IFERROR(__xludf.DUMMYFUNCTION("""COMPUTED_VALUE"""),"Atun 120g Peppersoup Spice (12x)") -> Atun 120g Peppersoup Spice (12x) | J5: =IFERROR(__xludf.DUMMYFUNCTION("""COMPUTED_VALUE"""),46031.0) -> 46031 | K5: =IFERROR(__xludf.DUMMYFUNCTION("""COMPUTED_VALUE"""),"Jendol Supermarket, IPAJA") -> Jendol Supermarket, IPAJA | L5: =IFERROR(__xludf.DUMMYFUNCTION("""COMPUTED_VALUE"""),"Sales") -> Sales | M5: =IFERROR(__xludf.DUMMYFUNCTION("""COMPUTED_VALUE"""),"DT:000092") -> DT:000092 | N5: =IFERROR(__xludf.DUMMYFUNCTION("""COMPUTED_VALUE"""),0.5) -> 0.5 | O5: =IFERROR(__xludf.DUMMYFUNCTION("""COMPUTED_VALUE"""),16744.19) -> 16744.19 | P5: =sumif(M:M,M5,O:O) -> 16744.19
A6: Atun 120g Peppersoup Spice (12x) | B6: 46031 | C6: Jendol Supermarket, IPAJA | D6: Sales | E6: DT:000092 | F6: 0.5 | G6: 16744.19 | I6: =IFERROR(__xludf.DUMMYFUNCTION("""COMPUTED_VALUE"""),"Atun 120g Peppersoup Spice (12x)") -> Atun 120g Peppersoup Spice (12x) | J6: =IFERROR(__xludf.DUMMYFUNCTION("""COMPUTED_VALUE"""),46032.0) -> 46032 | K6: =IFERROR(__xludf.DUMMYFUNCTION("""COMPUTED_VALUE"""),"Am to Pm Supermarket, Martins Rd.") -> Am to Pm Supermarket, Martins Rd. | L6: =IFERROR(__xludf.DUMMYFUNCTION("""COMPUTED_VALUE"""),"Sales") -> Sales | M6: =IFERROR(__xludf.DUMMYFUNCTION("""COMPUTED_VALUE"""),"DT:000104") -> DT:000104 | N6: =IFERROR(__xludf.DUMMYFUNCTION("""COMPUTED_VALUE"""),1.0) -> 1 | O6: =IFERROR(__xludf.DUMMYFUNCTION("""COMPUTED_VALUE"""),33488.37) -> 33488.37 | P6: =sumif(M:M,M6,O:O) -> 61395.35
A7: Atun 120g Peppersoup Spice (12x) | B7: 46032 | C7: Am to Pm Supermarket, Martins Rd. | D7: Sales | E7: DT:000104 | F7: 1 | G7: 33488.37 | I7: =IFERROR(__xludf.DUMMYFUNCTION("""COMPUTED_VALUE"""),"Atun 120g Peppersoup Spice (12x)") -> Atun 120g Peppersoup Spice (12x) | J7: =IFERROR(__xludf.DUMMYFUNCTION("""COMPUTED_VALUE"""),46032.0) -> 46032 | K7: =IFERROR(__xludf.DUMMYFUNCTION("""COMPUTED_VALUE"""),"Jendol Supermarket, IBAFO") -> Jendol Supermarket, IBAFO | L7: =IFERROR(__xludf.DUMMYFUNCTION("""COMPUTED_VALUE"""),"Sales") -> Sales | M7: =IFERROR(__xludf.DUMMYFUNCTION("""COMPUTED_VALUE"""),"DT:000115") -> DT:000115 | N7: =IFERROR(__xludf.DUMMYFUNCTION("""COMPUTED_VALUE"""),2.0) -> 2 | O7: =IFERROR(__xludf.DUMMYFUNCTION("""COMPUTED_VALUE"""),66976.74) -> 66976.74 | P7: =sumif(M:M,M7,O:O) -> 66976.74
A8: Atun 120g Peppersoup Spice (12x) | B8: 46032 | C8: Jendol Supermarket, IBAFO | D8: Sales | E8: DT:000115 | F8: 2 | G8: 66976.74 | I8: =IFERROR(__xludf.DUMMYFUNCTION("""COMPUTED_VALUE"""),"Atun 120g Peppersoup Spice (12x)") -> Atun 120g Peppersoup Spice (12x) | J8: =IFERROR(__xludf.DUMMYFUNCTION("""COMPUTED_VALUE"""),46035.0) -> 46035 | K8: =IFERROR(__xludf.DUMMYFUNCTION("""COMPUTED_VALUE"""),"Jendol Supermarket, AJAH") -> Jendol Supermarket, AJAH | L8: =IFERROR(__xludf.DUMMYFUNCTION("""COMPUTED_VALUE"""),"Sales") -> Sales | M8: =IFERROR(__xludf.DUMMYFUNCTION("""COMPUTED_VALUE"""),"DT:000130") -> DT:000130 | N8: =IFERROR(__xludf.DUMMYFUNCTION("""COMPUTED_VALUE"""),1.0) -> 1 | O8: =IFERROR(__xludf.DUMMYFUNCTION("""COMPUTED_VALUE"""),33488.37) -> 33488.37 | P8: =sumif(M:M,M8,O:O) -> 33488.37
A9: Atun 120g Peppersoup Spice (12x) | B9: 46035 | C9: Jendol Supermarket, AJAH | D9: Sales | E9: DT:000130 | F9: 1 | G9: 33488.37 | I9: =IFERROR(__xludf.DUMMYFUNCTION("""COMPUTED_VALUE"""),"Atun 120g Peppersoup Spice (12x)") -> Atun 120g Peppersoup Spice (12x) | J9: =IFERROR(__xludf.DUMMYFUNCTION("""COMPUTED_VALUE"""),46035.0) -> 46035 | K9: =IFERROR(__xludf.DUMMYFUNCTION("""COMPUTED_VALUE"""),"Skymart Supermarket, SANGOTEDO") -> Skymart Supermarket, SANGOTEDO | L9: =IFERROR(__xludf.DUMMYFUNCTION("""COMPUTED_VALUE"""),"Sales") -> Sales | M9: =IFERROR(__xludf.DUMMYFUNCTION("""COMPUTED_VALUE"""),"DT:000133") -> DT:000133 | N9: =IFERROR(__xludf.DUMMYFUNCTION("""COMPUTED_VALUE"""),1.0) -> 1 | O9: =IFERROR(__xludf.DUMMYFUNCTION("""COMPUTED_VALUE"""),33488.37) -> 33488.37 | P9: =sumif(M:M,M9,O:O) -> 61395.35
A10: Atun 120g Peppersoup Spice (12x) | B10: 46035 | C10: Skymart Supermarket, SANGOTEDO | D10: Sales | E10: DT:000133 | F10: 1 | G10: 33488.37 | I10: =IFERROR(__xludf.DUMMYFUNCTION("""COMPUTED_VALUE"""),"Atun 120g Peppersoup Spice (12x)") -> Atun 120g Peppersoup Spice (12x) | J10: =IFERROR(__xludf.DUMMYFUNCTION("""COMPUTED_VALUE"""),46036.0) -> 46036 | K10: =IFERROR(__xludf.DUMMYFUNCTION("""COMPUTED_VALUE"""),"Jendol Supermarket, IJEDE") -> Jendol Supermarket, IJEDE | L10: =IFERROR(__xludf.DUMMYFUNCTION("""COMPUTED_VALUE"""),"Sales") -> Sales | M10: =IFERROR(__xludf.DUMMYFUNCTION("""COMPUTED_VALUE"""),"DT:000162") -> DT:000162 | N10: =IFERROR(__xludf.DUMMYFUNCTION("""COMPUTED_VALUE"""),1.0) -> 1 | O10: =IFERROR(__xludf.DUMMYFUNCTION("""COMPUTED_VALUE"""),33488.37) -> 33488.37 | P10: =sumif(M:M,M10,O:O) -> 33488.37
A11: Atun 120g Peppersoup Spice (12x) | B11: 46036 | C11: Jendol Supermarket, IJEDE | D11: Sales | E11: DT:000162 | F11: 1 | G11: 33488.37 | I11: =IFERROR(__xludf.DUMMYFUNCTION("""COMPUTED_VALUE"""),"Atun 120g Peppersoup Spice (12x)") -> Atun 120g Peppersoup Spice (12x) | J11: =IFERROR(__xludf.DUMMYFUNCTION("""COMPUTED_VALUE"""),46036.0) -> 46036 | K11: =IFERROR(__xludf.DUMMYFUNCTION("""COMPUTED_VALUE"""),"Jendol supermarket, OJUORE") -> Jendol supermarket, OJUORE | L11: =IFERROR(__xludf.DUMMYFUNCTION("""COMPUTED_VALUE"""),"Sales") -> Sales | M11: =IFERROR(__xludf.DUMMYFUNCTION("""COMPUTED_VALUE"""),"DT:000166") -> DT:000166 | N11: =IFERROR(__xludf.DUMMYFUNCTION("""COMPUTED_VALUE"""),0.5) -> 0.5 | O11: =IFERROR(__xludf.DUMMYFUNCTION("""COMPUTED_VALUE"""),16744.19) -> 16744.19 | P11: =sumif(M:M,M11,O:O) -> 16744.19
A12: Atun 120g Peppersoup Spice (12x) | B12: 46036 | C12: Jendol supermarket, OJUORE | D12: Sales | E12: DT:000166 | F12: 0.5 | G12: 16744.19 | I12: =IFERROR(__xludf.DUMMYFUNCTION("""COMPUTED_VALUE"""),"Atun 120g Peppersoup Spice (12x)") -> Atun 120g Peppersoup Spice (12x) | J12: =IFERROR(__xludf.DUMMYFUNCTION("""COMPUTED_VALUE"""),46038.0) -> 46038 | K12: =IFERROR(__xludf.DUMMYFUNCTION("""COMPUTED_VALUE"""),"Jendol Supermarket, ISHERI (Rg.11)") -> Jendol Supermarket, ISHERI (Rg.11) | L12: =IFERROR(__xludf.DUMMYFUNCTION("""COMPUTED_VALUE"""),"Sales") -> Sales | M12: =IFERROR(__xludf.DUMMYFUNCTION("""COMPUTED_VALUE"""),"DT:000207") -> DT:000207 | N12: =IFERROR(__xludf.DUMMYFUNCTION("""COMPUTED_VALUE"""),1.0) -> 1 | O12: =IFERROR(__xludf.DUMMYFUNCTION("""COMPUTED_VALUE"""),33488.37) -> 33488.37 | P12: =sumif(M:M,M12,O:O) -> 33488.37
A13: Atun 120g Peppersoup Spice (12x) | B13: 46038 | C13: Jendol Supermarket, ISHERI (Rg.11) | D13: Sales | E13: DT:000207 | F13: 1 | G13: 33488.37 | I13: =IFERROR(__xludf.DUMMYFUNCTION("""COMPUTED_VALUE"""),"Atun 120g Peppersoup Spice (12x)") -> Atun 120g Peppersoup Spice (12x) | J13: =IFERROR(__xludf.DUMMYFUNCTION("""COMPUTED_VALUE"""),46038.0) -> 46038 | K13: =IFERROR(__xludf.DUMMYFUNCTION("""COMPUTED_VALUE"""),"Jendol Supermarket, IPAJA") -> Jendol Supermarket, IPAJA | L13: =IFERROR(__xludf.DUMMYFUNCTION("""COMPUTED_VALUE"""),"Sales") -> Sales | M13: =IFERROR(__xludf.DUMMYFUNCTION("""COMPUTED_VALUE"""),"DT:000217") -> DT:000217 | N13: =IFERROR(__xludf.DUMMYFUNCTION("""COMPUTED_VALUE"""),1.0) -> 1 | O13: =IFERROR(__xludf.DUMMYFUNCTION("""COMPUTED_VALUE"""),33488.37) -> 33488.37 | P13: =sumif(M:M,M13,O:O) -> 33488.37
A14: Atun 120g Peppersoup Spice (12x) | B14: 46038 | C14: Jendol Supermarket, IPAJA | D14: Sales | E14: DT:000217 | F14: 1 | G14: 33488.37 | I14: =IFERROR(__xludf.DUMMYFUNCTION("""COMPUTED_VALUE"""),"Atun 120g Peppersoup Spice (12x)") -> Atun 120g Peppersoup Spice (12x) | J14: =IFERROR(__xludf.DUMMYFUNCTION("""COMPUTED_VALUE"""),46042.0) -> 46042 | K14: =IFERROR(__xludf.DUMMYFUNCTION("""COMPUTED_VALUE"""),"Double Sam Supermarket, 22 IKD AWOLOWO ROAD") -> Double Sam Supermarket, 22 IKD AWOLOWO ROAD | L14: =IFERROR(__xludf.DUMMYFUNCTION("""COMPUTED_VALUE"""),"Sales") -> Sales | M14: =IFERROR(__xludf.DUMMYFUNCTION("""COMPUTED_VALUE"""),"DT:000279") -> DT:000279 | N14: =IFERROR(__xludf.DUMMYFUNCTION("""COMPUTED_VALUE"""),0.5) -> 0.5 | O14: =IFERROR(__xludf.DUMMYFUNCTION("""COMPUTED_VALUE"""),18000.0) -> 18000 | P14: =sumif(M:M,M14,O:O) -> 18000
A15: Atun 120g Peppersoup Spice (12x) | B15: 46042 | C15: Double Sam Supermarket, 22 IKD AWOLOWO ROAD | D15: Sales | E15: DT:000279 | F15: 0.5 | G15: 18000 | I15: =IFERROR(__xludf.DUMMYFUNCTION("""COMPUTED_VALUE"""),"Atun 120g Peppersoup Spice (12x)") -> Atun 120g Peppersoup Spice (12x) | J15: =IFERROR(__xludf.DUMMYFUNCTION("""COMPUTED_VALUE"""),46046.0) -> 46046 | K15: =IFERROR(__xludf.DUMMYFUNCTION("""COMPUTED_VALUE"""),"Jendol Supermarket, ONIBUKUN") -> Jendol Supermarket, ONIBUKUN | L15: =IFERROR(__xludf.DUMMYFUNCTION("""COMPUTED_VALUE"""),"Sales") -> Sales | M15: =IFERROR(__xludf.DUMMYFUNCTION("""COMPUTED_VALUE"""),"DT:000374") -> DT:000374 | N15: =IFERROR(__xludf.DUMMYFUNCTION("""COMPUTED_VALUE"""),0.5) -> 0.5 | O15: =IFERROR(__xludf.DUMMYFUNCTION("""COMPUTED_VALUE"""),16744.19) -> 16744.19 | P15: =sumif(M:M,M15,O:O) -> 16744.19
A16: Atun 120g Peppersoup Spice (12x) | B16: 46046 | C16: Jendol Supermarket, ONIBUKUN | D16: Sales | E16: DT:000374 | F16: 0.5 | G16: 16744.19 | I16: =IFERROR(__xludf.DUMMYFUNCTION("""COMPUTED_VALUE"""),"Atun 120g Peppersoup Spice (12x)") -> Atun 120g Peppersoup Spice (12x) | J16: =IFERROR(__xludf.DUMMYFUNCTION("""COMPUTED_VALUE"""),46051.0) -> 46051 | K16: =IFERROR(__xludf.DUMMYFUNCTION("""COMPUTED_VALUE"""),"Jendol Supermarket, ALAKUKO") -> Jendol Supermarket, ALAKUKO | L16: =IFERROR(__xludf.DUMMYFUNCTION("""COMPUTED_VALUE"""),"Sales") -> Sales | M16: =IFERROR(__xludf.DUMMYFUNCTION("""COMPUTED_VALUE"""),"DT:000509") -> DT:000509 | N16: =IFERROR(__xludf.DUMMYFUNCTION("""COMPUTED_VALUE"""),1.0) -> 1 | O16: =IFERROR(__xludf.DUMMYFUNCTION("""COMPUTED_VALUE"""),33488.37) -> 33488.37 | P16: =sumif(M:M,M16,O:O) -> 33488.37
A17: Atun 120g Peppersoup Spice (12x) | B17: 46051 | C17: Jendol Supermarket, ALAKUKO | D17: Sales | E17: DT:000509 | F17: 1 | G17: 33488.37 | I17: =IFERROR(__xludf.DUMMYFUNCTION("""COMPUTED_VALUE"""),"Atun 120g Peppersoup Spice (12x)") -> Atun 120g Peppersoup Spice (12x) | J17: =IFERROR(__xludf.DUMMYFUNCTION("""COMPUTED_VALUE"""),46052.0) -> 46052 | K17: =IFERROR(__xludf.DUMMYFUNCTION("""COMPUTED_VALUE"""),"Jendol Supermarket, OJODU") -> Jendol Supermarket, OJODU | L17: =IFERROR(__xludf.DUMMYFUNCTION("""COMPUTED_VALUE"""),"Sales") -> Sales | M17: =IFERROR(__xludf.DUMMYFUNCTION("""COMPUTED_VALUE"""),"DT:000536") -> DT:000536 | N17: =IFERROR(__xludf.DUMMYFUNCTION("""COMPUTED_VALUE"""),1.0) -> 1 | O17: =IFERROR(__xludf.DUMMYFUNCTION("""COMPUTED_VALUE"""),33488.37) -> 33488.37 | P17: =sumif(M:M,M17,O:O) -> 33488.37
A18: Atun 120g Peppersoup Spice (12x) | B18: 46052 | C18: Jendol Supermarket, OJODU | D18: Sales | E18: DT:000536 | F18: 1 | G18: 33488.37 | I18: =IFERROR(__xludf.DUMMYFUNCTION("""COMPUTED_VALUE"""),"Atun 1.5litre Palm Oil (6x)") -> Atun 1.5litre Palm Oil (6x) | J18: =IFERROR(__xludf.DUMMYFUNCTION("""COMPUTED_VALUE"""),46032.0) -> 46032 | K18: =IFERROR(__xludf.DUMMYFUNCTION("""COMPUTED_VALUE"""),"Am to Pm Supermarket, Martins Rd.") -> Am to Pm Supermarket, Martins Rd. | L18: =IFERROR(__xludf.DUMMYFUNCTION("""COMPUTED_VALUE"""),"Sales") -> Sales | M18: =IFERROR(__xludf.DUMMYFUNCTION("""COMPUTED_VALUE"""),"DT:000104") -> DT:000104 | N18: =IFERROR(__xludf.DUMMYFUNCTION("""COMPUTED_VALUE"""),1.0) -> 1 | O18: =IFERROR(__xludf.DUMMYFUNCTION("""COMPUTED_VALUE"""),27906.98) -> 27906.98 | P18: =sumif(M:M,M18,O:O) -> 61395.35
A19: Atun 1.5litre Palm Oil (6x) | B19: 46032 | C19: Am to Pm Supermarket, Martins Rd. | D19: Sales | E19: DT:000104 | F19: 1 | G19: 27906.98 | I19: =IFERROR(__xludf.DUMMYFUNCTION("""COMPUTED_VALUE"""),"Atun 1.5litre Palm Oil (6x)") -> Atun 1.5litre Palm Oil (6x) | J19: =IFERROR(__xludf.DUMMYFUNCTION("""COMPUTED_VALUE"""),46035.0) -> 46035 | K19: =IFERROR(__xludf.DUMMYFUNCTION("""COMPUTED_VALUE"""),"Skymart Supermarket, SANGOTEDO") -> Skymart Supermarket, SANGOTEDO | L19: =IFERROR(__xludf.DUMMYFUNCTION("""COMPUTED_VALUE"""),"Sales") -> Sales | M19: =IFERROR(__xludf.DUMMYFUNCTION("""COMPUTED_VALUE"""),"DT:000133") -> DT:000133 | N19: =IFERROR(__xludf.DUMMYFUNCTION("""COMPUTED_VALUE"""),1.0) -> 1 | O19: =IFERROR(__xludf.DUMMYFUNCTION("""COMPUTED_VALUE"""),27906.98) -> 27906.98 | P19: =sumif(M:M,M19,O:O) -> 61395.35
A20: Atun 1.5litre Palm Oil (6x) | B20: 46035 | C20: Skymart Supermarket, SANGOTEDO | D20: Sales | E20: DT:000133 | F20: 1 | G20: 27906.98 | I20: =IFERROR(__xludf.DUMMYFUNCTION("""COMPUTED_VALUE"""),"Atun 1.5litre Palm Oil (6x)") -> Atun 1.5litre Palm Oil (6x) | J20: =IFERROR(__xludf.DUMMYFUNCTION("""COMPUTED_VALUE"""),46038.0) -> 46038 | K20: =IFERROR(__xludf.DUMMYFUNCTION("""COMPUTED_VALUE"""),"Prestige Superstore, IPAJA") -> Prestige Superstore, IPAJA | L20: =IFERROR(__xludf.DUMMYFUNCTION("""COMPUTED_VALUE"""),"Sales") -> Sales | M20: =IFERROR(__xludf.DUMMYFUNCTION("""COMPUTED_VALUE"""),"DT:000224") -> DT:000224 | N20: =IFERROR(__xludf.DUMMYFUNCTION("""COMPUTED_VALUE"""),1.0) -> 1 | O20: =IFERROR(__xludf.DUMMYFUNCTION("""COMPUTED_VALUE"""),27906.98) -> 27906.98 | P20: =sumif(M:M,M20,O:O) -> 27906.98
A21: Atun 1.5litre Palm Oil (6x) | B21: 46038 | C21: Prestige Superstore, IPAJA | D21: Sales | E21: DT:000224 | F21: 1 | G21: 27906.98 | I21: =IFERROR(__xludf.DUMMYFUNCTION("""COMPUTED_VALUE"""),"Atun 1.5litre Palm Oil (6x)") -> Atun 1.5litre Palm Oil (6x) | J21: =IFERROR(__xludf.DUMMYFUNCTION("""COMPUTED_VALUE"""),46039.0) -> 46039 | K21: =IFERROR(__xludf.DUMMYFUNCTION("""COMPUTED_VALUE"""),"Excel Plus Supermarket, Orchid Rd.") -> Excel Plus Supermarket, Orchid Rd. | L21: =IFERROR(__xludf.DUMMYFUNCTION("""COMPUTED_VALUE"""),"Sales") -> Sales | M21: =IFERROR(__xludf.DUMMYFUNCTION("""COMPUTED_VALUE"""),"DT:000234") -> DT:000234 | N21: =IFERROR(__xludf.DUMMYFUNCTION("""COMPUTED_VALUE"""),1.0) -> 1 | O21: =IFERROR(__xludf.DUMMYFUNCTION("""COMPUTED_VALUE"""),27906.98) -> 27906.98 | P21: =sumif(M:M,M21,O:O) -> 50232.56
A22: Atun 1.5litre Palm Oil (6x) | B22: 46039 | C22: Excel Plus Supermarket, Orchid Rd. | D22: Sales | E22: DT:000234 | F22: 1 | G22: 27906.98 | I22: =IFERROR(__xludf.DUMMYFUNCTION("""COMPUTED_VALUE"""),"Atun 3kg Yellow Garri (4x)") -> Atun 3kg Yellow Garri (4x) | J22: =IFERROR(__xludf.DUMMYFUNCTION("""COMPUTED_VALUE"""),46039.0) -> 46039 | K22: =IFERROR(__xludf.DUMMYFUNCTION("""COMPUTED_VALUE"""),"Excel Plus Supermarket, Orchid Rd.") -> Excel Plus Supermarket, Orchid Rd. | L22: =IFERROR(__xludf.DUMMYFUNCTION("""COMPUTED_VALUE"""),"Sales") -> Sales | M22: =IFERROR(__xludf.DUMMYFUNCTION("""COMPUTED_VALUE"""),"DT:000234") -> DT:000234 | N22: =IFERROR(__xludf.DUMMYFUNCTION("""COMPUTED_VALUE"""),1.0) -> 1 | O22: =IFERROR(__xludf.DUMMYFUNCTION("""COMPUTED_VALUE"""),22325.58) -> 22325.58 | P22: =sumif(M:M,M22,O:O) -> 50232.56
A23: Atun 3kg Yellow Garri (4x) | B23: 46039 | C23: Excel Plus Supermarket, Orchid Rd. | D23: Sales | E23: DT:000234 | F23: 1 | G23: 22325.58 | P23: =sumif(M:M,M23,O:O) -> 0
P24: =sumif(M:M,M24,O:O) -> 0
P25: =sumif(M:M,M25,O:O) -> 0
P26: =sumif(M:M,M26,O:O) -> 0
P27: =sumif(M:M,M27,O:O) -> 0
P28: =sumif(M:M,M28,O:O) -> 0
P29: =sumif(M:M,M29,O:O) -> 0
P30: =sumif(M:M,M30,O:O) -> 0
P31: =sumif(M:M,M31,O:O) -> 0
P32: =sumif(M:M,M32,O:O) -> 0
P33: =sumif(M:M,M33,O:O) -> 0
P34: =sumif(M:M,M34,O:O) -> 0
P35: =sumif(M:M,M35,O:O) -> 0
... P72: =sumif(M:M,M72,O:O) -> 0

Sheet Payment Advice
F2: =SUM(D:D) -> 604046.51

Sheet Dala Sales & Deliveries
H1: Total Invoices Delivered | I1: =countifs(B:B,"<>",F:F,"<>")-1 -> 17 | K1: Sku Performance | L1: Units | M1: Value
H2: Unique Locations Supplied | I2: {=(COUNTA(UNIQUE(C:C))-1)} -> 16 | K2: ='Internal Summary'!B41 -> Atun 1.5litre Palm Oil (6x) | L2: =sumif(D:D,K2,E:E) -> 4 | M2: =sumif(D:D,K2,F:F) -> 111627.92
H3: Total Value of orders | I3: =sum(F:F) -> 604046.51 | K3: ='Internal Summary'!B42 -> Atun 120g Peppersoup Spice (12x) | L3: =sumif(D:D,K3,E:E) -> 14 | M3: =sumif(D:D,K3,F:F) -> 470093.01
K4: ='Internal Summary'!B43 -> Atun 3kg Yellow Garri (4x) | L4: =sumif(D:D,K4,E:E) -> 1 | M4: =sumif(D:D,K4,F:F) -> 22325.58
K5: ='Internal Summary'!B44 | L5: =sumif(D:D,K5,E:E) -> 0 | M5: =sumif(D:D,K5,F:F) -> 0
K6: ='Internal Summary'!B45 | L6: =sumif(D:D,K6,E:E) -> 0 | M6: =sumif(D:D,K6,F:F) -> 0
K7: ='Internal Summary'!B46 | L7: =sumif(D:D,K7,E:E) -> 0 | M7: =sumif(D:D,K7,F:F) -> 0
K8: ='Internal Summary'!B47 | L8: =sumif(D:D,K8,E:E) -> 0 | M8: =sumif(D:D,K8,F:F) -> 0
K9: ='Internal Summary'!B48 | L9: =sumif(D:D,K9,E:E) -> 0 | M9: =sumif(D:D,K9,F:F) -> 0
K10: ='Internal Summary'!B49 | L10: =sumif(D:D,K10,E:E) -> 0 | M10: =sumif(D:D,K10,F:F) -> 0
K11: ='Internal Summary'!B50 | L11: =sumif(D:D,K11,E:E) -> 0 | M11: =sumif(D:D,K11,F:F) -> 0
K12: ='Internal Summary'!B51 | L12: =sumif(D:D,K12,E:E) -> 0 | M12: =sumif(D:D,K12,F:F) -> 0
K13: ='Internal Summary'!B52 | L13: =sumif(D:D,K13,E:E) -> 0 | M13: =sumif(D:D,K13,F:F) -> 0

Sheet External Delivery Fulfillment
H1: Total Invoices Delivered | I1: =countifs(B:B,"<>",F:F,"<>")-1 -> 0 | K1: Sku Performance | L1: Units | M1: Value
H2: Unique Locations Supplied | I2: {=(COUNTA(UNIQUE(C:C))-1)} -> 0 | K2: ='Internal Summary'!B41 -> Atun 1.5litre Palm Oil (6x) | L2: =sumif(D:D,K2,E:E) -> 0 | M2: =sumif(D:D,K2,F:F) -> 0
H3: Total Value of orders | I3: =sum(F:F) -> 0 | K3: ='Internal Summary'!B42 -> Atun 120g Peppersoup Spice (12x) | L3: =sumif(D:D,K3,E:E) -> 0 | M3: =sumif(D:D,K3,F:F) -> 0
K4: ='Internal Summary'!B43 -> Atun 3kg Yellow Garri (4x) | L4: =sumif(D:D,K4,E:E) -> 0 | M4: =sumif(D:D,K4,F:F) -> 0
K5: ='Internal Summary'!B44 | L5: =sumif(D:D,K5,E:E) -> 0 | M5: =sumif(D:D,K5,F:F) -> 0
K6: ='Internal Summary'!B45 | L6: =sumif(D:D,K6,E:E) -> 0 | M6: =sumif(D:D,K6,F:F) -> 0
K7: ='Internal Summary'!B46 | L7: =sumif(D:D,K7,E:E) -> 0 | M7: =sumif(D:D,K7,F:F) -> 0
K8: ='Internal Summary'!B47 | L8: =sumif(D:D,K8,E:E) -> 0 | M8: =sumif(D:D,K8,F:F) -> 0
K9: ='Internal Summary'!B48 | L9: =sumif(D:D,K9,E:E) -> 0 | M9: =sumif(D:D,K9,F:F) -> 0
K10: ='Internal Summary'!B49 | L10: =sumif(D:D,K10,E:E) -> 0 | M10: =sumif(D:D,K10,F:F) -> 0
K11: ='Internal Summary'!B50 | L11: =sumif(D:D,K11,E:E) -> 0 | M11: =sumif(D:D,K11,F:F) -> 0
K12: ='Internal Summary'!B51 | L12: =sumif(D:D,K12,E:E) -> 0 | M12: =sumif(D:D,K12,F:F) -> 0
K13: ='Internal Summary'!B52 | L13: =sumif(D:D,K13,E:E) -> 0 | M13: =sumif(D:D,K13,F:F) -> 0

Sheet Forwarding From Client
H1: Total Invoices Delivered | I1: =countifs(B:B,"<>",F:F,"<>")-1 -> 0 | K1: Sku Performance | L1: Units | M1: Value
H2: Unique Locations Supplied | I2: {=(COUNTA(UNIQUE(C:C))-1)} -> 0 | K2: ='Internal Summary'!B41 -> Atun 1.5litre Palm Oil (6x) | L2: =sumif(D:D,K2,E:E) -> 0 | M2: =sumif(D:D,K2,F:F) -> 0
H3: Total Value of orders | I3: =sum(F:F) -> 0 | K3: ='Internal Summary'!B42 -> Atun 120g Peppersoup Spice (12x) | L3: =sumif(D:D,K3,E:E) -> 0 | M3: =sumif(D:D,K3,F:F) -> 0
K4: ='Internal Summary'!B43 -> Atun 3kg Yellow Garri (4x) | L4: =sumif(D:D,K4,E:E) -> 0 | M4: =sumif(D:D,K4,F:F) -> 0
K5: ='Internal Summary'!B44 | L5: =sumif(D:D,K5,E:E) -> 0 | M5: =sumif(D:D,K5,F:F) -> 0
K6: ='Internal Summary'!B45 | L6: =sumif(D:D,K6,E:E) -> 0 | M6: =sumif(D:D,K6,F:F) -> 0
K7: ='Internal Summary'!B46 | L7: =sumif(D:D,K7,E:E) -> 0 | M7: =sumif(D:D,K7,F:F) -> 0
K8: ='Internal Summary'!B47 | L8: =sumif(D:D,K8,E:E) -> 0 | M8: =sumif(D:D,K8,F:F) -> 0
K9: ='Internal Summary'!B48 | L9: =sumif(D:D,K9,E:E) -> 0 | M9: =sumif(D:D,K9,F:F) -> 0
K10: ='Internal Summary'!B49 | L10: =sumif(D:D,K10,E:E) -> 0 | M10: =sumif(D:D,K10,F:F) -> 0
K11: ='Internal Summary'!B50 | L11: =sumif(D:D,K11,E:E) -> 0 | M11: =sumif(D:D,K11,F:F) -> 0
K12: ='Internal Summary'!B51 | L12: =sumif(D:D,K12,E:E) -> 0 | M12: =sumif(D:D,K12,F:F) -> 0
K13: ='Internal Summary'!B52 | L13: =sumif(D:D,K13,E:E) -> 0 | M13: =sumif(D:D,K13,F:F) -> 0

Sheet Dala Restocking
H1: Total Invoices Delivered | I1: =countifs(B:B,"<>",F:F,"<>")-1 -> 1 | K1: Sku Performance | L1: Units
H2: Unique Locations Supplied | I2: {=(COUNTA(UNIQUE(C:C,,0))-1)} -> 1 | K2: ='Internal Summary'!B41 -> Atun 1.5litre Palm Oil (6x) | L2: =sumif(D:D,K2,E:E) -> 0
H3: Total Value of orders | I3: =sum(F:F) -> 600111.59 | K3: ='Internal Summary'!B42 -> Atun 120g Peppersoup Spice (12x) | L3: =sumif(D:D,K3,E:E) -> 17.92
K4: ='Internal Summary'!B43 -> Atun 3kg Yellow Garri (4x) | L4: =sumif(D:D,K4,E:E) -> 0
K5: ='Internal Summary'!B44 | L5: =sumif(D:D,K5,E:E) -> 0
K6: ='Internal Summary'!B45 | L6: =sumif(D:D,K6,E:E) -> 0
K7: ='Internal Summary'!B46 | L7: =sumif(D:D,K7,E:E) -> 0
K8: ='Internal Summary'!B47 | L8: =sumif(D:D,K8,E:E) -> 0
K9: ='Internal Summary'!B48 | L9: =sumif(D:D,K9,E:E) -> 0
K10: ='Internal Summary'!B49 | L10: =sumif(D:D,K10,E:E) -> 0
K11: ='Internal Summary'!B50 | L11: =sumif(D:D,K11,E:E) -> 0
K12: ='Internal Summary'!B51 | L12: =sumif(D:D,K12,E:E) -> 0
K13: ='Internal Summary'!B52 | L13: =sumif(D:D,K13,E:E) -> 0

Sheet Client Restocking
H1: Total Invoices Delivered | I1: =countifs(B:B,"<>",F:F,"<>")-1 -> 0 | K1: Sku Performance | L1: Units
H2: Unique Locations Supplied | I2: {=(COUNTA(UNIQUE(C:C,,0))-1)} -> 0 | K2: ='Internal Summary'!B41 -> Atun 1.5litre Palm Oil (6x) | L2: =sumif(D:D,K2,E:E) -> 0
H3: Total Value of orders | I3: =sum(F:F) -> 0 | K3: ='Internal Summary'!B42 -> Atun 120g Peppersoup Spice (12x) | L3: =sumif(D:D,K3,E:E) -> 0
K4: ='Internal Summary'!B43 -> Atun 3kg Yellow Garri (4x) | L4: =sumif(D:D,K4,E:E) -> 0
K5: ='Internal Summary'!B44 | L5: =sumif(D:D,K5,E:E) -> 0
K6: ='Internal Summary'!B45 | L6: =sumif(D:D,K6,E:E) -> 0
K7: ='Internal Summary'!B46 | L7: =sumif(D:D,K7,E:E) -> 0
K8: ='Internal Summary'!B47 | L8: =sumif(D:D,K8,E:E) -> 0
K9: ='Internal Summary'!B48 | L9: =sumif(D:D,K9,E:E) -> 0
K10: ='Internal Summary'!B49 | L10: =sumif(D:D,K10,E:E) -> 0
K11: ='Internal Summary'!B50 | L11: =sumif(D:D,K11,E:E) -> 0
K12: ='Internal Summary'!B51 | L12: =sumif(D:D,K12,E:E) -> 0
K13: ='Internal Summary'!B52 | L13: =sumif(D:D,K13,E:E) -> 0

Sheet Internal Summary
B1: Description | C1: Units | D1: measurements | E1: total
A2: SALES | B2: Total Invoices Delivered | E2: ='Dala Sales & Deliveries'!I1+'External Delivery Fulfillment'!I1 -> 17
B3: Unique Locations Delivered To | E3: ='Raw Data'!AW2 -> 16
B4: Value of Dala Deliveries | E4: ='Dala Sales & Deliveries'!I3 -> 604046.51
B5: Value of External Deliveries | E5: ='External Delivery Fulfillment'!I3 -> 0
B6: VAT on sales | E6: =E4*1.075-E4 -> 45303.488
B7: Total Value of Deliveries | E7: =sum(E4:E6) -> 649350
A8: Remittance & Deductions | B8: Total Remitted to Partner
B9: Collection Fees | C9: 0.22 | E9: =E8*(C9+100%)-E8 -> 0
A10: Invoice Value Due | B10: Outstanding Paymets For Sales | E10: =E7-E8-E9 -> 649350
A11: Debts | B11: Unpaid Subscription | E11: =C11*D11 -> 0
B12: Collection Fees | E12: =E10*C9 -> 142857
B13: Delivery Fees | E13: =C27 -> 39480
B14: Pick up Delivery Fees | D14: Table 1 | E14: =C23 -> 26880
B15: Reimbursements Due To DALA | E15: 0
B16: Retailer Deductions | E16: =C31 -> 0
B17: Total Deductions | E17: =sum(E11:E16) -> 209217
A18: Remmittance Due | B18: Total Balance to Remitt | E18: =E10-E17+C37 -> 440133
A21: Inventory and Operational Fees
B22: Dala Pickup for Warehouse | C22: =U70 -> 17.92
B23: Warehouse Delivery Fee | C23: =V70 -> 26880
B24: Forwarding to Retail | C24: =S70 -> 0
B25: Forwarding Delivery Fee | C25: =T70 -> 0
B26: Dala Sales | C26: =67 -> 67
B27: Dala Delivery Fees | C27: =P70 -> 39480
B28: Exteranl Deliveries | C28: =Q70 -> 0
B29: External Delivery Fees | C29: ='External Delivery Fulfillment'!I3*7% -> 0
B30: Product Defects and Expirey Issues | C30: =F70 -> 0
B31: Deductions From Retailer | C31: 0
B32: Samples used | C32: =I70 -> 0
B33: Produce Replacements | C33: 0
B34: Expected Closing Inventory | C34: =L70 -> 36.5
B35: Physical Stock count | C35: =K70 -> 36.5
B36: Inventory Shortages | C36: 0
B37: Inventory Shortage Costs | C37: 0
B40: SKUs | C40: Retail Value | D40: Inbound Delivery Fee | E40: Outbound Delivery Fee | F40: Defects/Expirey | G40: Deductions | H40: Opening Inventory | I40: Samples Used | J40: Product Replacements | K40: Physical Closing Stock Count | L40: Expected Closing Inventory | M40: Inventory Shortages | N40: Shortages Costs | O40: Dala Deliveries | P40: Retail Sales Fee | Q40: External Delivery | R40: External Delivery Fee | S40: Forwarding from Client | T40: Forwarding Delivery Fee | U40: Dala Restocking | V40: Dala Restocking Fee | W40: Client Restocking
B41: Atun 1.5litre Palm Oil (6x) | C41: 30000 | D41: 2150 | E41: =C41*0.07 -> 2100 | G41: =F41*C41 -> 0 | K41: 13 | L41: 13 | M41: =K41-L41 -> 0 | N41: =M41*C41 -> 0 | O41: ='Dala Sales & Deliveries'!L2 -> 4 | P41: =O41*E41 -> 8400 | Q41: ='External Delivery Fulfillment'!L2 -> 0 | R41: =Q41*E41 -> 0 | S41: ='Forwarding From Client'!L2 -> 0 | T41: =S41*E41 -> 0 | U41: ='Dala Restocking'!L2 -> 0 | V41: =U41*D41 -> 0 | W41: ='Client Restocking'!L2 -> 0
B42: Atun 120g Peppersoup Spice (12x) | C42: 30000 | D42: 1500 | E42: =C42*0.07 -> 2100 | G42: =F42*C42 -> 0 | K42: 13 | L42: 13 | M42: =K42-L42 -> 0 | N42: =M42*C42 -> 0 | O42: ='Dala Sales & Deliveries'!L3 -> 14 | P42: =O42*E42 -> 29400 | Q42: ='External Delivery Fulfillment'!L3 -> 0 | R42: =Q42*E42 -> 0 | S42: ='Forwarding From Client'!L3 -> 0 | T42: =S42*E42 -> 0 | U42: ='Dala Restocking'!L3 -> 17.92 | V42: =U42*D42 -> 26880 | W42: ='Client Restocking'!L3 -> 0
B43: Atun 3kg Yellow Garri (4x) | C43: 24000 | D43: 1700 | E43: =C43*0.07 -> 1680 | G43: =F43*C43 -> 0 | K43: 10.5 | L43: 10.5 | M43: =K43-L43 -> 0 | N43: =M43*C43 -> 0 | O43: ='Dala Sales & Deliveries'!L4 -> 1 | P43: =O43*E43 -> 1680 | Q43: ='External Delivery Fulfillment'!L4 -> 0 | R43: =Q43*E43 -> 0 | S43: ='Forwarding From Client'!L4 -> 0 | T43: =S43*E43 -> 0 | U43: ='Dala Restocking'!L4 -> 0 | V43: =U43*D43 -> 0 | W43: ='Client Restocking'!L4 -> 0
G44: =F44*C44 -> 0 | L44: =H44+U44+W44-O44-Q44-I44-J44 -> 0 | M44: =K44-L44 -> 0 | N44: =M44*C44 -> 0 | O44: ='Dala Sales & Deliveries'!L5 -> 0 | P44: =O44*E44 -> 0 | Q44: ='External Delivery Fulfillment'!L5 -> 0 | R44: =Q44*E44 -> 0 | S44: ='Forwarding From Client'!L5 -> 0 | T44: =S44*E44 -> 0 | U44: ='Dala Restocking'!L5 -> 0 | V44: =U44*D44 -> 0 | W44: ='Client Restocking'!L5 -> 0
...
