Workbook

Sheet Raw Data
A1: Exported from Tally | I1: Dala Sales & Deliveries | R1: External Deliveries | Z1: Forwarding From Client | AH1: Client Restock | AP1: Dala Restock | AX1: Unique Locations
A2: item name | B2: Date | C2: Particulars | D2: Vch Type | E2: Vch No. | F2: Quantity | G2: Value | I2: item name | J2: Date | K2: Particulars | L2: Vch Type | M2: Vch No. | N2: Quantity | O2: Value | P2: Total Value | R2: item name | S2: Date | T2: Particulars | U2: Vch Type | V2: Vch No. | W2: Quantity | X2: Value | Z2: item name | AA2: Date | AB2: Particulars | AC2: Vch Type | AD2: Vch No. | AE2: Quantity | AF2: Value | AH2: item name | AI2: Date | AJ2: Particulars | AK2: Vch Type | AL2: Vch No. | AM2: Quantity | AN2: Value | AP2: item name | AQ2: Date | AR2: Particulars | AS2: Vch Type | AT2: Vch No. | AU2: Quantity | AV2: Value | AX2: {=counta(unique(C:C))-2} -> 15
A3: 350ml Bugo Strawberry Yoghurt (12x) | B3: 1/13/2026 | C3: Prestige Superstore, IYANA ISHASHI | D3: Sales | E3: DT:000142 | F3: 0.5 | G3: 12000 | I3: =IFERROR(__xludf.DUMMYFUNCTION("IFERROR( FILTER($A$3:$G1844, LEN($A$3:$A1844), LOWER(TRIM($D$3:$D1844))=""sales""), )"),"350ml Bugo Strawberry Yoghurt (12x)") -> 350ml Bugo Strawberry Yoghurt (12x) | J3: =IFERROR(__xludf.DUMMYFUNCTION("""COMPUTED_VALUE"""),"1/13/2026") -> 1/13/2026 | K3: =IFERROR(__xludf.DUMMYFUNCTION("""COMPUTED_VALUE"""),"Prestige Superstore, IYANA ISHASHI") -> Prestige Superstore, IYANA ISHASHI | L3: =IFERROR(__xludf.DUMMYFUNCTION("""COMPUTED_VALUE"""),"Sales") -> Sales | M3: =IFERROR(__xludf.DUMMYFUNCTION("""COMPUTED_VALUE"""),"DT:000142") -> DT:000142 | N3: =IFERROR(__xludf.DUMMYFUNCTION("""COMPUTED_VALUE"""),0.5) -> 0.5 | O3: =IFERROR(__xludf.DUMMYFUNCTION("""COMPUTED_VALUE"""),12000.0) -> 12000 | P3: =sumif(M:M,M3,O:O) -> 26400 | R3: =IFERROR(__xludf.DUMMYFUNCTION("IFERROR( FILTER($A$3:$G1844, LEN($A$3:$A1844), REGEXMATCH(LOWER(TRIM($D$3:$D1844)), ""\bjournal\b"")), )"),"") | AH3: =IFERROR(__xludf.DUMMYFUNCTION("IFERROR(FILTER($A$3:$G1844, LEN($A$3:$A1844), LOWER(TRIM($D$3:$D1844))=""Inventory Supplied by Brands""),)"),"") | AP3: =IFERROR(__xludf.DUMMYFUNCTION("IFERROR(FILTER($A$3:$G1844, LEN($A$3:$A1844), LOWER(TRIM($D$3:$D1844))=""Inventory Pickup by Dala""),) "),"")
A4: 350ml Bugo Strawberry Yoghurt (12x) | B4: 1/13/2026 | C4: Prestige Superstore, IGANDO | D4: Sales | E4: DT:000150 | F4: 0.5 | G4: 12000 | I4: =IFERROR(__xludf.DUMMYFUNCTION("""COMPUTED_VALUE"""),"350ml Bugo Strawberry Yoghurt (12x)") -> 350ml Bugo Strawberry Yoghurt (12x) | J4: =IFERROR(__xludf.DUMMYFUNCTION("""COMPUTED_VALUE"""),"1/13/2026") -> 1/13/2026 | K4: =IFERROR(__xludf.DUMMYFUNCTION("""COMPUTED_VALUE"""),"Prestige Superstore, IGANDO") -> Prestige Superstore, IGANDO | L4: =IFERROR(__xludf.DUMMYFUNCTION("""COMPUTED_VALUE"""),"Sales") -> Sales | M4: =IFERROR(__xludf.DUMMYFUNCTION("""COMPUTED_VALUE"""),"DT:000150") -> DT:000150 | N4: =IFERROR(__xludf.DUMMYFUNCTION("""COMPUTED_VALUE"""),0.5) -> 0.5 | O4: =IFERROR(__xludf.DUMMYFUNCTION("""COMPUTED_VALUE"""),12000.0) -> 12000 | P4: =sumif(M:M,M4,O:O) -> 24000
A5: 350ml Bugo Strawberry Yoghurt (12x) | B5: 1/16/2026 | C5: Katta Supermarket | D5: Sales | E5: DT:000222 | F5: 0.5 | G5: 12000 | I5: =IFERROR(__xludf.DUMMYFUNCTION("""COMPUTED_VALUE"""),"350ml Bugo Strawberry Yoghurt (12x)") -> 350ml Bugo Strawberry Yoghurt (12x) | J5: =IFERROR(__xludf.DUMMYFUNCTION("""COMPUTED_VALUE"""),"1/16/2026") -> 1/16/2026 | K5: =IFERROR(__xludf.DUMMYFUNCTION("""COMPUTED_VALUE"""),"Katta Supermarket") -> Katta Supermarket | L5: =IFERROR(__xludf.DUMMYFUNCTION("""COMPUTED_VALUE"""),"Sales") -> Sales | M5: =IFERROR(__xludf.DUMMYFUNCTION("""COMPUTED_VALUE"""),"DT:000222") -> DT:000222 | N5: =IFERROR(__xludf.DUMMYFUNCTION("""COMPUTED_VALUE"""),0.5) -> 0.5 | O5: =IFERROR(__xludf.DUMMYFUNCTION("""COMPUTED_VALUE"""),12000.0) -> 12000 | P5: =sumif(M:M,M5,O:O) -> 24000
A6: 350ml Bugo Strawberry Yoghurt (12x) | B6: 1/17/2026 | C6: Excel Plus Supermarket, Orchid Rd. | D6: Sales | E6: DT:000235 | F6: 1 | G6: 24000 | I6: =IFERROR(__xludf.DUMMYFUNCTION("""COMPUTED_VALUE"""),"350ml Bugo Strawberry Yoghurt (12x)") -> 350ml Bugo Strawberry Yoghurt (12x) | J6: =IFERROR(__xludf.DUMMYFUNCTION("""COMPUTED_VALUE"""),"1/17/2026") -> 1/17/2026 | K6: =IFERROR(__xludf.DUMMYFUNCTION("""COMPUTED_VALUE"""),"Excel Plus Supermarket, Orchid Rd.") -> Excel Plus Supermarket, Orchid Rd. | L6: =IFERROR(__xludf.DUMMYFUNCTION("""COMPUTED_VALUE"""),"Sales") -> Sales | M6: =IFERROR(__xludf.DUMMYFUNCTION("""COMPUTED_VALUE"""),"DT:000235") -> DT:000235 | N6: =IFERROR(__xludf.DUMMYFUNCTION("""COMPUTED_VALUE"""),1.0) -> 1 | O6: =IFERROR(__xludf.DUMMYFUNCTION("""COMPUTED_VALUE"""),24000.0) -> 24000 | P6: =sumif(M:M,M6,O:O) -> 48000
A7: 350ml Bugo Strawberry Yoghurt (12x) | B7: 1/20/2026 | C7: Li.M Supermarket, IJOKO | D7: Sales | E7: DT:000283 | F7: 0.5 | G7: 12000 | I7: =IFERROR(__xludf.DUMMYFUNCTION("""COMPUTED_VALUE"""),"350ml Bugo Strawberry Yoghurt (12x)") -> 350ml Bugo Strawberry Yoghurt (12x) | J7: =IFERROR(__xludf.DUMMYFUNCTION("""COMPUTED_VALUE"""),"1/20/2026") -> 1/20/2026 | K7: =IFERROR(__xludf.DUMMYFUNCTION("""COMPUTED_VALUE"""),"Li.M Supermarket, IJOKO") -> Li.M Supermarket, IJOKO | L7: =IFERROR(__xludf.DUMMYFUNCTION("""COMPUTED_VALUE"""),"Sales") -> Sales | M7: =IFERROR(__xludf.DUMMYFUNCTION("""COMPUTED_VALUE"""),"DT:000283") -> DT:000283 | N7: =IFERROR(__xludf.DUMMYFUNCTION("""COMPUTED_VALUE"""),0.5) -> 0.5 | O7: =IFERROR(__xludf.DUMMYFUNCTION("""COMPUTED_VALUE"""),12000.0) -> 12000 | P7: =sumif(M:M,M7,O:O) -> 81600
A8: 350ml Bugo Strawberry Yoghurt (12x) | B8: 1/26/2026 | C8: D-Arena Supermarket, LEKKI | D8: Sales | E8: DT:000396 | F8: 0.5 | G8: 12000 | I8: =IFERROR(__xludf.DUMMYFUNCTION("""COMPUTED_VALUE"""),"350ml Bugo Strawberry Yoghurt (12x)") -> 350ml Bugo Strawberry Yoghurt (12x) | J8: =IFERROR(__xludf.DUMMYFUNCTION("""COMPUTED_VALUE"""),"1/26/2026") -> 1/26/2026 | K8: =IFERROR(__xludf.DUMMYFUNCTION("""COMPUTED_VALUE"""),"D-Arena Supermarket, LEKKI") -> D-Arena Supermarket, LEKKI | L8: =IFERROR(__xludf.DUMMYFUNCTION("""COMPUTED_VALUE"""),"Sales") -> Sales | M8: =IFERROR(__xludf.DUMMYFUNCTION("""COMPUTED_VALUE"""),"DT:000396") -> DT:000396 | N8: =IFERROR(__xludf.DUMMYFUNCTION("""COMPUTED_VALUE"""),0.5) -> 0.5 | O8: =IFERROR(__xludf.DUMMYFUNCTION("""COMPUTED_VALUE"""),12000.0) -> 12000 | P8: =sumif(M:M,M8,O:O) -> 12000
A9: 350ml Bugo Vanila Yoghurt (12x) | B9: 1/13/2026 | C9: Prestige Superstore, IGANDO | D9: Sales | E9: DT:000150 | F9: 0.5 | G9: 12000 | I9: =IFERROR(__xludf.DUMMYFUNCTION("""COMPUTED_VALUE"""),"350ml Bugo Vanila Yoghurt (12x)") -> 350ml Bugo Vanila Yoghurt (12x) | J9: =IFERROR(__xludf.DUMMYFUNCTION("""COMPUTED_VALUE"""),"1/13/2026") -> 1/13/2026 | K9: =IFERROR(__xludf.DUMMYFUNCTION("""COMPUTED_VALUE"""),"Prestige Superstore, IGANDO") -> Prestige Superstore, IGANDO | L9: =IFERROR(__xludf.DUMMYFUNCTION("""COMPUTED_VALUE"""),"Sales") -> Sales | M9: =IFERROR(__xludf.DUMMYFUNCTION("""COMPUTED_VALUE"""),"DT:000150") -> DT:000150 | N9: =IFERROR(__xludf.DUMMYFUNCTION("""COMPUTED_VALUE"""),0.5) -> 0.5 | O9: =IFERROR(__xludf.DUMMYFUNCTION("""COMPUTED_VALUE"""),12000.0) -> 12000 | P9: =sumif(M:M,M9,O:O) -> 24000
A10: 350ml Bugo Vanila Yoghurt (12x) | B10: 1/16/2026 | C10: Katta Supermarket | D10: Sales | E10: DT:000222 | F10: 0.5 | G10: 12000 | I10: =IFERROR(__xludf.DUMMYFUNCTION("""COMPUTED_VALUE"""),"350ml Bugo Vanila Yoghurt (12x)") -> 350ml Bugo Vanila Yoghurt (12x) | J10: =IFERROR(__xludf.DUMMYFUNCTION("""COMPUTED_VALUE"""),"1/16/2026") -> 1/16/2026 | K10: =IFERROR(__xludf.DUMMYFUNCTION("""COMPUTED_VALUE"""),"Katta Supermarket") -> Katta Supermarket | L10: =IFERROR(__xludf.DUMMYFUNCTION("""COMPUTED_VALUE"""),"Sales") -> Sales | M10: =IFERROR(__xludf.DUMMYFUNCTION("""COMPUTED_VALUE"""),"DT:000222") -> DT:000222 | N10: =IFERROR(__xludf.DUMMYFUNCTION("""COMPUTED_VALUE"""),0.5) -> 0.5 | O10: =IFERROR(__xludf.DUMMYFUNCTION("""COMPUTED_VALUE"""),12000.0) -> 12000 | P10: =sumif(M:M,M10,O:O) -> 24000
A11: 350ml Bugo Vanila Yoghurt (12x) | B11: 1/17/2026 | C11: Excel Plus Supermarket, Orchid Rd. | D11: Sales | E11: DT:000235 | F11: 1 | G11: 24000 | I11: =IFERROR(__xludf.DUMMYFUNCTION("""COMPUTED_VALUE"""),"350ml Bugo Vanila Yoghurt (12x)") -> 350ml Bugo Vanila Yoghurt (12x) | J11: =IFERROR(__xludf.DUMMYFUNCTION("""COMPUTED_VALUE"""),"1/17/2026") -> 1/17/2026 | K11: =IFERROR(__xludf.DUMMYFUNCTION("""COMPUTED_VALUE"""),"Excel Plus Supermarket, Orchid Rd.") -> Excel Plus Supermarket, Orchid Rd. | L11: =IFERROR(__xludf.DUMMYFUNCTION("""COMPUTED_VALUE"""),"Sales") -> Sales | M11: =IFERROR(__xludf.DUMMYFUNCTION("""COMPUTED_VALUE"""),"DT:000235") -> DT:000235 | N11: =IFERROR(__xludf.DUMMYFUNCTION("""COMPUTED_VALUE"""),1.0) -> 1 | O11: =IFERROR(__xludf.DUMMYFUNCTION("""COMPUTED_VALUE"""),24000.0) -> 24000 | P11: =sumif(M:M,M11,O:O) -> 48000
A12: 350ml Bugo Vanila Yoghurt (12x) | B12: 1/20/2026 | C12: Li.M Supermarket, IJOKO | D12: Sales | E12: DT:000283 | F12: 0.5 | G12: 12000 | I12: =IFERROR(__xludf.DUMMYFUNCTION("""COMPUTED_VALUE"""),"350ml Bugo Vanila Yoghurt (12x)") -> 350ml Bugo Vanila Yoghurt (12x) | J12: =IFERROR(__xludf.DUMMYFUNCTION("""COMPUTED_VALUE"""),"1/20/2026") -> 1/20/2026 | K12: =IFERROR(__xludf.DUMMYFUNCTION("""COMPUTED_VALUE"""),"Li.M Supermarket, IJOKO") -> Li.M Supermarket, IJOKO | L12: =IFERROR(__xludf.DUMMYFUNCTION("""COMPUTED_VALUE"""),"Sales") -> Sales | M12: =IFERROR(__xludf.DUMMYFUNCTION("""COMPUTED_VALUE"""),"DT:000283") -> DT:000283 | N12: =IFERROR(__xludf.DUMMYFUNCTION("""COMPUTED_VALUE"""),0.5) -> 0.5 | O12: =IFERROR(__xludf.DUMMYFUNCTION("""COMPUTED_VALUE"""),12000.0) -> 12000 | P12: =sumif(M:M,M12,O:O) -> 81600
A13: 350ml Bugo Vanila Yoghurt (12x) | B13: 1/21/2026 | C13: Renees Supermarket, LEKKI CENTRAL MOSQUE | D13: Sales | E13: DT:000295 | F13: 1 | G13: 24000 | I13: =IFERROR(__xludf.DUMMYFUNCTION("""COMPUTED_VALUE"""),"350ml Bugo Vanila Yoghurt (12x)") -> 350ml Bugo Vanila Yoghurt (12x) | J13: =IFERROR(__xludf.DUMMYFUNCTION("""COMPUTED_VALUE"""),"1/21/2026") -> 1/21/2026 | K13: =IFERROR(__xludf.DUMMYFUNCTION("""COMPUTED_VALUE"""),"Renees Supermarket, LEKKI CENTRAL MOSQUE") -> Renees Supermarket, LEKKI CENTRAL MOSQUE | L13: =IFERROR(__xludf.DUMMYFUNCTION("""COMPUTED_VALUE"""),"Sales") -> Sales | M13: =IFERROR(__xludf.DUMMYFUNCTION("""COMPUTED_VALUE"""),"DT:000295") -> DT:000295 | N13: =IFERROR(__xludf.DUMMYFUNCTION("""COMPUTED_VALUE"""),1.0) -> 1 | O13: =IFERROR(__xludf.DUMMYFUNCTION("""COMPUTED_VALUE"""),24000.0) -> 24000 | P13: =sumif(M:M,M13,O:O) -> 52800
A14: 500ml Bugo Plain Yoghurt (12x) | B14: 46143 | C14: Divine Help Supermarket, SHAGAMU IKD | D14: Sales | E14: DT:000473 | F14: 0.25 | G14: 7200 | I14: =IFERROR(__xludf.DUMMYFUNCTION("""COMPUTED_VALUE"""),"500ml Bugo Plain Yoghurt (12x)") -> 500ml Bugo Plain Yoghurt (12x) | J14: =IFERROR(__xludf.DUMMYFUNCTION("""COMPUTED_VALUE"""),46143.0) -> 46143 | K14: =IFERROR(__xludf.DUMMYFUNCTION("""COMPUTED_VALUE"""),"Divine Help Supermarket, SHAGAMU IKD") -> Divine Help Supermarket, SHAGAMU IKD | L14: =IFERROR(__xludf.DUMMYFUNCTION("""COMPUTED_VALUE"""),"Sales") -> Sales | M14: =IFERROR(__xludf.DUMMYFUNCTION("""COMPUTED_VALUE"""),"DT:000473") -> DT:000473 | N14: =IFERROR(__xludf.DUMMYFUNCTION("""COMPUTED_VALUE"""),0.25) -> 0.25 | O14: =IFERROR(__xludf.DUMMYFUNCTION("""COMPUTED_VALUE"""),7200.0) -> 7200 | P14: =sumif(M:M,M14,O:O) -> 64800
A15: 500ml Bugo Strawberry Yoghurt (12x) | B15: 46143 | C15: Divine Help supermarket, AGBEDE IKD | D15: Sales | E15: DT:000471 | F15: 0.5 | G15: 14400 | I15: =IFERROR(__xludf.DUMMYFUNCTION("""COMPUTED_VALUE"""),"500ml Bugo Strawberry Yoghurt (12x)") -> 500ml Bugo Strawberry Yoghurt (12x) | J15: =IFERROR(__xludf.DUMMYFUNCTION("""COMPUTED_VALUE"""),46143.0) -> 46143 | K15: =IFERROR(__xludf.DUMMYFUNCTION("""COMPUTED_VALUE"""),"Divine Help supermarket, AGBEDE IKD") -> Divine Help supermarket, AGBEDE IKD | L15: =IFERROR(__xludf.DUMMYFUNCTION("""COMPUTED_VALUE"""),"Sales") -> Sales | M15: =IFERROR(__xludf.DUMMYFUNCTION("""COMPUTED_VALUE"""),"DT:000471") -> DT:000471 | N15: =IFERROR(__xludf.DUMMYFUNCTION("""COMPUTED_VALUE"""),0.5) -> 0.5 | O15: =IFERROR(__xludf.DUMMYFUNCTION("""COMPUTED_VALUE"""),14400.0) -> 14400 | P15: =sumif(M:M,M15,O:O) -> 28800
A16: 500ml Bugo Strawberry Yoghurt (12x) | B16: 46143 | C16: Divine Help Supermarket, SHAGAMU IKD | D16: Sales | E16: DT:000473 | F16: 1 | G16: 28800 | I16: =IFERROR(__xludf.DUMMYFUNCTION("""COMPUTED_VALUE"""),"500ml Bugo Strawberry Yoghurt (12x)") -> 500ml Bugo Strawberry Yoghurt (12x) | J16: =IFERROR(__xludf.DUMMYFUNCTION("""COMPUTED_VALUE"""),46143.0) -> 46143 | K16: =IFERROR(__xludf.DUMMYFUNCTION("""COMPUTED_VALUE"""),"Divine Help Supermarket, SHAGAMU IKD") -> Divine Help Supermarket, SHAGAMU IKD | L16: =IFERROR(__xludf.DUMMYFUNCTION("""COMPUTED_VALUE"""),"Sales") -> Sales | M16: =IFERROR(__xludf.DUMMYFUNCTION("""COMPUTED_VALUE"""),"DT:000473") -> DT:000473 | N16: =IFERROR(__xludf.DUMMYFUNCTION("""COMPUTED_VALUE"""),1.0) -> 1 | O16: =IFERROR(__xludf.DUMMYFUNCTION("""COMPUTED_VALUE"""),28800.0) -> 28800 | P16: =sumif(M:M,M16,O:O) -> 64800
A17: 500ml Bugo Strawberry Yoghurt (12x) | B17: 46296 | C17: Am to Pm Supermarket, Martins Rd. | D17: Sales | E17: DT:000105 | F17: 0.5 | G17: 14400 | I17: =IFERROR(__xludf.DUMMYFUNCTION("""COMPUTED_VALUE"""),"500ml Bugo Strawberry Yoghurt (12x)") -> 500ml Bugo Strawberry Yoghurt (12x) | J17: =IFERROR(__xludf.DUMMYFUNCTION("""COMPUTED_VALUE"""),46296.0) -> 46296 | K17: =IFERROR(__xludf.DUMMYFUNCTION("""COMPUTED_VALUE"""),"Am to Pm Supermarket, Martins Rd.") -> Am to Pm Supermarket, Martins Rd. | L17: =IFERROR(__xludf.DUMMYFUNCTION("""COMPUTED_VALUE"""),"Sales") -> Sales | M17: =IFERROR(__xludf.DUMMYFUNCTION("""COMPUTED_VALUE"""),"DT:000105") -> DT:000105 | N17: =IFERROR(__xludf.DUMMYFUNCTION("""COMPUTED_VALUE"""),0.5) -> 0.5 | O17: =IFERROR(__xludf.DUMMYFUNCTION("""COMPUTED_VALUE"""),14400.0) -> 14400 | P17: =sumif(M:M,M17,O:O) -> 28800
A18: 500ml Bugo Strawberry Yoghurt (12x) | B18: 1/13/2026 | C18: Prestige Superstore, IYANA ISHASHI | D18: Sales | E18: DT:000142 | F18: 0.5 | G18: 14400 | I18: =IFERROR(__xludf.DUMMYFUNCTION("""COMPUTED_VALUE"""),"500ml Bugo Strawberry Yoghurt (12x)") -> 500ml Bugo Strawberry Yoghurt (12x) | J18: =IFERROR(__xludf.DUMMYFUNCTION("""COMPUTED_VALUE"""),"1/13/2026") -> 1/13/2026 | K18: =IFERROR(__xludf.DUMMYFUNCTION("""COMPUTED_VALUE"""),"Prestige Superstore, IYANA ISHASHI") -> Prestige Superstore, IYANA ISHASHI | L18: =IFERROR(__xludf.DUMMYFUNCTION("""COMPUTED_VALUE"""),"Sales") -> Sales | M18: =IFERROR(__xludf.DUMMYFUNCTION("""COMPUTED_VALUE"""),"DT:000142") -> DT:000142 | N18: =IFERROR(__xludf.DUMMYFUNCTION("""COMPUTED_VALUE"""),0.5) -> 0.5 | O18: =IFERROR(__xludf.DUMMYFUNCTION("""COMPUTED_VALUE"""),14400.0) -> 14400 | P18: =sumif(M:M,M18,O:O) -> 26400
A19: 500ml Bugo Strawberry Yoghurt (12x) | B19: 1/15/2026 | C19: Ozzy Supermarket, VICTORY PARK EST. | D19: Sales | E19: DT:000192 | F19: 0.5 | G19: 14400 | I19: =IFERROR(__xludf.DUMMYFUNCTION("""COMPUTED_VALUE"""),"500ml Bugo Strawberry Yoghurt (12x)") -> 500ml Bugo Strawberry Yoghurt (12x) | J19: =IFERROR(__xludf.DUMMYFUNCTION("""COMPUTED_VALUE"""),"1/15/2026") -> 1/15/2026 | K19: =IFERROR(__xludf.DUMMYFUNCTION("""COMPUTED_VALUE"""),"Ozzy Supermarket, VICTORY PARK EST.") -> Ozzy Supermarket, VICTORY PARK EST. | L19: =IFERROR(__xludf.DUMMYFUNCTION("""COMPUTED_VALUE"""),"Sales") -> Sales | M19: =IFERROR(__xludf.DUMMYFUNCTION("""COMPUTED_VALUE"""),"DT:000192") -> DT:000192 | N19: =IFERROR(__xludf.DUMMYFUNCTION("""COMPUTED_VALUE"""),0.5) -> 0.5 | O19: =IFERROR(__xludf.DUMMYFUNCTION("""COMPUTED_VALUE"""),14400.0) -> 14400 | P19: =sumif(M:M,M19,O:O) -> 28800
A20: 500ml Bugo Strawberry Yoghurt (12x) | B20: 1/20/2026 | C20: Double Sam Supermarket, 22 IKD AWOLOWO ROAD | D20: Sales | E20: DT:000279 | F20: 1 | G20: 28800 | I20: =IFERROR(__xludf.DUMMYFUNCTION("""COMPUTED_VALUE"""),"500ml Bugo Strawberry Yoghurt (12x)") -> 500ml Bugo Strawberry Yoghurt (12x) | J20: =IFERROR(__xludf.DUMMYFUNCTION("""COMPUTED_VALUE"""),"1/20/2026") -> 1/20/2026 | K20: =IFERROR(__xludf.DUMMYFUNCTION("""COMPUTED_VALUE"""),"Double Sam Supermarket, 22 IKD AWOLOWO ROAD") -> Double Sam Supermarket, 22 IKD AWOLOWO ROAD | L20: =IFERROR(__xludf.DUMMYFUNCTION("""COMPUTED_VALUE"""),"Sales") -> Sales | M20: =IFERROR(__xludf.DUMMYFUNCTION("""COMPUTED_VALUE"""),"DT:000279") -> DT:000279 | N20: =IFERROR(__xludf.DUMMYFUNCTION("""COMPUTED_VALUE"""),1.0) -> 1 | O20: =IFERROR(__xludf.DUMMYFUNCTION("""COMPUTED_VALUE"""),28800.0) -> 28800 | P20: =sumif(M:M,M20,O:O) -> 57600
A21: 500ml Bugo Strawberry Yoghurt (12x) | B21: 1/20/2026 | C21: Li.M Supermarket, IJOKO | D21: Sales | E21: DT:000283 | F21: 1 | G21: 28800 | I21: =IFERROR(__xludf.DUMMYFUNCTION("""COMPUTED_VALUE"""),"500ml Bugo Strawberry Yoghurt (12x)") -> 500ml Bugo Strawberry Yoghurt (12x) | J21: =IFERROR(__xludf.DUMMYFUNCTION("""COMPUTED_VALUE"""),"1/20/2026") -> 1/20/2026 | K21: =IFERROR(__xludf.DUMMYFUNCTION("""COMPUTED_VALUE"""),"Li.M Supermarket, IJOKO") -> Li.M Supermarket, IJOKO | L21: =IFERROR(__xludf.DUMMYFUNCTION("""COMPUTED_VALUE"""),"Sales") -> Sales | M21: =IFERROR(__xludf.DUMMYFUNCTION("""COMPUTED_VALUE"""),"DT:000283") -> DT:000283 | N21: =IFERROR(__xludf.DUMMYFUNCTION("""COMPUTED_VALUE"""),1.0) -> 1 | O21: =IFERROR(__xludf.DUMMYFUNCTION("""COMPUTED_VALUE"""),28800.0) -> 28800 | P21: =sumif(M:M,M21,O:O) -> 81600
A22: 500ml Bugo Strawberry Yoghurt (12x) | B22: 1/21/2026 | C22: Renees Supermarket, LEKKI CENTRAL MOSQUE | D22: Sales | E22: DT:000295 | F22: 1 | G22: 28800 | I22: =IFERROR(__xludf.DUMMYFUNCTION("""COMPUTED_VALUE"""),"500ml Bugo Strawberry Yoghurt (12x)") -> 500ml Bugo Strawberry Yoghurt (12x) | J22: =IFERROR(__xludf.DUMMYFUNCTION("""COMPUTED_VALUE"""),"1/21/2026") -> 1/21/2026 | K22: =IFERROR(__xludf.DUMMYFUNCTION("""COMPUTED_VALUE"""),"Renees Supermarket, LEKKI CENTRAL MOSQUE") -> Renees Supermarket, LEKKI CENTRAL MOSQUE | L22: =IFERROR(__xludf.DUMMYFUNCTION("""COMPUTED_VALUE"""),"Sales") -> Sales | M22: =IFERROR(__xludf.DUMMYFUNCTION("""COMPUTED_VALUE"""),"DT:000295") -> DT:000295 | N22: =IFERROR(__xludf.DUMMYFUNCTION("""COMPUTED_VALUE"""),1.0) -> 1 | O22: =IFERROR(__xludf.DUMMYFUNCTION("""COMPUTED_VALUE"""),28800.0) -> 28800 | P22: =sumif(M:M,M22,O:O) -> 52800
A23: 500ml Bugo Strawberry Yoghurt (12x) | B23: 1/29/2026 | C23: Lady Ricky Catering Service/ Smooth and Sweet Swallow | D23: Sales | E23: DT:000479 | F23: 2 | G23: 57600 | I23: =IFERROR(__xludf.DUMMYFUNCTION("""COMPUTED_VALUE"""),"500ml Bugo Strawberry Yoghurt (12x)") -> 500ml Bugo Strawberry Yoghurt (12x) | J23: =IFERROR(__xludf.DUMMYFUNCTION("""COMPUTED_VALUE"""),"1/29/2026") -> 1/29/2026 | K23: =IFERROR(__xludf.DUMMYFUNCTION("""COMPUTED_VALUE"""),"Lady Ricky Catering Service/ Smooth and Sweet Swallow") -> Lady Ricky Catering Service/ Smooth and Sweet Swallow | L23: =IFERROR(__xludf.DUMMYFUNCTION("""COMPUTED_VALUE"""),"Sales") -> Sales | M23: =IFERROR(__xludf.DUMMYFUNCTION("""COMPUTED_VALUE"""),"DT:000479") -> DT:000479 | N23: =IFERROR(__xludf.DUMMYFUNCTION("""COMPUTED_VALUE"""),2.0) -> 2 | O23: =IFERROR(__xludf.DUMMYFUNCTION("""COMPUTED_VALUE"""),57600.0) -> 57600 | P23: =sumif(M:M,M23,O:O) -> 64800
A24: 500ml Bugo Strawberry Yoghurt (12x) | B24: 1/29/2026 | C24: Prestige Superstore, IYANA ISHASHI | D24: Sales | E24: DT:000497 | F24: 0.25 | G24: 7200 | I24: =IFERROR(__xludf.DUMMYFUNCTION("""COMPUTED_VALUE"""),"500ml Bugo Strawberry Yoghurt (12x)") -> 500ml Bugo Strawberry Yoghurt (12x) | J24: =IFERROR(__xludf.DUMMYFUNCTION("""COMPUTED_VALUE"""),"1/29/2026") -> 1/29/2026 | K24: =IFERROR(__xludf.DUMMYFUNCTION("""COMPUTED_VALUE"""),"Prestige Superstore, IYANA ISHASHI") -> Prestige Superstore, IYANA ISHASHI | L24: =IFERROR(__xludf.DUMMYFUNCTION("""COMPUTED_VALUE"""),"Sales") -> Sales | M24: =IFERROR(__xludf.DUMMYFUNCTION("""COMPUTED_VALUE"""),"DT:000497") -> DT:000497 | N24: =IFERROR(__xludf.DUMMYFUNCTION("""COMPUTED_VALUE"""),0.25) -> 0.25 | O24: =IFERROR(__xludf.DUMMYFUNCTION("""COMPUTED_VALUE"""),7200.0) -> 7200 | P24: =sumif(M:M,M24,O:O) -> 21600
A25: 500ml Bugo Sweetened Greek Yoghurt (12x) | B25: 1/16/2026 | C25: Hutoos Supermarket, OKO OBA | D25: Sales | E25: DT:000223 | F25: 0.5 | G25: 23400 | I25: =IFERROR(__xludf.DUMMYFUNCTION("""COMPUTED_VALUE"""),"500ml Bugo Sweetened Greek Yoghurt (12x)") -> 500ml Bugo Sweetened Greek Yoghurt (12x) | J25: =IFERROR(__xludf.DUMMYFUNCTION("""COMPUTED_VALUE"""),"1/16/2026") -> 1/16/2026 | K25: =IFERROR(__xludf.DUMMYFUNCTION("""COMPUTED_VALUE"""),"Hutoos Supermarket, OKO OBA") -> Hutoos Supermarket, OKO OBA | L25: =IFERROR(__xludf.DUMMYFUNCTION("""COMPUTED_VALUE"""),"Sales") -> Sales | M25: =IFERROR(__xludf.DUMMYFUNCTION("""COMPUTED_VALUE"""),"DT:000223") -> DT:000223 | N25: =IFERROR(__xludf.DUMMYFUNCTION("""COMPUTED_VALUE"""),0.5) -> 0.5 | O25: =IFERROR(__xludf.DUMMYFUNCTION("""COMPUTED_VALUE"""),23400.0) -> 23400 | P25: =sumif(M:M,M25,O:O) -> 23400
A26: 500ml Bugo Sweetened Greek Yoghurt (12x) | B26: 1/22/2026 | C26: D'Emperor Superstore | D26: Sales | E26: DT:000344 | F26: 0.5 | G26: 23400 | I26: =IFERROR(__xludf.DUMMYFUNCTION("""COMPUTED_VALUE"""),"500ml Bugo Sweetened Greek Yoghurt (12x)") -> 500ml Bugo Sweetened Greek Yoghurt (12x) | J26: =IFERROR(__xludf.DUMMYFUNCTION("""COMPUTED_VALUE"""),"1/22/2026") -> 1/22/2026 | K26: =IFERROR(__xludf.DUMMYFUNCTION("""COMPUTED_VALUE"""),"D'Emperor Superstore") -> D'Emperor Superstore | L26: =IFERROR(__xludf.DUMMYFUNCTION("""COMPUTED_VALUE"""),"Sales") -> Sales | M26: =IFERROR(__xludf.DUMMYFUNCTION("""COMPUTED_VALUE"""),"DT:000344") -> DT:000344 | N26: =IFERROR(__xludf.DUMMYFUNCTION("""COMPUTED_VALUE"""),0.5) -> 0.5 | O26: =IFERROR(__xludf.DUMMYFUNCTION("""COMPUTED_VALUE"""),23400.0) -> 23400 | P26: =sumif(M:M,M26,O:O) -> 23400
A27: 500ml Bugo Vanila Yoghurt (12x) | B27: 46143 | C27: Divine Help supermarket, AGBEDE IKD | D27: Sales | E27: DT:000471 | F27: 0.5 | G27: 14400 | I27: =IFERROR(__xludf.DUMMYFUNCTION("""COMPUTED_VALUE"""),"500ml Bugo Vanila Yoghurt (12x)") -> 500ml Bugo Vanila Yoghurt (12x) | J27: =IFERROR(__xludf.DUMMYFUNCTION("""COMPUTED_VALUE"""),46143.0) -> 46143 | K27: =IFERROR(__xludf.DUMMYFUNCTION("""COMPUTED_VALUE"""),"Divine Help supermarket, AGBEDE IKD") -> Divine Help supermarket, AGBEDE IKD | L27: =IFERROR(__xludf.DUMMYFUNCTION("""COMPUTED_VALUE"""),"Sales") -> Sales | M27: =IFERROR(__xludf.DUMMYFUNCTION("""COMPUTED_VALUE"""),"DT:000471") -> DT:000471 | N27: =IFERROR(__xludf.DUMMYFUNCTION("""COMPUTED_VALUE"""),0.5) -> 0.5 | O27: =IFERROR(__xludf.DUMMYFUNCTION("""COMPUTED_VALUE"""),14400.0) -> 14400 | P27: =sumif(M:M,M27,O:O) -> 28800
A28: 500ml Bugo Vanila Yoghurt (12x) | B28: 46143 | C28: Divine Help Supermarket, SHAGAMU IKD | D28: Sales | E28: DT:000473 | F28: 1 | G28: 28800 | I28: =IFERROR(__xludf.DUMMYFUNCTION("""COMPUTED_VALUE"""),"500ml Bugo Vanila Yoghurt (12x)") -> 500ml Bugo Vanila Yoghurt (12x) | J28: =IFERROR(__xludf.DUMMYFUNCTION("""COMPUTED_VALUE"""),46143.0) -> 46143 | K28: =IFERROR(__xludf.DUMMYFUNCTION("""COMPUTED_VALUE"""),"Divine Help Supermarket, SHAGAMU IKD") -> Divine Help Supermarket, SHAGAMU IKD | L28: =IFERROR(__xludf.DUMMYFUNCTION("""COMPUTED_VALUE"""),"Sales") -> Sales | M28: =IFERROR(__xludf.DUMMYFUNCTION("""COMPUTED_VALUE"""),"DT:000473") -> DT:000473 | N28: =IFERROR(__xludf.DUMMYFUNCTION("""COMPUTED_VALUE"""),1.0) -> 1 | O28: =IFERROR(__xludf.DUMMYFUNCTION("""COMPUTED_VALUE"""),28800.0) -> 28800 | P28: =sumif(M:M,M28,O:O) -> 64800
A29: 500ml Bugo Vanila Yoghurt (12x) | B29: 46296 | C29: Am to Pm Supermarket, Martins Rd. | D29: Sales | E29: DT:000105 | F29: 0.5 | G29: 14400 | I29: =IFERROR(__xludf.DUMMYFUNCTION("""COMPUTED_VALUE"""),"500ml Bugo Vanila Yoghurt (12x)") -> 500ml Bugo Vanila Yoghurt (12x) | J29: =IFERROR(__xludf.DUMMYFUNCTION("""COMPUTED_VALUE"""),46296.0) -> 46296 | K29: =IFERROR(__xludf.DUMMYFUNCTION("""COMPUTED_VALUE"""),"Am to Pm Supermarket, Martins Rd.") -> Am to Pm Supermarket, Martins Rd. | L29: =IFERROR(__xludf.DUMMYFUNCTION("""COMPUTED_VALUE"""),"Sales") -> Sales | M29: =IFERROR(__xludf.DUMMYFUNCTION("""COMPUTED_VALUE"""),"DT:000105") -> DT:000105 | N29: =IFERROR(__xludf.DUMMYFUNCTION("""COMPUTED_VALUE"""),0.5) -> 0.5 | O29: =IFERROR(__xludf.DUMMYFUNCTION("""COMPUTED_VALUE"""),14400.0) -> 14400 | P29: =sumif(M:M,M29,O:O) -> 28800
A30: 500ml Bugo Vanila Yoghurt (12x) | B30: 1/13/2026 | C30: Skymart Supermarket, SANGOTEDO | D30: Sales | E30: DT:000134 | F30: 1 | G30: 28800 | I30: =IFERROR(__xludf.DUMMYFUNCTION("""COMPUTED_VALUE"""),"500ml Bugo Vanila Yoghurt (12x)") -> 500ml Bugo Vanila Yoghurt (12x) | J30: =IFERROR(__xludf.DUMMYFUNCTION("""COMPUTED_VALUE"""),"1/13/2026") -> 1/13/2026 | K30: =IFERROR(__xludf.DUMMYFUNCTION("""COMPUTED_VALUE"""),"Skymart Supermarket, SANGOTEDO") -> Skymart Supermarket, SANGOTEDO | L30: =IFERROR(__xludf.DUMMYFUNCTION("""COMPUTED_VALUE"""),"Sales") -> Sales | M30: =IFERROR(__xludf.DUMMYFUNCTION("""COMPUTED_VALUE"""),"DT:000134") -> DT:000134 | N30: =IFERROR(__xludf.DUMMYFUNCTION("""COMPUTED_VALUE"""),1.0) -> 1 | O30: =IFERROR(__xludf.DUMMYFUNCTION("""COMPUTED_VALUE"""),28800.0) -> 28800 | P30: =sumif(M:M,M30,O:O) -> 28800
A31: 500ml Bugo Vanila Yoghurt (12x) | B31: 1/15/2026 | C31: Ozzy Supermarket, VICTORY PARK EST. | D31: Sales | E31: DT:000192 | F31: 0.5 | G31: 14400 | I31: =IFERROR(__xludf.DUMMYFUNCTION("""COMPUTED_VALUE"""),"500ml Bugo Vanila Yoghurt (12x)") -> 500ml Bugo Vanila Yoghurt (12x) | J31: =IFERROR(__xludf.DUMMYFUNCTION("""COMPUTED_VALUE"""),"1/15/2026") -> 1/15/2026 | K31: =IFERROR(__xludf.DUMMYFUNCTION("""COMPUTED_VALUE"""),"Ozzy Supermarket, VICTORY PARK EST.") -> Ozzy Supermarket, VICTORY PARK EST. | L31: =IFERROR(__xludf.DUMMYFUNCTION("""COMPUTED_VALUE"""),"Sales") -> Sales | M31: =IFERROR(__xludf.DUMMYFUNCTION("""COMPUTED_VALUE"""),"DT:000192") -> DT:000192 | N31: =IFERROR(__xludf.DUMMYFUNCTION("""COMPUTED_VALUE"""),0.5) -> 0.5 | O31: =IFERROR(__xludf.DUMMYFUNCTION("""COMPUTED_VALUE"""),14400.0) -> 14400 | P31: =sumif(M:M,M31,O:O) -> 28800
A32: 500ml Bugo Vanila Yoghurt (12x) | B32: 1/20/2026 | C32: Double Sam Supermarket, 22 IKD AWOLOWO ROAD | D32: Sales | E32: DT:000279 | F32: 1 | G32: 28800 | I32: =IFERROR(__xludf.DUMMYFUNCTION("""COMPUTED_VALUE"""),"500ml Bugo Vanila Yoghurt (12x)") -> 500ml Bugo Vanila Yoghurt (12x) | J32: =IFERROR(__xludf.DUMMYFUNCTION("""COMPUTED_VALUE"""),"1/20/2026") -> 1/20/2026 | K32: =IFERROR(__xludf.DUMMYFUNCTION("""COMPUTED_VALUE"""),"Double Sam Supermarket, 22 IKD AWOLOWO ROAD") -> Double Sam Supermarket, 22 IKD AWOLOWO ROAD | L32: =IFERROR(__xludf.DUMMYFUNCTION("""COMPUTED_VALUE"""),"Sales") -> Sales | M32: =IFERROR(__xludf.DUMMYFUNCTION("""COMPUTED_VALUE"""),"DT:000279") -> DT:000279 | N32: =IFERROR(__xludf.DUMMYFUNCTION("""COMPUTED_VALUE"""),1.0) -> 1 | O32: =IFERROR(__xludf.DUMMYFUNCTION("""COMPUTED_VALUE"""),28800.0) -> 28800 | P32: =sumif(M:M,M32,O:O) -> 57600
A33: 500ml Bugo Vanila Yoghurt (12x) | B33: 1/20/2026 | C33: Li.M Supermarket, IJOKO | D33: Sales | E33: DT:000283 | F33: 1 | G33: 28800 | I33: =IFERROR(__xludf.DUMMYFUNCTION("""COMPUTED_VALUE"""),"500ml Bugo Vanila Yoghurt (12x)") -> 500ml Bugo Vanila Yoghurt (12x) | J33: =IFERROR(__xludf.DUMMYFUNCTION("""COMPUTED_VALUE"""),"1/20/2026") -> 1/20/2026 | K33: =IFERROR(__xludf.DUMMYFUNCTION("""COMPUTED_VALUE"""),"Li.M Supermarket, IJOKO") -> Li.M Supermarket, IJOKO | L33: =IFERROR(__xludf.DUMMYFUNCTION("""COMPUTED_VALUE"""),"Sales") -> Sales | M33: =IFERROR(__xludf.DUMMYFUNCTION("""COMPUTED_VALUE"""),"DT:000283") -> DT:000283 | N33: =IFERROR(__xludf.DUMMYFUNCTION("""COMPUTED_VALUE"""),1.0) -> 1 | O33: =IFERROR(__xludf.DUMMYFUNCTION("""COMPUTED_VALUE"""),28800.0) -> 28800 | P33: =sumif(M:M,M33,O:O) -> 81600
A34: 500ml Bugo Vanila Yoghurt (12x) | B34: 1/29/2026 | C34: Lady Ricky Catering Service/ Smooth and Sweet Swallow | D34: Sales | E34: DT:000479 | F34: 0.25 | G34: 7200 | I34: =IFERROR(__xludf.DUMMYFUNCTION("""COMPUTED_VALUE"""),"500ml Bugo Vanila Yoghurt (12x)") -> 500ml Bugo Vanila Yoghurt (12x) | J34: =IFERROR(__xludf.DUMMYFUNCTION("""COMPUTED_VALUE"""),"1/29/2026") -> 1/29/2026 | K34: =IFERROR(__xludf.DUMMYFUNCTION("""COMPUTED_VALUE"""),"Lady Ricky Catering Service/ Smooth and Sweet Swallow") -> Lady Ricky Catering Service/ Smooth and Sweet Swallow | L34: =IFERROR(__xludf.DUMMYFUNCTION("""COMPUTED_VALUE"""),"Sales") -> Sales | M34: =IFERROR(__xludf.DUMMYFUNCTION("""COMPUTED_VALUE"""),"DT:000479") -> DT:000479 | N34: =IFERROR(__xludf.DUMMYFUNCTION("""COMPUTED_VALUE"""),0.25) -> 0.25 | O34: =IFERROR(__xludf.DUMMYFUNCTION("""COMPUTED_VALUE"""),7200.0) -> 7200 | P34: =sumif(M:M,M34,O:O) -> 64800
A35: 500ml Bugo Vanila Yoghurt (12x) | B35: 1/29/2026 | C35: Prestige Superstore, IYANA ISHASHI | D35: Sales | E35: DT:000497 | F35: 0.5 | G35: 14400 | I35: =IFERROR(__xludf.DUMMYFUNCTION("""COMPUTED_VALUE"""),"500ml Bugo Vanila Yoghurt (12x)") -> 500ml Bugo Vanila Yoghurt (12x) | J35: =IFERROR(__xludf.DUMMYFUNCTION("""COMPUTED_VALUE"""),"1/29/2026") -> 1/29/2026 | K35: =IFERROR(__xludf.DUMMYFUNCTION("""COMPUTED_VALUE"""),"Prestige Superstore, IYANA ISHASHI") -> Prestige Superstore, IYANA ISHASHI | L35: =IFERROR(__xludf.DUMMYFUNCTION("""COMPUTED_VALUE"""),"Sales") -> Sales | M35: =IFERROR(__xludf.DUMMYFUNCTION("""COMPUTED_VALUE"""),"DT:000497") -> DT:000497 | N35: =IFERROR(__xludf.DUMMYFUNCTION("""COMPUTED_VALUE"""),0.5) -> 0.5 | O35: =IFERROR(__xludf.DUMMYFUNCTION("""COMPUTED_VALUE"""),14400.0) -> 14400 | P35: =sumif(M:M,M35,O:O) -> 21600
P36: =sumif(M:M,M36,O:O) -> 0
P37: =sumif(M:M,M37,O:O) -> 0
P38: =sumif(M:M,M38,O:O) -> 0
P39: =sumif(M:M,M39,O:O) -> 0
P40: =sumif(M:M,M40,O:O) -> 0
...

Sheet Payment Advice
F2: =sum(D:D) -> 639600

Sheet Dala Sales & Deliveries
H1: Total Invoices Delivered | I1: =countifs(B:B,"<>",F:F,"<>")-1 -> 17 | K1: Sku Performance | L1: Units | M1: Value
H2: Unique Locations Supplied | I2: {=(COUNTA(UNIQUE(C:C))-1)} -> 16 | K2: ='Internal Summary'!B41 -> 1Ltrs Bugo Sweetened Greek Yoghurt (6x) | L2: =sumif(D:D,K2,E:E) -> 0 | M2: =sumif(D:D,K2,F:F) -> 0
H3: Total Value of orders | I3: =sum(F:F) -> 639600 | K3: ='Internal Summary'!B42 -> 1Ltrs Bugo Unsweetened Greek Yoghurt (6x) | L3: =sumif(D:D,K3,E:E) -> 0 | M3: =sumif(D:D,K3,F:F) -> 0
K4: ='Internal Summary'!B43 -> 350ml Bugo Plain Yoghurt (12x) | L4: =sumif(D:D,K4,E:E) -> 0 | M4: =sumif(D:D,K4,F:F) -> 0
K5: ='Internal Summary'!B44 -> 350ml Bugo Strawberry Yoghurt (12x) | L5: =sumif(D:D,K5,E:E) -> 3.5 | M5: =sumif(D:D,K5,F:F) -> 84000
K6: ='Internal Summary'!B45 -> 350ml Bugo Vanila Yoghurt (12x) | L6: =sumif(D:D,K6,E:E) -> 3.5 | M6: =sumif(D:D,K6,F:F) -> 84000
K7: ='Internal Summary'!B46 -> 500ml Bugo Plain Yoghurt (12x) | L7: =sumif(D:D,K7,E:E) -> 0.25 | M7: =sumif(D:D,K7,F:F) -> 7200
K8: ='Internal Summary'!B47 -> 500ml Bugo Strawberry Yoghurt (12x) | L8: =sumif(D:D,K8,E:E) -> 8.25 | M8: =sumif(D:D,K8,F:F) -> 237600
K9: ='Internal Summary'!B48 -> 500ml Bugo Sweetened Greek Yoghurt (12x) | L9: =sumif(D:D,K9,E:E) -> 1 | M9: =sumif(D:D,K9,F:F) -> 46800
K10: ='Internal Summary'!B49 -> 500ml Bugo Unsweetened Greek Yoghurt (12x) | L10: =sumif(D:D,K10,E:E) -> 0 | M10: =sumif(D:D,K10,F:F) -> 0
K11: ='Internal Summary'!B50 -> 500ml Bugo Vanila Yoghurt (12x) | L11: =sumif(D:D,K11,E:E) -> 6.25 | M11: =sumif(D:D,K11,F:F) -> 180000
A12: 45758 | K12: ='Internal Summary'!B51 | L12: =sumif(D:D,K12,E:E) -> 0 | M12: =sumif(D:D,K12,F:F) -> 0
K13: ='Internal Summary'!B52 | L13: =sumif(D:D,K13,E:E) -> 0 | M13: =sumif(D:D,K13,F:F) -> 0

Sheet External Delivery Fulfillment
H1: Total Invoices Delivered | I1: =countifs(B:B,"<>",F:F,"<>")-1 -> 0 | K1: Sku Performance | L1: Units | M1: Value
H2: Unique Locations Supplied | I2: {=(COUNTA(UNIQUE(C:C))-1)} -> 0 | K2: ='Internal Summary'!B41 -> 1Ltrs Bugo Sweetened Greek Yoghurt (6x) | L2: =sumif(D:D,K2,E:E) -> 0 | M2: =sumif(D:D,K2,F:F) -> 0
H3: Total Value of orders | I3: =sum(F:F) -> 0 | K3: ='Internal Summary'!B42 -> 1Ltrs Bugo Unsweetened Greek Yoghurt (6x) | L3: =sumif(D:D,K3,E:E) -> 0 | M3: =sumif(D:D,K3,F:F) -> 0
K4: ='Internal Summary'!B43 -> 350ml Bugo Plain Yoghurt (12x) | L4: =sumif(D:D,K4,E:E) -> 0 | M4: =sumif(D:D,K4,F:F) -> 0
K5: ='Internal Summary'!B44 -> 350ml Bugo Strawberry Yoghurt (12x) | L5: =sumif(D:D,K5,E:E) -> 0 | M5: =sumif(D:D,K5,F:F) -> 0
K6: ='Internal Summary'!B45 -> 350ml Bugo Vanila Yoghurt (12x) | L6: =sumif(D:D,K6,E:E) -> 0 | M6: =sumif(D:D,K6,F:F) -> 0
K7: ='Internal Summary'!B46 -> 500ml Bugo Plain Yoghurt (12x) | L7: =sumif(D:D,K7,E:E) -> 0 | M7: =sumif(D:D,K7,F:F) -> 0
K8: ='Internal Summary'!B47 -> 500ml Bugo Strawberry Yoghurt (12x) | L8: =sumif(D:D,K8,E:E) -> 0 | M8: =sumif(D:D,K8,F:F) -> 0
K9: ='Internal Summary'!B48 -> 500ml Bugo Sweetened Greek Yoghurt (12x) | L9: =sumif(D:D,K9,E:E) -> 0 | M9: =sumif(D:D,K9,F:F) -> 0
K10: ='Internal Summary'!B49 -> 500ml Bugo Unsweetened Greek Yoghurt (12x) | L10: =sumif(D:D,K10,E:E) -> 0 | M10: =sumif(D:D,K10,F:F) -> 0
K11: ='Internal Summary'!B50 -> 500ml Bugo Vanila Yoghurt (12x) | L11: =sumif(D:D,K11,E:E) -> 0 | M11: =sumif(D:D,K11,F:F) -> 0
K12: ='Internal Summary'!B51 | L12: =sumif(D:D,K12,E:E) -> 0 | M12: =sumif(D:D,K12,F:F) -> 0
K13: ='Internal Summary'!B52 | L13: =sumif(D:D,K13,E:E) -> 0 | M13: =sumif(D:D,K13,F:F) -> 0

Sheet Forwarding From Client
H1: Total Invoices Delivered | I1: =countifs(B:B,"<>",F:F,"<>")-1 -> 0 | K1: Sku Performance | L1: Units | M1: Value
H2: Unique Locations Supplied | I2: {=(COUNTA(UNIQUE(C:C))-1)} -> 0 | K2: ='Internal Summary'!B41 -> 1Ltrs Bugo Sweetened Greek Yoghurt (6x) | L2: =sumif(D:D,K2,E:E) -> 0 | M2: =sumif(D:D,K2,F:F) -> 0
H3: Total Value of orders | I3: =sum(F:F) -> 0 | K3: ='Internal Summary'!B42 -> 1Ltrs Bugo Unsweetened Greek Yoghurt (6x) | L3: =sumif(D:D,K3,E:E) -> 0 | M3: =sumif(D:D,K3,F:F) -> 0
K4: ='Internal Summary'!B43 -> 350ml Bugo Plain Yoghurt (12x) | L4: =sumif(D:D,K4,E:E) -> 0 | M4: =sumif(D:D,K4,F:F) -> 0
K5: ='Internal Summary'!B44 -> 350ml Bugo Strawberry Yoghurt (12x) | L5: =sumif(D:D,K5,E:E) -> 0 | M5: =sumif(D:D,K5,F:F) -> 0
K6: ='Internal Summary'!B45 -> 350ml Bugo Vanila Yoghurt (12x) | L6: =sumif(D:D,K6,E:E) -> 0 | M6: =sumif(D:D,K6,F:F) -> 0
K7: ='Internal Summary'!B46 -> 500ml Bugo Plain Yoghurt (12x) | L7: =sumif(D:D,K7,E:E) -> 0 | M7: =sumif(D:D,K7,F:F) -> 0
K8: ='Internal Summary'!B47 -> 500ml Bugo Strawberry Yoghurt (12x) | L8: =sumif(D:D,K8,E:E) -> 0 | M8: =sumif(D:D,K8,F:F) -> 0
K9: ='Internal Summary'!B48 -> 500ml Bugo Sweetened Greek Yoghurt (12x) | L9: =sumif(D:D,K9,E:E) -> 0 | M9: =sumif(D:D,K9,F:F) -> 0
K10: ='Internal Summary'!B49 -> 500ml Bugo Unsweetened Greek Yoghurt (12x) | L10: =sumif(D:D,K10,E:E) -> 0 | M10: =sumif(D:D,K10,F:F) -> 0
K11: ='Internal Summary'!B50 -> 500ml Bugo Vanila Yoghurt (12x) | L11: =sumif(D:D,K11,E:E) -> 0 | M11: =sumif(D:D,K11,F:F) -> 0
K12: ='Internal Summary'!B51 | L12: =sumif(D:D,K12,E:E) -> 0 | M12: =sumif(D:D,K12,F:F) -> 0
K13: ='Internal Summary'!B52 | L13: =sumif(D:D,K13,E:E) -> 0 | M13: =sumif(D:D,K13,F:F) -> 0

Sheet Dala Restocking
H1: Total Invoices Delivered | I1: =countifs(B:B,"<>",F:F,"<>")-1 -> 0 | K1: Sku Performance | L1: Units
H2: Unique Locations Supplied | I2: {=(COUNTA(UNIQUE(C:C,,0))-1)} -> 0 | K2: ='Internal Summary'!B41 -> 1Ltrs Bugo Sweetened Greek Yoghurt (6x) | L2: =sumif(D:D,K2,E:E) -> 0
H3: Total Value of orders | I3: =sum(F:F) -> 0 | K3: ='Internal Summary'!B42 -> 1Ltrs Bugo Unsweetened Greek Yoghurt (6x) | L3: =sumif(D:D,K3,E:E) -> 0
K4: ='Internal Summary'!B43 -> 350ml Bugo Plain Yoghurt (12x) | L4: =sumif(D:D,K4,E:E) -> 0
K5: ='Internal Summary'!B44 -> 350ml Bugo Strawberry Yoghurt (12x) | L5: =sumif(D:D,K5,E:E) -> 0
K6: ='Internal Summary'!B45 -> 350ml Bugo Vanila Yoghurt (12x) | L6: =sumif(D:D,K6,E:E) -> 0
K7: ='Internal Summary'!B46 -> 500ml Bugo Plain Yoghurt (12x) | L7: =sumif(D:D,K7,E:E) -> 0
K8: ='Internal Summary'!B47 -> 500ml Bugo Strawberry Yoghurt (12x) | L8: =sumif(D:D,K8,E:E) -> 0
K9: ='Internal Summary'!B48 -> 500ml Bugo Sweetened Greek Yoghurt (12x) | L9: =sumif(D:D,K9,E:E) -> 0
K10: ='Internal Summary'!B49 -> 500ml Bugo Unsweetened Greek Yoghurt (12x) | L10: =sumif(D:D,K10,E:E) -> 0
K11: ='Internal Summary'!B50 -> 500ml Bugo Vanila Yoghurt (12x) | L11: =sumif(D:D,K11,E:E) -> 0
K12: ='Internal Summary'!B51 | L12: =sumif(D:D,K12,E:E) -> 0
K13: ='Internal Summary'!B52 | L13: =sumif(D:D,K13,E:E) -> 0

Sheet Client Restocking
H1: Total Invoices Delivered | I1: =countifs(B:B,"<>",F:F,"<>")-1 -> 0 | K1: Sku Performance | L1: Units
H2: Unique Locations Supplied | I2: {=(COUNTA(UNIQUE(C:C,,0))-1)} -> 0 | K2: ='Internal Summary'!B41 -> 1Ltrs Bugo Sweetened Greek Yoghurt (6x) | L2: =sumif(D:D,K2,E:E) -> 0
H3: Total Value of orders | I3: =sum(F:F) -> 0 | K3: ='Internal Summary'!B42 -> 1Ltrs Bugo Unsweetened Greek Yoghurt (6x) | L3: =sumif(D:D,K3,E:E) -> 0
K4: ='Internal Summary'!B43 -> 350ml Bugo Plain Yoghurt (12x) | L4: =sumif(D:D,K4,E:E) -> 0
K5: ='Internal Summary'!B44 -> 350ml Bugo Strawberry Yoghurt (12x) | L5: =sumif(D:D,K5,E:E) -> 0
K6: ='Internal Summary'!B45 -> 350ml Bugo Vanila Yoghurt (12x) | L6: =sumif(D:D,K6,E:E) -> 0
K7: ='Internal Summary'!B46 -> 500ml Bugo Plain Yoghurt (12x) | L7: =sumif(D:D,K7,E:E) -> 0
K8: ='Internal Summary'!B47 -> 500ml Bugo Strawberry Yoghurt (12x) | L8: =sumif(D:D,K8,E:E) -> 0
K9: ='Internal Summary'!B48 -> 500ml Bugo Sweetened Greek Yoghurt (12x) | L9: =sumif(D:D,K9,E:E) -> 0
K10: ='Internal Summary'!B49 -> 500ml Bugo Unsweetened Greek Yoghurt (12x) | L10: =sumif(D:D,K10,E:E) -> 0
K11: ='Internal Summary'!B50 -> 500ml Bugo Vanila Yoghurt (12x) | L11: =sumif(D:D,K11,E:E) -> 0
K12: ='Internal Summary'!B51 | L12: =sumif(D:D,K12,E:E) -> 0
K13: ='Internal Summary'!B52 | L13: =sumif(D:D,K13,E:E) -> 0

Sheet Internal Summary
B1: Description | C1: Units | D1: measurements | E1: total
A2: SALES | B2: Total Invoices Delivered | E2: ='Dala Sales & Deliveries'!I1+'External Delivery Fulfillment'!I1 -> 17
B3: Unique Locations Delivered To | E3: ='Raw Data'!AX2 -> 15
B4: Value of Dala Deliveries | E4: ='Dala Sales & Deliveries'!I3 -> 639600
B5: Value of External Deliveries | E5: ='External Delivery Fulfillment'!I3 -> 0
B6: VAT on sales
B7: Total Value of Deliveries | E7: =sum(E4:E6) -> 639600
A8: Remittance & Deductions | B8: Total Remitted to Partner
B9: Collection Fees | C9: 0.1 | E9: =E8*(C9+100%)-E8 -> 0
A10: Invoice Value Due | B10: Outstanding Paymets For Sales | E10: =E7-E8-E9 -> 639600
A11: Debts | B11: Unpaid Subscription | C11: 0 | D11: 0 | E11: =C11*D11 -> 0
B12: Collection Fees | E12: =E10*C9 -> 63960
B13: Delivery Fees | E13: =C27 -> 31980
B14: Delivery Fees External & Pickup | D14: Table 1 | E14: =C23+C29 -> 0
B15: Reimbursements Due To DALA | E15: 0
B16: Retailer Deductions | E16: =C31 -> 0
B17: Total Deductions | E17: =sum(E11:E16) -> 95940
A18: Remmittance Due | B18: Total Balance to Remitt | E18: =E10-E17+C37 -> 543660
A21: Inventory and Operational Fees
B22: Dala Pickup for Warehouse | C22: =U70 -> 0
B23: Warehouse Delivery Fee | C23: ='Dala Restocking'!I3*3% -> 0
B24: Forwarding to Retail | C24: =S70 -> 0
B25: Forwarding Delivery Fee | C25: =T70 -> 0
B26: Dala Sales | C26: 0
B27: Dala Delivery Fees | C27: =E10*5% -> 31980
B28: Exteranl Deliveries | C28: =Q70 -> 0
B29: External Delivery Fees | C29: ='External Delivery Fulfillment'!I4*5% -> 0
B30: Product Defects and Expirey Issues | C30: =F70 -> 0
B31: Deductions From Retailer | C31: =G70 -> 0
B32: Samples used | C32: =I70 -> 0
B33: Produce Replacements | C33: =J70 -> 0
B34: Expected Closing Inventory | C34: 0
B35: Physical Stock count | C35: =K70 -> 10.25
B36: Inventory Shortages | C36: 0
B37: Inventory Shortage Costs | C37: 0
B40: SKUs | C40: Retail Value | D40: Inbound Delivery Fee | E40: Outbound Delivery Fee | F40: Defects/Expirey | G40: Deductions | H40: Opening Inventory | I40: Samples Used | J40: Product Replacements | K40: Physical Closing Stock Count | L40: Expected Closing Inventory | M40: Inventory Shortages | N40: Shortages Costs | O40: Dala Deliveries | P40: Retail Sales Fee | Q40: External Delivery | R40: External Delivery Fee | S40: Forwarding from Client | T40: Forwarding Delivery Fee | U40: Dala Restocking | V40: Dala Restocking Fee | W40: Client Restocking
B41: 1Ltrs Bugo Sweetened Greek Yoghurt (6x) | G41: =F41*C41 -> 0 | K41: 0 | L41: 0 | M41: =K41-L41 -> 0 | N41: =M41*C41 -> 0 | O41: ='Dala Sales & Deliveries'!L2 -> 0 | P41: =O41*E41 -> 0 | Q41: ='External Delivery Fulfillment'!L2 -> 0 | R41: =Q41*E41 -> 0 | S41: ='Forwarding From Client'!L2 -> 0 | T41: =S41*E41 -> 0 | U41: ='Dala Restocking'!L2 -> 0 | V41: =U41*D41 -> 0 | W41: ='Client Restocking'!L2 -> 0
B42: 1Ltrs Bugo Unsweetened Greek Yoghurt (6x) | G42: =F42*C42 -> 0 | K42: 0 | L42: 0 | M42: =K42-L42 -> 0 | N42: =M42*C42 -> 0 | O42: ='Dala Sales & Deliveries'!L3 -> 0 | P42: =O42*E42 -> 0 | Q42: ='External Delivery Fulfillment'!L3 -> 0 | R42: =Q42*E42 -> 0 | S42: ='Forwarding From Client'!L3 -> 0 | T42: =S42*E42 -> 0 | U42: ='Dala Restocking'!L3 -> 0 | V42: =U42*D42 -> 0 | W42: ='Client Restocking'!L3 -> 0
B43: 350ml Bugo Plain Yoghurt (12x) | G43: =F43*C43 -> 0 | K43: 0 | L43: 0 | M43: =K43-L43 -> 0 | N43: =M43*C43 -> 0 | O43: ='Dala Sales & Deliveries'!L4 -> 0 | P43: =O43*E43 -> 0 | Q43: ='External Delivery Fulfillment'!L4 -> 0 | R43: =Q43*E43 -> 0 | S43: ='Forwarding From Client'!L4 -> 0 | T43: =S43*E43 -> 0 | U43: ='Dala Restocking'!L4 -> 0 | V43: =U43*D43 -> 0 | W43: ='Client Restocking'!L4 -> 0
B44: 350ml Bugo Strawberry Yoghurt (12x) | G44: =F44*C44 -> 0 | K44: 5.5 | L44: 0 | M44: =K44-L44 -> 5.5 | N44: =M44*C44 -> 0 | O44: ='Dala Sales & Deliveries'!L5 -> 3.5 | P44: =O44*E44 -> 0 | Q44: ='External Delivery Fulfillment'!L5 -> 0 | R44: =Q44*E44 -> 0 | S44: ='Forwarding From Client'!L5 -> 0 | T44: =S44*E44 -> 0 | U44: ='Dala Restocking'!L5 -> 0 | V44: =U44*D44 -> 0 | W44: ='Client Restocking'!L5 -> 0
...
