Workbook

Sheet Raw Data
A1: Exported from Tally | I1: Dala Sales & Deliveries | Q1: External Deliveries | Y1: Forwarding From Client | AG1: Client Restock | AO1: Dala Restock | AW1: Unique Locations
A2: item name | B2: Date | C2: Particulars | D2: Vch Type | E2: Vch No. | F2: Quantity | G2: Value | I2: item name | J2: Date | K2: Particulars | L2: Vch Type | M2: Vch No. | N2: Quantity | O2: Value | P2: Total Value | Q2: item name | R2: Date | S2: Particulars | T2: Vch Type | U2: Vch No. | V2: Quantity | W2: Value | Y2: item name | Z2: Date | AA2: Particulars | AB2: Vch Type | AC2: Vch No. | AD2: Quantity | AE2: Value | AG2: item name | AH2: Date | AI2: Particulars | AJ2: Vch Type | AK2: Vch No. | AL2: Quantity | AM2: Value | AO2: item name | AP2: Date | AQ2: Particulars | AR2: Vch Type | AS2: Vch No. | AT2: Quantity | AU2: Value | AW2: {=counta(unique(C:C))-2} -> 9
A3: 350ml Orisirisi Wallnut Drink (12x) | B3: 46072 | C3: Orisirisi Catring Service | D3: Inventory Supplied by Brands | E3: 2055 | F3: 1.75 | G3: 37800 | I3: =IFERROR(__xludf.DUMMYFUNCTION("IFERROR( FILTER($A$3:$G1844, LEN($A$3:$A1844), LOWER(TRIM($D$3:$D1844))=""sales""), )"),"350ml Orisirisi Wallnut with Ginger Drink (12x)") -> 350ml Orisirisi Wallnut with Ginger Drink (12x) | J3: =IFERROR(__xludf.DUMMYFUNCTION("""COMPUTED_VALUE"""),46069.0) -> 46069 | K3: =IFERROR(__xludf.DUMMYFUNCTION("""COMPUTED_VALUE"""),"Jendol Supermarket, AKASOLORI") -> Jendol Supermarket, AKASOLORI | L3: =IFERROR(__xludf.DUMMYFUNCTION("""COMPUTED_VALUE"""),"Sales") -> Sales | M3: =IFERROR(__xludf.DUMMYFUNCTION("""COMPUTED_VALUE"""),"DT:000958") -> DT:000958 | N3: =IFERROR(__xludf.DUMMYFUNCTION("""COMPUTED_VALUE"""),0.5) -> 0.5 | O3: =IFERROR(__xludf.DUMMYFUNCTION("""COMPUTED_VALUE"""),10800.0) -> 10800 | P3: =SUMIF(M:M,M3,O:O) -> 62400 | Q3: =IFERROR(__xludf.DUMMYFUNCTION("IFERROR( FILTER($A$3:$G1844, LEN($A$3:$A1844), REGEXMATCH(LOWER(TRIM($D$3:$D1844)), ""\bjournal\b"")), )"),"") | AG3: =IFERROR(__xludf.DUMMYFUNCTION("IFERROR(FILTER($A$3:$G1844, LEN($A$3:$A1844), LOWER(TRIM($D$3:$D1844))=""Inventory Supplied by Brands""),)"),"350ml Orisirisi Wallnut Drink (12x)") -> 350ml Orisirisi Wallnut Drink (12x) | AH3: =IFERROR(__xludf.DUMMYFUNCTION("""COMPUTED_VALUE"""),46072.0) -> 46072 | AI3: =IFERROR(__xludf.DUMMYFUNCTION("""COMPUTED_VALUE"""),"Orisirisi Catring Service") -> Orisirisi Catring Service | AJ3: =IFERROR(__xludf.DUMMYFUNCTION("""COMPUTED_VALUE"""),"Inventory Supplied by Brands") -> Inventory Supplied by Brands | AK3: =IFERROR(__xludf.DUMMYFUNCTION("""COMPUTED_VALUE"""),2055.0) -> 2055 | AL3: =IFERROR(__xludf.DUMMYFUNCTION("""COMPUTED_VALUE"""),1.75) -> 1.75 | AM3: =IFERROR(__xludf.DUMMYFUNCTION("""COMPUTED_VALUE"""),37800.0) -> 37800 | AO3: =IFERROR(__xludf.DUMMYFUNCTION("IFERROR(FILTER($A$3:$G1844, LEN($A$3:$A1844), LOWER(TRIM($D$3:$D1844))=""Inventory Pickup by Dala""),) "),"")
A4: 350ml Orisirisi Wallnut with Ginger Drink (12x) | B4: 46072 | C4: Orisirisi Catring Service | D4: Inventory Supplied by Brands | E4: 2055 | F4: 6 | G4: 129600 | I4: =IFERROR(__xludf.DUMMYFUNCTION("""COMPUTED_VALUE"""),"350ml Orisirisi Wallnut with Ginger Drink (12x)") -> 350ml Orisirisi Wallnut with Ginger Drink (12x) | J4: =IFERROR(__xludf.DUMMYFUNCTION("""COMPUTED_VALUE"""),46072.0) -> 46072 | K4: =IFERROR(__xludf.DUMMYFUNCTION("""COMPUTED_VALUE"""),"Buymore Supermarket, ISHERI") -> Buymore Supermarket, ISHERI | L4: =IFERROR(__xludf.DUMMYFUNCTION("""COMPUTED_VALUE"""),"Sales") -> Sales | M4: =IFERROR(__xludf.DUMMYFUNCTION("""COMPUTED_VALUE"""),"DT:001044") -> DT:001044 | N4: =IFERROR(__xludf.DUMMYFUNCTION("""COMPUTED_VALUE"""),1.0) -> 1 | O4: =IFERROR(__xludf.DUMMYFUNCTION("""COMPUTED_VALUE"""),21600.0) -> 21600 | P4: =SUMIF(M:M,M4,O:O) -> 21600 | AG4: =IFERROR(__xludf.DUMMYFUNCTION("""COMPUTED_VALUE"""),"350ml Orisirisi Wallnut with Ginger Drink (12x)") -> 350ml Orisirisi Wallnut with Ginger Drink (12x) | AH4: =IFERROR(__xludf.DUMMYFUNCTION("""COMPUTED_VALUE"""),46072.0) -> 46072 | AI4: =IFERROR(__xludf.DUMMYFUNCTION("""COMPUTED_VALUE"""),"Orisirisi Catring Service") -> Orisirisi Catring Service | AJ4: =IFERROR(__xludf.DUMMYFUNCTION("""COMPUTED_VALUE"""),"Inventory Supplied by Brands") -> Inventory Supplied by Brands | AK4: =IFERROR(__xludf.DUMMYFUNCTION("""COMPUTED_VALUE"""),2055.0) -> 2055 | AL4: =IFERROR(__xludf.DUMMYFUNCTION("""COMPUTED_VALUE"""),6.0) -> 6 | AM4: =IFERROR(__xludf.DUMMYFUNCTION("""COMPUTED_VALUE"""),129600.0) -> 129600
A5: 500ml Orisirisi Tiger Nut Drink (12x) | B5: 46072 | C5: Orisirisi Catring Service | D5: Inventory Supplied by Brands | E5: 2055 | F5: 8 | G5: 220800 | I5: =IFERROR(__xludf.DUMMYFUNCTION("""COMPUTED_VALUE"""),"500ml Orisirisi Tiger Nut Drink (12x)") -> 500ml Orisirisi Tiger Nut Drink (12x) | J5: =IFERROR(__xludf.DUMMYFUNCTION("""COMPUTED_VALUE"""),46066.0) -> 46066 | K5: =IFERROR(__xludf.DUMMYFUNCTION("""COMPUTED_VALUE"""),"Individual") -> Individual | L5: =IFERROR(__xludf.DUMMYFUNCTION("""COMPUTED_VALUE"""),"Sales") -> Sales | M5: =IFERROR(__xludf.DUMMYFUNCTION("""COMPUTED_VALUE"""),"DT:000885") -> DT:000885 | N5: =IFERROR(__xludf.DUMMYFUNCTION("""COMPUTED_VALUE"""),0.25) -> 0.25 | O5: =IFERROR(__xludf.DUMMYFUNCTION("""COMPUTED_VALUE"""),6900.0) -> 6900 | P5: =SUMIF(M:M,M5,O:O) -> 6900 | AG5: =IFERROR(__xludf.DUMMYFUNCTION("""COMPUTED_VALUE"""),"500ml Orisirisi Tiger Nut Drink (12x)") -> 500ml Orisirisi Tiger Nut Drink (12x) | AH5: =IFERROR(__xludf.DUMMYFUNCTION("""COMPUTED_VALUE"""),46072.0) -> 46072 | AI5: =IFERROR(__xludf.DUMMYFUNCTION("""COMPUTED_VALUE"""),"Orisirisi Catring Service") -> Orisirisi Catring Service | AJ5: =IFERROR(__xludf.DUMMYFUNCTION("""COMPUTED_VALUE"""),"Inventory Supplied by Brands") -> Inventory Supplied by Brands | AK5: =IFERROR(__xludf.DUMMYFUNCTION("""COMPUTED_VALUE"""),2055.0) -> 2055 | AL5: =IFERROR(__xludf.DUMMYFUNCTION("""COMPUTED_VALUE"""),8.0) -> 8 | AM5: =IFERROR(__xludf.DUMMYFUNCTION("""COMPUTED_VALUE"""),220800.0) -> 220800
A6: 500ml Orisirisi Zobo Drink (12x) | B6: 46072 | C6: Orisirisi Catring Service | D6: Inventory Supplied by Brands | E6: 2055 | F6: 9 | G6: 216000 | I6: =IFERROR(__xludf.DUMMYFUNCTION("""COMPUTED_VALUE"""),"500ml Orisirisi Tiger Nut Drink (12x)") -> 500ml Orisirisi Tiger Nut Drink (12x) | J6: =IFERROR(__xludf.DUMMYFUNCTION("""COMPUTED_VALUE"""),46066.0) -> 46066 | K6: =IFERROR(__xludf.DUMMYFUNCTION("""COMPUTED_VALUE"""),"Alvira Mart") -> Alvira Mart | L6: =IFERROR(__xludf.DUMMYFUNCTION("""COMPUTED_VALUE"""),"Sales") -> Sales | M6: =IFERROR(__xludf.DUMMYFUNCTION("""COMPUTED_VALUE"""),"DT:000910") -> DT:000910 | N6: =IFERROR(__xludf.DUMMYFUNCTION("""COMPUTED_VALUE"""),1.0) -> 1 | O6: =IFERROR(__xludf.DUMMYFUNCTION("""COMPUTED_VALUE"""),27600.0) -> 27600 | P6: =SUMIF(M:M,M6,O:O) -> 51600 | AG6: =IFERROR(__xludf.DUMMYFUNCTION("""COMPUTED_VALUE"""),"500ml Orisirisi Zobo Drink (12x)") -> 500ml Orisirisi Zobo Drink (12x) | AH6: =IFERROR(__xludf.DUMMYFUNCTION("""COMPUTED_VALUE"""),46072.0) -> 46072 | AI6: =IFERROR(__xludf.DUMMYFUNCTION("""COMPUTED_VALUE"""),"Orisirisi Catring Service") -> Orisirisi Catring Service | AJ6: =IFERROR(__xludf.DUMMYFUNCTION("""COMPUTED_VALUE"""),"Inventory Supplied by Brands") -> Inventory Supplied by Brands | AK6: =IFERROR(__xludf.DUMMYFUNCTION("""COMPUTED_VALUE"""),2055.0) -> 2055 | AL6: =IFERROR(__xludf.DUMMYFUNCTION("""COMPUTED_VALUE"""),9.0) -> 9 | AM6: =IFERROR(__xludf.DUMMYFUNCTION("""COMPUTED_VALUE"""),216000.0) -> 216000
A7: 500ml Orisirisi Zobo with Date Drink (12x) | B7: 46072 | C7: Orisirisi Catring Service | D7: Inventory Supplied by Brands | E7: 2055 | F7: 9 | G7: 216000 | I7: =IFERROR(__xludf.DUMMYFUNCTION("""COMPUTED_VALUE"""),"500ml Orisirisi Tiger Nut Drink (12x)") -> 500ml Orisirisi Tiger Nut Drink (12x) | J7: =IFERROR(__xludf.DUMMYFUNCTION("""COMPUTED_VALUE"""),46069.0) -> 46069 | K7: =IFERROR(__xludf.DUMMYFUNCTION("""COMPUTED_VALUE"""),"CMART Supermarket, ONIRU") -> CMART Supermarket, ONIRU | L7: =IFERROR(__xludf.DUMMYFUNCTION("""COMPUTED_VALUE"""),"Sales") -> Sales | M7: =IFERROR(__xludf.DUMMYFUNCTION("""COMPUTED_VALUE"""),"DT:000938") -> DT:000938 | N7: =IFERROR(__xludf.DUMMYFUNCTION("""COMPUTED_VALUE"""),0.5) -> 0.5 | O7: =IFERROR(__xludf.DUMMYFUNCTION("""COMPUTED_VALUE"""),13800.0) -> 13800 | P7: =SUMIF(M:M,M7,O:O) -> 37800 | AG7: =IFERROR(__xludf.DUMMYFUNCTION("""COMPUTED_VALUE"""),"500ml Orisirisi Zobo with Date Drink (12x)") -> 500ml Orisirisi Zobo with Date Drink (12x) | AH7: =IFERROR(__xludf.DUMMYFUNCTION("""COMPUTED_VALUE"""),46072.0) -> 46072 | AI7: =IFERROR(__xludf.DUMMYFUNCTION("""COMPUTED_VALUE"""),"Orisirisi Catring Service") -> Orisirisi Catring Service | AJ7: =IFERROR(__xludf.DUMMYFUNCTION("""COMPUTED_VALUE"""),"Inventory Supplied by Brands") -> Inventory Supplied by Brands | AK7: =IFERROR(__xludf.DUMMYFUNCTION("""COMPUTED_VALUE"""),2055.0) -> 2055 | AL7: =IFERROR(__xludf.DUMMYFUNCTION("""COMPUTED_VALUE"""),9.0) -> 9 | AM7: =IFERROR(__xludf.DUMMYFUNCTION("""COMPUTED_VALUE"""),216000.0) -> 216000
A8: 350ml Orisirisi Wallnut with Ginger Drink (12x) | B8: 46069 | C8: Jendol Supermarket, AKASOLORI | D8: Sales | E8: DT:000958 | F8: 0.5 | G8: 10800 | I8: =IFERROR(__xludf.DUMMYFUNCTION("""COMPUTED_VALUE"""),"500ml Orisirisi Tiger Nut Drink (12x)") -> 500ml Orisirisi Tiger Nut Drink (12x) | J8: =IFERROR(__xludf.DUMMYFUNCTION("""COMPUTED_VALUE"""),46069.0) -> 46069 | K8: =IFERROR(__xludf.DUMMYFUNCTION("""COMPUTED_VALUE"""),"Jendol Supermarket, AKASOLORI") -> Jendol Supermarket, AKASOLORI | L8: =IFERROR(__xludf.DUMMYFUNCTION("""COMPUTED_VALUE"""),"Sales") -> Sales | M8: =IFERROR(__xludf.DUMMYFUNCTION("""COMPUTED_VALUE"""),"DT:000958") -> DT:000958 | N8: =IFERROR(__xludf.DUMMYFUNCTION("""COMPUTED_VALUE"""),1.0) -> 1 | O8: =IFERROR(__xludf.DUMMYFUNCTION("""COMPUTED_VALUE"""),27600.0) -> 27600 | P8: =SUMIF(M:M,M8,O:O) -> 62400
A9: 350ml Orisirisi Wallnut with Ginger Drink (12x) | B9: 46072 | C9: Buymore Supermarket, ISHERI | D9: Sales | E9: DT:001044 | F9: 1 | G9: 21600 | I9: =IFERROR(__xludf.DUMMYFUNCTION("""COMPUTED_VALUE"""),"500ml Orisirisi Tiger Nut Drink (12x)") -> 500ml Orisirisi Tiger Nut Drink (12x) | J9: =IFERROR(__xludf.DUMMYFUNCTION("""COMPUTED_VALUE"""),46069.0) -> 46069 | K9: =IFERROR(__xludf.DUMMYFUNCTION("""COMPUTED_VALUE"""),"Jendol Supermarket, IJEDE") -> Jendol Supermarket, IJEDE | L9: =IFERROR(__xludf.DUMMYFUNCTION("""COMPUTED_VALUE"""),"Sales") -> Sales | M9: =IFERROR(__xludf.DUMMYFUNCTION("""COMPUTED_VALUE"""),"DT:000959") -> DT:000959 | N9: =IFERROR(__xludf.DUMMYFUNCTION("""COMPUTED_VALUE"""),1.0) -> 1 | O9: =IFERROR(__xludf.DUMMYFUNCTION("""COMPUTED_VALUE"""),27600.0) -> 27600 | P9: =SUMIF(M:M,M9,O:O) -> 27600
A10: 500ml Orisirisi Tiger Nut Drink (12x) | B10: 46066 | C10: Individual | D10: Sales | E10: DT:000885 | F10: 0.25 | G10: 6900 | I10: =IFERROR(__xludf.DUMMYFUNCTION("""COMPUTED_VALUE"""),"500ml Orisirisi Tiger Nut Drink (12x)") -> 500ml Orisirisi Tiger Nut Drink (12x) | J10: =IFERROR(__xludf.DUMMYFUNCTION("""COMPUTED_VALUE"""),46071.0) -> 46071 | K10: =IFERROR(__xludf.DUMMYFUNCTION("""COMPUTED_VALUE"""),"Renees Supermarket, LEKKI CENTRAL MOSQUE") -> Renees Supermarket, LEKKI CENTRAL MOSQUE | L10: =IFERROR(__xludf.DUMMYFUNCTION("""COMPUTED_VALUE"""),"Sales") -> Sales | M10: =IFERROR(__xludf.DUMMYFUNCTION("""COMPUTED_VALUE"""),"DT:000973") -> DT:000973 | N10: =IFERROR(__xludf.DUMMYFUNCTION("""COMPUTED_VALUE"""),1.0) -> 1 | O10: =IFERROR(__xludf.DUMMYFUNCTION("""COMPUTED_VALUE"""),27600.0) -> 27600 | P10: =SUMIF(M:M,M10,O:O) -> 27600
A11: 500ml Orisirisi Tiger Nut Drink (12x) | B11: 46066 | C11: Alvira Mart | D11: Sales | E11: DT:000910 | F11: 1 | G11: 27600 | I11: =IFERROR(__xludf.DUMMYFUNCTION("""COMPUTED_VALUE"""),"500ml Orisirisi Tiger Nut Drink (12x)") -> 500ml Orisirisi Tiger Nut Drink (12x) | J11: =IFERROR(__xludf.DUMMYFUNCTION("""COMPUTED_VALUE"""),46071.0) -> 46071 | K11: =IFERROR(__xludf.DUMMYFUNCTION("""COMPUTED_VALUE"""),"Value Village Superstore") -> Value Village Superstore | L11: =IFERROR(__xludf.DUMMYFUNCTION("""COMPUTED_VALUE"""),"Sales") -> Sales | M11: =IFERROR(__xludf.DUMMYFUNCTION("""COMPUTED_VALUE"""),"DT:000983") -> DT:000983 | N11: =IFERROR(__xludf.DUMMYFUNCTION("""COMPUTED_VALUE"""),1.0) -> 1 | O11: =IFERROR(__xludf.DUMMYFUNCTION("""COMPUTED_VALUE"""),27600.0) -> 27600 | P11: =SUMIF(M:M,M11,O:O) -> 27600
A12: 500ml Orisirisi Tiger Nut Drink (12x) | B12: 46069 | C12: CMART Supermarket, ONIRU | D12: Sales | E12: DT:000938 | F12: 0.5 | G12: 13800 | I12: =IFERROR(__xludf.DUMMYFUNCTION("""COMPUTED_VALUE"""),"500ml Orisirisi Zobo Drink (12x)") -> 500ml Orisirisi Zobo Drink (12x) | J12: =IFERROR(__xludf.DUMMYFUNCTION("""COMPUTED_VALUE"""),46069.0) -> 46069 | K12: =IFERROR(__xludf.DUMMYFUNCTION("""COMPUTED_VALUE"""),"CMART Supermarket, ONIRU") -> CMART Supermarket, ONIRU | L12: =IFERROR(__xludf.DUMMYFUNCTION("""COMPUTED_VALUE"""),"Sales") -> Sales | M12: =IFERROR(__xludf.DUMMYFUNCTION("""COMPUTED_VALUE"""),"DT:000938") -> DT:000938 | N12: =IFERROR(__xludf.DUMMYFUNCTION("""COMPUTED_VALUE"""),0.5) -> 0.5 | O12: =IFERROR(__xludf.DUMMYFUNCTION("""COMPUTED_VALUE"""),12000.0) -> 12000 | P12: =SUMIF(M:M,M12,O:O) -> 37800
A13: 500ml Orisirisi Tiger Nut Drink (12x) | B13: 46069 | C13: Jendol Supermarket, AKASOLORI | D13: Sales | E13: DT:000958 | F13: 1 | G13: 27600 | I13: =IFERROR(__xludf.DUMMYFUNCTION("""COMPUTED_VALUE"""),"500ml Orisirisi Zobo Drink (12x)") -> 500ml Orisirisi Zobo Drink (12x) | J13: =IFERROR(__xludf.DUMMYFUNCTION("""COMPUTED_VALUE"""),46071.0) -> 46071 | K13: =IFERROR(__xludf.DUMMYFUNCTION("""COMPUTED_VALUE"""),"Compramart Supermarket, MOBILE Rd.") -> Compramart Supermarket, MOBILE Rd. | L13: =IFERROR(__xludf.DUMMYFUNCTION("""COMPUTED_VALUE"""),"Sales") -> Sales | M13: =IFERROR(__xludf.DUMMYFUNCTION("""COMPUTED_VALUE"""),"DT:001056") -> DT:001056 | N13: =IFERROR(__xludf.DUMMYFUNCTION("""COMPUTED_VALUE"""),0.5) -> 0.5 | O13: =IFERROR(__xludf.DUMMYFUNCTION("""COMPUTED_VALUE"""),12000.0) -> 12000 | P13: =SUMIF(M:M,M13,O:O) -> 24000
A14: 500ml Orisirisi Tiger Nut Drink (12x) | B14: 46069 | C14: Jendol Supermarket, IJEDE | D14: Sales | E14: DT:000959 | F14: 1 | G14: 27600 | I14: =IFERROR(__xludf.DUMMYFUNCTION("""COMPUTED_VALUE"""),"500ml Orisirisi Zobo with Date Drink (12x)") -> 500ml Orisirisi Zobo with Date Drink (12x) | J14: =IFERROR(__xludf.DUMMYFUNCTION("""COMPUTED_VALUE"""),46066.0) -> 46066 | K14: =IFERROR(__xludf.DUMMYFUNCTION("""COMPUTED_VALUE"""),"Alvira Mart") -> Alvira Mart | L14: =IFERROR(__xludf.DUMMYFUNCTION("""COMPUTED_VALUE"""),"Sales") -> Sales | M14: =IFERROR(__xludf.DUMMYFUNCTION("""COMPUTED_VALUE"""),"DT:000910") -> DT:000910 | N14: =IFERROR(__xludf.DUMMYFUNCTION("""COMPUTED_VALUE"""),1.0) -> 1 | O14: =IFERROR(__xludf.DUMMYFUNCTION("""COMPUTED_VALUE"""),24000.0) -> 24000 | P14: =SUMIF(M:M,M14,O:O) -> 51600
A15: 500ml Orisirisi Tiger Nut Drink (12x) | B15: 46071 | C15: Renees Supermarket, LEKKI CENTRAL MOSQUE | D15: Sales | E15: DT:000973 | F15: 1 | G15: 27600 | I15: =IFERROR(__xludf.DUMMYFUNCTION("""COMPUTED_VALUE"""),"500ml Orisirisi Zobo with Date Drink (12x)") -> 500ml Orisirisi Zobo with Date Drink (12x) | J15: =IFERROR(__xludf.DUMMYFUNCTION("""COMPUTED_VALUE"""),46069.0) -> 46069 | K15: =IFERROR(__xludf.DUMMYFUNCTION("""COMPUTED_VALUE"""),"CMART Supermarket, ONIRU") -> CMART Supermarket, ONIRU | L15: =IFERROR(__xludf.DUMMYFUNCTION("""COMPUTED_VALUE"""),"Sales") -> Sales | M15: =IFERROR(__xludf.DUMMYFUNCTION("""COMPUTED_VALUE"""),"DT:000938") -> DT:000938 | N15: =IFERROR(__xludf.DUMMYFUNCTION("""COMPUTED_VALUE"""),0.5) -> 0.5 | O15: =IFERROR(__xludf.DUMMYFUNCTION("""COMPUTED_VALUE"""),12000.0) -> 12000 | P15: =SUMIF(M:M,M15,O:O) -> 37800
A16: 500ml Orisirisi Tiger Nut Drink (12x) | B16: 46071 | C16: Value Village Superstore | D16: Sales | E16: DT:000983 | F16: 1 | G16: 27600 | I16: =IFERROR(__xludf.DUMMYFUNCTION("""COMPUTED_VALUE"""),"500ml Orisirisi Zobo with Date Drink (12x)") -> 500ml Orisirisi Zobo with Date Drink (12x) | J16: =IFERROR(__xludf.DUMMYFUNCTION("""COMPUTED_VALUE"""),46069.0) -> 46069 | K16: =IFERROR(__xludf.DUMMYFUNCTION("""COMPUTED_VALUE"""),"Jendol Supermarket, AKASOLORI") -> Jendol Supermarket, AKASOLORI | L16: =IFERROR(__xludf.DUMMYFUNCTION("""COMPUTED_VALUE"""),"Sales") -> Sales | M16: =IFERROR(__xludf.DUMMYFUNCTION("""COMPUTED_VALUE"""),"DT:000958") -> DT:000958 | N16: =IFERROR(__xludf.DUMMYFUNCTION("""COMPUTED_VALUE"""),1.0) -> 1 | O16: =IFERROR(__xludf.DUMMYFUNCTION("""COMPUTED_VALUE"""),24000.0) -> 24000 | P16: =SUMIF(M:M,M16,O:O) -> 62400
A17: 500ml Orisirisi Zobo Drink (12x) | B17: 46069 | C17: CMART Supermarket, ONIRU | D17: Sales | E17: DT:000938 | F17: 0.5 | G17: 12000 | I17: =IFERROR(__xludf.DUMMYFUNCTION("""COMPUTED_VALUE"""),"500ml Orisirisi Zobo with Date Drink (12x)") -> 500ml Orisirisi Zobo with Date Drink (12x) | J17: =IFERROR(__xludf.DUMMYFUNCTION("""COMPUTED_VALUE"""),46071.0) -> 46071 | K17: =IFERROR(__xludf.DUMMYFUNCTION("""COMPUTED_VALUE"""),"Compramart Supermarket, MOBILE Rd.") -> Compramart Supermarket, MOBILE Rd. | L17: =IFERROR(__xludf.DUMMYFUNCTION("""COMPUTED_VALUE"""),"Sales") -> Sales | M17: =IFERROR(__xludf.DUMMYFUNCTION("""COMPUTED_VALUE"""),"DT:001056") -> DT:001056 | N17: =IFERROR(__xludf.DUMMYFUNCTION("""COMPUTED_VALUE"""),0.5) -> 0.5 | O17: =IFERROR(__xludf.DUMMYFUNCTION("""COMPUTED_VALUE"""),12000.0) -> 12000 | P17: =SUMIF(M:M,M17,O:O) -> 24000
A18: 500ml Orisirisi Zobo Drink (12x) | B18: 46071 | C18: Compramart Supermarket, MOBILE Rd. | D18: Sales | E18: DT:001056 | F18: 0.5 | G18: 12000 | P18: =SUMIF(M:M,M18,O:O) -> 0
A19: 500ml Orisirisi Zobo with Date Drink (12x) | B19: 46066 | C19: Alvira Mart | D19: Sales | E19: DT:000910 | F19: 1 | G19: 24000 | P19: =SUMIF(M:M,M19,O:O) -> 0
A20: 500ml Orisirisi Zobo with Date Drink (12x) | B20: 46069 | C20: CMART Supermarket, ONIRU | D20: Sales | E20: DT:000938 | F20: 0.5 | G20: 12000 | P20: =SUMIF(M:M,M20,O:O) -> 0
A21: 500ml Orisirisi Zobo with Date Drink (12x) | B21: 46069 | C21: Jendol Supermarket, AKASOLORI | D21: Sales | E21: DT:000958 | F21: 1 | G21: 24000 | P21: =SUMIF(M:M,M21,O:O) -> 0
A22: 500ml Orisirisi Zobo with Date Drink (12x) | B22: 46071 | C22: Compramart Supermarket, MOBILE Rd. | D22: Sales | E22: DT:001056 | F22: 0.5 | G22: 12000 | P22: =SUMIF(M:M,M22,O:O) -> 0
P23: =SUMIF(M:M,M23,O:O) -> 0
P24: =SUMIF(M:M,M24,O:O) -> 0
P25: =SUMIF(M:M,M25,O:O) -> 0
P26: =SUMIF(M:M,M26,O:O) -> 0
P27: =SUMIF(M:M,M27,O:O) -> 0
P28: =SUMIF(M:M,M28,O:O) -> 0
P29: =SUMIF(M:M,M29,O:O) -> 0
P30: =SUMIF(M:M,M30,O:O) -> 0
P31: =SUMIF(M:M,M31,O:O) -> 0
P32: =SUMIF(M:M,M32,O:O) -> 0
P33: =SUMIF(M:M,M33,O:O) -> 0
P34: =SUMIF(M:M,M34,O:O) -> 0
... P277: =SUMIF(M:M,M277,O:O) -> 0
T975: {=counta(UNIQUE(S2:S960))-1} -> 0 | AI975: {=UNIQUE(AI2:AI590)} -> Particulars | AQ975: {=UNIQUE(AQ2:AQ590)} -> Particulars
AI976: Orisirisi Catring Service

Sheet Payment Advice
F2: =sum(D:D) -> 287100

Sheet Dala Sales & Deliveries
H1: Total Invoices Delivered | I1: =countifs(B:B,"<>",F:F,"<>")-1 -> 9 | K1: Sku Performance | L1: Units | M1: Value
H2: Unique Locations Supplied | I2: {=(COUNTA(UNIQUE(C:C))-1)} -> 9 | K2: ='Internal Summary'!B40 -> 350ml Orisirisi Wallnut Drink (12x) | L2: =sumif(D:D,K2,E:E) -> 0 | M2: =sumif(D:D,K2,F:F) -> 0
H3: Total Value of orders | I3: =sum(F:F) -> 287100 | K3: ='Internal Summary'!B41 -> 350ml Orisirisi Wallnut with Ginger Drink (12x) | L3: =sumif(D:D,K3,E:E) -> 1.5 | M3: =sumif(D:D,K3,F:F) -> 32400
K4: ='Internal Summary'!B42 -> 500ml Orisirisi Tiger Nut Drink (12x) | L4: =sumif(D:D,K4,E:E) -> 5.75 | M4: =sumif(D:D,K4,F:F) -> 158700
K5: ='Internal Summary'!B43 -> 500ml Orisirisi Zobo Drink (12x) | L5: =sumif(D:D,K5,E:E) -> 1 | M5: =sumif(D:D,K5,F:F) -> 24000
K6: ='Internal Summary'!B44 -> 500ml Orisirisi Zobo with Date Drink (12x) | L6: =sumif(D:D,K6,E:E) -> 3 | M6: =sumif(D:D,K6,F:F) -> 72000
K7: ='Internal Summary'!B45 | L7: =sumif(D:D,K7,E:E) -> 0 | M7: =sumif(D:D,K7,F:F) -> 0
K8: ='Internal Summary'!B46 | L8: =sumif(D:D,K8,E:E) -> 0 | M8: =sumif(D:D,K8,F:F) -> 0
K9: ='Internal Summary'!B47 | L9: =sumif(D:D,K9,E:E) -> 0 | M9: =sumif(D:D,K9,F:F) -> 0
K10: ='Internal Summary'!B48 | L10: =sumif(D:D,K10,E:E) -> 0 | M10: =sumif(D:D,K10,F:F) -> 0
K11: ='Internal Summary'!B49 | L11: =sumif(D:D,K11,E:E) -> 0 | M11: =sumif(D:D,K11,F:F) -> 0
K12: ='Internal Summary'!B50 | L12: =sumif(D:D,K12,E:E) -> 0 | M12: =sumif(D:D,K12,F:F) -> 0
K13: ='Internal Summary'!B51 | L13: =sumif(D:D,K13,E:E) -> 0 | M13: =sumif(D:D,K13,F:F) -> 0

Sheet External Delivery Fulfillment
H1: Total Invoices Delivered | I1: =countifs(B:B,"<>",F:F,"<>")-1 -> 0 | K1: Sku Performance | L1: Units | M1: Value
H2: Unique Locations Supplied | I2: {=(COUNTA(UNIQUE(C:C))-1)} -> 0 | K2: ='Internal Summary'!B40 -> 350ml Orisirisi Wallnut Drink (12x) | L2: =sumif(D:D,K2,E:E) -> 0 | M2: =sumif(D:D,K2,F:F) -> 0
H3: Total Value of orders | I3: =sum(F:F) -> 0 | K3: ='Internal Summary'!B41 -> 350ml Orisirisi Wallnut with Ginger Drink (12x) | L3: =sumif(D:D,K3,E:E) -> 0 | M3: =sumif(D:D,K3,F:F) -> 0
K4: ='Internal Summary'!B42 -> 500ml Orisirisi Tiger Nut Drink (12x) | L4: =sumif(D:D,K4,E:E) -> 0 | M4: =sumif(D:D,K4,F:F) -> 0
K5: ='Internal Summary'!B43 -> 500ml Orisirisi Zobo Drink (12x) | L5: =sumif(D:D,K5,E:E) -> 0 | M5: =sumif(D:D,K5,F:F) -> 0
K6: ='Internal Summary'!B44 -> 500ml Orisirisi Zobo with Date Drink (12x) | L6: =sumif(D:D,K6,E:E) -> 0 | M6: =sumif(D:D,K6,F:F) -> 0
K7: ='Internal Summary'!B45 | L7: =sumif(D:D,K7,E:E) -> 0 | M7: =sumif(D:D,K7,F:F) -> 0
K8: ='Internal Summary'!B46 | L8: =sumif(D:D,K8,E:E) -> 0 | M8: =sumif(D:D,K8,F:F) -> 0
K9: ='Internal Summary'!B47 | L9: =sumif(D:D,K9,E:E) -> 0 | M9: =sumif(D:D,K9,F:F) -> 0
K10: ='Internal Summary'!B48 | L10: =sumif(D:D,K10,E:E) -> 0 | M10: =sumif(D:D,K10,F:F) -> 0
K11: ='Internal Summary'!B49 | L11: =sumif(D:D,K11,E:E) -> 0 | M11: =sumif(D:D,K11,F:F) -> 0
K12: ='Internal Summary'!B50 | L12: =sumif(D:D,K12,E:E) -> 0 | M12: =sumif(D:D,K12,F:F) -> 0
K13: ='Internal Summary'!B51 | L13: =sumif(D:D,K13,E:E) -> 0 | M13: =sumif(D:D,K13,F:F) -> 0

Sheet Forwarding From Client
H1: Total Invoices Delivered | I1: =countifs(B:B,"<>",F:F,"<>")-1 -> 0 | K1: Sku Performance | L1: Units | M1: Value
H2: Unique Locations Supplied | I2: {=(COUNTA(UNIQUE(C:C))-1)} -> 0 | K2: ='Internal Summary'!B40 -> 350ml Orisirisi Wallnut Drink (12x) | L2: =sumif(D:D,K2,E:E) -> 0 | M2: =sumif(D:D,K2,F:F) -> 0
H3: Total Value of orders | I3: =sum(F:F) -> 0 | K3: ='Internal Summary'!B41 -> 350ml Orisirisi Wallnut with Ginger Drink (12x) | L3: =sumif(D:D,K3,E:E) -> 0 | M3: =sumif(D:D,K3,F:F) -> 0
K4: ='Internal Summary'!B42 -> 500ml Orisirisi Tiger Nut Drink (12x) | L4: =sumif(D:D,K4,E:E) -> 0 | M4: =sumif(D:D,K4,F:F) -> 0
K5: ='Internal Summary'!B43 -> 500ml Orisirisi Zobo Drink (12x) | L5: =sumif(D:D,K5,E:E) -> 0 | M5: =sumif(D:D,K5,F:F) -> 0
K6: ='Internal Summary'!B44 -> 500ml Orisirisi Zobo with Date Drink (12x) | L6: =sumif(D:D,K6,E:E) -> 0 | M6: =sumif(D:D,K6,F:F) -> 0
K7: ='Internal Summary'!B45 | L7: =sumif(D:D,K7,E:E) -> 0 | M7: =sumif(D:D,K7,F:F) -> 0
K8: ='Internal Summary'!B46 | L8: =sumif(D:D,K8,E:E) -> 0 | M8: =sumif(D:D,K8,F:F) -> 0
K9: ='Internal Summary'!B47 | L9: =sumif(D:D,K9,E:E) -> 0 | M9: =sumif(D:D,K9,F:F) -> 0
K10: ='Internal Summary'!B48 | L10: =sumif(D:D,K10,E:E) -> 0 | M10: =sumif(D:D,K10,F:F) -> 0
K11: ='Internal Summary'!B49 | L11: =sumif(D:D,K11,E:E) -> 0 | M11: =sumif(D:D,K11,F:F) -> 0
K12: ='Internal Summary'!B50 | L12: =sumif(D:D,K12,E:E) -> 0 | M12: =sumif(D:D,K12,F:F) -> 0
K13: ='Internal Summary'!B51 | L13: =sumif(D:D,K13,E:E) -> 0 | M13: =sumif(D:D,K13,F:F) -> 0

Sheet Dala Restocking
H1: Total Invoices Delivered | I1: =countifs(B:B,"<>",F:F,"<>")-1 -> 0 | K1: Sku Performance | L1: Units
H2: Unique Locations Supplied | I2: {=(COUNTA(UNIQUE(C:C,,0))-1)} -> 0 | K2: ='Internal Summary'!B40 -> 350ml Orisirisi Wallnut Drink (12x) | L2: =sumif(D:D,K2,E:E) -> 0
H3: Total Value of orders | I3: =sum(F:F) -> 0 | K3: ='Internal Summary'!B41 -> 350ml Orisirisi Wallnut with Ginger Drink (12x) | L3: =sumif(D:D,K3,E:E) -> 0
K4: ='Internal Summary'!B42 -> 500ml Orisirisi Tiger Nut Drink (12x) | L4: =sumif(D:D,K4,E:E) -> 0
K5: ='Internal Summary'!B43 -> 500ml Orisirisi Zobo Drink (12x) | L5: =sumif(D:D,K5,E:E) -> 0
K6: ='Internal Summary'!B44 -> 500ml Orisirisi Zobo with Date Drink (12x) | L6: =sumif(D:D,K6,E:E) -> 0
K7: ='Internal Summary'!B45 | L7: =sumif(D:D,K7,E:E) -> 0
K8: ='Internal Summary'!B46 | L8: =sumif(D:D,K8,E:E) -> 0
K9: ='Internal Summary'!B47 | L9: =sumif(D:D,K9,E:E) -> 0
K10: ='Internal Summary'!B48 | L10: =sumif(D:D,K10,E:E) -> 0
K11: ='Internal Summary'!B49 | L11: =sumif(D:D,K11,E:E) -> 0
K12: ='Internal Summary'!B50 | L12: =sumif(D:D,K12,E:E) -> 0
K13: ='Internal Summary'!B51 | L13: =sumif(D:D,K13,E:E) -> 0

Sheet Client Restocking
H1: Total Invoices Delivered | I1: =countifs(B:B,"<>",F:F,"<>")-1 -> 1 | K1: Sku Performance | L1: Units
H2: Unique Locations Supplied | I2: {=(COUNTA(UNIQUE(C:C,,0))-1)} -> 1 | K2: ='Internal Summary'!B40 -> 350ml Orisirisi Wallnut Drink (12x) | L2: =sumif(D:D,K2,E:E) -> 1.75
H3: Total Value of orders | I3: =sum(F:F) -> 820200 | K3: ='Internal Summary'!B41 -> 350ml Orisirisi Wallnut with Ginger Drink (12x) | L3: =sumif(D:D,K3,E:E) -> 6
K4: ='Internal Summary'!B42 -> 500ml Orisirisi Tiger Nut Drink (12x) | L4: =sumif(D:D,K4,E:E) -> 8
K5: ='Internal Summary'!B43 -> 500ml Orisirisi Zobo Drink (12x) | L5: =sumif(D:D,K5,E:E) -> 9
K6: ='Internal Summary'!B44 -> 500ml Orisirisi Zobo with Date Drink (12x) | L6: =sumif(D:D,K6,E:E) -> 9
K7: ='Internal Summary'!B45 | L7: =sumif(D:D,K7,E:E) -> 0
K8: ='Internal Summary'!B46 | L8: =sumif(D:D,K8,E:E) -> 0
K9: ='Internal Summary'!B47 | L9: =sumif(D:D,K9,E:E) -> 0
K10: ='Internal Summary'!B48 | L10: =sumif(D:D,K10,E:E) -> 0
K11: ='Internal Summary'!B49 | L11: =sumif(D:D,K11,E:E) -> 0
K12: ='Internal Summary'!B50 | L12: =sumif(D:D,K12,E:E) -> 0
K13: ='Internal Summary'!B51 | L13: =sumif(D:D,K13,E:E) -> 0

Sheet Internal Summary
B1: Description | C1: Units | D1: measurements | E1: total
A2: SALES | B2: Total Invoices Delivered | E2: ='Dala Sales & Deliveries'!I1+'External Delivery Fulfillment'!I1 -> 9
B3: Unique Locations Delivered To | E3: ='Raw Data'!AW2 -> 9
B4: Value of Dala Deliveries | E4: ='Dala Sales & Deliveries'!I3 -> 287100
B5: Value of External Deliveries | E5: ='External Delivery Fulfillment'!I3 -> 0
B6: VAT on sales | E6: 0
B7: Total Value of Deliveries | E7: =sum(E4:E6) -> 287100
A8: Remittance & Deductions | B8: Total Remitted to Partner
B9: Collection Fees | C9: 0.1 | E9: =E8*(C9+100%)-E8 -> 0
A10: Invoice Value Due | B10: Outstanding Paymets For Sales | E10: =E7-E8-E9 -> 287100
A11: Debts | B11: Unpaid Subscription | C11: 0 | D11: 0 | E11: =C11*D11 -> 0
B12: Collection Fees | E12: =E7*C9 -> 28710
B13: Delivery Fees | E13: =C26 -> 8613
B14: Delivery Fees External & Pickup | D14: Table 1 | E14: =C29+C22 -> 0 | F14: free
B15: Reimbursements Due To DALA | E15: 0
B16: Retailer Deductions (EXPIRY) | E16: =C31 -> 0
B17: Total Deductions | E17: =sum(E11:E16) -> 37323
A18: Remmittance Due | B18: Total Balance to Remitt | E18: =E10-E17 -> 249777
A20: Inventory and Operational Fees
B21: Dala Pickup for Warehouse | C21: =U69 -> 0
B22: Warehouse Delivery Fee | C22: ='Dala Restocking'!I3*3% -> 0
B23: Forwarding to Retail | C23: =S69 -> 0
B24: Forwarding Delivery Fee | C24: =T69 -> 0
B25: Dala Sales | C25: 0
B26: Dala Delivery Fees | C26: =E7*3% -> 8613
B27: Exteranl Deliveries | C27: =Q69 -> 0
B28: External Delivery Fees | C28: ='External Delivery Fulfillment'!I3*3% -> 0
B29: Product Defects and Expirey Issues | C29: =F69 -> 0
B30: Deductions From Retailer | C30: 0
B31: Samples used | C31: =I69 -> 0
B32: Produce Replacements | C32: 0
B33: Expected Closing Inventory | C33: =L69 -> 24.58
B34: Physical Stock count | C34: =K69 -> 8.5
B35: Inventory Shortages | C35: 0
B36: Inventory Shortage Costs | C36: 0
B39: SKUs | C39: Retail Value | D39: Inbound Delivery Fee | E39: Outbound Delivery Fee | F39: Defects/Expirey | G39: Deductions | H39: Opening Inventory | I39: Samples Used | J39: Product Replacements | K39: Physical Closing Stock Count | L39: Expected Closing Inventory | M39: Inventory Shortages | N39: Shortages Costs | O39: Dala Deliveries | P39: Retail Sales Fee | Q39: External Delivery | R39: External Delivery Fee | S39: Forwarding from Client | T39: Forwarding Delivery Fee | U39: Dala Restocking | V39: Dala Restocking Fee | W39: Client Restocking
B40: 350ml Orisirisi Wallnut Drink (12x) | C40: 21600 | G40: =F40*C40 -> 0 | K40: 3.75 | L40: 3.75 | M40: =K40-L40 -> 0 | N40: =M40*C40 -> 0 | O40: ='Dala Sales & Deliveries'!L2 -> 0 | P40: =O40*E40 -> 0 | Q40: ='External Delivery Fulfillment'!L2 -> 0 | R40: =Q40*E40 -> 0 | S40: ='Forwarding From Client'!L2 -> 0 | T40: =S40*E40 -> 0 | U40: ='Dala Restocking'!L2 -> 0 | V40: =U40*D40 -> 0 | W40: ='Client Restocking'!L2 -> 1.75
B41: 350ml Orisirisi Wallnut with Ginger Drink (12x) | C41: 21600 | G41: =F41*C41 -> 0 | K41: 3.25 | L41: 7 | M41: =K41-L41 -> -3.75 | N41: =M41*C41 -> -81000 | O41: ='Dala Sales & Deliveries'!L3 -> 1.5 | P41: =O41*E41 -> 0 | Q41: ='External Delivery Fulfillment'!L3 -> 0 | R41: =Q41*E41 -> 0 | S41: ='Forwarding From Client'!L3 -> 0 | T41: =S41*E41 -> 0 | U41: ='Dala Restocking'!L3 -> 0 | V41: =U41*D41 -> 0 | W41: ='Client Restocking'!L3 -> 6
B42: 500ml Orisirisi Tiger Nut Drink (12x) | C42: 27600 | G42: =F42*C42 -> 0 | K42: 0.25 | L42: 5.67 | M42: =K42-L42 -> -5.42 | N42: =M42*C42 -> -149592 | O42: ='Dala Sales & Deliveries'!L4 -> 5.75 | P42: =O42*E42 -> 0 | Q42: ='External Delivery Fulfillment'!L4 -> 0 | R42: =Q42*E42 -> 0 | S42: ='Forwarding From Client'!L4 -> 0 | T42: =S42*E42 -> 0 | U42: ='Dala Restocking'!L4 -> 0 | V42: =U42*D42 -> 0 | W42: ='Client Restocking'!L4 -> 8
B43: 500ml Orisirisi Zobo Drink (12x) | C43: 24000 | G43: =F43*C43 -> 0 | K43: 1 | L43: 5.08 | M43: =K43-L43 -> -4.08 | N43: =M43*C43 -> -97920 | O43: ='Dala Sales & Deliveries'!L5 -> 1 | P43: =O43*E43 -> 0 | Q43: ='External Delivery Fulfillment'!L5 -> 0 | R43: =Q43*E43 -> 0 | S43: ='Forwarding From Client'!L5 -> 0 | T43: =S43*E43 -> 0 | U43: ='Dala Restocking'!L5 -> 0 | V43: =U43*D43 -> 0 | W43: ='Client Restocking'!L5 -> 9
...
