Workbook

Sheet Raw Data
A1: Exported from Tally | I1: Dala Sales & Deliveries | R1: External Deliveries | Z1: Forwarding From Client | AH1: Client Restock | AP1: Dala Restock | AX1: Unique Locations
A2: item name | B2: Date | C2: Particulars | D2: Vch Type | E2: Vch No. | F2: Quantity | G2: Value | I2: item name | J2: Date | K2: Particulars | L2: Vch Type | M2: Vch No. | N2: Quantity | O2: Value | P2: Total Vaue | R2: item name | S2: Date | T2: Particulars | U2: Vch Type | V2: Vch No. | W2: Quantity | X2: Value | Z2: item name | AA2: Date | AB2: Particulars | AC2: Vch Type | AD2: Vch No. | AE2: Quantity | AF2: Value | AH2: item name | AI2: Date | AJ2: Particulars | AK2: Vch Type | AL2: Vch No. | AM2: Quantity | AN2: Value | AP2: item name | AQ2: Date | AR2: Particulars | AS2: Vch Type | AT2: Vch No. | AU2: Quantity | AV2: Value | AX2: {=counta(unique(C:C))-3} -> 18
A3: Jadens Fruitamil (12x) | B3: 46034 | C3: Prince Ebeano, JAKANDE | D3: Journal | E3: 12 | F3: 2 | G3: 120000 | I3: =IFERROR(__xludf.DUMMYFUNCTION("IFERROR( FILTER($A$3:$G1002, LEN($A$3:$A1002), LOWER(TRIM($D$3:$D1002))=""sales""), )"),"Jadens Fruitamil (12x)") -> Jadens Fruitamil (12x) | J3: =IFERROR(__xludf.DUMMYFUNCTION("""COMPUTED_VALUE"""),46031.0) -> 46031 | K3: =IFERROR(__xludf.DUMMYFUNCTION("""COMPUTED_VALUE"""),"Hutoos Supermarket, Ogba") -> Hutoos Supermarket, Ogba | L3: =IFERROR(__xludf.DUMMYFUNCTION("""COMPUTED_VALUE"""),"Sales") -> Sales | M3: =IFERROR(__xludf.DUMMYFUNCTION("""COMPUTED_VALUE"""),"DT:000083") -> DT:000083 | N3: =IFERROR(__xludf.DUMMYFUNCTION("""COMPUTED_VALUE"""),0.5) -> 0.5 | O3: =IFERROR(__xludf.DUMMYFUNCTION("""COMPUTED_VALUE"""),30000.0) -> 30000 | P3: =sumif(M:M,M3,O:O) -> 30000 | R3: =IFERROR(__xludf.DUMMYFUNCTION("IFERROR( FILTER($A$3:$G1002, LEN($A$3:$A1002), REGEXMATCH(LOWER(TRIM($D$3:$D1002)), ""\bjournal\b"")), ) "),"Jadens Fruitamil (12x)") -> Jadens Fruitamil (12x) | S3: =IFERROR(__xludf.DUMMYFUNCTION("""COMPUTED_VALUE"""),46034.0) -> 46034 | T3: =IFERROR(__xludf.DUMMYFUNCTION("""COMPUTED_VALUE"""),"Prince Ebeano, JAKANDE") -> Prince Ebeano, JAKANDE | U3: =IFERROR(__xludf.DUMMYFUNCTION("""COMPUTED_VALUE"""),"Journal") -> Journal | V3: =IFERROR(__xludf.DUMMYFUNCTION("""COMPUTED_VALUE"""),12.0) -> 12 | W3: =IFERROR(__xludf.DUMMYFUNCTION("""COMPUTED_VALUE"""),2.0) -> 2 | X3: =IFERROR(__xludf.DUMMYFUNCTION("""COMPUTED_VALUE"""),120000.0) -> 120000 | AH3: =IFERROR(__xludf.DUMMYFUNCTION("IFERROR(FILTER($A$3:$G1002, LEN($A$3:$A1002), LOWER(TRIM($D$3:$D1002))=""Inventory Supplied by Brands""),)"),"") | AP3: =IFERROR(__xludf.DUMMYFUNCTION("IFERROR(FILTER($A$3:$G1002, LEN($A$3:$A1002), LOWER(TRIM($D$3:$D1002))=""Inventory Pickup by Dala""),) "),"")
A4: Jadens Mixagrain (12x) | B4: 46034 | C4: Prince Ebeano, JAKANDE | D4: Journal | E4: 12 | F4: 1 | G4: 60000 | I4: =IFERROR(__xludf.DUMMYFUNCTION("""COMPUTED_VALUE"""),"Jadens Fruitamil (12x)") -> Jadens Fruitamil (12x) | J4: =IFERROR(__xludf.DUMMYFUNCTION("""COMPUTED_VALUE"""),46031.0) -> 46031 | K4: =IFERROR(__xludf.DUMMYFUNCTION("""COMPUTED_VALUE"""),"Reno Supermarket, EJIGBO") -> Reno Supermarket, EJIGBO | L4: =IFERROR(__xludf.DUMMYFUNCTION("""COMPUTED_VALUE"""),"Sales") -> Sales | M4: =IFERROR(__xludf.DUMMYFUNCTION("""COMPUTED_VALUE"""),"DT:000098") -> DT:000098 | N4: =IFERROR(__xludf.DUMMYFUNCTION("""COMPUTED_VALUE"""),0.5) -> 0.5 | O4: =IFERROR(__xludf.DUMMYFUNCTION("""COMPUTED_VALUE"""),30000.0) -> 30000 | P4: =sumif(M:M,M4,O:O) -> 90000 | R4: =IFERROR(__xludf.DUMMYFUNCTION("""COMPUTED_VALUE"""),"Jadens Mixagrain (12x)") -> Jadens Mixagrain (12x) | S4: =IFERROR(__xludf.DUMMYFUNCTION("""COMPUTED_VALUE"""),46034.0) -> 46034 | T4: =IFERROR(__xludf.DUMMYFUNCTION("""COMPUTED_VALUE"""),"Prince Ebeano, JAKANDE") -> Prince Ebeano, JAKANDE | U4: =IFERROR(__xludf.DUMMYFUNCTION("""COMPUTED_VALUE"""),"Journal") -> Journal | V4: =IFERROR(__xludf.DUMMYFUNCTION("""COMPUTED_VALUE"""),12.0) -> 12 | W4: =IFERROR(__xludf.DUMMYFUNCTION("""COMPUTED_VALUE"""),1.0) -> 1 | X4: =IFERROR(__xludf.DUMMYFUNCTION("""COMPUTED_VALUE"""),60000.0) -> 60000
A5: Jadens Nuttymeal (12x) | B5: 46034 | C5: Prince Ebeano, JAKANDE | D5: Journal | E5: 12 | F5: 1 | G5: 60000 | I5: =IFERROR(__xludf.DUMMYFUNCTION("""COMPUTED_VALUE"""),"Jadens Fruitamil (12x)") -> Jadens Fruitamil (12x) | J5: =IFERROR(__xludf.DUMMYFUNCTION("""COMPUTED_VALUE"""),46036.0) -> 46036 | K5: =IFERROR(__xludf.DUMMYFUNCTION("""COMPUTED_VALUE"""),"Reno Supermarket, COUNCIL") -> Reno Supermarket, COUNCIL | L5: =IFERROR(__xludf.DUMMYFUNCTION("""COMPUTED_VALUE"""),"Sales") -> Sales | M5: =IFERROR(__xludf.DUMMYFUNCTION("""COMPUTED_VALUE"""),"DT:000155") -> DT:000155 | N5: =IFERROR(__xludf.DUMMYFUNCTION("""COMPUTED_VALUE"""),0.5) -> 0.5 | O5: =IFERROR(__xludf.DUMMYFUNCTION("""COMPUTED_VALUE"""),30000.0) -> 30000 | P5: =sumif(M:M,M5,O:O) -> 60000 | R5: =IFERROR(__xludf.DUMMYFUNCTION("""COMPUTED_VALUE"""),"Jadens Nuttymeal (12x)") -> Jadens Nuttymeal (12x) | S5: =IFERROR(__xludf.DUMMYFUNCTION("""COMPUTED_VALUE"""),46034.0) -> 46034 | T5: =IFERROR(__xludf.DUMMYFUNCTION("""COMPUTED_VALUE"""),"Prince Ebeano, JAKANDE") -> Prince Ebeano, JAKANDE | U5: =IFERROR(__xludf.DUMMYFUNCTION("""COMPUTED_VALUE"""),"Journal") -> Journal | V5: =IFERROR(__xludf.DUMMYFUNCTION("""COMPUTED_VALUE"""),12.0) -> 12 | W5: =IFERROR(__xludf.DUMMYFUNCTION("""COMPUTED_VALUE"""),1.0) -> 1 | X5: =IFERROR(__xludf.DUMMYFUNCTION("""COMPUTED_VALUE"""),60000.0) -> 60000
A6: Jadens Fruitamil (12x) | B6: 46035 | C6: Supersaver, OGUDU | D6: Journal | E6: 13 | F6: 0.5 | G6: 30000 | I6: =IFERROR(__xludf.DUMMYFUNCTION("""COMPUTED_VALUE"""),"Jadens Fruitamil (12x)") -> Jadens Fruitamil (12x) | J6: =IFERROR(__xludf.DUMMYFUNCTION("""COMPUTED_VALUE"""),46036.0) -> 46036 | K6: =IFERROR(__xludf.DUMMYFUNCTION("""COMPUTED_VALUE"""),"Twins Faja Supermarket, IKOTUN Road") -> Twins Faja Supermarket, IKOTUN Road | L6: =IFERROR(__xludf.DUMMYFUNCTION("""COMPUTED_VALUE"""),"Sales") -> Sales | M6: =IFERROR(__xludf.DUMMYFUNCTION("""COMPUTED_VALUE"""),"DT:000171") -> DT:000171 | N6: =IFERROR(__xludf.DUMMYFUNCTION("""COMPUTED_VALUE"""),0.5) -> 0.5 | O6: =IFERROR(__xludf.DUMMYFUNCTION("""COMPUTED_VALUE"""),30000.0) -> 30000 | P6: =sumif(M:M,M6,O:O) -> 90000 | R6: =IFERROR(__xludf.DUMMYFUNCTION("""COMPUTED_VALUE"""),"Jadens Fruitamil (12x)") -> Jadens Fruitamil (12x) | S6: =IFERROR(__xludf.DUMMYFUNCTION("""COMPUTED_VALUE"""),46035.0) -> 46035 | T6: =IFERROR(__xludf.DUMMYFUNCTION("""COMPUTED_VALUE"""),"Supersaver, OGUDU") -> Supersaver, OGUDU | U6: =IFERROR(__xludf.DUMMYFUNCTION("""COMPUTED_VALUE"""),"Journal") -> Journal | V6: =IFERROR(__xludf.DUMMYFUNCTION("""COMPUTED_VALUE"""),13.0) -> 13 | W6: =IFERROR(__xludf.DUMMYFUNCTION("""COMPUTED_VALUE"""),0.5) -> 0.5 | X6: =IFERROR(__xludf.DUMMYFUNCTION("""COMPUTED_VALUE"""),30000.0) -> 30000
A7: Jadens Fussy-Pops (12x) | B7: 46035 | C7: Home Affairs Supermarket, GBAGADA | D7: Journal | E7: 14 | F7: 0.5 | G7: 30000 | I7: =IFERROR(__xludf.DUMMYFUNCTION("""COMPUTED_VALUE"""),"Jadens Fruitamil (12x)") -> Jadens Fruitamil (12x) | J7: =IFERROR(__xludf.DUMMYFUNCTION("""COMPUTED_VALUE"""),46036.0) -> 46036 | K7: =IFERROR(__xludf.DUMMYFUNCTION("""COMPUTED_VALUE"""),"Prestige Superstore, IGANDO") -> Prestige Superstore, IGANDO | L7: =IFERROR(__xludf.DUMMYFUNCTION("""COMPUTED_VALUE"""),"Sales") -> Sales | M7: =IFERROR(__xludf.DUMMYFUNCTION("""COMPUTED_VALUE"""),"DT:000173") -> DT:000173 | N7: =IFERROR(__xludf.DUMMYFUNCTION("""COMPUTED_VALUE"""),0.5) -> 0.5 | O7: =IFERROR(__xludf.DUMMYFUNCTION("""COMPUTED_VALUE"""),30000.0) -> 30000 | P7: =sumif(M:M,M7,O:O) -> 60000 | R7: =IFERROR(__xludf.DUMMYFUNCTION("""COMPUTED_VALUE"""),"Jadens Fussy-Pops (12x)") -> Jadens Fussy-Pops (12x) | S7: =IFERROR(__xludf.DUMMYFUNCTION("""COMPUTED_VALUE"""),46035.0) -> 46035 | T7: =IFERROR(__xludf.DUMMYFUNCTION("""COMPUTED_VALUE"""),"Home Affairs Supermarket, GBAGADA") -> Home Affairs Supermarket, GBAGADA | U7: =IFERROR(__xludf.DUMMYFUNCTION("""COMPUTED_VALUE"""),"Journal") -> Journal | V7: =IFERROR(__xludf.DUMMYFUNCTION("""COMPUTED_VALUE"""),14.0) -> 14 | W7: =IFERROR(__xludf.DUMMYFUNCTION("""COMPUTED_VALUE"""),0.5) -> 0.5 | X7: =IFERROR(__xludf.DUMMYFUNCTION("""COMPUTED_VALUE"""),30000.0) -> 30000
A8: Jadens Mixagrain (12x) | B8: 46035 | C8: Home Affairs Supermarket, GBAGADA | D8: Journal | E8: 14 | F8: 0.5 | G8: 30000 | I8: =IFERROR(__xludf.DUMMYFUNCTION("""COMPUTED_VALUE"""),"Jadens Fruitamil (12x)") -> Jadens Fruitamil (12x) | J8: =IFERROR(__xludf.DUMMYFUNCTION("""COMPUTED_VALUE"""),46037.0) -> 46037 | K8: =IFERROR(__xludf.DUMMYFUNCTION("""COMPUTED_VALUE"""),"Ozzy Supermarket, VICTORY PARK EST.") -> Ozzy Supermarket, VICTORY PARK EST. | L8: =IFERROR(__xludf.DUMMYFUNCTION("""COMPUTED_VALUE"""),"Sales") -> Sales | M8: =IFERROR(__xludf.DUMMYFUNCTION("""COMPUTED_VALUE"""),"DT:000192") -> DT:000192 | N8: =IFERROR(__xludf.DUMMYFUNCTION("""COMPUTED_VALUE"""),0.5) -> 0.5 | O8: =IFERROR(__xludf.DUMMYFUNCTION("""COMPUTED_VALUE"""),30000.0) -> 30000 | P8: =sumif(M:M,M8,O:O) -> 90000 | R8: =IFERROR(__xludf.DUMMYFUNCTION("""COMPUTED_VALUE"""),"Jadens Mixagrain (12x)") -> Jadens Mixagrain (12x) | S8: =IFERROR(__xludf.DUMMYFUNCTION("""COMPUTED_VALUE"""),46035.0) -> 46035 | T8: =IFERROR(__xludf.DUMMYFUNCTION("""COMPUTED_VALUE"""),"Home Affairs Supermarket, GBAGADA") -> Home Affairs Supermarket, GBAGADA | U8: =IFERROR(__xludf.DUMMYFUNCTION("""COMPUTED_VALUE"""),"Journal") -> Journal | V8: =IFERROR(__xludf.DUMMYFUNCTION("""COMPUTED_VALUE"""),14.0) -> 14 | W8: =IFERROR(__xludf.DUMMYFUNCTION("""COMPUTED_VALUE"""),0.5) -> 0.5 | X8: =IFERROR(__xludf.DUMMYFUNCTION("""COMPUTED_VALUE"""),30000.0) -> 30000
A9: Jadens Nuttymeal (12x) | B9: 46035 | C9: Home Affairs Supermarket, GBAGADA | D9: Journal | E9: 14 | F9: 0.5 | G9: 30000 | I9: =IFERROR(__xludf.DUMMYFUNCTION("""COMPUTED_VALUE"""),"Jadens Fussy-Pops (12x)") -> Jadens Fussy-Pops (12x) | J9: =IFERROR(__xludf.DUMMYFUNCTION("""COMPUTED_VALUE"""),46031.0) -> 46031 | K9: =IFERROR(__xludf.DUMMYFUNCTION("""COMPUTED_VALUE"""),"Reno Supermarket, EJIGBO") -> Reno Supermarket, EJIGBO | L9: =IFERROR(__xludf.DUMMYFUNCTION("""COMPUTED_VALUE"""),"Sales") -> Sales | M9: =IFERROR(__xludf.DUMMYFUNCTION("""COMPUTED_VALUE"""),"DT:000098") -> DT:000098 | N9: =IFERROR(__xludf.DUMMYFUNCTION("""COMPUTED_VALUE"""),0.5) -> 0.5 | O9: =IFERROR(__xludf.DUMMYFUNCTION("""COMPUTED_VALUE"""),30000.0) -> 30000 | P9: =sumif(M:M,M9,O:O) -> 90000 | R9: =IFERROR(__xludf.DUMMYFUNCTION("""COMPUTED_VALUE"""),"Jadens Nuttymeal (12x)") -> Jadens Nuttymeal (12x) | S9: =IFERROR(__xludf.DUMMYFUNCTION("""COMPUTED_VALUE"""),46035.0) -> 46035 | T9: =IFERROR(__xludf.DUMMYFUNCTION("""COMPUTED_VALUE"""),"Home Affairs Supermarket, GBAGADA") -> Home Affairs Supermarket, GBAGADA | U9: =IFERROR(__xludf.DUMMYFUNCTION("""COMPUTED_VALUE"""),"Journal") -> Journal | V9: =IFERROR(__xludf.DUMMYFUNCTION("""COMPUTED_VALUE"""),14.0) -> 14 | W9: =IFERROR(__xludf.DUMMYFUNCTION("""COMPUTED_VALUE"""),0.5) -> 0.5 | X9: =IFERROR(__xludf.DUMMYFUNCTION("""COMPUTED_VALUE"""),30000.0) -> 30000
A10: Jadens Fruitamil (12x) | B10: 46036 | C10: Health Rite | D10: Journal | E10: 15 | F10: 1 | G10: 60000 | I10: =IFERROR(__xludf.DUMMYFUNCTION("""COMPUTED_VALUE"""),"Jadens Mixagrain (12x)") -> Jadens Mixagrain (12x) | J10: =IFERROR(__xludf.DUMMYFUNCTION("""COMPUTED_VALUE"""),46035.0) -> 46035 | K10: =IFERROR(__xludf.DUMMYFUNCTION("""COMPUTED_VALUE"""),"Prime Mart Superstores, OKOKOMAIKO") -> Prime Mart Superstores, OKOKOMAIKO | L10: =IFERROR(__xludf.DUMMYFUNCTION("""COMPUTED_VALUE"""),"Sales") -> Sales | M10: =IFERROR(__xludf.DUMMYFUNCTION("""COMPUTED_VALUE"""),"DT:000146") -> DT:000146 | N10: =IFERROR(__xludf.DUMMYFUNCTION("""COMPUTED_VALUE"""),0.5) -> 0.5 | O10: =IFERROR(__xludf.DUMMYFUNCTION("""COMPUTED_VALUE"""),30000.0) -> 30000 | P10: =sumif(M:M,M10,O:O) -> 30000 | R10: =IFERROR(__xludf.DUMMYFUNCTION("""COMPUTED_VALUE"""),"Jadens Fruitamil (12x)") -> Jadens Fruitamil (12x) | S10: =IFERROR(__xludf.DUMMYFUNCTION("""COMPUTED_VALUE"""),46036.0) -> 46036 | T10: =IFERROR(__xludf.DUMMYFUNCTION("""COMPUTED_VALUE"""),"Health Rite") -> Health Rite | U10: =IFERROR(__xludf.DUMMYFUNCTION("""COMPUTED_VALUE"""),"Journal") -> Journal | V10: =IFERROR(__xludf.DUMMYFUNCTION("""COMPUTED_VALUE"""),15.0) -> 15 | W10: =IFERROR(__xludf.DUMMYFUNCTION("""COMPUTED_VALUE"""),1.0) -> 1 | X10: =IFERROR(__xludf.DUMMYFUNCTION("""COMPUTED_VALUE"""),60000.0) -> 60000
A11: Jadens Fussy-Pops (12x) | B11: 46036 | C11: Health Rite | D11: Journal | E11: 15 | F11: 1 | G11: 60000 | I11: =IFERROR(__xludf.DUMMYFUNCTION("""COMPUTED_VALUE"""),"Jadens Mixagrain (12x)") -> Jadens Mixagrain (12x) | J11: =IFERROR(__xludf.DUMMYFUNCTION("""COMPUTED_VALUE"""),46036.0) -> 46036 | K11: =IFERROR(__xludf.DUMMYFUNCTION("""COMPUTED_VALUE"""),"Twins Faja Supermarket, IKOTUN Road") -> Twins Faja Supermarket, IKOTUN Road | L11: =IFERROR(__xludf.DUMMYFUNCTION("""COMPUTED_VALUE"""),"Sales") -> Sales | M11: =IFERROR(__xludf.DUMMYFUNCTION("""COMPUTED_VALUE"""),"DT:000171") -> DT:000171 | N11: =IFERROR(__xludf.DUMMYFUNCTION("""COMPUTED_VALUE"""),0.5) -> 0.5 | O11: =IFERROR(__xludf.DUMMYFUNCTION("""COMPUTED_VALUE"""),30000.0) -> 30000 | P11: =sumif(M:M,M11,O:O) -> 90000 | R11: =IFERROR(__xludf.DUMMYFUNCTION("""COMPUTED_VALUE"""),"Jadens Fussy-Pops (12x)") -> Jadens Fussy-Pops (12x) | S11: =IFERROR(__xludf.DUMMYFUNCTION("""COMPUTED_VALUE"""),46036.0) -> 46036 | T11: =IFERROR(__xludf.DUMMYFUNCTION("""COMPUTED_VALUE"""),"Health Rite") -> Health Rite | U11: =IFERROR(__xludf.DUMMYFUNCTION("""COMPUTED_VALUE"""),"Journal") -> Journal | V11: =IFERROR(__xludf.DUMMYFUNCTION("""COMPUTED_VALUE"""),15.0) -> 15 | W11: =IFERROR(__xludf.DUMMYFUNCTION("""COMPUTED_VALUE"""),1.0) -> 1 | X11: =IFERROR(__xludf.DUMMYFUNCTION("""COMPUTED_VALUE"""),60000.0) -> 60000
A12: Jadens Mixagrain (12x) | B12: 46036 | C12: Health Rite | D12: Journal | E12: 15 | F12: 1 | G12: 60000 | I12: =IFERROR(__xludf.DUMMYFUNCTION("""COMPUTED_VALUE"""),"Jadens Nuttymeal (12x)") -> Jadens Nuttymeal (12x) | J12: =IFERROR(__xludf.DUMMYFUNCTION("""COMPUTED_VALUE"""),46031.0) -> 46031 | K12: =IFERROR(__xludf.DUMMYFUNCTION("""COMPUTED_VALUE"""),"Reno Supermarket, EJIGBO") -> Reno Supermarket, EJIGBO | L12: =IFERROR(__xludf.DUMMYFUNCTION("""COMPUTED_VALUE"""),"Sales") -> Sales | M12: =IFERROR(__xludf.DUMMYFUNCTION("""COMPUTED_VALUE"""),"DT:000098") -> DT:000098 | N12: =IFERROR(__xludf.DUMMYFUNCTION("""COMPUTED_VALUE"""),0.5) -> 0.5 | O12: =IFERROR(__xludf.DUMMYFUNCTION("""COMPUTED_VALUE"""),30000.0) -> 30000 | P12: =sumif(M:M,M12,O:O) -> 90000 | R12: =IFERROR(__xludf.DUMMYFUNCTION("""COMPUTED_VALUE"""),"Jadens Mixagrain (12x)") -> Jadens Mixagrain (12x) | S12: =IFERROR(__xludf.DUMMYFUNCTION("""COMPUTED_VALUE"""),46036.0) -> 46036 | T12: =IFERROR(__xludf.DUMMYFUNCTION("""COMPUTED_VALUE"""),"Health Rite") -> Health Rite | U12: =IFERROR(__xludf.DUMMYFUNCTION("""COMPUTED_VALUE"""),"Journal") -> Journal | V12: =IFERROR(__xludf.DUMMYFUNCTION("""COMPUTED_VALUE"""),15.0) -> 15 | W12: =IFERROR(__xludf.DUMMYFUNCTION("""COMPUTED_VALUE"""),1.0) -> 1 | X12: =IFERROR(__xludf.DUMMYFUNCTION("""COMPUTED_VALUE"""),60000.0) -> 60000
A13: Jadens Nuttymeal (12x) | B13: 46036 | C13: Health Rite | D13: Journal | E13: 15 | F13: 1 | G13: 60000 | I13: =IFERROR(__xludf.DUMMYFUNCTION("""COMPUTED_VALUE"""),"Jadens Nuttymeal (12x)") -> Jadens Nuttymeal (12x) | J13: =IFERROR(__xludf.DUMMYFUNCTION("""COMPUTED_VALUE"""),46035.0) -> 46035 | K13: =IFERROR(__xludf.DUMMYFUNCTION("""COMPUTED_VALUE"""),"Prime Mart Superstores, IYANA ISASHI") -> Prime Mart Superstores, IYANA ISASHI | L13: =IFERROR(__xludf.DUMMYFUNCTION("""COMPUTED_VALUE"""),"Sales") -> Sales | M13: =IFERROR(__xludf.DUMMYFUNCTION("""COMPUTED_VALUE"""),"DT:000143") -> DT:000143 | N13: =IFERROR(__xludf.DUMMYFUNCTION("""COMPUTED_VALUE"""),0.5) -> 0.5 | O13: =IFERROR(__xludf.DUMMYFUNCTION("""COMPUTED_VALUE"""),30000.0) -> 30000 | P13: =sumif(M:M,M13,O:O) -> 30000 | R13: =IFERROR(__xludf.DUMMYFUNCTION("""COMPUTED_VALUE"""),"Jadens Nuttymeal (12x)") -> Jadens Nuttymeal (12x) | S13: =IFERROR(__xludf.DUMMYFUNCTION("""COMPUTED_VALUE"""),46036.0) -> 46036 | T13: =IFERROR(__xludf.DUMMYFUNCTION("""COMPUTED_VALUE"""),"Health Rite") -> Health Rite | U13: =IFERROR(__xludf.DUMMYFUNCTION("""COMPUTED_VALUE"""),"Journal") -> Journal | V13: =IFERROR(__xludf.DUMMYFUNCTION("""COMPUTED_VALUE"""),15.0) -> 15 | W13: =IFERROR(__xludf.DUMMYFUNCTION("""COMPUTED_VALUE"""),1.0) -> 1 | X13: =IFERROR(__xludf.DUMMYFUNCTION("""COMPUTED_VALUE"""),60000.0) -> 60000
A14: Jadens Fruitamil (12x) | B14: 46036 | C14: Jendol Supermarket, AKASOLORI | D14: Journal | E14: 17 | F14: 1 | G14: 60000 | I14: =IFERROR(__xludf.DUMMYFUNCTION("""COMPUTED_VALUE"""),"Jadens Nuttymeal (12x)") -> Jadens Nuttymeal (12x) | J14: =IFERROR(__xludf.DUMMYFUNCTION("""COMPUTED_VALUE"""),46036.0) -> 46036 | K14: =IFERROR(__xludf.DUMMYFUNCTION("""COMPUTED_VALUE"""),"Reno Supermarket, COUNCIL") -> Reno Supermarket, COUNCIL | L14: =IFERROR(__xludf.DUMMYFUNCTION("""COMPUTED_VALUE"""),"Sales") -> Sales | M14: =IFERROR(__xludf.DUMMYFUNCTION("""COMPUTED_VALUE"""),"DT:000155") -> DT:000155 | N14: =IFERROR(__xludf.DUMMYFUNCTION("""COMPUTED_VALUE"""),0.5) -> 0.5 | O14: =IFERROR(__xludf.DUMMYFUNCTION("""COMPUTED_VALUE"""),30000.0) -> 30000 | P14: =sumif(M:M,M14,O:O) -> 60000 | R14: =IFERROR(__xludf.DUMMYFUNCTION("""COMPUTED_VALUE"""),"Jadens Fruitamil (12x)") -> Jadens Fruitamil (12x) | S14: =IFERROR(__xludf.DUMMYFUNCTION("""COMPUTED_VALUE"""),46036.0) -> 46036 | T14: =IFERROR(__xludf.DUMMYFUNCTION("""COMPUTED_VALUE"""),"Jendol Supermarket, AKASOLORI") -> Jendol Supermarket, AKASOLORI | U14: =IFERROR(__xludf.DUMMYFUNCTION("""COMPUTED_VALUE"""),"Journal") -> Journal | V14: =IFERROR(__xludf.DUMMYFUNCTION("""COMPUTED_VALUE"""),17.0) -> 17 | W14: =IFERROR(__xludf.DUMMYFUNCTION("""COMPUTED_VALUE"""),1.0) -> 1 | X14: =IFERROR(__xludf.DUMMYFUNCTION("""COMPUTED_VALUE"""),60000.0) -> 60000
A15: Jadens Fussy-Pops (12x) | B15: 46036 | C15: Jendol Supermarket, AKASOLORI | D15: Journal | E15: 17 | F15: 1 | G15: 60000 | I15: =IFERROR(__xludf.DUMMYFUNCTION("""COMPUTED_VALUE"""),"Jadens Nuttymeal (12x)") -> Jadens Nuttymeal (12x) | J15: =IFERROR(__xludf.DUMMYFUNCTION("""COMPUTED_VALUE"""),46036.0) -> 46036 | K15: =IFERROR(__xludf.DUMMYFUNCTION("""COMPUTED_VALUE"""),"Twins Faja Supermarket, IKOTUN Road") -> Twins Faja Supermarket, IKOTUN Road | L15: =IFERROR(__xludf.DUMMYFUNCTION("""COMPUTED_VALUE"""),"Sales") -> Sales | M15: =IFERROR(__xludf.DUMMYFUNCTION("""COMPUTED_VALUE"""),"DT:000171") -> DT:000171 | N15: =IFERROR(__xludf.DUMMYFUNCTION("""COMPUTED_VALUE"""),0.5) -> 0.5 | O15: =IFERROR(__xludf.DUMMYFUNCTION("""COMPUTED_VALUE"""),30000.0) -> 30000 | P15: =sumif(M:M,M15,O:O) -> 90000 | R15: =IFERROR(__xludf.DUMMYFUNCTION("""COMPUTED_VALUE"""),"Jadens Fussy-Pops (12x)") -> Jadens Fussy-Pops (12x) | S15: =IFERROR(__xludf.DUMMYFUNCTION("""COMPUTED_VALUE"""),46036.0) -> 46036 | T15: =IFERROR(__xludf.DUMMYFUNCTION("""COMPUTED_VALUE"""),"Jendol Supermarket, AKASOLORI") -> Jendol Supermarket, AKASOLORI | U15: =IFERROR(__xludf.DUMMYFUNCTION("""COMPUTED_VALUE"""),"Journal") -> Journal | V15: =IFERROR(__xludf.DUMMYFUNCTION("""COMPUTED_VALUE"""),17.0) -> 17 | W15: =IFERROR(__xludf.DUMMYFUNCTION("""COMPUTED_VALUE"""),1.0) -> 1 | X15: =IFERROR(__xludf.DUMMYFUNCTION("""COMPUTED_VALUE"""),60000.0) -> 60000
A16: Jadens Fruitamil (12x) | B16: 46036 | C16: Jendol Supermarket, IJEDE | D16: Journal | E16: 18 | F16: 1 | G16: 60000 | I16: =IFERROR(__xludf.DUMMYFUNCTION("""COMPUTED_VALUE"""),"Jadens Nuttymeal (12x)") -> Jadens Nuttymeal (12x) | J16: =IFERROR(__xludf.DUMMYFUNCTION("""COMPUTED_VALUE"""),46036.0) -> 46036 | K16: =IFERROR(__xludf.DUMMYFUNCTION("""COMPUTED_VALUE"""),"Prestige Superstore, IGANDO") -> Prestige Superstore, IGANDO | L16: =IFERROR(__xludf.DUMMYFUNCTION("""COMPUTED_VALUE"""),"Sales") -> Sales | M16: =IFERROR(__xludf.DUMMYFUNCTION("""COMPUTED_VALUE"""),"DT:000173") -> DT:000173 | N16: =IFERROR(__xludf.DUMMYFUNCTION("""COMPUTED_VALUE"""),0.5) -> 0.5 | O16: =IFERROR(__xludf.DUMMYFUNCTION("""COMPUTED_VALUE"""),30000.0) -> 30000 | P16: =sumif(M:M,M16,O:O) -> 60000 | R16: =IFERROR(__xludf.DUMMYFUNCTION("""COMPUTED_VALUE"""),"Jadens Fruitamil (12x)") -> Jadens Fruitamil (12x) | S16: =IFERROR(__xludf.DUMMYFUNCTION("""COMPUTED_VALUE"""),46036.0) -> 46036 | T16: =IFERROR(__xludf.DUMMYFUNCTION("""COMPUTED_VALUE"""),"Jendol Supermarket, IJEDE") -> Jendol Supermarket, IJEDE | U16: =IFERROR(__xludf.DUMMYFUNCTION("""COMPUTED_VALUE"""),"Journal") -> Journal | V16: =IFERROR(__xludf.DUMMYFUNCTION("""COMPUTED_VALUE"""),18.0) -> 18 | W16: =IFERROR(__xludf.DUMMYFUNCTION("""COMPUTED_VALUE"""),1.0) -> 1 | X16: =IFERROR(__xludf.DUMMYFUNCTION("""COMPUTED_VALUE"""),60000.0) -> 60000
A17: Jadens Fussy-Pops (12x) | B17: 46036 | C17: Jendol Supermarket, IJEDE | D17: Journal | E17: 18 | F17: 1 | G17: 60000 | I17: =IFERROR(__xludf.DUMMYFUNCTION("""COMPUTED_VALUE"""),"Jadens Nuttymeal (12x)") -> Jadens Nuttymeal (12x) | J17: =IFERROR(__xludf.DUMMYFUNCTION("""COMPUTED_VALUE"""),46037.0) -> 46037 | K17: =IFERROR(__xludf.DUMMYFUNCTION("""COMPUTED_VALUE"""),"Ozzy Supermarket, VICTORY PARK EST.") -> Ozzy Supermarket, VICTORY PARK EST. | L17: =IFERROR(__xludf.DUMMYFUNCTION("""COMPUTED_VALUE"""),"Sales") -> Sales | M17: =IFERROR(__xludf.DUMMYFUNCTION("""COMPUTED_VALUE"""),"DT:000192") -> DT:000192 | N17: =IFERROR(__xludf.DUMMYFUNCTION("""COMPUTED_VALUE"""),1.0) -> 1 | O17: =IFERROR(__xludf.DUMMYFUNCTION("""COMPUTED_VALUE"""),60000.0) -> 60000 | P17: =sumif(M:M,M17,O:O) -> 90000 | R17: =IFERROR(__xludf.DUMMYFUNCTION("""COMPUTED_VALUE"""),"Jadens Fussy-Pops (12x)") -> Jadens Fussy-Pops (12x) | S17: =IFERROR(__xludf.DUMMYFUNCTION("""COMPUTED_VALUE"""),46036.0) -> 46036 | T17: =IFERROR(__xludf.DUMMYFUNCTION("""COMPUTED_VALUE"""),"Jendol Supermarket, IJEDE") -> Jendol Supermarket, IJEDE | U17: =IFERROR(__xludf.DUMMYFUNCTION("""COMPUTED_VALUE"""),"Journal") -> Journal | V17: =IFERROR(__xludf.DUMMYFUNCTION("""COMPUTED_VALUE"""),18.0) -> 18 | W17: =IFERROR(__xludf.DUMMYFUNCTION("""COMPUTED_VALUE"""),1.0) -> 1 | X17: =IFERROR(__xludf.DUMMYFUNCTION("""COMPUTED_VALUE"""),60000.0) -> 60000
A18: Jadens Mixagrain (12x) | B18: 46036 | C18: Jendol Supermarket, IJEDE | D18: Journal | E18: 18 | F18: 1 | G18: 60000 | P18: =sumif(M:M,M18,O:O) -> 0 | R18: =IFERROR(__xludf.DUMMYFUNCTION("""COMPUTED_VALUE"""),"Jadens Mixagrain (12x)") -> Jadens Mixagrain (12x) | S18: =IFERROR(__xludf.DUMMYFUNCTION("""COMPUTED_VALUE"""),46036.0) -> 46036 | T18: =IFERROR(__xludf.DUMMYFUNCTION("""COMPUTED_VALUE"""),"Jendol Supermarket, IJEDE") -> Jendol Supermarket, IJEDE | U18: =IFERROR(__xludf.DUMMYFUNCTION("""COMPUTED_VALUE"""),"Journal") -> Journal | V18: =IFERROR(__xludf.DUMMYFUNCTION("""COMPUTED_VALUE"""),18.0) -> 18 | W18: =IFERROR(__xludf.DUMMYFUNCTION("""COMPUTED_VALUE"""),1.0) -> 1 | X18: =IFERROR(__xludf.DUMMYFUNCTION("""COMPUTED_VALUE"""),60000.0) -> 60000
A19: Jadens Nuttymeal (12x) | B19: 46036 | C19: Jendol Supermarket, IJEDE | D19: Journal | E19: 18 | F19: 1 | G19: 60000 | P19: =sumif(M:M,M19,O:O) -> 0 | R19: =IFERROR(__xludf.DUMMYFUNCTION("""COMPUTED_VALUE"""),"Jadens Nuttymeal (12x)") -> Jadens Nuttymeal (12x) | S19: =IFERROR(__xludf.DUMMYFUNCTION("""COMPUTED_VALUE"""),46036.0) -> 46036 | T19: =IFERROR(__xludf.DUMMYFUNCTION("""COMPUTED_VALUE"""),"Jendol Supermarket, IJEDE") -> Jendol Supermarket, IJEDE | U19: =IFERROR(__xludf.DUMMYFUNCTION("""COMPUTED_VALUE"""),"Journal") -> Journal | V19: =IFERROR(__xludf.DUMMYFUNCTION("""COMPUTED_VALUE"""),18.0) -> 18 | W19: =IFERROR(__xludf.DUMMYFUNCTION("""COMPUTED_VALUE"""),1.0) -> 1 | X19: =IFERROR(__xludf.DUMMYFUNCTION("""COMPUTED_VALUE"""),60000.0) -> 60000
A20: Jadens Fussy-Pops (12x) | B20: 46036 | C20: Jendol Supermarket, OJUORE | D20: Journal | E20: 19 | F20: 0.5 | G20: 30000 | P20: =sumif(M:M,M20,O:O) -> 0 | R20: =IFERROR(__xludf.DUMMYFUNCTION("""COMPUTED_VALUE"""),"Jadens Fussy-Pops (12x)") -> Jadens Fussy-Pops (12x) | S20: =IFERROR(__xludf.DUMMYFUNCTION("""COMPUTED_VALUE"""),46036.0) -> 46036 | T20: =IFERROR(__xludf.DUMMYFUNCTION("""COMPUTED_VALUE"""),"Jendol Supermarket, OJUORE") -> Jendol Supermarket, OJUORE | U20: =IFERROR(__xludf.DUMMYFUNCTION("""COMPUTED_VALUE"""),"Journal") -> Journal | V20: =IFERROR(__xludf.DUMMYFUNCTION("""COMPUTED_VALUE"""),19.0) -> 19 | W20: =IFERROR(__xludf.DUMMYFUNCTION("""COMPUTED_VALUE"""),0.5) -> 0.5 | X20: =IFERROR(__xludf.DUMMYFUNCTION("""COMPUTED_VALUE"""),30000.0) -> 30000
A21: Jadens Fruitamil (12x) | B21: 46037 | C21: Blenco Supermarket, SANGOTEDO | D21: Journal | E21: 21 | F21: 2 | G21: 120000 | P21: =sumif(M:M,M21,O:O) -> 0 | R21: =IFERROR(__xludf.DUMMYFUNCTION("""COMPUTED_VALUE"""),"Jadens Fruitamil (12x)") -> Jadens Fruitamil (12x) | S21: =IFERROR(__xludf.DUMMYFUNCTION("""COMPUTED_VALUE"""),46037.0) -> 46037 | T21: =IFERROR(__xludf.DUMMYFUNCTION("""COMPUTED_VALUE"""),"Blenco Supermarket, SANGOTEDO") -> Blenco Supermarket, SANGOTEDO | U21: =IFERROR(__xludf.DUMMYFUNCTION("""COMPUTED_VALUE"""),"Journal") -> Journal | V21: =IFERROR(__xludf.DUMMYFUNCTION("""COMPUTED_VALUE"""),21.0) -> 21 | W21: =IFERROR(__xludf.DUMMYFUNCTION("""COMPUTED_VALUE"""),2.0) -> 2 | X21: =IFERROR(__xludf.DUMMYFUNCTION("""COMPUTED_VALUE"""),120000.0) -> 120000
A22: Jadens Fussy-Pops (12x) | B22: 46037 | C22: Blenco Supermarket, SANGOTEDO | D22: Journal | E22: 21 | F22: 2 | G22: 120000 | P22: =sumif(M:M,M22,O:O) -> 0 | R22: =IFERROR(__xludf.DUMMYFUNCTION("""COMPUTED_VALUE"""),"Jadens Fussy-Pops (12x)") -> Jadens Fussy-Pops (12x) | S22: =IFERROR(__xludf.DUMMYFUNCTION("""COMPUTED_VALUE"""),46037.0) -> 46037 | T22: =IFERROR(__xludf.DUMMYFUNCTION("""COMPUTED_VALUE"""),"Blenco Supermarket, SANGOTEDO") -> Blenco Supermarket, SANGOTEDO | U22: =IFERROR(__xludf.DUMMYFUNCTION("""COMPUTED_VALUE"""),"Journal") -> Journal | V22: =IFERROR(__xludf.DUMMYFUNCTION("""COMPUTED_VALUE"""),21.0) -> 21 | W22: =IFERROR(__xludf.DUMMYFUNCTION("""COMPUTED_VALUE"""),2.0) -> 2 | X22: =IFERROR(__xludf.DUMMYFUNCTION("""COMPUTED_VALUE"""),120000.0) -> 120000
A23: Jadens Mixagrain (12x) | B23: 46037 | C23: Blenco Supermarket, SANGOTEDO | D23: Journal | E23: 21 | F23: 2 | G23: 120000 | P23: =sumif(M:M,M23,O:O) -> 0 | R23: =IFERROR(__xludf.DUMMYFUNCTION("""COMPUTED_VALUE"""),"Jadens Mixagrain (12x)") -> Jadens Mixagrain (12x) | S23: =IFERROR(__xludf.DUMMYFUNCTION("""COMPUTED_VALUE"""),46037.0) -> 46037 | T23: =IFERROR(__xludf.DUMMYFUNCTION("""COMPUTED_VALUE"""),"Blenco Supermarket, SANGOTEDO") -> Blenco Supermarket, SANGOTEDO | U23: =IFERROR(__xludf.DUMMYFUNCTION("""COMPUTED_VALUE"""),"Journal") -> Journal | V23: =IFERROR(__xludf.DUMMYFUNCTION("""COMPUTED_VALUE"""),21.0) -> 21 | W23: =IFERROR(__xludf.DUMMYFUNCTION("""COMPUTED_VALUE"""),2.0) -> 2 | X23: =IFERROR(__xludf.DUMMYFUNCTION("""COMPUTED_VALUE"""),120000.0) -> 120000
A24: Jadens Nuttymeal (12x) | B24: 46037 | C24: Blenco Supermarket, SANGOTEDO | D24: Journal | E24: 21 | F24: 2 | G24: 120000 | P24: =sumif(M:M,M24,O:O) -> 0 | R24: =IFERROR(__xludf.DUMMYFUNCTION("""COMPUTED_VALUE"""),"Jadens Nuttymeal (12x)") -> Jadens Nuttymeal (12x) | S24: =IFERROR(__xludf.DUMMYFUNCTION("""COMPUTED_VALUE"""),46037.0) -> 46037 | T24: =IFERROR(__xludf.DUMMYFUNCTION("""COMPUTED_VALUE"""),"Blenco Supermarket, SANGOTEDO") -> Blenco Supermarket, SANGOTEDO | U24: =IFERROR(__xludf.DUMMYFUNCTION("""COMPUTED_VALUE"""),"Journal") -> Journal | V24: =IFERROR(__xludf.DUMMYFUNCTION("""COMPUTED_VALUE"""),21.0) -> 21 | W24: =IFERROR(__xludf.DUMMYFUNCTION("""COMPUTED_VALUE"""),2.0) -> 2 | X24: =IFERROR(__xludf.DUMMYFUNCTION("""COMPUTED_VALUE"""),120000.0) -> 120000
A25: Jadens Mixagrain (12x) | B25: 46037 | C25: Prince Ebeano, OLOGOLO | D25: Journal | E25: 23 | F25: 3 | G25: 180000 | P25: =sumif(M:M,M25,O:O) -> 0 | R25: =IFERROR(__xludf.DUMMYFUNCTION("""COMPUTED_VALUE"""),"Jadens Mixagrain (12x)") -> Jadens Mixagrain (12x) | S25: =IFERROR(__xludf.DUMMYFUNCTION("""COMPUTED_VALUE"""),46037.0) -> 46037 | T25: =IFERROR(__xludf.DUMMYFUNCTION("""COMPUTED_VALUE"""),"Prince Ebeano, OLOGOLO") -> Prince Ebeano, OLOGOLO | U25: =IFERROR(__xludf.DUMMYFUNCTION("""COMPUTED_VALUE"""),"Journal") -> Journal | V25: =IFERROR(__xludf.DUMMYFUNCTION("""COMPUTED_VALUE"""),23.0) -> 23 | W25: =IFERROR(__xludf.DUMMYFUNCTION("""COMPUTED_VALUE"""),3.0) -> 3 | X25: =IFERROR(__xludf.DUMMYFUNCTION("""COMPUTED_VALUE"""),180000.0) -> 180000
A26: Jadens Nuttymeal (12x) | B26: 46037 | C26: Prince Ebeano, OLOGOLO | D26: Journal | E26: 23 | F26: 3 | G26: 180000 | P26: =sumif(M:M,M26,O:O) -> 0 | R26: =IFERROR(__xludf.DUMMYFUNCTION("""COMPUTED_VALUE"""),"Jadens Nuttymeal (12x)") -> Jadens Nuttymeal (12x) | S26: =IFERROR(__xludf.DUMMYFUNCTION("""COMPUTED_VALUE"""),46037.0) -> 46037 | T26: =IFERROR(__xludf.DUMMYFUNCTION("""COMPUTED_VALUE"""),"Prince Ebeano, OLOGOLO") -> Prince Ebeano, OLOGOLO | U26: =IFERROR(__xludf.DUMMYFUNCTION("""COMPUTED_VALUE"""),"Journal") -> Journal | V26: =IFERROR(__xludf.DUMMYFUNCTION("""COMPUTED_VALUE"""),23.0) -> 23 | W26: =IFERROR(__xludf.DUMMYFUNCTION("""COMPUTED_VALUE"""),3.0) -> 3 | X26: =IFERROR(__xludf.DUMMYFUNCTION("""COMPUTED_VALUE"""),180000.0) -> 180000
A27: Jadens Nuttymeal (12x) | B27: 46031 | C27: Jendol, IPAJA | D27: Journal | E27: 5 | F27: 1 | G27: 60000 | P27: =sumif(M:M,M27,O:O) -> 0 | R27: =IFERROR(__xludf.DUMMYFUNCTION("""COMPUTED_VALUE"""),"Jadens Nuttymeal (12x)") -> Jadens Nuttymeal (12x) | S27: =IFERROR(__xludf.DUMMYFUNCTION("""COMPUTED_VALUE"""),46031.0) -> 46031 | T27: =IFERROR(__xludf.DUMMYFUNCTION("""COMPUTED_VALUE"""),"Jendol, IPAJA") -> Jendol, IPAJA | U27: =IFERROR(__xludf.DUMMYFUNCTION("""COMPUTED_VALUE"""),"Journal") -> Journal | V27: =IFERROR(__xludf.DUMMYFUNCTION("""COMPUTED_VALUE"""),5.0) -> 5 | W27: =IFERROR(__xludf.DUMMYFUNCTION("""COMPUTED_VALUE"""),1.0) -> 1 | X27: =IFERROR(__xludf.DUMMYFUNCTION("""COMPUTED_VALUE"""),60000.0) -> 60000
A28: Jadens Fruitamil (12x) | B28: 46031 | C28: Jendol Supermarket, ISHERI | D28: Journal | E28: 6 | F28: 1 | G28: 60000 | P28: =sumif(M:M,M28,O:O) -> 0 | R28: =IFERROR(__xludf.DUMMYFUNCTION("""COMPUTED_VALUE"""),"Jadens Fruitamil (12x)") -> Jadens Fruitamil (12x) | S28: =IFERROR(__xludf.DUMMYFUNCTION("""COMPUTED_VALUE"""),46031.0) -> 46031 | T28: =IFERROR(__xludf.DUMMYFUNCTION("""COMPUTED_VALUE"""),"Jendol Supermarket, ISHERI") -> Jendol Supermarket, ISHERI | U28: =IFERROR(__xludf.DUMMYFUNCTION("""COMPUTED_VALUE"""),"Journal") -> Journal | V28: =IFERROR(__xludf.DUMMYFUNCTION("""COMPUTED_VALUE"""),6.0) -> 6 | W28: =IFERROR(__xludf.DUMMYFUNCTION("""COMPUTED_VALUE"""),1.0) -> 1 | X28: =IFERROR(__xludf.DUMMYFUNCTION("""COMPUTED_VALUE"""),60000.0) -> 60000
A29: Jadens Fussy-Pops (12x) | B29: 46031 | C29: Jendol Supermarket, ISHERI | D29: Journal | E29: 6 | F29: 1 | G29: 60000 | P29: =sumif(M:M,M29,O:O) -> 0 | R29: =IFERROR(__xludf.DUMMYFUNCTION("""COMPUTED_VALUE"""),"Jadens Fussy-Pops (12x)") -> Jadens Fussy-Pops (12x) | S29: =IFERROR(__xludf.DUMMYFUNCTION("""COMPUTED_VALUE"""),46031.0) -> 46031 | T29: =IFERROR(__xludf.DUMMYFUNCTION("""COMPUTED_VALUE"""),"Jendol Supermarket, ISHERI") -> Jendol Supermarket, ISHERI | U29: =IFERROR(__xludf.DUMMYFUNCTION("""COMPUTED_VALUE"""),"Journal") -> Journal | V29: =IFERROR(__xludf.DUMMYFUNCTION("""COMPUTED_VALUE"""),6.0) -> 6 | W29: =IFERROR(__xludf.DUMMYFUNCTION("""COMPUTED_VALUE"""),1.0) -> 1 | X29: =IFERROR(__xludf.DUMMYFUNCTION("""COMPUTED_VALUE"""),60000.0) -> 60000
A30: Jadens Mixagrain (12x) | B30: 46031 | C30: Jendol Supermarket, ISHERI | D30: Journal | E30: 6 | F30: 1 | G30: 60000 | P30: =sumif(M:M,M30,O:O) -> 0 | R30: =IFERROR(__xludf.DUMMYFUNCTION("""COMPUTED_VALUE"""),"Jadens Mixagrain (12x)") -> Jadens Mixagrain (12x) | S30: =IFERROR(__xludf.DUMMYFUNCTION("""COMPUTED_VALUE"""),46031.0) -> 46031 | T30: =IFERROR(__xludf.DUMMYFUNCTION("""COMPUTED_VALUE"""),"Jendol Supermarket, ISHERI") -> Jendol Supermarket, ISHERI | U30: =IFERROR(__xludf.DUMMYFUNCTION("""COMPUTED_VALUE"""),"Journal") -> Journal | V30: =IFERROR(__xludf.DUMMYFUNCTION("""COMPUTED_VALUE"""),6.0) -> 6 | W30: =IFERROR(__xludf.DUMMYFUNCTION("""COMPUTED_VALUE"""),1.0) -> 1 | X30: =IFERROR(__xludf.DUMMYFUNCTION("""COMPUTED_VALUE"""),60000.0) -> 60000
A31: Jadens Nuttymeal (12x) | B31: 46031 | C31: Jendol Supermarket, ISHERI | D31: Journal | E31: 6 | F31: 1 | G31: 60000 | P31: =sumif(M:M,M31,O:O) -> 0 | R31: =IFERROR(__xludf.DUMMYFUNCTION("""COMPUTED_VALUE"""),"Jadens Nuttymeal (12x)") -> Jadens Nuttymeal (12x) | S31: =IFERROR(__xludf.DUMMYFUNCTION("""COMPUTED_VALUE"""),46031.0) -> 46031 | T31: =IFERROR(__xludf.DUMMYFUNCTION("""COMPUTED_VALUE"""),"Jendol Supermarket, ISHERI") -> Jendol Supermarket, ISHERI | U31: =IFERROR(__xludf.DUMMYFUNCTION("""COMPUTED_VALUE"""),"Journal") -> Journal | V31: =IFERROR(__xludf.DUMMYFUNCTION("""COMPUTED_VALUE"""),6.0) -> 6 | W31: =IFERROR(__xludf.DUMMYFUNCTION("""COMPUTED_VALUE"""),1.0) -> 1 | X31: =IFERROR(__xludf.DUMMYFUNCTION("""COMPUTED_VALUE"""),60000.0) -> 60000
A32: Jadens Fruitamil (12x) | B32: 46031 | C32: Renee Supermarket, IKOYI | D32: Journal | E32: 8 | F32: 1 | G32: 60000 | P32: =sumif(M:M,M32,O:O) -> 0 | R32: =IFERROR(__xludf.DUMMYFUNCTION("""COMPUTED_VALUE"""),"Jadens Fruitamil (12x)") -> Jadens Fruitamil (12x) | S32: =IFERROR(__xludf.DUMMYFUNCTION("""COMPUTED_VALUE"""),46031.0) -> 46031 | T32: =IFERROR(__xludf.DUMMYFUNCTION("""COMPUTED_VALUE"""),"Renee Supermarket, IKOYI") -> Renee Supermarket, IKOYI | U32: =IFERROR(__xludf.DUMMYFUNCTION("""COMPUTED_VALUE"""),"Journal") -> Journal | V32: =IFERROR(__xludf.DUMMYFUNCTION("""COMPUTED_VALUE"""),8.0) -> 8 | W32: =IFERROR(__xludf.DUMMYFUNCTION("""COMPUTED_VALUE"""),1.0) -> 1 | X32: =IFERROR(__xludf.DUMMYFUNCTION("""COMPUTED_VALUE"""),60000.0) -> 60000
A33: Jadens Fussy-Pops (12x) | B33: 46031 | C33: Renee Supermarket, IKOYI | D33: Journal | E33: 8 | F33: 1 | G33: 60000 | P33: =sumif(M:M,M33,O:O) -> 0 | R33: =IFERROR(__xludf.DUMMYFUNCTION("""COMPUTED_VALUE"""),"Jadens Fussy-Pops (12x)") -> Jadens Fussy-Pops (12x) | S33: =IFERROR(__xludf.DUMMYFUNCTION("""COMPUTED_VALUE"""),46031.0) -> 46031 | T33: =IFERROR(__xludf.DUMMYFUNCTION("""COMPUTED_VALUE"""),"Renee Supermarket, IKOYI") -> Renee Supermarket, IKOYI | U33: =IFERROR(__xludf.DUMMYFUNCTION("""COMPUTED_VALUE"""),"Journal") -> Journal | V33: =IFERROR(__xludf.DUMMYFUNCTION("""COMPUTED_VALUE"""),8.0) -> 8 | W33: =IFERROR(__xludf.DUMMYFUNCTION("""COMPUTED_VALUE"""),1.0) -> 1 | X33: =IFERROR(__xludf.DUMMYFUNCTION("""COMPUTED_VALUE"""),60000.0) -> 60000
A34: Jadens Mixagrain (12x) | B34: 46031 | C34: Renee Supermarket, IKOYI | D34: Journal | E34: 8 | F34: 1 | G34: 60000 | P34: =sumif(M:M,M34,O:O) -> 0 | R34: =IFERROR(__xludf.DUMMYFUNCTION("""COMPUTED_VALUE"""),"Jadens Mixagrain (12x)") -> Jadens Mixagrain (12x) | S34: =IFERROR(__xludf.DUMMYFUNCTION("""COMPUTED_VALUE"""),46031.0) -> 46031 | T34: =IFERROR(__xludf.DUMMYFUNCTION("""COMPUTED_VALUE"""),"Renee Supermarket, IKOYI") -> Renee Supermarket, IKOYI | U34: =IFERROR(__xludf.DUMMYFUNCTION("""COMPUTED_VALUE"""),"Journal") -> Journal | V34: =IFERROR(__xludf.DUMMYFUNCTION("""COMPUTED_VALUE"""),8.0) -> 8 | W34: =IFERROR(__xludf.DUMMYFUNCTION("""COMPUTED_VALUE"""),1.0) -> 1 | X34: =IFERROR(__xludf.DUMMYFUNCTION("""COMPUTED_VALUE"""),60000.0) -> 60000
A35: Jadens Nuttymeal (12x) | B35: 46031 | C35: Renee Supermarket, IKOYI | D35: Journal | E35: 8 | F35: 1 | G35: 60000 | P35: =sumif(M:M,M35,O:O) -> 0 | R35: =IFERROR(__xludf.DUMMYFUNCTION("""COMPUTED_VALUE"""),"Jadens Nuttymeal (12x)") -> Jadens Nuttymeal (12x) | S35: =IFERROR(__xludf.DUMMYFUNCTION("""COMPUTED_VALUE"""),46031.0) -> 46031 | T35: =IFERROR(__xludf.DUMMYFUNCTION("""COMPUTED_VALUE"""),"Renee Supermarket, IKOYI") -> Renee Supermarket, IKOYI | U35: =IFERROR(__xludf.DUMMYFUNCTION("""COMPUTED_VALUE"""),"Journal") -> Journal | V35: =IFERROR(__xludf.DUMMYFUNCTION("""COMPUTED_VALUE"""),8.0) -> 8 | W35: =IFERROR(__xludf.DUMMYFUNCTION("""COMPUTED_VALUE"""),1.0) -> 1 | X35: =IFERROR(__xludf.DUMMYFUNCTION("""COMPUTED_VALUE"""),60000.0) -> 60000
A36: Jadens Fruitamil (12x) | B36: 46031 | C36: Hutoos Supermarket, Ogba | D36: Sales | E36: DT:000083 | F36: 0.5 | G36: 30000 | P36: =sumif(M:M,M36,O:O) -> 0
A37: Jadens Fruitamil (12x) | B37: 46031 | C37: Reno Supermarket, EJIGBO | D37: Sales | E37: DT:000098 | F37: 0.5 | G37: 30000 | P37: =sumif(M:M,M37,O:O) -> 0
A38: Jadens Fruitamil (12x) | B38: 46036 | C38: Reno Supermarket, COUNCIL | D38: Sales | E38: DT:000155 | F38: 0.5 | G38: 30000 | P38: =sumif(M:M,M38,O:O) -> 0
A39: Jadens Fruitamil (12x) | B39: 46036 | C39: Twins Faja Supermarket, IKOTUN Road | D39: Sales | E39: DT:000171 | F39: 0.5 | G39: 30000 | P39: =sumif(M:M,M39,O:O) -> 0
A40: Jadens Fruitamil (12x) | B40: 46036 | C40: Prestige Superstore, IGANDO | D40: Sales | E40: DT:000173 | F40: 0.5 | G40: 30000 | P40: =sumif(M:M,M40,O:O) -> 0
...

Sheet Sheet10

Sheet Payment Advice
F2: =SUM(D:D) -> 480000

Sheet Dala Sales & Deliveries
H1: Total Invoices Delivered | I1: =countifs(B:B,"<>",F:F,"<>")-1 -> 8 | K1: Sku Performance | L1: Units | M1: Value
H2: Unique Locations Supplied | I2: {=(COUNTA(UNIQUE(C:C))-1)} -> 8 | K2: Jadens Fruitamil (12x) | L2: =sumif(D:D,K2,E:E) -> 3 | M2: =sumif(D:D,K2,F:F) -> 180000
H3: Total Value of orders | I3: =sum(F:F) -> 480000 | K3: Jadens Fussy-Pops (12x) | L3: =sumif(D:D,K3,E:E) -> 0.5 | M3: =sumif(D:D,K3,F:F) -> 30000
K4: Jadens Mixagrain (12x) | L4: =sumif(D:D,K4,E:E) -> 1 | M4: =sumif(D:D,K4,F:F) -> 60000
K5: Jadens Nuttymeal (12x) | L5: =sumif(D:D,K5,E:E) -> 3.5 | M5: =sumif(D:D,K5,F:F) -> 210000

Sheet External Delivery Fulfillment
H1: Total Invoices Delivered | I1: =countifs(B:B,"<>",F:F,"<>")-1 -> 12 | K1: Sku Performance | L1: Units | M1: Value
H2: Unique Locations Supplied | I2: {=(COUNTA(UNIQUE(C:C))-1)} -> 12 | K2: Jadens Fruitamil (12x) | L2: =sumif(D:D,K2,E:E) -> 9.5 | M2: =sumif(D:D,K2,F:F) -> 570000
H3: Total Value of orders | I3: =sum(F:F) -> 2370000 | K3: Jadens Fussy-Pops (12x) | L3: =sumif(D:D,K3,E:E) -> 8 | M3: =sumif(D:D,K3,F:F) -> 480000
K4: Jadens Mixagrain (12x) | L4: =sumif(D:D,K4,E:E) -> 10.5 | M4: =sumif(D:D,K4,F:F) -> 630000
K5: Jadens Nuttymeal (12x) | L5: =sumif(D:D,K5,E:E) -> 11.5 | M5: =sumif(D:D,K5,F:F) -> 690000

Sheet Forwarding From Client
H1: Total Invoices Delivered | I1: =countifs(B:B,"<>",F:F,"<>")-1 -> 0 | K1: Sku Performance | L1: Units | M1: Value
H2: Unique Locations Supplied | I2: {=(COUNTA(UNIQUE(C:C))-1)} -> 0 | K2: AGS- Jadens Fruitamil (12x) | L2: =sumif(D:D,K2,E:E) -> 0
H3: Total Value of orders | I3: =sum(F:F) -> 0 | K3: AGS- Jadens Fussy-Pops (12x) | L3: =sumif(D:D,K3,E:E) -> 0
K4: AGS- Jadens Mixagrain (12x) | L4: =sumif(D:D,K4,E:E) -> 0
K5: AGS- Jadens Nuttymeal (12x) | L5: =sumif(D:D,K5,E:E) -> 0

Sheet Dala Restocking
H1: Total Invoices Delivered | I1: =countifs(B:B,"<>",F:F,"<>")-1 -> 0 | K1: Sku Performance | L1: Units
H2: Unique Locations Supplied | I2: {=(COUNTA(UNIQUE(C:C,,0))-1)} -> 0 | K2: Jadens Fruitamil (12x) | L2: =sumif(D:D,K2,E:E) -> 0
H3: Total Value of orders | I3: =sum(F:F) -> 0 | K3: Jadens Fussy-Pops (12x) | L3: =sumif(D:D,K3,E:E) -> 0
K4: Jadens Mixagrain (12x) | L4: =sumif(D:D,K4,E:E) -> 0
K5: Jadens Nuttymeal (12x) | L5: =sumif(D:D,K5,E:E) -> 0

Sheet Client Restocking
H1: Total Invoices Delivered | I1: =countifs(B:B,"<>",F:F,"<>")-1 -> 0 | K1: Sku Performance | L1: Units
H2: Unique Locations Supplied | I2: {=(COUNTA(UNIQUE(C:C,,0))-1)} -> 0 | K2: AGS- Jadens Fruitamil (12x) | L2: =sumif(D:D,K2,E:E) -> 0
H3: Total Value of orders | I3: =sum(F:F) -> 0 | K3: AGS- Jadens Fussy-Pops (12x) | L3: =sumif(D:D,K3,E:E) -> 0
K4: AGS- Jadens Mixagrain (12x) | L4: =sumif(D:D,K4,E:E) -> 0
K5: AGS- Jadens Nuttymeal (12x) | L5: =sumif(D:D,K5,E:E) -> 0

Sheet Internal Summary
B1: Description | C1: Units | D1: measurements | E1: total
A2: SALES | B2: Total Invoices Delivered | E2: ='Dala Sales & Deliveries'!I1+'External Delivery Fulfillment'!I1 -> 20
B3: Unique Locations Delivered To | E3: ='Raw Data'!AX2 -> 18
B4: Value of Dala Deliveries | E4: ='Dala Sales & Deliveries'!I3 -> 480000
B5: Value of External Deliveries | E5: ='External Delivery Fulfillment'!I3 -> 2370000
B6: Total Value of Deliveries | E6: =sum(E4:E5) -> 2850000
A7: Remittance & Deductions | B7: Total Remitted to Partner
B8: Collection Fees | C8: 0.07 | E8: =E7*(C8+100%)-E7 -> 0
A9: Invoice Value Due | B9: Outstanding Payments For Sales | E9: =E4-E7-E8 -> 480000
A10: Debts | B10: Unpaid Subscription | C10: 0 | E10: =C10*D10 -> 0
B11: Collection Fees | E11: =C8*E4 -> 33600
B12: Delivery Fees | E12: =C26 -> 16320
B13: Delivery Fees External & Pickup | D13: Table 1 | E13: =C22+C28 -> 80580
B14: Reimbursements Due To DALA | E14: 0
B15: Retailer Deductions | E15: =C30 -> 0
B16: Total Deductions | E16: =sum(E10:E15) -> 130500
A17: Remmittance Due | B17: Total Balance to Remitt | E17: =E9-E16+C36 -> 349500
A20: Inventory and Operational Fees
B21: Dala Pickup for Warehouse | C21: =U69 -> 0
B22: Warehouse Delivery Fee | C22: =V69 -> 0
B23: Forwarding to Retail | C23: =S69 -> 0
B24: Forwarding Delivery Fee | C24: =T69 -> 0
B25: Dala Sales | C25: =O69 -> 8
B26: Dala Delivery Fees | C26: =P69 -> 16320
B27: Exteranl Deliveries | C27: =Q69 -> 39.5
B28: External Delivery Fees | C28: =R69 -> 80580
B29: Product Defects and Expirey Issues | C29: =F69 -> 0
B30: Deductions From Retailer | C30: =G69 -> 0
B31: Samples used | C31: =I69 -> 0
B32: Produce Replacements | C32: =J69 -> 0
B33: Expected Closing Inventory | C33: =L69 -> 15
B34: Physical Stock count | C34: =K69 -> 20.6
B35: Inventory Shortages | C35: 0
B36: Inventory Shortage Costs | C36: 0
B39: SKUs | C39: Retail Value | D39: Inbound Delivery Fee | E39: Outbound Delivery Fee | F39: Defects/Expirey | G39: Deductions | H39: Opening Inventory | I39: Samples Used | J39: Product Replacements | K39: Physical Closing Stock Count | L39: Expected Closing Inventory | M39: Inventory Shortages | N39: Shortages Costs | O39: Dala Deliveries | P39: Retail Sales Fee | Q39: External Delivery | R39: External Delivery Fee | S39: Forwarding from Client | T39: Forwarding Delivery Fee | U39: Dala Restocking | V39: Dala Restocking Fee | W39: Client Restocking
B40: Jadens Fruitamil (12x) | C40: 60000 | D40: =2.2%*C40 -> 1320 | E40: 2040 | G40: =F40*C40 -> 0 | K40: 1.25 | L40: 1.25 | M40: =K40-L40 -> 0 | N40: =M40*C40 -> 0 | O40: ='Dala Sales & Deliveries'!L2 -> 3 | P40: =O40*E40 -> 6120 | Q40: ='External Delivery Fulfillment'!L2 -> 9.5 | R40: =Q40*E40 -> 19380 | S40: ='Forwarding From Client'!L2 -> 0 | T40: =S40*E40 -> 0 | U40: ='Dala Restocking'!L2 -> 0 | V40: =U40*D40 -> 0 | W40: ='Client Restocking'!L2 -> 0
B41: Jadens Fussy-Pops (12x) | C41: 60000 | D41: =2.2%*C41 -> 1320 | E41: 2040 | G41: =F41*C41 -> 0 | K41: 3.75 | L41: 3.75 | M41: =K41-L41 -> 0 | N41: =M41*C41 -> 0 | O41: ='Dala Sales & Deliveries'!L3 -> 0.5 | P41: =O41*E41 -> 1020 | Q41: ='External Delivery Fulfillment'!L3 -> 8 | R41: =Q41*E41 -> 16320 | S41: ='Forwarding From Client'!L3 -> 0 | T41: =S41*E41 -> 0 | U41: ='Dala Restocking'!L3 -> 0 | V41: =U41*D41 -> 0 | W41: ='Client Restocking'!L3 -> 0
B42: Jadens Mixagrain (12x) | C42: 60000 | D42: =2.2%*C42 -> 1320 | E42: 2040 | G42: =F42*C42 -> 0 | K42: 10 | L42: 10 | M42: =K42-L42 -> 0 | N42: =M42*C42 -> 0 | O42: ='Dala Sales & Deliveries'!L4 -> 1 | P42: =O42*E42 -> 2040 | Q42: ='External Delivery Fulfillment'!L4 -> 10.5 | R42: =Q42*E42 -> 21420 | S42: ='Forwarding From Client'!L4 -> 0 | T42: =S42*E42 -> 0 | U42: ='Dala Restocking'!L4 -> 0 | V42: =U42*D42 -> 0 | W42: ='Client Restocking'!L4 -> 0
B43: Jadens Nuttymeal (12x) | C43: 60000 | D43: =2.2%*C43 -> 1320 | E43: 2040 | G43: =F43*C43 -> 0 | K43: 5.6 | M43: =K43-L43 -> 5.6 | N43: =M43*C43 -> 336000 | O43: ='Dala Sales & Deliveries'!L5 -> 3.5 | P43: =O43*E43 -> 7140 | Q43: ='External Delivery Fulfillment'!L5 -> 11.5 | R43: =Q43*E43 -> 23460 | S43: ='Forwarding From Client'!L5 -> 0 | T43: =S43*E43 -> 0 | U43: ='Dala Restocking'!L5 -> 0 | V43: =U43*D43 -> 0 | W43: ='Client Restocking'!L5 -> 0
G44: =F44*C44 -> 0 | L44: =H44+U44+W44-O44-Q44-I44-J44 -> 0 | M44: =K44-L44 -> 0 | N44: =M44*C44 -> 0 | P44: =O44*E44 -> 0 | R44: =Q44*E44 -> 0 | S44: ='Forwarding From Client'!L6 | T44: =S44*E44 -> 0 | V44: =U44*D44 -> 0
...
