Workbook

Sheet Raw Data
A1: Exported from Tally | I1: Dala Sales & Deliveries | M1: , | R1: External Deliveries | Z1: Forwarding From Client | AH1: Client Restock | AP1: Dala Restock | AX1: Unique Locations
A2: item name | B2: Date | C2: Particulars | D2: Vch Type | E2: Vch No. | F2: Quantity | G2: Value | I2: item name | J2: Date | K2: Particulars | L2: Vch Type | M2: Vch No. | N2: Quantity | O2: Value | P2: Total Value | R2: item name | S2: Date | T2: Particulars | U2: Vch Type | V2: Vch No. | W2: Quantity | X2: Value | Z2: item name | AA2: Date | AB2: Particulars | AC2: Vch Type | AD2: Vch No. | AE2: Quantity | AF2: Value | AH2: item name | AI2: Date | AJ2: Particulars | AK2: Vch Type | AL2: Vch No. | AM2: Quantity | AN2: Value | AP2: item name | AQ2: Date | AR2: Particulars | AS2: Vch Type | AT2: Vch No. | AU2: Quantity | AV2: Value | AX2: {=counta(unique(C:C))-2} -> 0
A3: 300g Bunnies Cereals | B3: 45875 | C3: Taiwo Supermarket, ISOLO | D3: Sales | E3: DT:002060 | F3: 1 | G3: 20465.12 | I3: 300g Bunnies Cereals | J3: 45875 | K3: Taiwo Supermarket, ISOLO | L3: Sales | M3: DT:002060 | N3: 1 | O3: 20465.12 | P3: =sumif(M:M,M3,O:O) -> 40930.24
A4: 350g Pocco Cornflakes Cereal | B4: 45875 | C4: Taiwo Supermarket, ISOLO | D4: Sales | E4: DT:002060 | F4: 1 | G4: 20465.12 | I4: 350g Pocco Cornflakes Cereal | J4: 45875 | K4: Taiwo Supermarket, ISOLO | L4: Sales | M4: DT:002060 | N4: 1 | O4: 20465.12 | P4: =sumif(M:M,M4,O:O) -> 40930.24
P5: =sumif(M:M,M5,O:O) -> 0
P6: =sumif(M:M,M6,O:O) -> 0
P7: =sumif(M:M,M7,O:O) -> 0
P8: =sumif(M:M,M8,O:O) -> 0
P9: =sumif(M:M,M9,O:O) -> 0
P10: =sumif(M:M,M10,O:O) -> 0
P11: =sumif(M:M,M11,O:O) -> 0
P12: =sumif(M:M,M12,O:O) -> 0
P13: =sumif(M:M,M13,O:O) -> 0
P14: =sumif(M:M,M14,O:O) -> 0
P15: =sumif(M:M,M15,O:O) -> 0
P16: =sumif(M:M,M16,O:O) -> 0
... P186: =sumif(M:M,M186,O:O) -> 0

Sheet payment Advice

Sheet Dala Sales & Deliveries
H1: Total Invoices Delivered | I1: =countifs(B:B,"<>",F:F,"<>")-1 -> 1 | K1: Sku Performance | L1: Units | M1: Value
H2: Unique Locations Supplied | I2: {=(COUNTA(UNIQUE(C:C))-1)} -> 1 | K2: ='Internal Summary'!B40 -> 25g Bunnies Cereal | L2: =sumif(D:D,K2,E:E) -> 0 | M2: =sumif(D:D,K2,F:F) -> 0
H3: Total Value of orders | I3: =sum(F:F) -> 40930.24 | K3: ='Internal Summary'!B41 -> 300g Bunnies Cereals | L3: =sumif(D:D,K3,E:E) -> 1 | M3: =sumif(D:D,K3,F:F) -> 20465.12
K4: ='Internal Summary'!B42 -> 30g Pocco Cornflakes Cereal | L4: =sumif(D:D,K4,E:E) -> 0 | M4: =sumif(D:D,K4,F:F) -> 0
K5: ='Internal Summary'!B43 -> 350g Pocco Cornflakes Cereal | L5: =sumif(D:D,K5,E:E) -> 1 | M5: =sumif(D:D,K5,F:F) -> 20465.12
K6: ='Internal Summary'!B44 | L6: =sumif(D:D,K6,E:E) -> 0 | M6: =sumif(D:D,K6,F:F) -> 0
K7: ='Internal Summary'!B45 | L7: =sumif(D:D,K7,E:E) -> 0 | M7: =sumif(D:D,K7,F:F) -> 0
K8: ='Internal Summary'!B46 | L8: =sumif(D:D,K8,E:E) -> 0 | M8: =sumif(D:D,K8,F:F) -> 0
K9: ='Internal Summary'!B47 | L9: =sumif(D:D,K9,E:E) -> 0 | M9: =sumif(D:D,K9,F:F) -> 0
K10: ='Internal Summary'!B48 | L10: =sumif(D:D,K10,E:E) -> 0 | M10: =sumif(D:D,K10,F:F) -> 0
K11: ='Internal Summary'!B49 | L11: =sumif(D:D,K11,E:E) -> 0 | M11: =sumif(D:D,K11,F:F) -> 0
A12: 45758 | K12: ='Internal Summary'!B50 | L12: =sumif(D:D,K12,E:E) -> 0 | M12: =sumif(D:D,K12,F:F) -> 0
K13: ='Internal Summary'!B51 | L13: =sumif(D:D,K13,E:E) -> 0 | M13: =sumif(D:D,K13,F:F) -> 0

Sheet External Delivery Fulfillment
H1: Total Invoices Delivered | I1: =countifs(B:B,"<>",F:F,"<>")-1 -> 0 | K1: Sku Performance | L1: Units | M1: Value
H2: Unique Locations Supplied | I2: {=(COUNTA(UNIQUE(C:C))-1)} -> 0 | K2: ='Internal Summary'!B40 -> 25g Bunnies Cereal | L2: =sumif(D:D,K2,E:E) -> 0 | M2: =sumif(D:D,K2,F:F) -> 0
H3: Total Value of orders | I3: =sum(F:F) -> 0 | K3: ='Internal Summary'!B41 -> 300g Bunnies Cereals | L3: =sumif(D:D,K3,E:E) -> 0 | M3: =sumif(D:D,K3,F:F) -> 0
K4: ='Internal Summary'!B42 -> 30g Pocco Cornflakes Cereal | L4: =sumif(D:D,K4,E:E) -> 0 | M4: =sumif(D:D,K4,F:F) -> 0
K5: ='Internal Summary'!B43 -> 350g Pocco Cornflakes Cereal | L5: =sumif(D:D,K5,E:E) -> 0 | M5: =sumif(D:D,K5,F:F) -> 0
K6: ='Internal Summary'!B44 | L6: =sumif(D:D,K6,E:E) -> 0 | M6: =sumif(D:D,K6,F:F) -> 0
K7: ='Internal Summary'!B45 | L7: =sumif(D:D,K7,E:E) -> 0 | M7: =sumif(D:D,K7,F:F) -> 0
K8: ='Internal Summary'!B46 | L8: =sumif(D:D,K8,E:E) -> 0 | M8: =sumif(D:D,K8,F:F) -> 0
K9: ='Internal Summary'!B47 | L9: =sumif(D:D,K9,E:E) -> 0 | M9: =sumif(D:D,K9,F:F) -> 0
K10: ='Internal Summary'!B48 | L10: =sumif(D:D,K10,E:E) -> 0 | M10: =sumif(D:D,K10,F:F) -> 0
K11: ='Internal Summary'!B49 | L11: =sumif(D:D,K11,E:E) -> 0 | M11: =sumif(D:D,K11,F:F) -> 0
K12: ='Internal Summary'!B50 | L12: =sumif(D:D,K12,E:E) -> 0 | M12: =sumif(D:D,K12,F:F) -> 0
K13: ='Internal Summary'!B51 | L13: =sumif(D:D,K13,E:E) -> 0 | M13: =sumif(D:D,K13,F:F) -> 0

Sheet Forwarding From Client
H1: Total Invoices Delivered | I1: =countifs(B:B,"<>",F:F,"<>")-1 -> 0 | K1: Sku Performance | L1: Units | M1: Value
H2: Unique Locations Supplied | I2: {=(COUNTA(UNIQUE(C:C))-1)} -> 0 | K2: ='Internal Summary'!B40 -> 25g Bunnies Cereal | L2: =sumif(D:D,K2,E:E) -> 0 | M2: =sumif(D:D,K2,F:F) -> 0
H3: Total Value of orders | I3: =sum(F:F) -> 0 | K3: ='Internal Summary'!B41 -> 300g Bunnies Cereals | L3: =sumif(D:D,K3,E:E) -> 0 | M3: =sumif(D:D,K3,F:F) -> 0
K4: ='Internal Summary'!B42 -> 30g Pocco Cornflakes Cereal | L4: =sumif(D:D,K4,E:E) -> 0 | M4: =sumif(D:D,K4,F:F) -> 0
K5: ='Internal Summary'!B43 -> 350g Pocco Cornflakes Cereal | L5: =sumif(D:D,K5,E:E) -> 0 | M5: =sumif(D:D,K5,F:F) -> 0
K6: ='Internal Summary'!B44 | L6: =sumif(D:D,K6,E:E) -> 0 | M6: =sumif(D:D,K6,F:F) -> 0
K7: ='Internal Summary'!B45 | L7: =sumif(D:D,K7,E:E) -> 0 | M7: =sumif(D:D,K7,F:F) -> 0
K8: ='Internal Summary'!B46 | L8: =sumif(D:D,K8,E:E) -> 0 | M8: =sumif(D:D,K8,F:F) -> 0
K9: ='Internal Summary'!B47 | L9: =sumif(D:D,K9,E:E) -> 0 | M9: =sumif(D:D,K9,F:F) -> 0
K10: ='Internal Summary'!B48 | L10: =sumif(D:D,K10,E:E) -> 0 | M10: =sumif(D:D,K10,F:F) -> 0
K11: ='Internal Summary'!B49 | L11: =sumif(D:D,K11,E:E) -> 0 | M11: =sumif(D:D,K11,F:F) -> 0
K12: ='Internal Summary'!B50 | L12: =sumif(D:D,K12,E:E) -> 0 | M12: =sumif(D:D,K12,F:F) -> 0
K13: ='Internal Summary'!B51 | L13: =sumif(D:D,K13,E:E) -> 0 | M13: =sumif(D:D,K13,F:F) -> 0

Sheet Dala Restocking
H1: Total Invoices Delivered | I1: =countifs(B:B,"<>",F:F,"<>")-1 -> 0 | K1: Sku Performance | L1: Units
H2: Unique Locations Supplied | I2: {=(COUNTA(UNIQUE(C:C,,0))-1)} -> 0 | K2: ='Internal Summary'!B40 -> 25g Bunnies Cereal | L2: =sumif(D:D,K2,E:E) -> 0
H3: Total Value of orders | I3: =sum(F:F) -> 0 | K3: ='Internal Summary'!B41 -> 300g Bunnies Cereals | L3: =sumif(D:D,K3,E:E) -> 0
K4: ='Internal Summary'!B42 -> 30g Pocco Cornflakes Cereal | L4: =sumif(D:D,K4,E:E) -> 0
K5: ='Internal Summary'!B43 -> 350g Pocco Cornflakes Cereal | L5: =sumif(D:D,K5,E:E) -> 0
K6: ='Internal Summary'!B44 | L6: =sumif(D:D,K6,E:E) -> 0
K7: ='Internal Summary'!B45 | L7: =sumif(D:D,K7,E:E) -> 0
K8: ='Internal Summary'!B46 | L8: =sumif(D:D,K8,E:E) -> 0
K9: ='Internal Summary'!B47 | L9: =sumif(D:D,K9,E:E) -> 0
K10: ='Internal Summary'!B48 | L10: =sumif(D:D,K10,E:E) -> 0
K11: ='Internal Summary'!B49 | L11: =sumif(D:D,K11,E:E) -> 0
K12: ='Internal Summary'!B50 | L12: =sumif(D:D,K12,E:E) -> 0
K13: ='Internal Summary'!B51 | L13: =sumif(D:D,K13,E:E) -> 0

Sheet Client Restocking
H1: Total Invoices Delivered | I1: =countifs(B:B,"<>",F:F,"<>")-1 -> 0 | K1: Sku Performance | L1: Units
H2: Unique Locations Supplied | I2: {=(COUNTA(UNIQUE(C:C,,0))-1)} -> 0 | K2: ='Internal Summary'!B40 -> 25g Bunnies Cereal | L2: =sumif(D:D,K2,E:E) -> 0
H3: Total Value of orders | I3: =sum(F:F) -> 0 | K3: ='Internal Summary'!B41 -> 300g Bunnies Cereals | L3: =sumif(D:D,K3,E:E) -> 0
K4: ='Internal Summary'!B42 -> 30g Pocco Cornflakes Cereal | L4: =sumif(D:D,K4,E:E) -> 0
K5: ='Internal Summary'!B43 -> 350g Pocco Cornflakes Cereal | L5: =sumif(D:D,K5,E:E) -> 0
K6: ='Internal Summary'!B44 | L6: =sumif(D:D,K6,E:E) -> 0
K7: ='Internal Summary'!B45 | L7: =sumif(D:D,K7,E:E) -> 0
K8: ='Internal Summary'!B46 | L8: =sumif(D:D,K8,E:E) -> 0
K9: ='Internal Summary'!B47 | L9: =sumif(D:D,K9,E:E) -> 0
K10: ='Internal Summary'!B48 | L10: =sumif(D:D,K10,E:E) -> 0
K11: ='Internal Summary'!B49 | L11: =sumif(D:D,K11,E:E) -> 0
K12: ='Internal Summary'!B50 | L12: =sumif(D:D,K12,E:E) -> 0
K13: ='Internal Summary'!B51 | L13: =sumif(D:D,K13,E:E) -> 0

Sheet Internal Summary
B1: Description | C1: Units | D1: measurements | E1: total
A2: SALES | B2: Total Invoices Delivered | E2: ='Dala Sales & Deliveries'!I1+'External Delivery Fulfillment'!I1 -> 1
B3: Unique Locations Delivered To | E3: ='Raw Data'!AX2 -> 0
B4: Value of Dala Deliveries | E4: ='Dala Sales & Deliveries'!I3 -> 40930.24
B5: Value of External Deliveries | E5: ='External Delivery Fulfillment'!I3 -> 0
B6: VAT on sales | E6: =E4*1.075-E4 -> 3069.768
B7: Total Value of Deliveries | E7: =sum(E4:E6) -> 44000.008
A8: Remittance & Deductions | B8: Total Remitted to Partner
B9: Collection Fees | C9: 0.12 | E9: =E8*(C9+100%)-E8 -> 0
A10: Invoice Value Due | B10: Outstanding Paymets For Sales | E10: =E7-E8-E9 -> 44000.008
A11: Debts | B11: Unpaid Subscription | C11: 1 | D11: 150000 | E11: =C11*D11 -> 150000
B12: Collection Fees | E12: =E10*C9 -> 5280.001
B13: Delivery Fees | D13: Table 1 | E13: =C22+C26 -> 2000
B14: Reimbursements Due To DALA | E14: 0
B15: Retailer Deductions | E15: =C30 -> 0
B16: Total Deductions | E16: =sum(E11:E15) -> 157280
A17: Remmittance Due | B17: Total Balance to Remitt | E17: =E10-E16+C36 -> -113279.99
A20: Inventory and Operational Fees
B21: Dala Pickup for Warehouse | C21: =U69 -> 0
B22: Warehouse Delivery Fee | C22: =V69 -> 0
B23: Forwarding to Retail | C23: =S69 -> 0
B24: Forwarding Delivery Fee | C24: =T69 -> 0
B25: Dala Sales | C25: =67 -> 67
B26: Dala Delivery Fees | C26: =P69 -> 2000
B27: Exteranl Deliveries | C27: =Q69 -> 0
B28: External Delivery Fees | C28: =R69 -> 0
B29: Product Defects and Expirey Issues | C29: =F69 -> 0
B30: Deductions From Retailer | C30: =G69 -> 0
B31: Samples used | C31: =I69 -> 0
B32: Produce Replacements | C32: =J69 -> 0
B33: Expected Closing Inventory | C33: 0
B34: Physical Stock count | C34: =K69 -> 54.5
B35: Inventory Shortages | C35: 0
B36: Inventory Shortage Costs | C36: 0
B39: SKUs | C39: Retail Value | D39: Inbound Delivery Fee | E39: Outbound Delivery Fee | F39: Defects/Expirey | G39: Deductions | H39: Opening Inventory | I39: Samples Used | J39: Product Replacements | K39: Physical Closing Stock Count | L39: Expected Closing Inventory | M39: Inventory Shortages | N39: Shortages Costs | O39: Dala Deliveries | P39: Retail Sales Fee | Q39: External Delivery | R39: External Delivery Fee | S39: Forwarding from Client | T39: Forwarding Delivery Fee | U39: Dala Restocking | V39: Dala Restocking Fee | W39: Client Restocking
B40: 25g Bunnies Cereal | C40: 16800 | D40: 500 | E40: 800 | G40: =F40*C40 -> 0 | K40: 3.5 | L40: =H40+U40+W40-O40-Q40-I40-J40 -> 0 | M40: =K40-L40 -> 3.5 | N40: =M40*C40 -> 58800 | O40: ='Dala Sales & Deliveries'!L2 -> 0 | P40: =O40*E40 -> 0 | Q40: ='External Delivery Fulfillment'!L2 -> 0 | R40: =Q40*E40 -> 0 | S40: ='Forwarding From Client'!L2 -> 0 | T40: =S40*E40 -> 0 | U40: ='Dala Restocking'!L2 -> 0 | V40: =U40*D40 -> 0 | W40: ='Client Restocking'!L2 -> 0
B41: 300g Bunnies Cereals | C41: 22000 | D41: 650 | E41: 1000 | G41: =F41*C41 -> 0 | K41: 24 | L41: =H41+U41+W41-O41-Q41-I41-J41 -> -1 | M41: =K41-L41 -> 25 | N41: =M41*C41 -> 550000 | O41: ='Dala Sales & Deliveries'!L3 -> 1 | P41: =O41*E41 -> 1000 | Q41: ='External Delivery Fulfillment'!L3 -> 0 | R41: =Q41*E41 -> 0 | S41: ='Forwarding From Client'!L3 -> 0 | T41: =S41*E41 -> 0 | U41: ='Dala Restocking'!L3 -> 0 | V41: =U41*D41 -> 0 | W41: ='Client Restocking'!L3 -> 0
B42: 30g Pocco Cornflakes Cereal | C42: 16800 | D42: 500 | E42: 800 | G42: =F42*C42 -> 0 | K42: 2.5 | L42: =H42+U42+W42-O42-Q42-I42-J42 -> 0 | M42: =K42-L42 -> 2.5 | N42: =M42*C42 -> 42000 | O42: ='Dala Sales & Deliveries'!L4 -> 0 | P42: =O42*E42 -> 0 | Q42: ='External Delivery Fulfillment'!L4 -> 0 | R42: =Q42*E42 -> 0 | S42: ='Forwarding From Client'!L4 -> 0 | T42: =S42*E42 -> 0 | U42: ='Dala Restocking'!L4 -> 0 | V42: =U42*D42 -> 0 | W42: ='Client Restocking'!L4 -> 0
B43: 350g Pocco Cornflakes Cereal | C43: 22000 | D43: 650 | E43: 1000 | G43: =F43*C43 -> 0 | K43: 24.5 | L43: =H43+U43+W43-O43-Q43-I43-J43 -> -1 | M43: =K43-L43 -> 25.5 | N43: =M43*C43 -> 561000 | O43: ='Dala Sales & Deliveries'!L5 -> 1 | P43: =O43*E43 -> 1000 | Q43: ='External Delivery Fulfillment'!L5 -> 0 | R43: =Q43*E43 -> 0 | S43: ='Forwarding From Client'!L5 -> 0 | T43: =S43*E43 -> 0 | U43: ='Dala Restocking'!L5 -> 0 | V43: =U43*D43 -> 0 | W43: ='Client Restocking'!L5 -> 0
G44: =F44*C44 -> 0 | L44: =H44+U44+W44-O44-Q44-I44-J44 -> 0 | M44: =K44-L44 -> 0 | N44: =M44*C44 -> 0 | O44: ='Dala Sales & Deliveries'!L6 -> 0 | P44: =O44*E44 -> 0 | Q44: ='External Delivery Fulfillment'!L6 -> 0 | R44: =Q44*E44 -> 0 | S44: ='Forwarding From Client'!L6 -> 0 | T44: =S44*E44 -> 0 | U44: ='Dala Restocking'!L6 -> 0 | V44: =U44*D44 -> 0 | W44: ='Client Restocking'!L6 -> 0
...

Sheet External Summary
B1: Description | C1: Units | D1: measurements | E1: total
A2: SALES | B2: Total Invoices Delivered | E2: ='Dala Sales & Deliveries'!I1+'External Delivery Fulfillment'!I1+'Forwarding From Client'!I1 -> 1
B3: Unique Locations Delivered To | E3: ='Raw Data'!AX2 -> 0
B4: Value of Dala Deliveries | E4: ='Dala Sales & Deliveries'!I3 -> 40930.24
B5: VAT | E5: =E4*1.075-E4 -> 3069.768
B6: Total Value of Deliveries | E6: =sum(E4:E5) -> 44000.008
A7: Remittance & Deductions | B7: Total Remitted to Partner
B8: Delivery Fees | C8: 0.06 | E8: =E7*(C8+100%)-E7 -> 0
B9: Collection Fees | C9: 0.1 | E9: =E7*(C9+100%)-E7 -> 0
A10: Debts | B10: Unpaid Subscription | C10: 1 | D10: 150000 | E10: =C10*D10 -> 150000
B11: Restocking Fees | E11: =V67 -> 0
B12: External Delivery Fees | E12: =R67 -> 0
B13: Reimbursements Due To DALA | E13: 0
B14: Retailer Deductions | E14: =C28 -> 0
B15: Total Owed to Dala | E15: =sum(E10:E14) -> 150000
A18: Inventory and Operational Fees
B19: Dala Pickup for Warehouse | C19: =U67 -> 0
B20: Warehouse Delivery Fee | C20: =V67 -> 0
B21: Forwarding to Retail | C21: =S67 -> 0
B22: Forwarding Delivery Fee | C22: =T67 -> 0
B23: Dala Sales | C23: =O67 -> 2
B24: Dala Delivery Fees | C24: =P67 -> 2000
B25: Exteranl Deliveries | C25: =Q67 -> 0
B26: External Delivery Fees | C26: =R67 -> 0
B27: Product Defects and Expirey Issues | C27: =F67 -> 0
B28: Deductions From Retailer | C28: =G67 -> 0
B29: Samples used | C29: =I67 -> 0
B30: Returns/Replacements | C30: =J67 -> 0
B31: Expected Closing Inventory | C31: =L67 -> -2
B32: Physical Stock count | C32: =K67 -> 54.5
B33: Inventory Shortages | C33: 0
B34: Inventory Shortage Costs | C34: 0
B37: SKUs | C37: Retail Value | D37: Inbound Delivery Fee | E37: Outbound Delivery Fee | F37: Defects/Expirey | G37: Deductions | H37: Opening Inventory | I37: Samples Used | J37: Product Replacements | K37: Physical Closing Stock Count | L37: Expected Closing Inventory | M37: Inventory Shortages | N37: Shortages Costs | O37: Dala Sales | P37: Retail Sales Fee | Q37: External Delivery | R37: External Delivery Fee | S37: Forwarding from Client | T37: Forwarding Delivery Fee | U37: Dala Restocking | V37: Dala Restocking Fee | W37: Client Restocking
B38: 25g Bunnies Cereal | C38: ='Internal Summary'!C40 -> 16800 | D38: ='Internal Summary'!D40 -> 500 | E38: ='Internal Summary'!E40 -> 800 | G38: =F38*C38 -> 0 | K38: 3.5 | L38: =H38+U38+W38-O38-Q38-I38-J38 -> 0 | M38: =K38-L38 -> 3.5 | N38: =M38*C38 -> 58800 | O38: ='Dala Sales & Deliveries'!L2 -> 0 | P38: =O38*E38 -> 0 | Q38: ='External Delivery Fulfillment'!L2 -> 0 | R38: =Q38*E38 -> 0 | S38: ='Forwarding From Client'!L2 -> 0 | T38: =S38*E38 -> 0 | U38: ='Dala Restocking'!L2 -> 0 | V38: =U38*D38 -> 0 | W38: ='Client Restocking'!L2 -> 0
B39: 300g Bunnies Cereals | C39: ='Internal Summary'!C41 -> 22000 | D39: ='Internal Summary'!D41 -> 650 | E39: ='Internal Summary'!E41 -> 1000 | G39: =F39*C39 -> 0 | K39: 24 | L39: =H39+U39+W39-O39-Q39-I39-J39 -> -1 | M39: =K39-L39 -> 25 | N39: =M39*C39 -> 550000 | O39: ='Dala Sales & Deliveries'!L3 -> 1 | P39: =O39*E39 -> 1000 | Q39: ='External Delivery Fulfillment'!L3 -> 0 | R39: =Q39*E39 -> 0 | S39: ='Forwarding From Client'!L3 -> 0 | T39: =S39*E39 -> 0 | U39: ='Dala Restocking'!L3 -> 0 | V39: =U39*D39 -> 0 | W39: ='Client Restocking'!L3 -> 0
B40: 30g Pocco Cornflakes Cereal | C40: ='Internal Summary'!C42 -> 16800 | D40: ='Internal Summary'!D42 -> 500 | E40: ='Internal Summary'!E42 -> 800 | G40: =F40*C40 -> 0 | K40: 2.5 | L40: =H40+U40+W40-O40-Q40-I40-J40 -> 0 | M40: =K40-L40 -> 2.5 | N40: =M40*C40 -> 42000 | O40: ='Dala Sales & Deliveries'!L4 -> 0 | P40: =O40*E40 -> 0 | Q40: ='External Delivery Fulfillment'!L4 -> 0 | R40: =Q40*E40 -> 0 | S40: ='Forwarding From Client'!L4 -> 0 | T40: =S40*E40 -> 0 | U40: ='Dala Restocking'!L4 -> 0 | V40: =U40*D40 -> 0 | W40: ='Client Restocking'!L4 -> 0
B41: 350g Pocco Cornflakes Cereal | C41: ='Internal Summary'!C43 -> 22000 | D41: ='Internal Summary'!D43 -> 650 | E41: ='Internal Summary'!E43 -> 1000 | G41: =F41*C41 -> 0 | K41: 24.5 | L41: =H41+U41+W41-O41-Q41-I41-J41 -> -1 | M41: =K41-L41 -> 25.5 | N41: =M41*C41 -> 561000 | O41: ='Dala Sales & Deliveries'!L5 -> 1 | P41: =O41*E41 -> 1000 | Q41: ='External Delivery Fulfillment'!L5 -> 0 | R41: =Q41*E41 -> 0 | S41: ='Forwarding From Client'!L5 -> 0 | T41: =S41*E41 -> 0 | U41: ='Dala Restocking'!L5 -> 0 | V41: =U41*D41 -> 0 | W41: ='Client Restocking'!L5 -> 0
B42: ='Internal Summary'!B44 | C42: ='Internal Summary'!C44 | D42: ='Internal Summary'!D44 | E42: ='Internal Summary'!E44 | G42: =F42*C42 -> 0 | L42: =H42+U42+W42-O42-Q42-I42-J42 -> 0 | M42: =K42-L42 -> 0 | N42: =M42*C42 -> 0 | O42: ='Dala Sales & Deliveries'!L6 -> 0 | P42: =O42*E42 -> 0 | Q42: ='External Delivery Fulfillment'!L6 -> 0 | R42: =Q42*E42 -> 0 | S42: ='Forwarding From Client'!L6 -> 0 | T42: =S42*E42 -> 0 | U42: ='Dala Restocking'!L6 -> 0 | V42: =U42*D42 -> 0 | W42: ='Client Restocking'!L6 -> 0
B43: ='Internal Summary'!B45 | C43: ='Internal Summary'!C45 | D43: ='Internal Summary'!D45 | E43: ='Internal Summary'!E45 | G43: =F43*C43 -> 0 | L43: =H43+U43+W43-O43-Q43-I43-J43 -> 0 | M43: =K43-L43 -> 0 | N43: =M43*C43 -> 0 | O43: ='Dala Sales & Deliveries'!L7 -> 0 | P43: =O43*E43 -> 0 | Q43: ='External Delivery Fulfillment'!L7 -> 0 | R43: =Q43*E43 -> 0 | S43: ='Forwarding From Client'!L7 -> 0 | T43: =S43*E43 -> 0 | U43: ='Dala Restocking'!L7 -> 0 | V43: =U43*D43 -> 0 | W43: ='Client Restocking'!L7 -> 0
B44: ='Internal Summary'!B46 | C44: ='Internal Summary'!C46 | D44: ='Internal Summary'!D46 | E44: ='Internal Summary'!E46 | G44: =F44*C44 -> 0 | L44: =H44+U44+W44-O44-Q44-I44-J44 -> 0 | M44: =K44-L44 -> 0 | N44: =M44*C44 -> 0 | O44: ='Dala Sales & Deliveries'!L8 -> 0 | P44: =O44*E44 -> 0 | Q44: ='External Delivery Fulfillment'!L8 -> 0 | R44: =Q44*E44 -> 0 | S44: ='Forwarding From Client'!L8 -> 0 | T44: =S44*E44 -> 0 | U44: ='Dala Restocking'!L8 -> 0 | V44: =U44*D44 -> 0 | W44: ='Client Restocking'!L8 -> 0
...
