Workbook

Sheet Raw Data
I1: Dala Sales & Deliveries | R1: External Deliveries | Z1: Forwarding From Client | AH1: Client Restock | AP1: Dala Restock | AX1: Unique Locations
A2: item name | B2: Date | C2: Particulars | D2: Vch Type | E2: Vch No. | F2: Quantity | G2: Value | I2: item name | J2: Date | K2: Particulars | L2: Vch Type | M2: Vch No. | N2: Quantity | O2: Value | P2: Total Value | R2: item name | S2: Date | T2: Particulars | U2: Vch Type | V2: Vch No. | W2: Quantity | X2: Value | Z2: item name | AA2: Date | AB2: Particulars | AC2: Vch Type | AD2: Vch No. | AE2: Quantity | AF2: Value | AH2: item name | AI2: Date | AJ2: Particulars | AK2: Vch Type | AL2: Vch No. | AM2: Quantity | AN2: Value | AP2: item name | AQ2: Date | AR2: Particulars | AS2: Vch Type | AT2: Vch No. | AU2: Quantity | AV2: Value | AX2: {=counta(unique(C:C))-3} -> 4
A3: 150g Segunfunmi Hibiscus Tea pineapple, Cloves, Ginger (24x) | B3: 45668 | C3: Sambethel Supermarket | D3: Sales | E3: DT:003195 | F3: 0.50 ctn | G3: 21000 | I3: =IFERROR(__xludf.DUMMYFUNCTION("IFERROR( FILTER($A$3:$G1000, LEN($A$3:$A1000), LOWER(TRIM($D$3:$D1000))=""sales""), )"),"150g Segunfunmi Hibiscus Tea pineapple, Cloves, Ginger (24x)") -> 150g Segunfunmi Hibiscus Tea pineapple, Cloves, Ginger (24x) | J3: =IFERROR(__xludf.DUMMYFUNCTION("""COMPUTED_VALUE"""),45668.0) -> 45668 | K3: =IFERROR(__xludf.DUMMYFUNCTION("""COMPUTED_VALUE"""),"Sambethel Supermarket") -> Sambethel Supermarket | L3: =IFERROR(__xludf.DUMMYFUNCTION("""COMPUTED_VALUE"""),"Sales") -> Sales | M3: =IFERROR(__xludf.DUMMYFUNCTION("""COMPUTED_VALUE"""),"DT:003195") -> DT:003195 | N3: =IFERROR(__xludf.DUMMYFUNCTION("""COMPUTED_VALUE"""),"0.50 ctn") -> 0.50 ctn | O3: =IFERROR(__xludf.DUMMYFUNCTION("""COMPUTED_VALUE"""),21000.0) -> 21000 | P3: =sumif(M:M,M3,O:O) -> 21000 | R3: =IFERROR(__xludf.DUMMYFUNCTION("IFERROR( FILTER($A$3:$G1000, LEN($A$3:$A1000), REGEXMATCH(LOWER(TRIM($D$3:$D1000)), ""\bjournal\b"")), ) "),"") | AH3: =IFERROR(__xludf.DUMMYFUNCTION("IFERROR( FILTER($A$3:$G1000, LEN($A$3:$A1000), LOWER(TRIM($D$3:$D1000))=""Inventory Supplied by Brands""), )"),"") | AP3: =IFERROR(__xludf.DUMMYFUNCTION("IFERROR( FILTER($A$3:$G1000, LEN($A$3:$A1000), LOWER(TRIM($D$3:$D1000))=""Inventory Pickup by Dala""), ) "),"")
A4: 150g Segunfunmi Hibiscus Tea pineapple, Cloves, Ginger (24x) | B4: 45668 | C4: Value Exchange Supermarket, AREPO | D4: Sales | E4: DT:003203 | F4: 0.25 ctn | G4: 21000 | I4: =IFERROR(__xludf.DUMMYFUNCTION("""COMPUTED_VALUE"""),"150g Segunfunmi Hibiscus Tea pineapple, Cloves, Ginger (24x)") -> 150g Segunfunmi Hibiscus Tea pineapple, Cloves, Ginger (24x) | J4: =IFERROR(__xludf.DUMMYFUNCTION("""COMPUTED_VALUE"""),45668.0) -> 45668 | K4: =IFERROR(__xludf.DUMMYFUNCTION("""COMPUTED_VALUE"""),"Value Exchange Supermarket, AREPO") -> Value Exchange Supermarket, AREPO | L4: =IFERROR(__xludf.DUMMYFUNCTION("""COMPUTED_VALUE"""),"Sales") -> Sales | M4: =IFERROR(__xludf.DUMMYFUNCTION("""COMPUTED_VALUE"""),"DT:003203") -> DT:003203 | N4: =IFERROR(__xludf.DUMMYFUNCTION("""COMPUTED_VALUE"""),"0.25 ctn") -> 0.25 ctn | O4: =IFERROR(__xludf.DUMMYFUNCTION("""COMPUTED_VALUE"""),21000.0) -> 21000 | P4: =sumif(M:M,M4,O:O) -> 21000
A5: 1kg Segunfunmi Granola Oat, Fruit, Nut (12x) | B5: 45727 | C5: Jendol Supermarket, ISHERI (Rg.11) | D5: Sales | E5: DT:003208 | F5: 1.00 ctn | G5: 78000 | I5: =IFERROR(__xludf.DUMMYFUNCTION("""COMPUTED_VALUE"""),"1kg Segunfunmi Granola Oat, Fruit, Nut (12x)") -> 1kg Segunfunmi Granola Oat, Fruit, Nut (12x) | J5: =IFERROR(__xludf.DUMMYFUNCTION("""COMPUTED_VALUE"""),45727.0) -> 45727 | K5: =IFERROR(__xludf.DUMMYFUNCTION("""COMPUTED_VALUE"""),"Jendol Supermarket, ISHERI (Rg.11)") -> Jendol Supermarket, ISHERI (Rg.11) | L5: =IFERROR(__xludf.DUMMYFUNCTION("""COMPUTED_VALUE"""),"Sales") -> Sales | M5: =IFERROR(__xludf.DUMMYFUNCTION("""COMPUTED_VALUE"""),"DT:003208") -> DT:003208 | N5: =IFERROR(__xludf.DUMMYFUNCTION("""COMPUTED_VALUE"""),"1.00 ctn") -> 1.00 ctn | O5: =IFERROR(__xludf.DUMMYFUNCTION("""COMPUTED_VALUE"""),78000.0) -> 78000 | P5: =sumif(M:M,M5,O:O) -> 78000
A6: 2kg Segunfunmi Ofada Rice (12x) | B6: 45788 | C6: Renees Supermarket, LEKKI CENTRAL MOSQUE | D6: Sales | E6: DT:003254 | F6: 0.50 ctn | G6: 52800 | I6: =IFERROR(__xludf.DUMMYFUNCTION("""COMPUTED_VALUE"""),"2kg Segunfunmi Ofada Rice (12x)") -> 2kg Segunfunmi Ofada Rice (12x) | J6: =IFERROR(__xludf.DUMMYFUNCTION("""COMPUTED_VALUE"""),45788.0) -> 45788 | K6: =IFERROR(__xludf.DUMMYFUNCTION("""COMPUTED_VALUE"""),"Renees Supermarket, LEKKI CENTRAL MOSQUE") -> Renees Supermarket, LEKKI CENTRAL MOSQUE | L6: =IFERROR(__xludf.DUMMYFUNCTION("""COMPUTED_VALUE"""),"Sales") -> Sales | M6: =IFERROR(__xludf.DUMMYFUNCTION("""COMPUTED_VALUE"""),"DT:003254") -> DT:003254 | N6: =IFERROR(__xludf.DUMMYFUNCTION("""COMPUTED_VALUE"""),"0.50 ctn") -> 0.50 ctn | O6: =IFERROR(__xludf.DUMMYFUNCTION("""COMPUTED_VALUE"""),52800.0) -> 52800 | P6: =sumif(M:M,M6,O:O) -> 52800
A7: 500g Segunfunmi Granola Oat, Fruit, Nut (24x) | B7: 45668 | C7: Katta Supermarket | D7: Sales | E7: DT:003193 | F7: 0.25 ctn | G7: 19810.72 | I7: =IFERROR(__xludf.DUMMYFUNCTION("""COMPUTED_VALUE"""),"500g Segunfunmi Granola Oat, Fruit, Nut (24x)") -> 500g Segunfunmi Granola Oat, Fruit, Nut (24x) | J7: =IFERROR(__xludf.DUMMYFUNCTION("""COMPUTED_VALUE"""),45668.0) -> 45668 | K7: =IFERROR(__xludf.DUMMYFUNCTION("""COMPUTED_VALUE"""),"Katta Supermarket") -> Katta Supermarket | L7: =IFERROR(__xludf.DUMMYFUNCTION("""COMPUTED_VALUE"""),"Sales") -> Sales | M7: =IFERROR(__xludf.DUMMYFUNCTION("""COMPUTED_VALUE"""),"DT:003193") -> DT:003193 | N7: =IFERROR(__xludf.DUMMYFUNCTION("""COMPUTED_VALUE"""),"0.25 ctn") -> 0.25 ctn | O7: =IFERROR(__xludf.DUMMYFUNCTION("""COMPUTED_VALUE"""),19810.72) -> 19810.72 | P7: =sumif(M:M,M7,O:O) -> 19810.72
A8: 500g Segunfunmi Granola Oat, Fruit, Nut (24x) | B8: 45758 | C8: Jendol Supermarket, OJODU | D8: Sales | E8: DT:003248 | F8: 0.50 ctn | G8: 39621.43 | I8: =IFERROR(__xludf.DUMMYFUNCTION("""COMPUTED_VALUE"""),"500g Segunfunmi Granola Oat, Fruit, Nut (24x)") -> 500g Segunfunmi Granola Oat, Fruit, Nut (24x) | J8: =IFERROR(__xludf.DUMMYFUNCTION("""COMPUTED_VALUE"""),45758.0) -> 45758 | K8: =IFERROR(__xludf.DUMMYFUNCTION("""COMPUTED_VALUE"""),"Jendol Supermarket, OJODU") -> Jendol Supermarket, OJODU | L8: =IFERROR(__xludf.DUMMYFUNCTION("""COMPUTED_VALUE"""),"Sales") -> Sales | M8: =IFERROR(__xludf.DUMMYFUNCTION("""COMPUTED_VALUE"""),"DT:003248") -> DT:003248 | N8: =IFERROR(__xludf.DUMMYFUNCTION("""COMPUTED_VALUE"""),"0.50 ctn") -> 0.50 ctn | O8: =IFERROR(__xludf.DUMMYFUNCTION("""COMPUTED_VALUE"""),39621.43) -> 39621.43 | P8: =sumif(M:M,M8,O:O) -> 39621.43
P9: =sumif(M:M,M9,O:O) -> 0
P10: =sumif(M:M,M10,O:O) -> 0
P11: =sumif(M:M,M11,O:O) -> 0
P12: =sumif(M:M,M12,O:O) -> 0
P13: =sumif(M:M,M13,O:O) -> 0
P14: =sumif(M:M,M14,O:O) -> 0
P15: =sumif(M:M,M15,O:O) -> 0
P16: =sumif(M:M,M16,O:O) -> 0
P17: =sumif(M:M,M17,O:O) -> 0
P18: =sumif(M:M,M18,O:O) -> 0
P19: =sumif(M:M,M19,O:O) -> 0
P20: =sumif(M:M,M20,O:O) -> 0
... P86: =sumif(M:M,M86,O:O) -> 0

Sheet Paymnet Advice

Sheet Dala Sales & Deliveries
H1: Total Invoices Delivered | I1: =countifs(B:B,"<>",F:F,"<>")-1 -> 6 | K1: Sku Performance | L1: Units | M1: Value
H2: Unique Locations Supplied | I2: {=(COUNTA(UNIQUE(C:C))-1)} -> 6 | K2: ='Internal Summary'!B39 -> 150g Segunfunmi Granola Oat, Fruit, Nut (24x) | L2: =sumif(D:D,K2,E:E) -> 0 | M2: =sumif(D:D,K2,F:F) -> 0
H3: Total Value of orders | I3: =sum(F:F) -> 232232.15 | K3: ='Internal Summary'!B40 -> 150g Segunfunmi Hibiscus Tea pineapple, Cloves, Ginger (24x) | L3: =sumif(D:D,K3,E:E) -> 0 | M3: =sumif(D:D,K3,F:F) -> 42000
K4: ='Internal Summary'!B41 -> 1kg Segunfunmi Granola Oat, Fruit, Nut (12x) | L4: =sumif(D:D,K4,E:E) -> 0 | M4: =sumif(D:D,K4,F:F) -> 78000
K5: ='Internal Summary'!B42 -> 1kg Segunfunmi Lafun Flour Cassava (12x) | L5: =sumif(D:D,K5,E:E) -> 0 | M5: =sumif(D:D,K5,F:F) -> 0
K6: ='Internal Summary'!B43 -> 1kg Segunfunmi Ofada Rice (24x) | L6: =sumif(D:D,K6,E:E) -> 0 | M6: =sumif(D:D,K6,F:F) -> 0
K7: ='Internal Summary'!B44 -> 1kg Segunfunmi Yam Flour (12x) | L7: =sumif(D:D,K7,E:E) -> 0 | M7: =sumif(D:D,K7,F:F) -> 0
K8: ='Internal Summary'!B45 -> 200g Segunfunmi Chilli Pepper (12x) | L8: =sumif(D:D,K8,E:E) -> 0 | M8: =sumif(D:D,K8,F:F) -> 0
K9: ='Internal Summary'!B46 -> 250g Segunfunmi Granola Oat, Fruit, Nut (24x) | L9: =sumif(D:D,K9,E:E) -> 0 | M9: =sumif(D:D,K9,F:F) -> 0
K10: ='Internal Summary'!B47 -> 2kg Segunfunmi Ofada Rice (12x) | L10: =sumif(D:D,K10,E:E) -> 0 | M10: =sumif(D:D,K10,F:F) -> 52800
K11: ='Internal Summary'!B48 -> 500g Segunfunmi Granola Oat, Fruit, Nut (24x) | L11: =sumif(D:D,K11,E:E) -> 0 | M11: =sumif(D:D,K11,F:F) -> 0
K12: ='Internal Summary'!B49 -> 5kg Segunfunmi Ofada Rice (12x) | L12: =sumif(D:D,K12,E:E) -> 0 | M12: =sumif(D:D,K12,F:F) -> 0
K13: ='Internal Summary'!B50 | L13: =sumif(D:D,K13,E:E) -> 0 | M13: =sumif(D:D,K13,F:F) -> 0
K14: ='Internal Summary'!B51 | L14: =sumif(D:D,K14,E:E) -> 0 | M14: =sumif(D:D,K14,F:F) -> 0
K15: ='Internal Summary'!B52 | L15: =sumif(D:D,K15,E:E) -> 0 | M15: =sumif(D:D,K15,F:F) -> 0
... K51: ='Internal Summary'!B88 | L51: =sumif(D:D,K51,E:E) -> 0 | M51: =sumif(D:D,K51,F:F) -> 0

Sheet External Delivery Fulfillment
H1: Total Invoices Delivered | I1: =countifs(B:B,"<>",F:F,"<>")-1 -> 0 | K1: Sku Performance | L1: Units | M1: Value
H2: Unique Locations Supplied | I2: {=(COUNTA(UNIQUE(C:C))-1)} -> 0 | K2: ='Internal Summary'!B39 -> 150g Segunfunmi Granola Oat, Fruit, Nut (24x) | L2: =sumif(D:D,K2,E:E) -> 0 | M2: =sumif(D:D,K2,F:F) -> 0
H3: Total Value of orders | I3: =sum(F:F) -> 0 | K3: ='Internal Summary'!B40 -> 150g Segunfunmi Hibiscus Tea pineapple, Cloves, Ginger (24x) | L3: =sumif(D:D,K3,E:E) -> 0 | M3: =sumif(D:D,K3,F:F) -> 0
K4: ='Internal Summary'!B41 -> 1kg Segunfunmi Granola Oat, Fruit, Nut (12x) | L4: =sumif(D:D,K4,E:E) -> 0 | M4: =sumif(D:D,K4,F:F) -> 0
K5: ='Internal Summary'!B42 -> 1kg Segunfunmi Lafun Flour Cassava (12x) | L5: =sumif(D:D,K5,E:E) -> 0 | M5: =sumif(D:D,K5,F:F) -> 0
K6: ='Internal Summary'!B43 -> 1kg Segunfunmi Ofada Rice (24x) | L6: =sumif(D:D,K6,E:E) -> 0 | M6: =sumif(D:D,K6,F:F) -> 0
K7: ='Internal Summary'!B44 -> 1kg Segunfunmi Yam Flour (12x) | L7: =sumif(D:D,K7,E:E) -> 0 | M7: =sumif(D:D,K7,F:F) -> 0
K8: ='Internal Summary'!B45 -> 200g Segunfunmi Chilli Pepper (12x) | L8: =sumif(D:D,K8,E:E) -> 0 | M8: =sumif(D:D,K8,F:F) -> 0
K9: ='Internal Summary'!B46 -> 250g Segunfunmi Granola Oat, Fruit, Nut (24x) | L9: =sumif(D:D,K9,E:E) -> 0 | M9: =sumif(D:D,K9,F:F) -> 0
K10: ='Internal Summary'!B47 -> 2kg Segunfunmi Ofada Rice (12x) | L10: =sumif(D:D,K10,E:E) -> 0 | M10: =sumif(D:D,K10,F:F) -> 0
K11: ='Internal Summary'!B48 -> 500g Segunfunmi Granola Oat, Fruit, Nut (24x) | L11: =sumif(D:D,K11,E:E) -> 0 | M11: =sumif(D:D,K11,F:F) -> 0
K12: ='Internal Summary'!B49 -> 5kg Segunfunmi Ofada Rice (12x) | L12: =sumif(D:D,K12,E:E) -> 0 | M12: =sumif(D:D,K12,F:F) -> 0
K13: ='Internal Summary'!B50 | L13: =sumif(D:D,K13,E:E) -> 0 | M13: =sumif(D:D,K13,F:F) -> 0
K14: ='Internal Summary'!B51 | L14: =sumif(D:D,K14,E:E) -> 0 | M14: =sumif(D:D,K14,F:F) -> 0
K15: ='Internal Summary'!B52 | L15: =sumif(D:D,K15,E:E) -> 0 | M15: =sumif(D:D,K15,F:F) -> 0
... K24: ='Internal Summary'!B61 | L24: =sumif(D:D,K24,E:E) -> 0 | M24: =sumif(D:D,K24,F:F) -> 0

Sheet Forwarding From Client
H1: Total Invoices Delivered | I1: =countifs(B:B,"<>",F:F,"<>")-1 -> 0 | K1: Sku Performance | L1: Units | M1: Value
H2: Unique Locations Supplied | I2: {=(COUNTA(UNIQUE(C:C))-1)} -> 0 | K2: ='Internal Summary'!B39 -> 150g Segunfunmi Granola Oat, Fruit, Nut (24x) | L2: =sumif(D:D,K2,E:E) -> 0
H3: Total Value of orders | I3: =sum(F:F) -> 0 | K3: ='Internal Summary'!B40 -> 150g Segunfunmi Hibiscus Tea pineapple, Cloves, Ginger (24x) | L3: =sumif(D:D,K3,E:E) -> 0
K4: ='Internal Summary'!B41 -> 1kg Segunfunmi Granola Oat, Fruit, Nut (12x) | L4: =sumif(D:D,K4,E:E) -> 0
K5: ='Internal Summary'!B42 -> 1kg Segunfunmi Lafun Flour Cassava (12x) | L5: =sumif(D:D,K5,E:E) -> 0
K6: ='Internal Summary'!B43 -> 1kg Segunfunmi Ofada Rice (24x) | L6: =sumif(D:D,K6,E:E) -> 0
K7: ='Internal Summary'!B44 -> 1kg Segunfunmi Yam Flour (12x) | L7: =sumif(D:D,K7,E:E) -> 0
K8: ='Internal Summary'!B45 -> 200g Segunfunmi Chilli Pepper (12x) | L8: =sumif(D:D,K8,E:E) -> 0
K9: ='Internal Summary'!B46 -> 250g Segunfunmi Granola Oat, Fruit, Nut (24x) | L9: =sumif(D:D,K9,E:E) -> 0
K10: ='Internal Summary'!B47 -> 2kg Segunfunmi Ofada Rice (12x) | L10: =sumif(D:D,K10,E:E) -> 0
K11: ='Internal Summary'!B48 -> 500g Segunfunmi Granola Oat, Fruit, Nut (24x) | L11: =sumif(D:D,K11,E:E) -> 0
K12: ='Internal Summary'!B49 -> 5kg Segunfunmi Ofada Rice (12x) | L12: =sumif(D:D,K12,E:E) -> 0
K13: ='Internal Summary'!B50 | L13: =sumif(D:D,K13,E:E) -> 0
K14: ='Internal Summary'!B51 | L14: =sumif(D:D,K14,E:E) -> 0
K15: ='Internal Summary'!B52 | L15: =sumif(D:D,K15,E:E) -> 0

Sheet Dala Restocking
H1: Total Invoices Delivered | I1: =countifs(B:B,"<>",F:F,"<>")-1 -> 0 | K1: Sku Performance | L1: Units
H2: Unique Locations Supplied | I2: {=(COUNTA(UNIQUE(C:C,,0))-1)} -> 0 | K2: ='Internal Summary'!B39 -> 150g Segunfunmi Granola Oat, Fruit, Nut (24x) | L2: =sumif(D:D,K2,E:E) -> 0
H3: Total Value of orders | I3: =sum(F:F) -> 0 | K3: ='Internal Summary'!B40 -> 150g Segunfunmi Hibiscus Tea pineapple, Cloves, Ginger (24x) | L3: =sumif(D:D,K3,E:E) -> 0
K4: ='Internal Summary'!B41 -> 1kg Segunfunmi Granola Oat, Fruit, Nut (12x) | L4: =sumif(D:D,K4,E:E) -> 0
K5: ='Internal Summary'!B42 -> 1kg Segunfunmi Lafun Flour Cassava (12x) | L5: =sumif(D:D,K5,E:E) -> 0
K6: ='Internal Summary'!B43 -> 1kg Segunfunmi Ofada Rice (24x) | L6: =sumif(D:D,K6,E:E) -> 0
K7: ='Internal Summary'!B44 -> 1kg Segunfunmi Yam Flour (12x) | L7: =sumif(D:D,K7,E:E) -> 0
K8: ='Internal Summary'!B45 -> 200g Segunfunmi Chilli Pepper (12x) | L8: =sumif(D:D,K8,E:E) -> 0
K9: ='Internal Summary'!B46 -> 250g Segunfunmi Granola Oat, Fruit, Nut (24x) | L9: =sumif(D:D,K9,E:E) -> 0
K10: ='Internal Summary'!B47 -> 2kg Segunfunmi Ofada Rice (12x) | L10: =sumif(D:D,K10,E:E) -> 0
K11: ='Internal Summary'!B48 -> 500g Segunfunmi Granola Oat, Fruit, Nut (24x) | L11: =sumif(D:D,K11,E:E) -> 0
K12: ='Internal Summary'!B49 -> 5kg Segunfunmi Ofada Rice (12x) | L12: =sumif(D:D,K12,E:E) -> 0
K13: ='Internal Summary'!B50 | L13: =sumif(D:D,K13,E:E) -> 0
K14: ='Internal Summary'!B51 | L14: =sumif(D:D,K14,E:E) -> 0
K15: ='Internal Summary'!B52 | L15: =sumif(D:D,K15,E:E) -> 0
... K27: ='Internal Summary'!B64 | L27: =sumif(D:D,K27,E:E) -> 0

Sheet Client Restocking
H1: Total Invoices Delivered | I1: =countifs(B:B,"<>",F:F,"<>")-1 -> 0 | K1: Sku Performance | L1: Units
H2: Unique Locations Supplied | I2: {=(COUNTA(UNIQUE(C:C,,0))-1)} -> 0 | K2: ='Internal Summary'!B39 -> 150g Segunfunmi Granola Oat, Fruit, Nut (24x) | L2: =sumif(D:D,K2,E:E) -> 0
H3: Total Value of orders | I3: =sum(F:F) -> 0 | K3: ='Internal Summary'!B40 -> 150g Segunfunmi Hibiscus Tea pineapple, Cloves, Ginger (24x) | L3: =sumif(D:D,K3,E:E) -> 0
K4: ='Internal Summary'!B41 -> 1kg Segunfunmi Granola Oat, Fruit, Nut (12x) | L4: =sumif(D:D,K4,E:E) -> 0
K5: ='Internal Summary'!B42 -> 1kg Segunfunmi Lafun Flour Cassava (12x) | L5: =sumif(D:D,K5,E:E) -> 0
K6: ='Internal Summary'!B43 -> 1kg Segunfunmi Ofada Rice (24x) | L6: =sumif(D:D,K6,E:E) -> 0
K7: ='Internal Summary'!B44 -> 1kg Segunfunmi Yam Flour (12x) | L7: =sumif(D:D,K7,E:E) -> 0
K8: ='Internal Summary'!B45 -> 200g Segunfunmi Chilli Pepper (12x) | L8: =sumif(D:D,K8,E:E) -> 0
K9: ='Internal Summary'!B46 -> 250g Segunfunmi Granola Oat, Fruit, Nut (24x) | L9: =sumif(D:D,K9,E:E) -> 0
K10: ='Internal Summary'!B47 -> 2kg Segunfunmi Ofada Rice (12x) | L10: =sumif(D:D,K10,E:E) -> 0
K11: ='Internal Summary'!B48 -> 500g Segunfunmi Granola Oat, Fruit, Nut (24x) | L11: =sumif(D:D,K11,E:E) -> 0
K12: ='Internal Summary'!B49 -> 5kg Segunfunmi Ofada Rice (12x) | L12: =sumif(D:D,K12,E:E) -> 0
K13: ='Internal Summary'!B50 | L13: =sumif(D:D,K13,E:E) -> 0
K14: ='Internal Summary'!B51 | L14: =sumif(D:D,K14,E:E) -> 0
K15: ='Internal Summary'!B52 | L15: =sumif(D:D,K15,E:E) -> 0

Sheet Internal Summary
B1: Description | C1: Units | D1: measurements | E1: total
A2: SALES | B2: Total Invoices Delivered | E2: ='Dala Sales & Deliveries'!I1+'External Delivery Fulfillment'!I1 -> 6
B3: Unique Locations Delivered To | E3: ='Raw Data'!AX2 -> 4
B4: Value of Dala Deliveries | E4: ='Dala Sales & Deliveries'!I3 -> 232232.15
B5: VAT
B6: Total Value of Deliveries | E6: =sum(E4:E5) -> 232232.15
A7: Remittance & Deductions | B7: Total Remitted to Partner | E7: 0
B8: Collection Fees | C8: 0.15 | E8: =E7*(C8+100%)-E7 -> 0
A9: Invoice Value Due | B9: Outstanding Paymets For Sales | E9: =E6-E7-E8 -> 232232.15
A10: Debts | B10: Unpaid Subscription | C10: 0 | D10: 0 | E10: =C10*D10 -> 0
B11: Collection Fees | E11: =E4*C8 -> 34834.823
B12: Delivery Fees | D12: Table 1 | E12: =C21+C25 -> 0
B13: Reimbursements Due To DALA | E13: 0
B14: Retailer Deductions (EXPIRY) | E14: =C29 -> 0
B15: Total Deductions | E15: =sum(E10:E14) -> 34834.823
A16: Remmittance Due | B16: Total Balance to Remitt | E16: =E9-E15+C35 -> 197397.33
A19: Inventory and Operational Fees
B20: Dala Pickup for Warehouse | C20: =U68 -> 0
B21: Warehouse Delivery Fee | C21: =V68 -> 0
B22: Forwarding to Retail | C22: =S68 -> 0
B23: Forwarding Delivery Fee | C23: =T68 -> 0
B24: Dala Sales | C24: =67 -> 67
B25: Dala Delivery Fees | C25: =P68 -> 0
B26: Exteranl Deliveries | C26: =Q68 -> 0
B27: External Delivery Fees | C27: =R68 -> 0
B28: Product Defects and Expirey Issues | C28: =F68 -> 0
B29: Deductions From Retailer | C29: 0
B30: Samples used | C30: =I68 -> 0
B31: Produce Replacements | C31: 0
B32: Expected Closing Inventory | C32: =L68 -> 0
B33: Physical Stock count | C33: =K68 -> 0
B34: Inventory Shortages | C34: 0
B35: Inventory Shortage Costs | C35: 0
B38: SKUs | C38: Retail Value | D38: Inbound Delivery Fee | E38: Outbound Delivery Fee | F38: Defects/Expirey | G38: Deductions | H38: Opening Inventory | I38: Samples Used | J38: Product Replacements | K38: Physical Closing Stock Count | L38: Expected Closing Inventory | M38: Inventory Shortages | N38: Shortages Costs | O38: Dala Deliveries | P38: Retail Sales Fee | Q38: External Delivery | R38: External Delivery Fee | S38: Forwarding from Client | T38: Forwarding Delivery Fee | U38: Dala Restocking | V38: Dala Restocking Fee | W38: Client Restocking
B39: 150g Segunfunmi Granola Oat, Fruit, Nut (24x) | G39: =F39*C39 -> 0 | M39: =K39-L39 -> 0 | N39: =M39*C39 -> 0 | O39: ='Dala Sales & Deliveries'!L2 -> 0 | P39: =O39*E39 -> 0 | Q39: ='External Delivery Fulfillment'!L2 -> 0 | R39: =Q39*E39 -> 0 | S39: ='Forwarding From Client'!L2 -> 0 | T39: =S39*E39 -> 0 | U39: ='Dala Restocking'!L2 -> 0 | V39: =U39*D39 -> 0 | W39: ='Client Restocking'!L2 -> 0
B40: 150g Segunfunmi Hibiscus Tea pineapple, Cloves, Ginger (24x) | G40: =F40*C40 -> 0 | M40: =K40-L40 -> 0 | N40: =M40*C40 -> 0 | O40: ='Dala Sales & Deliveries'!L3 -> 0 | P40: =O40*E40 -> 0 | Q40: ='External Delivery Fulfillment'!L3 -> 0 | R40: =Q40*E40 -> 0 | S40: ='Forwarding From Client'!L3 -> 0 | T40: =S40*E40 -> 0 | U40: ='Dala Restocking'!L3 -> 0 | V40: =U40*D40 -> 0 | W40: ='Client Restocking'!L3 -> 0
B41: 1kg Segunfunmi Granola Oat, Fruit, Nut (12x) | G41: =F41*C41 -> 0 | M41: =K41-L41 -> 0 | N41: =M41*C41 -> 0 | O41: ='Dala Sales & Deliveries'!L4 -> 0 | P41: =O41*E41 -> 0 | Q41: ='External Delivery Fulfillment'!L4 -> 0 | R41: =Q41*E41 -> 0 | S41: ='Forwarding From Client'!L4 -> 0 | T41: =S41*E41 -> 0 | U41: ='Dala Restocking'!L4 -> 0 | V41: =U41*D41 -> 0 | W41: ='Client Restocking'!L4 -> 0
B42: 1kg Segunfunmi Lafun Flour Cassava (12x) | G42: =F42*C42 -> 0 | M42: =K42-L42 -> 0 | N42: =M42*C42 -> 0 | O42: ='Dala Sales & Deliveries'!L5 -> 0 | P42: =O42*E42 -> 0 | Q42: ='External Delivery Fulfillment'!L5 -> 0 | R42: =Q42*E42 -> 0 | S42: ='Forwarding From Client'!L5 -> 0 | T42: =S42*E42 -> 0 | U42: ='Dala Restocking'!L5 -> 0 | V42: =U42*D42 -> 0 | W42: ='Client Restocking'!L5 -> 0
B43: 1kg Segunfunmi Ofada Rice (24x) | G43: =F43*C43 -> 0 | M43: =K43-L43 -> 0 | N43: =M43*C43 -> 0 | O43: ='Dala Sales & Deliveries'!L6 -> 0 | P43: =O43*E43 -> 0 | Q43: ='External Delivery Fulfillment'!L6 -> 0 | R43: =Q43*E43 -> 0 | S43: ='Forwarding From Client'!L6 -> 0 | T43: =S43*E43 -> 0 | U43: ='Dala Restocking'!L6 -> 0 | V43: =U43*D43 -> 0 | W43: ='Client Restocking'!L6 -> 0
B44: 1kg Segunfunmi Yam Flour (12x) | G44: =F44*C44 -> 0 | M44: =K44-L44 -> 0 | N44: =M44*C44 -> 0 | O44: ='Dala Sales & Deliveries'!L7 -> 0 | P44: =O44*E44 -> 0 | Q44: ='External Delivery Fulfillment'!L7 -> 0 | R44: =Q44*E44 -> 0 | S44: ='Forwarding From Client'!L7 -> 0 | T44: =S44*E44 -> 0 | U44: ='Dala Restocking'!L7 -> 0 | V44: =U44*D44 -> 0 | W44: ='Client Restocking'!L7 -> 0
...
