Workbook

Sheet Raw Data
A1: Exported from Tally | I1: Dala Sales & Deliveries | R1: External Deliveries | Z1: Forwarding From Client | AH1: Client Restock | AP1: Dala Restock | AX1: Unique Locations
A2: item name | B2: Date | C2: Particulars | D2: Vch Type | E2: Vch No. | F2: Quantity | G2: Value | I2: item name | J2: Date | K2: Particulars | L2: Vch Type | M2: Vch No. | N2: Quantity | O2: Value | P2: Total Value | R2: item name | S2: Date | T2: Particulars | U2: Vch Type | V2: Vch No. | W2: Quantity | X2: Value | Z2: item name | AA2: Date | AB2: Particulars | AC2: Vch Type | AD2: Vch No. | AE2: Quantity | AF2: Value | AH2: item name | AI2: Date | AJ2: Particulars | AK2: Vch Type | AL2: Vch No. | AM2: Quantity | AN2: Value | AP2: item name | AQ2: Date | AR2: Particulars | AS2: Vch Type | AT2: Vch No. | AU2: Quantity | AV2: Value | AX2: {=counta(unique(C:C))-3} -> 0
A3: 100g Tosh Cocodia Coconut Flakes (12x) | B3: 45922 | C3: Tosh Cocodia | D3: Purchase Inv-Dala | E3: 2135 | F3: 5 | G3: 112500 | I3: 100g Tosh Cocodia Coconut Flakes (12x) | J3: 45924 | K3: Renees Supermarket, LEKKI CENTRAL MOSQUE | L3: Sales | M3: DT:002667 | N3: 1 | O3: 27000 | P3: =sumif(M:M,M3,O:O) -> 52000 | AP3: 100g Tosh Cocodia Coconut Flakes (12x) | AQ3: 45922 | AR3: Tosh Cocodia | AS3: Purchase Inv-Dala | AT3: 2135 | AU3: 5 | AV3: 112500
A4: 400g Tosh Cocodia Coconut Poundo (6x) | B4: 45922 | C4: Tosh Cocodia | D4: Purchase Inv-Dala | E4: 2135 | F4: 5.00 ctn | G4: 125000 | I4: 400g Tosh Cocodia Coconut Poundo (6x) | J4: 45924 | K4: Renees Supermarket, LEKKI CENTRAL MOSQUE | L4: Sales | M4: DT:002667 | N4: 1.00 ctn | O4: 25000 | P4: =sumif(M:M,M4,O:O) -> 52000 | AP4: 400g Tosh Cocodia Coconut Poundo (6x) | AQ4: 45922 | AR4: Tosh Cocodia | AS4: Purchase Inv-Dala | AT4: 2135 | AU4: 5.00 ctn | AV4: 125000
A5: 500ml Tosh Cocodia Coconut Oil (6x) | B5: 45922 | C5: Tosh Cocodia | D5: Purchase Inv-Dala | E5: 2135 | F5: 7.00 ctn | G5: 630000 | P5: =sumif(M:M,M5,O:O) -> 0 | AP5: 500ml Tosh Cocodia Coconut Oil (6x) | AQ5: 45922 | AR5: Tosh Cocodia | AS5: Purchase Inv-Dala | AT5: 2135 | AU5: 7.00 ctn | AV5: 630000
A6: 100g Tosh Cocodia Coconut Flakes (12x) | B6: 45924 | C6: Renees Supermarket, LEKKI CENTRAL MOSQUE | D6: Sales | E6: DT:002667 | F6: 1 | G6: 27000 | P6: =sumif(M:M,M6,O:O) -> 0
A7: 400g Tosh Cocodia Coconut Poundo (6x) | B7: 45924 | C7: Renees Supermarket, LEKKI CENTRAL MOSQUE | D7: Sales | E7: DT:002667 | F7: 1.00 ctn | G7: 25000 | P7: =sumif(M:M,M7,O:O) -> 0
P8: =sumif(M:M,M8,O:O) -> 0
P9: =sumif(M:M,M9,O:O) -> 0
P10: =sumif(M:M,M10,O:O) -> 0
P11: =sumif(M:M,M11,O:O) -> 0
P12: =sumif(M:M,M12,O:O) -> 0
P13: =sumif(M:M,M13,O:O) -> 0
P14: =sumif(M:M,M14,O:O) -> 0
P15: =sumif(M:M,M15,O:O) -> 0
P16: =sumif(M:M,M16,O:O) -> 0
P17: =sumif(M:M,M17,O:O) -> 0
P18: =sumif(M:M,M18,O:O) -> 0
P19: =sumif(M:M,M19,O:O) -> 0
... P88: =sumif(M:M,M88,O:O) -> 0

Sheet Paymnet Advice

Sheet Dala Sales & Deliveries
H1: Total Invoices Delivered | I1: =countifs(B:B,"<>",F:F,"<>")-1 -> 1 | K1: Sku Performance | L1: Units | M1: Value
H2: Unique Locations Supplied | I2: {=(COUNTA(UNIQUE(C:C))-1)} -> 1 | K2: ='Internal Summary'!B39 -> 100g Tosh Cocodia Coconut Flakes (12x) | L2: =sumif(D:D,K2,E:E) -> 1 | M2: =sumif(D:D,K2,F:F) -> 27000
H3: Total Value of orders | I3: =sum(F:F) -> 52000 | K3: ='Internal Summary'!B40 -> 400g Tosh Cocodia Coconut Poundo (6x) | L3: =sumif(D:D,K3,E:E) -> 0 | M3: =sumif(D:D,K3,F:F) -> 25000
K4: ='Internal Summary'!B41 -> 500ml Tosh Cocodia Coconut Oil (6x) | L4: =sumif(D:D,K4,E:E) -> 0 | M4: =sumif(D:D,K4,F:F) -> 0
K5: ='Internal Summary'!B42 | L5: =sumif(D:D,K5,E:E) -> 0 | M5: =sumif(D:D,K5,F:F) -> 0
K6: ='Internal Summary'!B43 | L6: =sumif(D:D,K6,E:E) -> 0 | M6: =sumif(D:D,K6,F:F) -> 0
K7: ='Internal Summary'!B44 | L7: =sumif(D:D,K7,E:E) -> 0 | M7: =sumif(D:D,K7,F:F) -> 0
K8: ='Internal Summary'!B45 | L8: =sumif(D:D,K8,E:E) -> 0 | M8: =sumif(D:D,K8,F:F) -> 0
K9: ='Internal Summary'!B46 | L9: =sumif(D:D,K9,E:E) -> 0 | M9: =sumif(D:D,K9,F:F) -> 0
K10: ='Internal Summary'!B47 | L10: =sumif(D:D,K10,E:E) -> 0 | M10: =sumif(D:D,K10,F:F) -> 0
K11: ='Internal Summary'!B48 | L11: =sumif(D:D,K11,E:E) -> 0 | M11: =sumif(D:D,K11,F:F) -> 0
A12: 45794 | K12: ='Internal Summary'!B49 | L12: =sumif(D:D,K12,E:E) -> 0 | M12: =sumif(D:D,K12,F:F) -> 0
K13: ='Internal Summary'!B50 | L13: =sumif(D:D,K13,E:E) -> 0 | M13: =sumif(D:D,K13,F:F) -> 0
K14: ='Internal Summary'!B51 | L14: =sumif(D:D,K14,E:E) -> 0 | M14: =sumif(D:D,K14,F:F) -> 0
K15: ='Internal Summary'!B52 | L15: =sumif(D:D,K15,E:E) -> 0 | M15: =sumif(D:D,K15,F:F) -> 0
K18: ='Internal Summary'!B55 | L18: =sumif(D:D,K18,E:E) -> 0 | M18: =sumif(D:D,K18,F:F) -> 0
K21: ='Internal Summary'!B58 | L21: =sumif(D:D,K21,E:E) -> 0 | M21: =sumif(D:D,K21,F:F) -> 0
K24: ='Internal Summary'!B61 | L24: =sumif(D:D,K24,E:E) -> 0 | M24: =sumif(D:D,K24,F:F) -> 0
K27: ='Internal Summary'!B64 | L27: =sumif(D:D,K27,E:E) -> 0 | M27: =sumif(D:D,K27,F:F) -> 0
K30: ='Internal Summary'!B67 | L30: =sumif(D:D,K30,E:E) -> 0 | M30: =sumif(D:D,K30,F:F) -> 0
K33: ='Internal Summary'!B70 | L33: =sumif(D:D,K33,E:E) -> 0 | M33: =sumif(D:D,K33,F:F) -> 0
K36: ='Internal Summary'!B73 | L36: =sumif(D:D,K36,E:E) -> 0 | M36: =sumif(D:D,K36,F:F) -> 0
K39: ='Internal Summary'!B76 | L39: =sumif(D:D,K39,E:E) -> 0 | M39: =sumif(D:D,K39,F:F) -> 0
K42: ='Internal Summary'!B79 | L42: =sumif(D:D,K42,E:E) -> 0 | M42: =sumif(D:D,K42,F:F) -> 0
... K51: ='Internal Summary'!B88 | L51: =sumif(D:D,K51,E:E) -> 0 | M51: =sumif(D:D,K51,F:F) -> 0

Sheet External Delivery Fulfillment
H1: Total Invoices Delivered | I1: =countifs(B:B,"<>",F:F,"<>")-1 -> 0 | K1: Sku Performance | L1: Units | M1: Value
H2: Unique Locations Supplied | I2: {=(COUNTA(UNIQUE(C:C))-1)} -> 0 | K2: ='Internal Summary'!B39 -> 100g Tosh Cocodia Coconut Flakes (12x) | L2: =sumif(D:D,K2,E:E) -> 0 | M2: =sumif(D:D,K2,F:F) -> 0
H3: Total Value of orders | I3: =sum(F:F) -> 0 | K3: ='Internal Summary'!B40 -> 400g Tosh Cocodia Coconut Poundo (6x) | L3: =sumif(D:D,K3,E:E) -> 0 | M3: =sumif(D:D,K3,F:F) -> 0
K4: ='Internal Summary'!B41 -> 500ml Tosh Cocodia Coconut Oil (6x) | L4: =sumif(D:D,K4,E:E) -> 0 | M4: =sumif(D:D,K4,F:F) -> 0
K5: ='Internal Summary'!B42 | L5: =sumif(D:D,K5,E:E) -> 0 | M5: =sumif(D:D,K5,F:F) -> 0
K6: ='Internal Summary'!B43 | L6: =sumif(D:D,K6,E:E) -> 0 | M6: =sumif(D:D,K6,F:F) -> 0
K7: ='Internal Summary'!B44 | L7: =sumif(D:D,K7,E:E) -> 0 | M7: =sumif(D:D,K7,F:F) -> 0
K8: ='Internal Summary'!B45 | L8: =sumif(D:D,K8,E:E) -> 0 | M8: =sumif(D:D,K8,F:F) -> 0
K9: ='Internal Summary'!B46 | L9: =sumif(D:D,K9,E:E) -> 0 | M9: =sumif(D:D,K9,F:F) -> 0
K10: ='Internal Summary'!B47 | L10: =sumif(D:D,K10,E:E) -> 0 | M10: =sumif(D:D,K10,F:F) -> 0
K11: ='Internal Summary'!B48 | L11: =sumif(D:D,K11,E:E) -> 0 | M11: =sumif(D:D,K11,F:F) -> 0
K12: ='Internal Summary'!B49 | L12: =sumif(D:D,K12,E:E) -> 0 | M12: =sumif(D:D,K12,F:F) -> 0
K13: ='Internal Summary'!B50 | L13: =sumif(D:D,K13,E:E) -> 0 | M13: =sumif(D:D,K13,F:F) -> 0
K14: ='Internal Summary'!B51 | L14: =sumif(D:D,K14,E:E) -> 0 | M14: =sumif(D:D,K14,F:F) -> 0
K15: ='Internal Summary'!B52 | L15: =sumif(D:D,K15,E:E) -> 0 | M15: =sumif(D:D,K15,F:F) -> 0
... K24: ='Internal Summary'!B61 | L24: =sumif(D:D,K24,E:E) -> 0 | M24: =sumif(D:D,K24,F:F) -> 0

Sheet Forwarding From Client
H1: Total Invoices Delivered | I1: =countifs(B:B,"<>",F:F,"<>")-1 -> 0 | K1: Sku Performance | L1: Units | M1: Value
H2: Unique Locations Supplied | I2: {=(COUNTA(UNIQUE(C:C))-1)} -> 0 | K2: ='Internal Summary'!B39 -> 100g Tosh Cocodia Coconut Flakes (12x) | L2: =sumif(D:D,K2,E:E) -> 0
H3: Total Value of orders | I3: =sum(F:F) -> 0 | K3: ='Internal Summary'!B40 -> 400g Tosh Cocodia Coconut Poundo (6x) | L3: =sumif(D:D,K3,E:E) -> 0
K4: ='Internal Summary'!B41 -> 500ml Tosh Cocodia Coconut Oil (6x) | L4: =sumif(D:D,K4,E:E) -> 0
K5: ='Internal Summary'!B42 | L5: =sumif(D:D,K5,E:E) -> 0
K6: ='Internal Summary'!B43 | L6: =sumif(D:D,K6,E:E) -> 0
K7: ='Internal Summary'!B44 | L7: =sumif(D:D,K7,E:E) -> 0
K8: ='Internal Summary'!B45 | L8: =sumif(D:D,K8,E:E) -> 0
K9: ='Internal Summary'!B46 | L9: =sumif(D:D,K9,E:E) -> 0
K10: ='Internal Summary'!B47 | L10: =sumif(D:D,K10,E:E) -> 0
K11: ='Internal Summary'!B48 | L11: =sumif(D:D,K11,E:E) -> 0
K12: ='Internal Summary'!B49 | L12: =sumif(D:D,K12,E:E) -> 0
K13: ='Internal Summary'!B50 | L13: =sumif(D:D,K13,E:E) -> 0
K14: ='Internal Summary'!B51 | L14: =sumif(D:D,K14,E:E) -> 0
K15: ='Internal Summary'!B52 | L15: =sumif(D:D,K15,E:E) -> 0

Sheet Dala Restocking
H1: Total Invoices Delivered | I1: =countifs(B:B,"<>",F:F,"<>")-1 -> 1 | K1: Sku Performance | L1: Units
H2: Unique Locations Supplied | I2: {=(COUNTA(UNIQUE(C:C,,0))-1)} -> 1 | K2: ='Internal Summary'!B39 -> 100g Tosh Cocodia Coconut Flakes (12x) | L2: =sumif(D:D,K2,E:E) -> 5
H3: Total Value of orders | I3: =sum(F:F) -> 867500 | K3: ='Internal Summary'!B40 -> 400g Tosh Cocodia Coconut Poundo (6x) | L3: =sumif(D:D,K3,E:E) -> 0
K4: ='Internal Summary'!B41 -> 500ml Tosh Cocodia Coconut Oil (6x) | L4: =sumif(D:D,K4,E:E) -> 0
K5: ='Internal Summary'!B42 | L5: =sumif(D:D,K5,E:E) -> 0
K6: ='Internal Summary'!B43 | L6: =sumif(D:D,K6,E:E) -> 0
K7: ='Internal Summary'!B44 | L7: =sumif(D:D,K7,E:E) -> 0
K8: ='Internal Summary'!B45 | L8: =sumif(D:D,K8,E:E) -> 0
K9: ='Internal Summary'!B46 | L9: =sumif(D:D,K9,E:E) -> 0
K10: ='Internal Summary'!B47 | L10: =sumif(D:D,K10,E:E) -> 0
K11: ='Internal Summary'!B48 | L11: =sumif(D:D,K11,E:E) -> 0
K12: ='Internal Summary'!B49 | L12: =sumif(D:D,K12,E:E) -> 0
K13: ='Internal Summary'!B50 | L13: =sumif(D:D,K13,E:E) -> 0
K14: ='Internal Summary'!B51 | L14: =sumif(D:D,K14,E:E) -> 0
K15: ='Internal Summary'!B52 | L15: =sumif(D:D,K15,E:E) -> 0
... K27: ='Internal Summary'!B64 | L27: =sumif(D:D,K27,E:E) -> 0

Sheet Client Restocking
H1: Total Invoices Delivered | I1: =countifs(B:B,"<>",F:F,"<>")-1 -> 0 | K1: Sku Performance | L1: Units
H2: Unique Locations Supplied | I2: {=(COUNTA(UNIQUE(C:C,,0))-1)} -> 0 | K2: ='Internal Summary'!B39 -> 100g Tosh Cocodia Coconut Flakes (12x) | L2: =sumif(D:D,K2,E:E) -> 0
H3: Total Value of orders | I3: =sum(F:F) -> 0 | K3: ='Internal Summary'!B40 -> 400g Tosh Cocodia Coconut Poundo (6x) | L3: =sumif(D:D,K3,E:E) -> 0
K4: ='Internal Summary'!B41 -> 500ml Tosh Cocodia Coconut Oil (6x) | L4: =sumif(D:D,K4,E:E) -> 0
K5: ='Internal Summary'!B42 | L5: =sumif(D:D,K5,E:E) -> 0
K6: ='Internal Summary'!B43 | L6: =sumif(D:D,K6,E:E) -> 0
K7: ='Internal Summary'!B44 | L7: =sumif(D:D,K7,E:E) -> 0
K8: ='Internal Summary'!B45 | L8: =sumif(D:D,K8,E:E) -> 0
K9: ='Internal Summary'!B46 | L9: =sumif(D:D,K9,E:E) -> 0
K10: ='Internal Summary'!B47 | L10: =sumif(D:D,K10,E:E) -> 0
K11: ='Internal Summary'!B48 | L11: =sumif(D:D,K11,E:E) -> 0
K12: ='Internal Summary'!B49 | L12: =sumif(D:D,K12,E:E) -> 0
K13: ='Internal Summary'!B50 | L13: =sumif(D:D,K13,E:E) -> 0
K14: ='Internal Summary'!B51 | L14: =sumif(D:D,K14,E:E) -> 0
K15: ='Internal Summary'!B52 | L15: =sumif(D:D,K15,E:E) -> 0

Sheet Internal Summary
B1: Description | C1: Units | D1: measurements | E1: total
A2: SALES | B2: Total Invoices Delivered | E2: ='Dala Sales & Deliveries'!I1+'External Delivery Fulfillment'!I1 -> 1
B3: Unique Locations Delivered To | E3: ='Raw Data'!AX2 -> 0
B4: Value of Dala Deliveries | E4: ='Dala Sales & Deliveries'!I3 -> 52000
B5: VAT
B6: Total Value of Deliveries | E6: =sum(E4:E5) -> 52000
A7: Remittance & Deductions | B7: Total Remitted to Partner | E7: 0
B8: Collection Fees | C8: 0.15 | E8: =E7*(C8+100%)-E7 -> 0
A9: Invoice Value Due | B9: Outstanding Paymets For Sales | E9: =E6-E7-E8 -> 52000
A10: Debts | B10: Unpaid Subscription | C10: 0 | D10: 0 | E10: =C10*D10 -> 0
B11: Collection Fees | E11: 0
B12: Delivery Fees | D12: Table 1 | E12: =C21+C25 -> 0
B13: Reimbursements Due To DALA | E13: 0
B14: Retailer Deductions (EXPIRY) | E14: =C29 -> 0
B15: Total Deductions | E15: =sum(E10:E14) -> 0
A16: Remmittance Due | B16: Total Balance to Remitt | E16: =E9-E15+C35 -> 52000
A19: Inventory and Operational Fees
B20: Dala Pickup for Warehouse | C20: =U68 -> 5
B21: Warehouse Delivery Fee | C21: =V68 -> 0
B22: Forwarding to Retail | C22: =S68 -> 0
B23: Forwarding Delivery Fee | C23: =T68 -> 0
B24: Dala Sales | C24: =67 -> 67
B25: Dala Delivery Fees | C25: =P68 -> 0
B26: Exteranl Deliveries | C26: =Q68 -> 0
B27: External Delivery Fees | C27: =R68 -> 0
B28: Product Defects and Expirey Issues | C28: =F68 -> 0
B29: Deductions From Retailer | C29: 0
B30: Samples used | C30: =I68 -> 0
B31: Produce Replacements | C31: 0
B32: Expected Closing Inventory | C32: =L68 -> 4
B33: Physical Stock count | C33: =K68 -> 0
B34: Inventory Shortages | C34: 0
B35: Inventory Shortage Costs | C35: 0
B38: SKUs | C38: Retail Value | D38: Inbound Delivery Fee | E38: Outbound Delivery Fee | F38: Defects/Expirey | G38: Deductions | H38: Opening Inventory | I38: Samples Used | J38: Product Replacements | K38: Physical Closing Stock Count | L38: Expected Closing Inventory | M38: Inventory Shortages | N38: Shortages Costs | O38: Dala Deliveries | P38: Retail Sales Fee | Q38: External Delivery | R38: External Delivery Fee | S38: Forwarding from Client | T38: Forwarding Delivery Fee | U38: Dala Restocking | V38: Dala Restocking Fee | W38: Client Restocking
B39: 100g Tosh Cocodia Coconut Flakes (12x) | C39: 27000 | G39: =F39*C39 -> 0 | L39: =H39+U39+W39-O39-Q39-I39-J39 -> 4 | M39: =K39-L39 -> -4 | N39: =M39*C39 -> -108000 | O39: ='Dala Sales & Deliveries'!L2 -> 1 | P39: =O39*E39 -> 0 | Q39: ='External Delivery Fulfillment'!L2 -> 0 | R39: =Q39*E39 -> 0 | S39: ='Forwarding From Client'!L2 -> 0 | T39: =S39*E39 -> 0 | U39: ='Dala Restocking'!L2 -> 5 | V39: =U39*D39 -> 0 | W39: ='Client Restocking'!L2 -> 0
B40: 400g Tosh Cocodia Coconut Poundo (6x) | G40: =F40*C40 -> 0 | L40: =H40+U40+W40-O40-Q40-I40-J40 -> 0 | M40: =K40-L40 -> 0 | N40: =M40*C40 -> 0 | O40: ='Dala Sales & Deliveries'!L3 -> 0 | P40: =O40*E40 -> 0 | Q40: ='External Delivery Fulfillment'!L3 -> 0 | R40: =Q40*E40 -> 0 | S40: ='Forwarding From Client'!L3 -> 0 | T40: =S40*E40 -> 0 | U40: ='Dala Restocking'!L3 -> 0 | V40: =U40*D40 -> 0 | W40: ='Client Restocking'!L3 -> 0
B41: 500ml Tosh Cocodia Coconut Oil (6x) | G41: =F41*C41 -> 0 | L41: =H41+U41+W41-O41-Q41-I41-J41 -> 0 | M41: =K41-L41 -> 0 | N41: =M41*C41 -> 0 | O41: ='Dala Sales & Deliveries'!L4 -> 0 | P41: =O41*E41 -> 0 | Q41: ='External Delivery Fulfillment'!L4 -> 0 | R41: =Q41*E41 -> 0 | S41: ='Forwarding From Client'!L4 -> 0 | T41: =S41*E41 -> 0 | U41: ='Dala Restocking'!L4 -> 0 | V41: =U41*D41 -> 0 | W41: ='Client Restocking'!L4 -> 0
G42: =F42*C42 -> 0 | L42: =H42+U42+W42-O42-Q42-I42-J42 -> 0 | M42: =K42-L42 -> 0 | N42: =M42*C42 -> 0 | O42: ='Dala Sales & Deliveries'!L5 -> 0 | P42: =O42*E42 -> 0 | Q42: ='External Delivery Fulfillment'!L5 -> 0 | R42: =Q42*E42 -> 0 | S42: ='Forwarding From Client'!L5 -> 0 | T42: =S42*E42 -> 0 | U42: ='Dala Restocking'!L5 -> 0 | V42: =U42*D42 -> 0 | W42: ='Client Restocking'!L5 -> 0
G43: =F43*C43 -> 0 | L43: =H43+U43+W43-O43-Q43-I43-J43 -> 0 | M43: =K43-L43 -> 0 | N43: =M43*C43 -> 0 | O43: ='Dala Sales & Deliveries'!L6 -> 0 | P43: =O43*E43 -> 0 | Q43: ='External Delivery Fulfillment'!L6 -> 0 | R43: =Q43*E43 -> 0 | S43: ='Forwarding From Client'!L6 -> 0 | T43: =S43*E43 -> 0 | U43: ='Dala Restocking'!L6 -> 0 | V43: =U43*D43 -> 0 | W43: ='Client Restocking'!L6 -> 0
G44: =F44*C44 -> 0 | L44: =H44+U44+W44-O44-Q44-I44-J44 -> 0 | M44: =K44-L44 -> 0 | N44: =M44*C44 -> 0 | O44: ='Dala Sales & Deliveries'!L7 -> 0 | P44: =O44*E44 -> 0 | Q44: ='External Delivery Fulfillment'!L7 -> 0 | R44: =Q44*E44 -> 0 | S44: ='Forwarding From Client'!L7 -> 0 | T44: =S44*E44 -> 0 | U44: ='Dala Restocking'!L7 -> 0 | V44: =U44*D44 -> 0 | W44: ='Client Restocking'!L7 -> 0
...

Sheet External Summary
B1: Description | C1: Units | D1: measurements | E1: total
A2: SALES | B2: Total Invoices Delivered | E2: ='Dala Sales & Deliveries'!I1+'External Delivery Fulfillment'!I1+'Forwarding From Client'!I1 -> 1
B3: Unique Locations Delivered To | E3: ='Raw Data'!AX2 -> 0
B4: Value of Dala Deliveries | E4: ='Dala Sales & Deliveries'!I3 -> 52000
B5: VAT | E5: =E4*1.075-E4 -> 3900
B6: Total Value of Deliveries | E6: =sum(E4:E5) -> 55900
A7: Remittance & Deductions | B7: Total Remitted to Partner
B8: Delivery Fees | C8: 0.04 | E8: =E7*(C8+100%)-E7 -> 0
B9: Collection Fees | C9: 0.07 | E9: =E7*(C9+100%)-E7 -> 0
A10: Debts | B10: Unpaid Subscription | D10: 350000 | E10: =C10*D10 -> 0
B11: Restocking Fees | E11: =V67 -> 0
B12: External Delivery Fees | E12: =C24 -> 0
B13: Reimbursements Due To DALA | E13: 0
B14: Retailer Deductions | E14: =C28 -> 0
B15: Total Owed to Dala | E15: =sum(E10:E14) -> 0
A18: Inventory and Operational Fees
B19: Dala Pickup for Warehouse | C19: =U67 -> 5
B20: Warehouse Delivery Fee | C20: =V67 -> 0
B21: Forwarding to Retail | C21: =S67 -> 0
B22: Forwarding Delivery Fee | C22: =T67 -> 0
B23: Dala Sales | C23: =O67 -> 1
B24: Dala Delivery Fees | C24: =P67 -> 0
B25: Exteranl Deliveries | C25: =Q67 -> 0
B26: External Delivery Fees | C26: =R67 -> 0
B27: Product Defects and Expirey Issues | C27: =F67 -> 0
B28: Deductions From Retailer | C28: =G67 -> 0
B29: Samples used | C29: =I67 -> 0
B30: Returns/Replacements | C30: =J67 -> 0
B31: Expected Closing Inventory | C31: =L67 -> 4
B32: Physical Stock count | C32: =K67 -> 33.5
B33: Inventory Shortages | C33: 0
B34: Inventory Shortage Costs | C34: 0
B37: SKUs | C37: Retail Value | D37: Inbound Delivery Fee | E37: Outbound Delivery Fee | F37: Defects/Expirey | G37: Deductions | H37: Opening Inventory | I37: Samples Used | J37: Product Replacements | K37: Physical Closing Stock Count | L37: Expected Closing Inventory | M37: Inventory Shortages | N37: Shortages Costs | O37: Dala Sales | P37: Retail Sales Fee | Q37: External Delivery | R37: External Delivery Fee | S37: Forwarding from Client | T37: Forwarding Delivery Fee | U37: Dala Restocking | V37: Dala Restocking Fee | W37: Client Restocking
B38: ='Internal Summary'!B39 -> 100g Tosh Cocodia Coconut Flakes (12x) | C38: ='Internal Summary'!C39 -> 27000 | D38: ='Internal Summary'!D39 | E38: ='Internal Summary'!E39 | G38: =F38*C38 -> 0 | K38: 0 | L38: =H38+U38+W38-O38-Q38-I38-J38 -> 4 | M38: =K38-L38 -> -4 | N38: =M38*C38 -> -108000 | O38: ='Dala Sales & Deliveries'!L2 -> 1 | P38: =O38*E38 -> 0 | Q38: ='External Delivery Fulfillment'!L2 -> 0 | R38: =Q38*E38 -> 0 | S38: ='Forwarding From Client'!L2 -> 0 | T38: =S38*E38 -> 0 | U38: ='Dala Restocking'!L2 -> 5 | V38: =U38*D38 -> 0 | W38: ='Client Restocking'!L2 -> 0
B39: ='Internal Summary'!B40 -> 400g Tosh Cocodia Coconut Poundo (6x) | C39: ='Internal Summary'!C40 | D39: ='Internal Summary'!D40 | E39: ='Internal Summary'!E40 | G39: =F39*C39 -> 0 | K39: 0 | L39: =H39+U39+W39-O39-Q39-I39-J39 -> 0 | M39: =K39-L39 -> 0 | O39: ='Dala Sales & Deliveries'!L3 -> 0 | P39: =O39*E39 -> 0 | Q39: ='External Delivery Fulfillment'!L3 -> 0 | R39: =Q39*E39 -> 0 | S39: ='Forwarding From Client'!L3 -> 0 | T39: =S39*E39 -> 0 | U39: ='Dala Restocking'!L3 -> 0 | V39: =U39*D39 -> 0 | W39: ='Client Restocking'!L3 -> 0
B40: ='Internal Summary'!B41 -> 500ml Tosh Cocodia Coconut Oil (6x) | C40: ='Internal Summary'!C41 | D40: ='Internal Summary'!D41 | E40: ='Internal Summary'!E41 | G40: =F40*C40 -> 0 | K40: 0 | L40: =H40+U40+W40-O40-Q40-I40-J40 -> 0 | M40: =K40-L40 -> 0 | O40: ='Dala Sales & Deliveries'!L4 -> 0 | P40: =O40*E40 -> 0 | Q40: ='External Delivery Fulfillment'!L4 -> 0 | R40: =Q40*E40 -> 0 | S40: ='Forwarding From Client'!L4 -> 0 | T40: =S40*E40 -> 0 | U40: ='Dala Restocking'!L4 -> 0 | V40: =U40*D40 -> 0 | W40: ='Client Restocking'!L4 -> 0
B41: ='Internal Summary'!B42 | C41: ='Internal Summary'!C42 | D41: ='Internal Summary'!D42 | E41: ='Internal Summary'!E42 | G41: =F41*C41 -> 0 | K41: 0 | L41: =H41+U41+W41-O41-Q41-I41-J41 -> 0 | M41: =K41-L41 -> 0 | O41: ='Dala Sales & Deliveries'!L5 -> 0 | P41: =O41*E41 -> 0 | Q41: ='External Delivery Fulfillment'!L5 -> 0 | R41: =Q41*E41 -> 0 | S41: ='Forwarding From Client'!L5 -> 0 | T41: =S41*E41 -> 0 | U41: ='Dala Restocking'!L5 -> 0 | V41: =U41*D41 -> 0 | W41: ='Client Restocking'!L5 -> 0
B42: ='Internal Summary'!B43 | C42: ='Internal Summary'!C43 | D42: ='Internal Summary'!D43 | E42: ='Internal Summary'!E43 | G42: =F42*C42 -> 0 | K42: 4.5 | L42: =H42+U42+W42-O42-Q42-I42-J42 -> 0 | M42: =K42-L42 -> 4.5 | O42: ='Dala Sales & Deliveries'!L6 -> 0 | P42: =O42*E42 -> 0 | Q42: ='External Delivery Fulfillment'!L6 -> 0 | R42: =Q42*E42 -> 0 | S42: ='Forwarding From Client'!L6 -> 0 | T42: =S42*E42 -> 0 | U42: ='Dala Restocking'!L6 -> 0 | V42: =U42*D42 -> 0 | W42: ='Client Restocking'!L6 -> 0
B43: ='Internal Summary'!B44 | C43: ='Internal Summary'!C44 | D43: ='Internal Summary'!D44 | E43: ='Internal Summary'!E44 | G43: =F43*C43 -> 0 | K43: 2 | L43: =H43+U43+W43-O43-Q43-I43-J43 -> 0 | M43: =K43-L43 -> 2 | O43: ='Dala Sales & Deliveries'!L7 -> 0 | P43: =O43*E43 -> 0 | Q43: ='External Delivery Fulfillment'!L7 -> 0 | R43: =Q43*E43 -> 0 | S43: ='Forwarding From Client'!L7 -> 0 | T43: =S43*E43 -> 0 | U43: ='Dala Restocking'!L7 -> 0 | V43: =U43*D43 -> 0 | W43: ='Client Restocking'!L7 -> 0
B44: ='Internal Summary'!B45 | C44: ='Internal Summary'!C45 | D44: ='Internal Summary'!D45 | E44: ='Internal Summary'!E45 | G44: =F44*C44 -> 0 | K44: 7 | L44: =H44+U44+W44-O44-Q44-I44-J44 -> 0 | M44: =K44-L44 -> 7 | O44: ='Dala Sales & Deliveries'!L8 -> 0 | P44: =O44*E44 -> 0 | Q44: ='External Delivery Fulfillment'!L8 -> 0 | R44: =Q44*E44 -> 0 | S44: ='Forwarding From Client'!L8 -> 0 | T44: =S44*E44 -> 0 | U44: ='Dala Restocking'!L8 -> 0 | V44: =U44*D44 -> 0 | W44: ='Client Restocking'!L8 -> 0
...
