Workbook

Sheet Raw Data
A1: Exported from Tally | I1: Dala Sales & Deliveries | Q1: External Deliveries | Y1: Forwarding From Client | AG1: Client Restock | AO1: Dala Restock | AW1: Unique Locations
A2: item name | B2: Date | C2: Particulars | D2: Vch Type | E2: Vch No. | F2: Quantity | G2: Value | I2: item name | J2: Date | K2: Particulars | L2: Vch Type | M2: Vch No. | N2: Quantity | O2: Value | P2: Total Value | Q2: item name | R2: Date | S2: Particulars | T2: Vch Type | U2: Vch No. | V2: Quantity | W2: Value | Y2: item name | Z2: Date | AA2: Particulars | AB2: Vch Type | AC2: Vch No. | AD2: Quantity | AE2: Value | AG2: item name | AH2: Date | AI2: Particulars | AJ2: Vch Type | AK2: Vch No. | AL2: Quantity | AM2: Value | AO2: item name | AP2: Date | AQ2: Particulars | AR2: Vch Type | AS2: Vch No. | AT2: Quantity | AU2: Value | AW2: {=counta(unique(C:C))-2} -> 3
A3: 350ml Orisirisi Wallnut Drink (12x) | B3: 46002 | C3: Renees Supermarket, LEKKI CENTRAL MOSQUE | D3: Sales | E3: DT:003433 | F3: 1 | G3: 21600 | I3: =IFERROR(__xludf.DUMMYFUNCTION("IFERROR( FILTER($A$3:$G1844, LEN($A$3:$A1844), LOWER(TRIM($D$3:$D1844))=""sales""), )"),"350ml Orisirisi Wallnut Drink (12x)") -> 350ml Orisirisi Wallnut Drink (12x) | J3: =IFERROR(__xludf.DUMMYFUNCTION("""COMPUTED_VALUE"""),46002.0) -> 46002 | K3: =IFERROR(__xludf.DUMMYFUNCTION("""COMPUTED_VALUE"""),"Renees Supermarket, LEKKI CENTRAL MOSQUE") -> Renees Supermarket, LEKKI CENTRAL MOSQUE | L3: =IFERROR(__xludf.DUMMYFUNCTION("""COMPUTED_VALUE"""),"Sales") -> Sales | M3: =IFERROR(__xludf.DUMMYFUNCTION("""COMPUTED_VALUE"""),"DT:003433") -> DT:003433 | N3: =IFERROR(__xludf.DUMMYFUNCTION("""COMPUTED_VALUE"""),1.0) -> 1 | O3: =IFERROR(__xludf.DUMMYFUNCTION("""COMPUTED_VALUE"""),21600.0) -> 21600 | P3: =SUMIF(M:M,M3,O:O) -> 21600 | Q3: =IFERROR(__xludf.DUMMYFUNCTION("IFERROR( FILTER($A$3:$G1844, LEN($A$3:$A1844), REGEXMATCH(LOWER(TRIM($D$3:$D1844)), ""\bjournal\b"")), )"),"") | AG3: =IFERROR(__xludf.DUMMYFUNCTION("IFERROR( FILTER($A$3:$G1844, LEN($A$3:$A1844), LOWER(TRIM($D$3:$D1844))=""Inventory Supplied by Brands ""), )"),"") | AO3: =IFERROR(__xludf.DUMMYFUNCTION("IFERROR( FILTER($A$3:$G1844, LEN($A$3:$A1844), LOWER(TRIM($D$3:$D1844))=""Inventory Pickup by Dala ""), )"),"")
A4: 350ml Orisirisi Wallnut with Ginger Drink (12x) | B4: 45941 | C4: Jesops Supermarket | D4: Sales | E4: DT:003365 | F4: 0.5 | G4: 10800 | I4: =IFERROR(__xludf.DUMMYFUNCTION("""COMPUTED_VALUE"""),"350ml Orisirisi Wallnut with Ginger Drink (12x)") -> 350ml Orisirisi Wallnut with Ginger Drink (12x) | J4: =IFERROR(__xludf.DUMMYFUNCTION("""COMPUTED_VALUE"""),45941.0) -> 45941 | K4: =IFERROR(__xludf.DUMMYFUNCTION("""COMPUTED_VALUE"""),"Jesops Supermarket") -> Jesops Supermarket | L4: =IFERROR(__xludf.DUMMYFUNCTION("""COMPUTED_VALUE"""),"Sales") -> Sales | M4: =IFERROR(__xludf.DUMMYFUNCTION("""COMPUTED_VALUE"""),"DT:003365") -> DT:003365 | N4: =IFERROR(__xludf.DUMMYFUNCTION("""COMPUTED_VALUE"""),0.5) -> 0.5 | O4: =IFERROR(__xludf.DUMMYFUNCTION("""COMPUTED_VALUE"""),10800.0) -> 10800 | P4: =SUMIF(M:M,M4,O:O) -> 24600
A5: 500ml Orisirisi Tiger Nut Drink (12x) | B5: 45849 | C5: Jendol Supermarket, ODOGUNYA | D5: Sales | E5: DT:003349 | F5: 0.5 | G5: 13800 | I5: =IFERROR(__xludf.DUMMYFUNCTION("""COMPUTED_VALUE"""),"500ml Orisirisi Tiger Nut Drink (12x)") -> 500ml Orisirisi Tiger Nut Drink (12x) | J5: =IFERROR(__xludf.DUMMYFUNCTION("""COMPUTED_VALUE"""),45849.0) -> 45849 | K5: =IFERROR(__xludf.DUMMYFUNCTION("""COMPUTED_VALUE"""),"Jendol Supermarket, ODOGUNYA") -> Jendol Supermarket, ODOGUNYA | L5: =IFERROR(__xludf.DUMMYFUNCTION("""COMPUTED_VALUE"""),"Sales") -> Sales | M5: =IFERROR(__xludf.DUMMYFUNCTION("""COMPUTED_VALUE"""),"DT:003349") -> DT:003349 | N5: =IFERROR(__xludf.DUMMYFUNCTION("""COMPUTED_VALUE"""),0.5) -> 0.5 | O5: =IFERROR(__xludf.DUMMYFUNCTION("""COMPUTED_VALUE"""),13800.0) -> 13800 | P5: =SUMIF(M:M,M5,O:O) -> 25800
A6: 500ml Orisirisi Tiger Nut Drink (12x) | B6: 45941 | C6: Jesops Supermarket | D6: Sales | E6: DT:003365 | F6: 0.5 | G6: 13800 | I6: =IFERROR(__xludf.DUMMYFUNCTION("""COMPUTED_VALUE"""),"500ml Orisirisi Tiger Nut Drink (12x)") -> 500ml Orisirisi Tiger Nut Drink (12x) | J6: =IFERROR(__xludf.DUMMYFUNCTION("""COMPUTED_VALUE"""),45941.0) -> 45941 | K6: =IFERROR(__xludf.DUMMYFUNCTION("""COMPUTED_VALUE"""),"Jesops Supermarket") -> Jesops Supermarket | L6: =IFERROR(__xludf.DUMMYFUNCTION("""COMPUTED_VALUE"""),"Sales") -> Sales | M6: =IFERROR(__xludf.DUMMYFUNCTION("""COMPUTED_VALUE"""),"DT:003365") -> DT:003365 | N6: =IFERROR(__xludf.DUMMYFUNCTION("""COMPUTED_VALUE"""),0.5) -> 0.5 | O6: =IFERROR(__xludf.DUMMYFUNCTION("""COMPUTED_VALUE"""),13800.0) -> 13800 | P6: =SUMIF(M:M,M6,O:O) -> 24600
A7: 500ml Orisirisi Zobo with Date Drink (12x) | B7: 45849 | C7: Jendol Supermarket, ODOGUNYA | D7: Sales | E7: DT:003349 | F7: 0.5 | G7: 12000 | I7: =IFERROR(__xludf.DUMMYFUNCTION("""COMPUTED_VALUE"""),"500ml Orisirisi Zobo with Date Drink (12x)") -> 500ml Orisirisi Zobo with Date Drink (12x) | J7: =IFERROR(__xludf.DUMMYFUNCTION("""COMPUTED_VALUE"""),45849.0) -> 45849 | K7: =IFERROR(__xludf.DUMMYFUNCTION("""COMPUTED_VALUE"""),"Jendol Supermarket, ODOGUNYA") -> Jendol Supermarket, ODOGUNYA | L7: =IFERROR(__xludf.DUMMYFUNCTION("""COMPUTED_VALUE"""),"Sales") -> Sales | M7: =IFERROR(__xludf.DUMMYFUNCTION("""COMPUTED_VALUE"""),"DT:003349") -> DT:003349 | N7: =IFERROR(__xludf.DUMMYFUNCTION("""COMPUTED_VALUE"""),0.5) -> 0.5 | O7: =IFERROR(__xludf.DUMMYFUNCTION("""COMPUTED_VALUE"""),12000.0) -> 12000 | P7: =SUMIF(M:M,M7,O:O) -> 25800
A8: 500ml Orisirisi Zobo with Date Drink (12x) | B8: 46002 | C8: Jendol Supermarket, OJODU | D8: Sales | E8: DT:003406 | F8: 0.5 | G8: 10800 | I8: =IFERROR(__xludf.DUMMYFUNCTION("""COMPUTED_VALUE"""),"500ml Orisirisi Zobo with Date Drink (12x)") -> 500ml Orisirisi Zobo with Date Drink (12x) | J8: =IFERROR(__xludf.DUMMYFUNCTION("""COMPUTED_VALUE"""),46002.0) -> 46002 | K8: =IFERROR(__xludf.DUMMYFUNCTION("""COMPUTED_VALUE"""),"Jendol Supermarket, OJODU") -> Jendol Supermarket, OJODU | L8: =IFERROR(__xludf.DUMMYFUNCTION("""COMPUTED_VALUE"""),"Sales") -> Sales | M8: =IFERROR(__xludf.DUMMYFUNCTION("""COMPUTED_VALUE"""),"DT:003406") -> DT:003406 | N8: =IFERROR(__xludf.DUMMYFUNCTION("""COMPUTED_VALUE"""),0.5) -> 0.5 | O8: =IFERROR(__xludf.DUMMYFUNCTION("""COMPUTED_VALUE"""),10800.0) -> 10800 | P8: =SUMIF(M:M,M8,O:O) -> 10800
P9: =SUMIF(M:M,M9,O:O) -> 0
P10: =SUMIF(M:M,M10,O:O) -> 0
P11: =SUMIF(M:M,M11,O:O) -> 0
P12: =SUMIF(M:M,M12,O:O) -> 0
P13: =SUMIF(M:M,M13,O:O) -> 0
P14: =SUMIF(M:M,M14,O:O) -> 0
P15: =SUMIF(M:M,M15,O:O) -> 0
P16: =SUMIF(M:M,M16,O:O) -> 0
P17: =SUMIF(M:M,M17,O:O) -> 0
P18: =SUMIF(M:M,M18,O:O) -> 0
P19: =SUMIF(M:M,M19,O:O) -> 0
P20: =SUMIF(M:M,M20,O:O) -> 0
... P22: =SUMIF(M:M,M22,O:O) -> 0
T975: {=counta(UNIQUE(S2:S960))-1} -> 0 | AI975: {=UNIQUE(AI2:AI590)} -> Particulars | AQ975: {=UNIQUE(AQ2:AQ590)} -> Particulars

Sheet Payment Advice

Sheet Dala Sales & Deliveries
H1: Total Invoices Delivered | I1: =countifs(B:B,"<>",F:F,"<>")-1 -> 4 | K1: Sku Performance | L1: Units | M1: Value
H2: Unique Locations Supplied | I2: {=(COUNTA(UNIQUE(C:C))-1)} -> 4 | K2: ='Internal Summary'!B40 -> 350ml Orisirisi Wallnut with Ginger Drink (12x) | L2: =sumif(D:D,K2,E:E) -> 0.5 | M2: =sumif(D:D,K2,F:F) -> 10800
H3: Total Value of orders | I3: =sum(F:F) -> 82800 | K3: ='Internal Summary'!B41 -> 500ml Orisirisi Tiger Nut Drink (12x) | L3: =sumif(D:D,K3,E:E) -> 1 | M3: =sumif(D:D,K3,F:F) -> 27600
K4: ='Internal Summary'!B42 -> 500ml Orisirisi Zobo with Date Drink (12x) | L4: =sumif(D:D,K4,E:E) -> 1 | M4: =sumif(D:D,K4,F:F) -> 22800
K5: ='Internal Summary'!B43 -> 350ml Orisirisi Wallnut Drink (12x) | L5: =sumif(D:D,K5,E:E) -> 1 | M5: =sumif(D:D,K5,F:F) -> 21600
K6: ='Internal Summary'!B44 -> 500ml Orisirisi Zobo Drink (12x) | L6: =sumif(D:D,K6,E:E) -> 0 | M6: =sumif(D:D,K6,F:F) -> 0
K7: ='Internal Summary'!B45 | L7: =sumif(D:D,K7,E:E) -> 0 | M7: =sumif(D:D,K7,F:F) -> 0
K8: ='Internal Summary'!B46 | L8: =sumif(D:D,K8,E:E) -> 0 | M8: =sumif(D:D,K8,F:F) -> 0
K9: ='Internal Summary'!B47 | L9: =sumif(D:D,K9,E:E) -> 0 | M9: =sumif(D:D,K9,F:F) -> 0
K10: ='Internal Summary'!B48 | L10: =sumif(D:D,K10,E:E) -> 0 | M10: =sumif(D:D,K10,F:F) -> 0
K11: ='Internal Summary'!B49 | L11: =sumif(D:D,K11,E:E) -> 0 | M11: =sumif(D:D,K11,F:F) -> 0
A12: 45758 | K12: ='Internal Summary'!B50 | L12: =sumif(D:D,K12,E:E) -> 0 | M12: =sumif(D:D,K12,F:F) -> 0
K13: ='Internal Summary'!B51 | L13: =sumif(D:D,K13,E:E) -> 0 | M13: =sumif(D:D,K13,F:F) -> 0

Sheet External Delivery Fulfillment
H1: Total Invoices Delivered | I1: =countifs(B:B,"<>",F:F,"<>")-1 -> 0 | K1: Sku Performance | L1: Units | M1: Value
H2: Unique Locations Supplied | I2: {=(COUNTA(UNIQUE(C:C))-1)} -> 0 | K2: ='Internal Summary'!B40 -> 350ml Orisirisi Wallnut with Ginger Drink (12x) | L2: =sumif(D:D,K2,E:E) -> 0 | M2: =sumif(D:D,K2,F:F) -> 0
H3: Total Value of orders | I3: =sum(F:F) -> 0 | K3: ='Internal Summary'!B41 -> 500ml Orisirisi Tiger Nut Drink (12x) | L3: =sumif(D:D,K3,E:E) -> 0 | M3: =sumif(D:D,K3,F:F) -> 0
K4: ='Internal Summary'!B42 -> 500ml Orisirisi Zobo with Date Drink (12x) | L4: =sumif(D:D,K4,E:E) -> 0 | M4: =sumif(D:D,K4,F:F) -> 0
K5: ='Internal Summary'!B43 -> 350ml Orisirisi Wallnut Drink (12x) | L5: =sumif(D:D,K5,E:E) -> 0 | M5: =sumif(D:D,K5,F:F) -> 0
K6: ='Internal Summary'!B44 -> 500ml Orisirisi Zobo Drink (12x) | L6: =sumif(D:D,K6,E:E) -> 0 | M6: =sumif(D:D,K6,F:F) -> 0
K7: ='Internal Summary'!B45 | L7: =sumif(D:D,K7,E:E) -> 0 | M7: =sumif(D:D,K7,F:F) -> 0
K8: ='Internal Summary'!B46 | L8: =sumif(D:D,K8,E:E) -> 0 | M8: =sumif(D:D,K8,F:F) -> 0
K9: ='Internal Summary'!B47 | L9: =sumif(D:D,K9,E:E) -> 0 | M9: =sumif(D:D,K9,F:F) -> 0
K10: ='Internal Summary'!B48 | L10: =sumif(D:D,K10,E:E) -> 0 | M10: =sumif(D:D,K10,F:F) -> 0
K11: ='Internal Summary'!B49 | L11: =sumif(D:D,K11,E:E) -> 0 | M11: =sumif(D:D,K11,F:F) -> 0
K12: ='Internal Summary'!B50 | L12: =sumif(D:D,K12,E:E) -> 0 | M12: =sumif(D:D,K12,F:F) -> 0
K13: ='Internal Summary'!B51 | L13: =sumif(D:D,K13,E:E) -> 0 | M13: =sumif(D:D,K13,F:F) -> 0

Sheet Forwarding From Client
H1: Total Invoices Delivered | I1: =countifs(B:B,"<>",F:F,"<>")-1 -> 0 | K1: Sku Performance | L1: Units | M1: Value
H2: Unique Locations Supplied | I2: {=(COUNTA(UNIQUE(C:C))-1)} -> 0 | K2: ='Internal Summary'!B40 -> 350ml Orisirisi Wallnut with Ginger Drink (12x) | L2: =sumif(D:D,K2,E:E) -> 0 | M2: =sumif(D:D,K2,F:F) -> 0
H3: Total Value of orders | I3: =sum(F:F) -> 0 | K3: ='Internal Summary'!B41 -> 500ml Orisirisi Tiger Nut Drink (12x) | L3: =sumif(D:D,K3,E:E) -> 0 | M3: =sumif(D:D,K3,F:F) -> 0
K4: ='Internal Summary'!B42 -> 500ml Orisirisi Zobo with Date Drink (12x) | L4: =sumif(D:D,K4,E:E) -> 0 | M4: =sumif(D:D,K4,F:F) -> 0
K5: ='Internal Summary'!B43 -> 350ml Orisirisi Wallnut Drink (12x) | L5: =sumif(D:D,K5,E:E) -> 0 | M5: =sumif(D:D,K5,F:F) -> 0
K6: ='Internal Summary'!B44 -> 500ml Orisirisi Zobo Drink (12x) | L6: =sumif(D:D,K6,E:E) -> 0 | M6: =sumif(D:D,K6,F:F) -> 0
K7: ='Internal Summary'!B45 | L7: =sumif(D:D,K7,E:E) -> 0 | M7: =sumif(D:D,K7,F:F) -> 0
K8: ='Internal Summary'!B46 | L8: =sumif(D:D,K8,E:E) -> 0 | M8: =sumif(D:D,K8,F:F) -> 0
K9: ='Internal Summary'!B47 | L9: =sumif(D:D,K9,E:E) -> 0 | M9: =sumif(D:D,K9,F:F) -> 0
K10: ='Internal Summary'!B48 | L10: =sumif(D:D,K10,E:E) -> 0 | M10: =sumif(D:D,K10,F:F) -> 0
K11: ='Internal Summary'!B49 | L11: =sumif(D:D,K11,E:E) -> 0 | M11: =sumif(D:D,K11,F:F) -> 0
K12: ='Internal Summary'!B50 | L12: =sumif(D:D,K12,E:E) -> 0 | M12: =sumif(D:D,K12,F:F) -> 0
K13: ='Internal Summary'!B51 | L13: =sumif(D:D,K13,E:E) -> 0 | M13: =sumif(D:D,K13,F:F) -> 0

Sheet Dala Restocking
H1: Total Invoices Delivered | I1: =countifs(B:B,"<>",F:F,"<>")-1 -> 0 | K1: Sku Performance | L1: Units
H2: Unique Locations Supplied | I2: {=(COUNTA(UNIQUE(C:C,,0))-1)} -> 0 | K2: ='Internal Summary'!B40 -> 350ml Orisirisi Wallnut with Ginger Drink (12x) | L2: =sumif(D:D,K2,E:E) -> 0
H3: Total Value of orders | I3: =sum(F:F) -> 0 | K3: ='Internal Summary'!B41 -> 500ml Orisirisi Tiger Nut Drink (12x) | L3: =sumif(D:D,K3,E:E) -> 0
K4: ='Internal Summary'!B42 -> 500ml Orisirisi Zobo with Date Drink (12x) | L4: =sumif(D:D,K4,E:E) -> 0
K5: ='Internal Summary'!B43 -> 350ml Orisirisi Wallnut Drink (12x) | L5: =sumif(D:D,K5,E:E) -> 0
K6: ='Internal Summary'!B44 -> 500ml Orisirisi Zobo Drink (12x) | L6: =sumif(D:D,K6,E:E) -> 0
K7: ='Internal Summary'!B45 | L7: =sumif(D:D,K7,E:E) -> 0
K8: ='Internal Summary'!B46 | L8: =sumif(D:D,K8,E:E) -> 0
K9: ='Internal Summary'!B47 | L9: =sumif(D:D,K9,E:E) -> 0
K10: ='Internal Summary'!B48 | L10: =sumif(D:D,K10,E:E) -> 0
K11: ='Internal Summary'!B49 | L11: =sumif(D:D,K11,E:E) -> 0
K12: ='Internal Summary'!B50 | L12: =sumif(D:D,K12,E:E) -> 0
K13: ='Internal Summary'!B51 | L13: =sumif(D:D,K13,E:E) -> 0

Sheet Client Restocking
H1: Total Invoices Delivered | I1: =countifs(B:B,"<>",F:F,"<>")-1 -> 0 | K1: Sku Performance | L1: Units
H2: Unique Locations Supplied | I2: {=(COUNTA(UNIQUE(C:C,,0))-1)} -> 0 | K2: ='Internal Summary'!B40 -> 350ml Orisirisi Wallnut with Ginger Drink (12x) | L2: =sumif(D:D,K2,E:E) -> 0
H3: Total Value of orders | I3: =sum(F:F) -> 0 | K3: ='Internal Summary'!B41 -> 500ml Orisirisi Tiger Nut Drink (12x) | L3: =sumif(D:D,K3,E:E) -> 0
K4: ='Internal Summary'!B42 -> 500ml Orisirisi Zobo with Date Drink (12x) | L4: =sumif(D:D,K4,E:E) -> 0
K5: ='Internal Summary'!B43 -> 350ml Orisirisi Wallnut Drink (12x) | L5: =sumif(D:D,K5,E:E) -> 0
K6: ='Internal Summary'!B44 -> 500ml Orisirisi Zobo Drink (12x) | L6: =sumif(D:D,K6,E:E) -> 0
K7: ='Internal Summary'!B45 | L7: =sumif(D:D,K7,E:E) -> 0
K8: ='Internal Summary'!B46 | L8: =sumif(D:D,K8,E:E) -> 0
K9: ='Internal Summary'!B47 | L9: =sumif(D:D,K9,E:E) -> 0
K10: ='Internal Summary'!B48 | L10: =sumif(D:D,K10,E:E) -> 0
K11: ='Internal Summary'!B49 | L11: =sumif(D:D,K11,E:E) -> 0
K12: ='Internal Summary'!B50 | L12: =sumif(D:D,K12,E:E) -> 0
K13: ='Internal Summary'!B51 | L13: =sumif(D:D,K13,E:E) -> 0

Sheet Internal Summary
B1: Description | C1: Units | D1: measurements | E1: total
A2: SALES | B2: Total Invoices Delivered | E2: ='Dala Sales & Deliveries'!I1+'External Delivery Fulfillment'!I1 -> 4
B3: Unique Locations Delivered To | E3: ='Raw Data'!AW2 -> 3
B4: Value of Dala Deliveries | E4: ='Dala Sales & Deliveries'!I3 -> 82800
B5: Value of External Deliveries | E5: ='External Delivery Fulfillment'!I3 -> 0
B6: VAT on sales | E6: 0
B7: Total Value of Deliveries | E7: =sum(E4:E6) -> 82800
A8: Remittance & Deductions | B8: Total Remitted to Partner
B9: Collection Fees | C9: 0.1 | E9: =E8*(C9+100%)-E8 -> 0
A10: Invoice Value Due | B10: Outstanding Paymets For Sales | E10: =E7-E8-E9 -> 82800
A11: Debts | B11: Unpaid Subscription | C11: 1 | D11: 0 | E11: =C11*D11 -> 0
B12: Collection Fees | E12: =E10*C9 -> 8280
B13: Delivery Fees | D13: Table 1 | E13: =E10*3% -> 2484
B14: Reimbursements Due To DALA | E14: 0
B15: Retailer Deductions | E15: =C30 -> 0
B16: Total Deductions | E16: =sum(E11:E15) -> 10764
A17: Remmittance Due | B17: Total Balance to Remitt | E17: =E10-E16+C36 -> 72036
A20: Inventory and Operational Fees
B21: Dala Pickup for Warehouse | C21: =U69 -> 0
B22: Warehouse Delivery Fee | C22: =V69 -> 0
B23: Forwarding to Retail | C23: =S69 -> 0
B24: Forwarding Delivery Fee | C24: =T69 -> 0
B25: Dala Sales | C25: =67 -> 67
B26: Dala Delivery Fees | C26: =P69 -> 0
B27: Exteranl Deliveries | C27: =Q69 -> 0
B28: External Delivery Fees | C28: =R69 -> 0
B29: Product Defects and Expirey Issues | C29: =F69 -> 0
B30: Deductions From Retailer | C30: =G69 -> 0
B31: Samples used | C31: =I69 -> 0
B32: Produce Replacements | C32: =J69 -> 0
B33: Expected Closing Inventory | C33: 0
B34: Physical Stock count | C34: =K69 -> 0
B35: Inventory Shortages | C35: 0
B36: Inventory Shortage Costs | C36: 0
B39: SKUs | C39: Retail Value | D39: Inbound Delivery Fee | E39: Outbound Delivery Fee | F39: Defects/Expirey | G39: Deductions | H39: Opening Inventory | I39: Samples Used | J39: Product Replacements | K39: Physical Closing Stock Count | L39: Expected Closing Inventory | M39: Inventory Shortages | N39: Shortages Costs | O39: Dala Deliveries | P39: Retail Sales Fee | Q39: External Delivery | R39: External Delivery Fee | S39: Forwarding from Client | T39: Forwarding Delivery Fee | U39: Dala Restocking | V39: Dala Restocking Fee | W39: Client Restocking
B40: 350ml Orisirisi Wallnut with Ginger Drink (12x) | G40: =F40*C40 -> 0 | L40: =H40+U40+W40-O40-Q40-I40-J40 -> -0.5 | M40: =K40-L40 -> 0.5 | N40: =M40*C40 -> 0 | O40: ='Dala Sales & Deliveries'!L2 -> 0.5 | P40: =O40*E40 -> 0 | Q40: ='External Delivery Fulfillment'!L2 -> 0 | R40: =Q40*E40 -> 0 | S40: ='Forwarding From Client'!L2 -> 0 | T40: =S40*E40 -> 0 | U40: ='Dala Restocking'!L2 -> 0 | V40: =U40*D40 -> 0 | W40: ='Client Restocking'!L2 -> 0
B41: 500ml Orisirisi Tiger Nut Drink (12x) | G41: =F41*C41 -> 0 | L41: =H41+U41+W41-O41-Q41-I41-J41 -> -1 | M41: =K41-L41 -> 1 | N41: =M41*C41 -> 0 | O41: ='Dala Sales & Deliveries'!L3 -> 1 | P41: =O41*E41 -> 0 | Q41: ='External Delivery Fulfillment'!L3 -> 0 | R41: =Q41*E41 -> 0 | S41: ='Forwarding From Client'!L3 -> 0 | T41: =S41*E41 -> 0 | U41: ='Dala Restocking'!L3 -> 0 | V41: =U41*D41 -> 0 | W41: ='Client Restocking'!L3 -> 0
B42: 500ml Orisirisi Zobo with Date Drink (12x) | G42: =F42*C42 -> 0 | L42: =H42+U42+W42-O42-Q42-I42-J42 -> -1 | M42: =K42-L42 -> 1 | N42: =M42*C42 -> 0 | O42: ='Dala Sales & Deliveries'!L4 -> 1 | P42: =O42*E42 -> 0 | Q42: ='External Delivery Fulfillment'!L4 -> 0 | R42: =Q42*E42 -> 0 | S42: ='Forwarding From Client'!L4 -> 0 | T42: =S42*E42 -> 0 | U42: ='Dala Restocking'!L4 -> 0 | V42: =U42*D42 -> 0 | W42: ='Client Restocking'!L4 -> 0
B43: 350ml Orisirisi Wallnut Drink (12x) | G43: =F43*C43 -> 0 | L43: =H43+U43+W43-O43-Q43-I43-J43 -> -1 | M43: =K43-L43 -> 1 | N43: =M43*C43 -> 0 | O43: ='Dala Sales & Deliveries'!L5 -> 1 | P43: =O43*E43 -> 0 | Q43: ='External Delivery Fulfillment'!L5 -> 0 | R43: =Q43*E43 -> 0 | S43: ='Forwarding From Client'!L5 -> 0 | T43: =S43*E43 -> 0 | U43: ='Dala Restocking'!L5 -> 0 | V43: =U43*D43 -> 0 | W43: ='Client Restocking'!L5 -> 0
B44: 500ml Orisirisi Zobo Drink (12x) | G44: =F44*C44 -> 0 | L44: =H44+U44+W44-O44-Q44-I44-J44 -> 0 | M44: =K44-L44 -> 0 | N44: =M44*C44 -> 0 | O44: ='Dala Sales & Deliveries'!L6 -> 0 | P44: =O44*E44 -> 0 | Q44: ='External Delivery Fulfillment'!L6 -> 0 | R44: =Q44*E44 -> 0 | S44: ='Forwarding From Client'!L6 -> 0 | T44: =S44*E44 -> 0 | U44: ='Dala Restocking'!L6 -> 0 | V44: =U44*D44 -> 0 | W44: ='Client Restocking'!L6 -> 0
...

Sheet External Summary
B1: Description | C1: Units | D1: measurements | E1: total
A2: SALES | B2: Total Invoices Delivered | E2: ='Dala Sales & Deliveries'!I1+'External Delivery Fulfillment'!I1+'Forwarding From Client'!I1 -> 4
B3: Unique Locations Delivered To | E3: ='Raw Data'!AW2 -> 3
B4: Value of Dala Deliveries | E4: ='Dala Sales & Deliveries'!I3 -> 82800
B5: VAT | E5: =E4*1.075-E4 -> 6210
B6: Total Value of Deliveries | E6: =sum(E4:E5) -> 89010
A7: Remittance & Deductions | B7: Total Remitted to Partner
B8: Delivery Fees | C8: 0.06 | E8: =E7*(C8+100%)-E7 -> 0
B9: Collection Fees | C9: 0.1 | E9: =E7*(C9+100%)-E7 -> 0
A10: Debts | B10: Unpaid Subscription | C10: 1 | D10: 150000 | E10: =C10*D10 -> 150000
B11: Restocking Fees | E11: =V67 -> 0
B12: External Delivery Fees | E12: =R67 -> 0
B13: Reimbursements Due To DALA | E13: 0
B14: Retailer Deductions | E14: =C28 -> 0
B15: Total Owed to Dala | E15: =sum(E10:E14) -> 150000
A18: Inventory and Operational Fees
B19: Dala Pickup for Warehouse | C19: =U67 -> 0
B20: Warehouse Delivery Fee | C20: =V67 -> 0
B21: Forwarding to Retail | C21: =S67 -> 0
B22: Forwarding Delivery Fee | C22: =T67 -> 0
B23: Dala Sales | C23: =O67 -> 3.5
B24: Dala Delivery Fees | C24: =P67 -> 0
B25: Exteranl Deliveries | C25: =Q67 -> 0
B26: External Delivery Fees | C26: =R67 -> 0
B27: Product Defects and Expirey Issues | C27: =F67 -> 0
B28: Deductions From Retailer | C28: =G67 -> 0
B29: Samples used | C29: =I67 -> 0
B30: Returns/Replacements | C30: =J67 -> 0
B31: Expected Closing Inventory | C31: =L67 -> -3.5
B32: Physical Stock count | C32: =K67 -> 0
B33: Inventory Shortages | C33: 0
B34: Inventory Shortage Costs | C34: 0
B37: SKUs | C37: Retail Value | D37: Inbound Delivery Fee | E37: Outbound Delivery Fee | F37: Defects/Expirey | G37: Deductions | H37: Opening Inventory | I37: Samples Used | J37: Product Replacements | K37: Physical Closing Stock Count | L37: Expected Closing Inventory | M37: Inventory Shortages | N37: Shortages Costs | O37: Dala Sales | P37: Retail Sales Fee | Q37: External Delivery | R37: External Delivery Fee | S37: Forwarding from Client | T37: Forwarding Delivery Fee | U37: Dala Restocking | V37: Dala Restocking Fee | W37: Client Restocking
B38: ='Internal Summary'!B40 -> 350ml Orisirisi Wallnut with Ginger Drink (12x) | C38: ='Internal Summary'!C40 | D38: ='Internal Summary'!D40 | E38: ='Internal Summary'!E40 | G38: =F38*C38 -> 0 | K38: ='Internal Summary'!K40 | L38: =H38+U38+W38-O38-Q38-I38-J38 -> -0.5 | M38: =K38-L38 -> 0.5 | N38: =M38*C38 -> 0 | O38: ='Dala Sales & Deliveries'!L2 -> 0.5 | P38: =O38*E38 -> 0 | Q38: ='External Delivery Fulfillment'!L2 -> 0 | R38: =Q38*E38 -> 0 | S38: ='Forwarding From Client'!L2 -> 0 | T38: =S38*E38 -> 0 | U38: ='Dala Restocking'!L2 -> 0 | V38: =U38*D38 -> 0 | W38: ='Client Restocking'!L2 -> 0
B39: ='Internal Summary'!B41 -> 500ml Orisirisi Tiger Nut Drink (12x) | C39: ='Internal Summary'!C41 | D39: ='Internal Summary'!D41 | E39: ='Internal Summary'!E41 | G39: =F39*C39 -> 0 | K39: ='Internal Summary'!K41 | L39: =H39+U39+W39-O39-Q39-I39-J39 -> -1 | M39: =K39-L39 -> 1 | N39: =M39*C39 -> 0 | O39: ='Dala Sales & Deliveries'!L3 -> 1 | P39: =O39*E39 -> 0 | Q39: ='External Delivery Fulfillment'!L3 -> 0 | R39: =Q39*E39 -> 0 | S39: ='Forwarding From Client'!L3 -> 0 | T39: =S39*E39 -> 0 | U39: ='Dala Restocking'!L3 -> 0 | V39: =U39*D39 -> 0 | W39: ='Client Restocking'!L3 -> 0
B40: ='Internal Summary'!B42 -> 500ml Orisirisi Zobo with Date Drink (12x) | C40: ='Internal Summary'!C42 | D40: ='Internal Summary'!D42 | E40: ='Internal Summary'!E42 | G40: =F40*C40 -> 0 | K40: ='Internal Summary'!K42 | L40: =H40+U40+W40-O40-Q40-I40-J40 -> -1 | M40: =K40-L40 -> 1 | N40: =M40*C40 -> 0 | O40: ='Dala Sales & Deliveries'!L4 -> 1 | P40: =O40*E40 -> 0 | Q40: ='External Delivery Fulfillment'!L4 -> 0 | R40: =Q40*E40 -> 0 | S40: ='Forwarding From Client'!L4 -> 0 | T40: =S40*E40 -> 0 | U40: ='Dala Restocking'!L4 -> 0 | V40: =U40*D40 -> 0 | W40: ='Client Restocking'!L4 -> 0
B41: ='Internal Summary'!B43 -> 350ml Orisirisi Wallnut Drink (12x) | C41: ='Internal Summary'!C43 | D41: ='Internal Summary'!D43 | E41: ='Internal Summary'!E43 | G41: =F41*C41 -> 0 | K41: ='Internal Summary'!K43 | L41: =H41+U41+W41-O41-Q41-I41-J41 -> -1 | M41: =K41-L41 -> 1 | N41: =M41*C41 -> 0 | O41: ='Dala Sales & Deliveries'!L5 -> 1 | P41: =O41*E41 -> 0 | Q41: ='External Delivery Fulfillment'!L5 -> 0 | R41: =Q41*E41 -> 0 | S41: ='Forwarding From Client'!L5 -> 0 | T41: =S41*E41 -> 0 | U41: ='Dala Restocking'!L5 -> 0 | V41: =U41*D41 -> 0 | W41: ='Client Restocking'!L5 -> 0
B42: ='Internal Summary'!B44 -> 500ml Orisirisi Zobo Drink (12x) | C42: ='Internal Summary'!C44 | D42: ='Internal Summary'!D44 | E42: ='Internal Summary'!E44 | G42: =F42*C42 -> 0 | L42: =H42+U42+W42-O42-Q42-I42-J42 -> 0 | M42: =K42-L42 -> 0 | N42: =M42*C42 -> 0 | O42: ='Dala Sales & Deliveries'!L6 -> 0 | P42: =O42*E42 -> 0 | Q42: ='External Delivery Fulfillment'!L6 -> 0 | R42: =Q42*E42 -> 0 | S42: ='Forwarding From Client'!L6 -> 0 | T42: =S42*E42 -> 0 | U42: ='Dala Restocking'!L6 -> 0 | V42: =U42*D42 -> 0 | W42: ='Client Restocking'!L6 -> 0
B43: ='Internal Summary'!B45 | C43: ='Internal Summary'!C45 | D43: ='Internal Summary'!D45 | E43: ='Internal Summary'!E45 | G43: =F43*C43 -> 0 | L43: =H43+U43+W43-O43-Q43-I43-J43 -> 0 | M43: =K43-L43 -> 0 | N43: =M43*C43 -> 0 | O43: ='Dala Sales & Deliveries'!L7 -> 0 | P43: =O43*E43 -> 0 | Q43: ='External Delivery Fulfillment'!L7 -> 0 | R43: =Q43*E43 -> 0 | S43: ='Forwarding From Client'!L7 -> 0 | T43: =S43*E43 -> 0 | U43: ='Dala Restocking'!L7 -> 0 | V43: =U43*D43 -> 0 | W43: ='Client Restocking'!L7 -> 0
B44: ='Internal Summary'!B46 | C44: ='Internal Summary'!C46 | D44: ='Internal Summary'!D46 | E44: ='Internal Summary'!E46 | G44: =F44*C44 -> 0 | L44: =H44+U44+W44-O44-Q44-I44-J44 -> 0 | M44: =K44-L44 -> 0 | N44: =M44*C44 -> 0 | O44: ='Dala Sales & Deliveries'!L8 -> 0 | P44: =O44*E44 -> 0 | Q44: ='External Delivery Fulfillment'!L8 -> 0 | R44: =Q44*E44 -> 0 | S44: ='Forwarding From Client'!L8 -> 0 | T44: =S44*E44 -> 0 | U44: ='Dala Restocking'!L8 -> 0 | V44: =U44*D44 -> 0 | W44: ='Client Restocking'!L8 -> 0
...
