Workbook

Sheet Raw Data
A1: Exported from Tally | I1: Dala Sales & Deliveries | Q1: External Deliveries | Y1: Forwarding From Client | AG1: Client Restock | AO1: Dala Restock | AW1: Unique Locations
A2: item name | B2: Date | C2: Particulars | D2: Vch Type | E2: Vch No. | F2: Quantity | G2: Value | I2: item name | J2: Date | K2: Particulars | L2: Vch Type | M2: Vch No. | N2: Quantity | O2: Value | P2: Total Value | Q2: item name | R2: Date | S2: Particulars | T2: Vch Type | U2: Vch No. | V2: Quantity | W2: Value | Y2: item name | Z2: Date | AA2: Particulars | AB2: Vch Type | AC2: Vch No. | AD2: Quantity | AE2: Value | AG2: item name | AH2: Date | AI2: Particulars | AJ2: Vch Type | AK2: Vch No. | AL2: Quantity | AM2: Value | AO2: item name | AP2: Date | AQ2: Particulars | AR2: Vch Type | AS2: Vch No. | AT2: Quantity | AU2: Value | AW2: {=counta(unique(C:C))-2} -> 2
A3: Zeef 250g Blended Locust Beans (12x) | B3: 46055 | C3: Mega Mart | D3: Sales | E3: DT:000563 | F3: 0.5 | G3: 21209.3 | I3: =IFERROR(__xludf.DUMMYFUNCTION("IFERROR( FILTER($A$3:$G1844, LEN($A$3:$A1844), LOWER(TRIM($D$3:$D1844))=""sales""), )"),"Zeef 250g Blended Locust Beans (12x)") -> Zeef 250g Blended Locust Beans (12x) | J3: =IFERROR(__xludf.DUMMYFUNCTION("""COMPUTED_VALUE"""),46055.0) -> 46055 | K3: =IFERROR(__xludf.DUMMYFUNCTION("""COMPUTED_VALUE"""),"Mega Mart") -> Mega Mart | L3: =IFERROR(__xludf.DUMMYFUNCTION("""COMPUTED_VALUE"""),"Sales") -> Sales | M3: =IFERROR(__xludf.DUMMYFUNCTION("""COMPUTED_VALUE"""),"DT:000563") -> DT:000563 | N3: =IFERROR(__xludf.DUMMYFUNCTION("""COMPUTED_VALUE"""),0.5) -> 0.5 | O3: =IFERROR(__xludf.DUMMYFUNCTION("""COMPUTED_VALUE"""),21209.3) -> 21209.3 | P3: =SUMIF(M:M,M3,O:O) -> 21209.3 | Q3: =IFERROR(__xludf.DUMMYFUNCTION("IFERROR( FILTER($A$3:$G1844, LEN($A$3:$A1844), REGEXMATCH(LOWER(TRIM($D$3:$D1844)), ""\bjournal\b"")), )"),"") | AG3: =IFERROR(__xludf.DUMMYFUNCTION("IFERROR( FILTER($A$3:$G1844, LEN($A$3:$A1844), LOWER(TRIM($D$3:$D1844))=""Inventory Supplied by Brands""), )"),"") | AO3: =IFERROR(__xludf.DUMMYFUNCTION("IFERROR( FILTER($A$3:$G1844, LEN($A$3:$A1844), LOWER(TRIM($D$3:$D1844))=""Inventory Pickup by Dala""), )"),"")
A4: Zeef 250g Blended Locust Beans (12x) | B4: 46055 | C4: Overseas Supermarket, FESTAC | D4: Sales | E4: DT:000553 | F4: 0.5 | G4: 21189.59 | I4: =IFERROR(__xludf.DUMMYFUNCTION("""COMPUTED_VALUE"""),"Zeef 250g Blended Locust Beans (12x)") -> Zeef 250g Blended Locust Beans (12x) | J4: =IFERROR(__xludf.DUMMYFUNCTION("""COMPUTED_VALUE"""),46055.0) -> 46055 | K4: =IFERROR(__xludf.DUMMYFUNCTION("""COMPUTED_VALUE"""),"Overseas Supermarket, FESTAC") -> Overseas Supermarket, FESTAC | L4: =IFERROR(__xludf.DUMMYFUNCTION("""COMPUTED_VALUE"""),"Sales") -> Sales | M4: =IFERROR(__xludf.DUMMYFUNCTION("""COMPUTED_VALUE"""),"DT:000553") -> DT:000553 | N4: =IFERROR(__xludf.DUMMYFUNCTION("""COMPUTED_VALUE"""),0.5) -> 0.5 | O4: =IFERROR(__xludf.DUMMYFUNCTION("""COMPUTED_VALUE"""),21189.59) -> 21189.59 | P4: =SUMIF(M:M,M4,O:O) -> 21189.59
A5: Zeef 1kg Groundrice Flour (12x) | B5: 46055 | C5: Taiwo Supermarket, ISOLO | D5: Sales | E5: DT:000552 | F5: 1 | G5: 50232.56 | I5: =IFERROR(__xludf.DUMMYFUNCTION("""COMPUTED_VALUE"""),"Zeef 1kg Groundrice Flour (12x)") -> Zeef 1kg Groundrice Flour (12x) | J5: =IFERROR(__xludf.DUMMYFUNCTION("""COMPUTED_VALUE"""),46055.0) -> 46055 | K5: =IFERROR(__xludf.DUMMYFUNCTION("""COMPUTED_VALUE"""),"Taiwo Supermarket, ISOLO") -> Taiwo Supermarket, ISOLO | L5: =IFERROR(__xludf.DUMMYFUNCTION("""COMPUTED_VALUE"""),"Sales") -> Sales | M5: =IFERROR(__xludf.DUMMYFUNCTION("""COMPUTED_VALUE"""),"DT:000552") -> DT:000552 | N5: =IFERROR(__xludf.DUMMYFUNCTION("""COMPUTED_VALUE"""),1.0) -> 1 | O5: =IFERROR(__xludf.DUMMYFUNCTION("""COMPUTED_VALUE"""),50232.56) -> 50232.56 | P5: =SUMIF(M:M,M5,O:O) -> 50232.56
P6: =SUMIF(M:M,M6,O:O) -> 0
P7: =SUMIF(M:M,M7,O:O) -> 0
P8: =SUMIF(M:M,M8,O:O) -> 0
P9: =SUMIF(M:M,M9,O:O) -> 0
P10: =SUMIF(M:M,M10,O:O) -> 0
P11: =SUMIF(M:M,M11,O:O) -> 0
P12: =SUMIF(M:M,M12,O:O) -> 0
P13: =SUMIF(M:M,M13,O:O) -> 0
P14: =SUMIF(M:M,M14,O:O) -> 0
P15: =SUMIF(M:M,M15,O:O) -> 0
P16: =SUMIF(M:M,M16,O:O) -> 0
P17: =SUMIF(M:M,M17,O:O) -> 0
... P66: =SUMIF(M:M,M66,O:O) -> 0
T975: {=counta(UNIQUE(S2:S960))-1} -> 0 | AI975: {=UNIQUE(AI2:AI590)} -> Particulars | AQ975: {=UNIQUE(AQ2:AQ590)} -> Particulars

Sheet Payment Advice
F2: =sum(D:D) -> 92631.45

Sheet Dala Sales & Deliveries
H1: Total Invoices Delivered | I1: =countifs(B:B,"<>",F:F,"<>")-1 -> 3 | K1: Sku Performance | L1: Units | M1: Value
H2: Unique Locations Supplied | I2: {=(COUNTA(UNIQUE(C:C))-1)} -> 3 | K2: ='Internal Summary'!B41 -> Zeef 1kg Groundrice Flour (12x) | L2: =sumif(D:D,K2,E:E) -> 1 | M2: =sumif(D:D,K2,F:F) -> 50232.56
H3: Total Value of orders | I3: =sum(F:F) -> 92631.45 | K3: ='Internal Summary'!B42 -> Zeef 250g Blended Locust Beans (12x) | L3: =sumif(D:D,K3,E:E) -> 1 | M3: =sumif(D:D,K3,F:F) -> 42398.89
K4: ='Internal Summary'!B43 -> Zeef 250g Locust Beans (12x) | L4: =sumif(D:D,K4,E:E) -> 0 | M4: =sumif(D:D,K4,F:F) -> 0
K5: ='Internal Summary'!B44 | L5: =sumif(D:D,K5,E:E) -> 0 | M5: =sumif(D:D,K5,F:F) -> 0
K6: ='Internal Summary'!B45 | L6: =sumif(D:D,K6,E:E) -> 0 | M6: =sumif(D:D,K6,F:F) -> 0
K7: ='Internal Summary'!B46 | L7: =sumif(D:D,K7,E:E) -> 0 | M7: =sumif(D:D,K7,F:F) -> 0
K8: ='Internal Summary'!B47 | L8: =sumif(D:D,K8,E:E) -> 0 | M8: =sumif(D:D,K8,F:F) -> 0
K9: ='Internal Summary'!B48 | L9: =sumif(D:D,K9,E:E) -> 0 | M9: =sumif(D:D,K9,F:F) -> 0
K10: ='Internal Summary'!B49 | L10: =sumif(D:D,K10,E:E) -> 0 | M10: =sumif(D:D,K10,F:F) -> 0
K11: ='Internal Summary'!B50 | L11: =sumif(D:D,K11,E:E) -> 0 | M11: =sumif(D:D,K11,F:F) -> 0
A12: 45758 | K12: ='Internal Summary'!B51 | L12: =sumif(D:D,K12,E:E) -> 0 | M12: =sumif(D:D,K12,F:F) -> 0
K13: ='Internal Summary'!B52 | L13: =sumif(D:D,K13,E:E) -> 0 | M13: =sumif(D:D,K13,F:F) -> 0

Sheet External Delivery Fulfillment
H1: Total Invoices Delivered | I1: =countifs(B:B,"<>",F:F,"<>")-1 -> 0 | K1: Sku Performance | L1: Units | M1: Value
H2: Unique Locations Supplied | I2: {=(COUNTA(UNIQUE(C:C))-1)} -> 0 | K2: ='Internal Summary'!B41 -> Zeef 1kg Groundrice Flour (12x) | L2: =sumif(D:D,K2,E:E) -> 0 | M2: =sumif(D:D,K2,F:F) -> 0
H3: Total Value of orders | I3: =sum(F:F) -> 0 | K3: ='Internal Summary'!B42 -> Zeef 250g Blended Locust Beans (12x) | L3: =sumif(D:D,K3,E:E) -> 0 | M3: =sumif(D:D,K3,F:F) -> 0
K4: ='Internal Summary'!B43 -> Zeef 250g Locust Beans (12x) | L4: =sumif(D:D,K4,E:E) -> 0 | M4: =sumif(D:D,K4,F:F) -> 0
K5: ='Internal Summary'!B44 | L5: =sumif(D:D,K5,E:E) -> 0 | M5: =sumif(D:D,K5,F:F) -> 0
K6: ='Internal Summary'!B45 | L6: =sumif(D:D,K6,E:E) -> 0 | M6: =sumif(D:D,K6,F:F) -> 0
K7: ='Internal Summary'!B46 | L7: =sumif(D:D,K7,E:E) -> 0 | M7: =sumif(D:D,K7,F:F) -> 0
K8: ='Internal Summary'!B47 | L8: =sumif(D:D,K8,E:E) -> 0 | M8: =sumif(D:D,K8,F:F) -> 0
K9: ='Internal Summary'!B48 | L9: =sumif(D:D,K9,E:E) -> 0 | M9: =sumif(D:D,K9,F:F) -> 0
K10: ='Internal Summary'!B49 | L10: =sumif(D:D,K10,E:E) -> 0 | M10: =sumif(D:D,K10,F:F) -> 0
K11: ='Internal Summary'!B50 | L11: =sumif(D:D,K11,E:E) -> 0 | M11: =sumif(D:D,K11,F:F) -> 0
K12: ='Internal Summary'!B51 | L12: =sumif(D:D,K12,E:E) -> 0 | M12: =sumif(D:D,K12,F:F) -> 0
K13: ='Internal Summary'!B52 | L13: =sumif(D:D,K13,E:E) -> 0 | M13: =sumif(D:D,K13,F:F) -> 0

Sheet Forwarding From Client
H1: Total Invoices Delivered | I1: =countifs(B:B,"<>",F:F,"<>")-1 -> 0 | K1: Sku Performance | L1: Units | M1: Value
H2: Unique Locations Supplied | I2: {=(COUNTA(UNIQUE(C:C))-1)} -> 0 | K2: ='Internal Summary'!B41 -> Zeef 1kg Groundrice Flour (12x) | L2: =sumif(D:D,K2,E:E) -> 0 | M2: =sumif(D:D,K2,F:F) -> 0
H3: Total Value of orders | I3: =sum(F:F) -> 0 | K3: ='Internal Summary'!B42 -> Zeef 250g Blended Locust Beans (12x) | L3: =sumif(D:D,K3,E:E) -> 0 | M3: =sumif(D:D,K3,F:F) -> 0
K4: ='Internal Summary'!B43 -> Zeef 250g Locust Beans (12x) | L4: =sumif(D:D,K4,E:E) -> 0 | M4: =sumif(D:D,K4,F:F) -> 0
K5: ='Internal Summary'!B44 | L5: =sumif(D:D,K5,E:E) -> 0 | M5: =sumif(D:D,K5,F:F) -> 0
K6: ='Internal Summary'!B45 | L6: =sumif(D:D,K6,E:E) -> 0 | M6: =sumif(D:D,K6,F:F) -> 0
K7: ='Internal Summary'!B46 | L7: =sumif(D:D,K7,E:E) -> 0 | M7: =sumif(D:D,K7,F:F) -> 0
K8: ='Internal Summary'!B47 | L8: =sumif(D:D,K8,E:E) -> 0 | M8: =sumif(D:D,K8,F:F) -> 0
K9: ='Internal Summary'!B48 | L9: =sumif(D:D,K9,E:E) -> 0 | M9: =sumif(D:D,K9,F:F) -> 0
K10: ='Internal Summary'!B49 | L10: =sumif(D:D,K10,E:E) -> 0 | M10: =sumif(D:D,K10,F:F) -> 0
K11: ='Internal Summary'!B50 | L11: =sumif(D:D,K11,E:E) -> 0 | M11: =sumif(D:D,K11,F:F) -> 0
K12: ='Internal Summary'!B51 | L12: =sumif(D:D,K12,E:E) -> 0 | M12: =sumif(D:D,K12,F:F) -> 0
K13: ='Internal Summary'!B52 | L13: =sumif(D:D,K13,E:E) -> 0 | M13: =sumif(D:D,K13,F:F) -> 0

Sheet Dala Restocking
H1: Total Invoices Delivered | I1: =countifs(B:B,"<>",F:F,"<>")-1 -> 0 | K1: Sku Performance | L1: Units
H2: Unique Locations Supplied | I2: {=(COUNTA(UNIQUE(C:C,,0))-1)} -> 0 | K2: ='Internal Summary'!B41 -> Zeef 1kg Groundrice Flour (12x) | L2: =sumif(D:D,K2,E:E) -> 0
H3: Total Value of orders | I3: =sum(F:F) -> 0 | K3: ='Internal Summary'!B42 -> Zeef 250g Blended Locust Beans (12x) | L3: =sumif(D:D,K3,E:E) -> 0
K4: ='Internal Summary'!B43 -> Zeef 250g Locust Beans (12x) | L4: =sumif(D:D,K4,E:E) -> 0
K5: ='Internal Summary'!B44 | L5: =sumif(D:D,K5,E:E) -> 0
K6: ='Internal Summary'!B45 | L6: =sumif(D:D,K6,E:E) -> 0
K7: ='Internal Summary'!B46 | L7: =sumif(D:D,K7,E:E) -> 0
K8: ='Internal Summary'!B47 | L8: =sumif(D:D,K8,E:E) -> 0
K9: ='Internal Summary'!B48 | L9: =sumif(D:D,K9,E:E) -> 0
K10: ='Internal Summary'!B49 | L10: =sumif(D:D,K10,E:E) -> 0
K11: ='Internal Summary'!B50 | L11: =sumif(D:D,K11,E:E) -> 0
K12: ='Internal Summary'!B51 | L12: =sumif(D:D,K12,E:E) -> 0
K13: ='Internal Summary'!B52 | L13: =sumif(D:D,K13,E:E) -> 0

Sheet Client Restocking
H1: Total Invoices Delivered | I1: =countifs(B:B,"<>",F:F,"<>")-1 -> 0 | K1: Sku Performance | L1: Units
H2: Unique Locations Supplied | I2: {=(COUNTA(UNIQUE(C:C,,0))-1)} -> 0 | K2: ='Internal Summary'!B41 -> Zeef 1kg Groundrice Flour (12x) | L2: =sumif(D:D,K2,E:E) -> 0
H3: Total Value of orders | I3: =sum(F:F) -> 0 | K3: ='Internal Summary'!B42 -> Zeef 250g Blended Locust Beans (12x) | L3: =sumif(D:D,K3,E:E) -> 0
K4: ='Internal Summary'!B43 -> Zeef 250g Locust Beans (12x) | L4: =sumif(D:D,K4,E:E) -> 0
K5: ='Internal Summary'!B44 | L5: =sumif(D:D,K5,E:E) -> 0
K6: ='Internal Summary'!B45 | L6: =sumif(D:D,K6,E:E) -> 0
K7: ='Internal Summary'!B46 | L7: =sumif(D:D,K7,E:E) -> 0
K8: ='Internal Summary'!B47 | L8: =sumif(D:D,K8,E:E) -> 0
K9: ='Internal Summary'!B48 | L9: =sumif(D:D,K9,E:E) -> 0
K10: ='Internal Summary'!B49 | L10: =sumif(D:D,K10,E:E) -> 0
K11: ='Internal Summary'!B50 | L11: =sumif(D:D,K11,E:E) -> 0
K12: ='Internal Summary'!B51 | L12: =sumif(D:D,K12,E:E) -> 0
K13: ='Internal Summary'!B52 | L13: =sumif(D:D,K13,E:E) -> 0

Sheet Internal Summary
B1: Description | C1: Units | D1: measurements | E1: total
A2: SALES | B2: Total Invoices Delivered | E2: ='Dala Sales & Deliveries'!I1+'External Delivery Fulfillment'!I1 -> 3
B3: Unique Locations Delivered To | E3: ='Raw Data'!AW2 -> 2
B4: Value of Dala Deliveries | E4: ='Dala Sales & Deliveries'!I3 -> 92631.45
B5: Value of External Deliveries | E5: ='External Delivery Fulfillment'!I3 -> 0
B6: VAT on sales | E6: =E4*1.075-E4 -> 6947.3588
B7: Total Value of Deliveries | E7: =sum(E4:E6) -> 99578.809
A8: Remittance & Deductions | B8: Total Remitted to Partner
B9: Collection Fees | C9: 0.1 | E9: =E8*(C9+100%)-E8 -> 0
A10: Invoice Value Due | B10: Outstanding Paymets For Sales | E10: =E7-E8-E9 -> 99578.809
A11: Debts | B11: Unpaid Subscription | C11: 1 | E11: =C11*D11 -> 0
B12: Collection Fees | E12: =E10*C9 -> 9957.8809
B13: Delivery Fees | D13: Table 1 | E13: =C27 -> 6000
B14: Delivery Fees External & Pickup | D14: Table 1 | E14: =C23+C29 -> 0
B15: Reimbursements Due To DALA | E15: 0
B16: Retailer Deductions | E16: =C31 -> 0
B17: Total Deductions | E17: =sum(E11:E16) -> 15957.881
A18: Remmittance Due | B18: Total Balance to Remitt | E18: =E10-E17+C37 -> 83620.928
A21: Inventory and Operational Fees
B22: Dala Pickup for Warehouse | C22: =U70 -> 0
B23: Warehouse Delivery Fee | C23: =V70 -> 0
B24: Forwarding to Retail | C24: =S70 -> 0
B25: Forwarding Delivery Fee | C25: =T70 -> 0
B26: Dala Sales | C26: 0
B27: Dala Delivery Fees | C27: =P70 -> 6000
B28: Exteranl Deliveries | C28: =Q70 -> 0
B29: External Delivery Fees | C29: =R70 -> 0
B30: Product Defects and Expirey Issues | C30: =F70 -> 0
B31: Deductions From Retailer | C31: =G70 -> 0
B32: Samples used | C32: =I70 -> 0
B33: Produce Replacements | C33: =J70 -> 0
B34: Expected Closing Inventory | C34: 0
B35: Physical Stock count | C35: =K70 -> 20.67
B36: Inventory Shortages | C36: 0
B37: Inventory Shortage Costs | C37: 0
B40: SKUs | C40: Retail Value | D40: Inbound Delivery Fee | E40: Outbound Delivery Fee | F40: Defects/Expirey | G40: Deductions | H40: Opening Inventory | I40: Samples Used | J40: Product Replacements | K40: Physical Closing Stock Count | L40: Expected Closing Inventory | M40: Inventory Shortages | N40: Shortages Costs | O40: Dala Deliveries | P40: Retail Sales Fee | Q40: External Delivery | R40: External Delivery Fee | S40: Forwarding from Client | T40: Forwarding Delivery Fee | U40: Dala Restocking | V40: Dala Restocking Fee | W40: Client Restocking
B41: Zeef 1kg Groundrice Flour (12x) | C41: 54000 | D41: 1500 | E41: 4500 | G41: =F41*C41 -> 0 | K41: 10.17 | L41: 10.17 | M41: =K41-L41 -> 0 | N41: =M41*C41 -> 0 | O41: ='Dala Sales & Deliveries'!L2 -> 1 | P41: =O41*E41 -> 4500 | Q41: ='External Delivery Fulfillment'!L2 -> 0 | R41: =Q41*E41 -> 0 | S41: ='Forwarding From Client'!L2 -> 0 | T41: =S41*E41 -> 0 | U41: ='Dala Restocking'!L2 -> 0 | V41: =U41*D41 -> 0 | W41: ='Client Restocking'!L2 -> 0
B42: Zeef 250g Blended Locust Beans (12x) | C42: 45600 | D42: 500 | E42: 1500 | G42: =F42*C42 -> 0 | K42: 10.5 | L42: 10.5 | M42: =K42-L42 -> 0 | N42: =M42*C42 -> 0 | O42: ='Dala Sales & Deliveries'!L3 -> 1 | P42: =O42*E42 -> 1500 | Q42: ='External Delivery Fulfillment'!L3 -> 0 | R42: =Q42*E42 -> 0 | S42: ='Forwarding From Client'!L3 -> 0 | T42: =S42*E42 -> 0 | U42: ='Dala Restocking'!L3 -> 0 | V42: =U42*D42 -> 0 | W42: ='Client Restocking'!L3 -> 0
B43: Zeef 250g Locust Beans (12x) | C43: 44400 | D43: 500 | E43: 1500 | G43: =F43*C43 -> 0 | K43: 0 | L43: 0 | M43: =K43-L43 -> 0 | N43: =M43*C43 -> 0 | O43: ='Dala Sales & Deliveries'!L4 -> 0 | P43: =O43*E43 -> 0 | Q43: ='External Delivery Fulfillment'!L4 -> 0 | R43: =Q43*E43 -> 0 | S43: ='Forwarding From Client'!L4 -> 0 | T43: =S43*E43 -> 0 | U43: ='Dala Restocking'!L4 -> 0 | V43: =U43*D43 -> 0 | W43: ='Client Restocking'!L4 -> 0
G44: =F44*C44 -> 0 | L44: =H44+U44+W44-O44-Q44-I44-J44 -> 0 | M44: =K44-L44 -> 0 | N44: =M44*C44 -> 0 | O44: ='Dala Sales & Deliveries'!L5 -> 0 | P44: =O44*E44 -> 0 | Q44: ='External Delivery Fulfillment'!L5 -> 0 | R44: =Q44*E44 -> 0 | S44: ='Forwarding From Client'!L5 -> 0 | T44: =S44*E44 -> 0 | U44: ='Dala Restocking'!L5 -> 0 | V44: =U44*D44 -> 0 | W44: ='Client Restocking'!L5 -> 0
...
