Workbook

Sheet Raw Data
A1: Exported from Tally | I1: Dala Sales & Deliveries | R1: External Deliveries | Z1: Forwarding From Client | AH1: Client Restock | AP1: Dala Restock | AX1: Unique Locations
A2: item name | B2: Date | C2: Particulars | D2: Vch Type | E2: Vch No. | F2: Quantity | G2: Value | I2: item name | J2: Date | K2: Particulars | L2: Vch Type | M2: Vch No. | N2: Quantity | O2: Value | P2: Total value | R2: item name | S2: Date | T2: Particulars | U2: Vch Type | V2: Vch No. | W2: Quantity | X2: Value | Z2: item name | AA2: Date | AB2: Particulars | AC2: Vch Type | AD2: Vch No. | AE2: Quantity | AF2: Value | AH2: item name | AI2: Date | AJ2: Particulars | AK2: Vch Type | AL2: Vch No. | AM2: Quantity | AN2: Value | AP2: item name | AQ2: Date | AR2: Particulars | AS2: Vch Type | AT2: Vch No. | AU2: Quantity | AV2: Value | AX2: {=counta(unique(C:C))-2} -> 7
A3: 500g Toddler Protein (12x) | B3: 45856 | C3: De Prince Supermarket, GBAGADA | D3: Journal | E3: 161 | F3: 4 | G3: 168000 | I3: 500g Toddler Protein (12x) | J3: 45860 | K3: Renees Supermarket, FREEDOM WAY | L3: Sales | M3: DT:001887 | N3: 1 | O3: 42000 | P3: =sumif(K:K,K3,O:O) -> 42000 | R3: 500g Toddler Protein (12x) | S3: 45856 | T3: De Prince Supermarket, GBAGADA | U3: Journal | V3: 161 | W3: 4 | X3: 168000
A4: 56g Lemongrass Tea (12x) | B4: 45862 | C4: Goodiss Supermarket | D4: Journal | E4: 177 | F4: 0.5 | G4: 17100 | I4: 500g Toddler Protein (12x) | J4: 45862 | K4: Renees Supermarket, LEKKI CENTRAL MOSQUE | L4: Sales | M4: DT:001917 | N4: 1 | O4: 42000 | P4: =sumif(K:K,K4,O:O) -> 110400 | R4: 56g Lemongrass Tea (12x) | S4: 45862 | T4: Goodiss Supermarket | U4: Journal | V4: 177 | W4: 0.5 | X4: 17100
A5: 56g Soursop Tea (12x) | B5: 45862 | C5: Goodiss Supermarket | D5: Journal | E5: 177 | F5: 0.5 | G5: 17100 | I5: 56g Lemongrass Tea (12x) | J5: 45862 | K5: Renees Supermarket, LEKKI CENTRAL MOSQUE | L5: Sales | M5: DT:001917 | N5: 1 | O5: 34200 | P5: =sumif(K:K,K5,O:O) -> 110400 | R5: 56g Soursop Tea (12x) | S5: 45862 | T5: Goodiss Supermarket | U5: Journal | V5: 177 | W5: 0.5 | X5: 17100
A6: 500g Toddler Protein (12x) | B6: 45856 | C6: Jendol, ABULEGBA | D6: Journal | E6: 162 | F6: 1 | G6: 42000 | I6: 56g Moringa Tea (12x) | J6: 45862 | K6: Renees Supermarket, LEKKI CENTRAL MOSQUE | L6: Sales | M6: DT:001917 | N6: 1 | O6: 34200 | P6: =sumif(K:K,K6,O:O) -> 110400 | R6: 500g Toddler Protein (12x) | S6: 45856 | T6: Jendol, ABULEGBA | U6: Journal | V6: 162 | W6: 1 | X6: 42000
A7: 56g Soursop Tea (12x) | B7: 45856 | C7: Jendol, ABULEGBA | D7: Journal | E7: 162 | F7: 0.5 | G7: 17100 | I7: 500g Toddler Protein (12x) | J7: 45860 | K7: Surplus Supermarket | L7: Sales | M7: DT:001889 | N7: 0.5 | O7: 21000 | P7: =sumif(K:K,K7,O:O) -> 21000 | R7: 56g Soursop Tea (12x) | S7: 45856 | T7: Jendol, ABULEGBA | U7: Journal | V7: 162 | W7: 0.5 | X7: 17100
A8: 500g Toddler Protein (12x) | B8: 45857 | C8: Jendol, IPAJA | D8: Journal | E8: 168 | F8: 1 | G8: 42000 | P8: =sumif(K:K,K8,O:O) -> 0 | R8: 500g Toddler Protein (12x) | S8: 45857 | T8: Jendol, IPAJA | U8: Journal | V8: 168 | W8: 1 | X8: 42000
A9: 500g Toddler Protein (12x) | B9: 45859 | C9: Jendol, OJODU | D9: Journal | E9: 169 | F9: 0.5 | G9: 21000 | P9: =sumif(K:K,K9,O:O) -> 0 | R9: 500g Toddler Protein (12x) | S9: 45859 | T9: Jendol, OJODU | U9: Journal | V9: 169 | W9: 0.5 | X9: 21000
A10: 500g Toddler Protein (12x) | B10: 45860 | C10: Renees Supermarket, FREEDOM WAY | D10: Sales | E10: DT:001887 | F10: 1 | G10: 42000 | P10: =sumif(K:K,K10,O:O) -> 0
A11: 500g Toddler Protein (12x) | B11: 45862 | C11: Renees Supermarket, LEKKI CENTRAL MOSQUE | D11: Sales | E11: DT:001917 | F11: 1 | G11: 42000 | P11: =sumif(K:K,K11,O:O) -> 0
A12: 56g Lemongrass Tea (12x) | B12: 45862 | C12: Renees Supermarket, LEKKI CENTRAL MOSQUE | D12: Sales | E12: DT:001917 | F12: 1 | G12: 34200 | P12: =sumif(K:K,K12,O:O) -> 0
A13: 56g Moringa Tea (12x) | B13: 45862 | C13: Renees Supermarket, LEKKI CENTRAL MOSQUE | D13: Sales | E13: DT:001917 | F13: 1 | G13: 34200 | P13: =sumif(K:K,K13,O:O) -> 0
A14: 500g Toddler Protein (12x) | B14: 45860 | C14: Surplus Supermarket | D14: Sales | E14: DT:001889 | F14: 0.5 | G14: 21000 | P14: =sumif(K:K,K14,O:O) -> 0
P15: =sumif(K:K,K15,O:O) -> 0
P16: =sumif(K:K,K16,O:O) -> 0
P17: =sumif(K:K,K17,O:O) -> 0
P18: =sumif(K:K,K18,O:O) -> 0
P19: =sumif(K:K,K19,O:O) -> 0
P20: =sumif(K:K,K20,O:O) -> 0
P21: =sumif(K:K,K21,O:O) -> 0
P22: =sumif(K:K,K22,O:O) -> 0
P23: =sumif(K:K,K23,O:O) -> 0
P24: =sumif(K:K,K24,O:O) -> 0
P25: =sumif(K:K,K25,O:O) -> 0
P26: =sumif(K:K,K26,O:O) -> 0
... P1844: =sumif(K:K,K1844,O:O) -> 0

Sheet Payment Advice

Sheet Dala Sales & Deliveries
H1: Total Invoices Delivered | I1: =countifs(B:B,"<>",F:F,"<>")-1 -> 3 | K1: Sku Performance | L1: Units | M1: Value
H2: Unique Locations Supplied | I2: {=(COUNTA(UNIQUE(C:C))-1)} -> 3 | K2: ='Internal Summary'!B40 -> 500g Toddler Protein (12x) | L2: =sumif(D:D,K2,E:E) -> 2.5 | M2: =sumif(D:D,K2,F:F) -> 105000
H3: Total Value of orders | I3: =sum(F:F) -> 173400 | K3: ='Internal Summary'!B41 -> 56g Lemongrass Tea (12x) | L3: =sumif(D:D,K3,E:E) -> 1 | M3: =sumif(D:D,K3,F:F) -> 34200
K4: ='Internal Summary'!B42 -> 56g Moringa Tea (12x) | L4: =sumif(D:D,K4,E:E) -> 1 | M4: =sumif(D:D,K4,F:F) -> 34200
K5: ='Internal Summary'!B43 -> 56g Soursop Tea (12x) | L5: =sumif(D:D,K5,E:E) -> 0 | M5: =sumif(D:D,K5,F:F) -> 0
K6: ='Internal Summary'!B44 | L6: =sumif(D:D,K6,E:E) -> 0 | M6: =sumif(D:D,K6,F:F) -> 0
K7: ='Internal Summary'!B45 | L7: =sumif(D:D,K7,E:E) -> 0 | M7: =sumif(D:D,K7,F:F) -> 0
K8: ='Internal Summary'!B46 | L8: =sumif(D:D,K8,E:E) -> 0 | M8: =sumif(D:D,K8,F:F) -> 0
K9: ='Internal Summary'!B47 | L9: =sumif(D:D,K9,E:E) -> 0 | M9: =sumif(D:D,K9,F:F) -> 0
K10: ='Internal Summary'!B48 | L10: =sumif(D:D,K10,E:E) -> 0 | M10: =sumif(D:D,K10,F:F) -> 0
K11: ='Internal Summary'!B49 | L11: =sumif(D:D,K11,E:E) -> 0 | M11: =sumif(D:D,K11,F:F) -> 0
A12: 45758 | K12: ='Internal Summary'!B50 | L12: =sumif(D:D,K12,E:E) -> 0 | M12: =sumif(D:D,K12,F:F) -> 0
K13: ='Internal Summary'!B51 | L13: =sumif(D:D,K13,E:E) -> 0 | M13: =sumif(D:D,K13,F:F) -> 0

Sheet External Delivery Fulfillment
H1: Total Invoices Delivered | I1: =countifs(B:B,"<>",F:F,"<>")-1 -> 5 | K1: Sku Performance | L1: Units | M1: Value | N1: Delivery Fee | O1: Total
H2: Unique Locations Supplied | I2: {=(COUNTA(UNIQUE(C:C))-1)} -> 5 | K2: ='Internal Summary'!B40 -> 500g Toddler Protein (12x) | L2: =sumif(D:D,K2,E:E) -> 6.5 | M2: =sumif(D:D,K2,F:F) -> 273000 | N2: 1250 | O2: =L2*N2 -> 8125
H3: Total Value of orders | I3: =sum(F:F) -> 324300 | K3: ='Internal Summary'!B41 -> 56g Lemongrass Tea (12x) | L3: =sumif(D:D,K3,E:E) -> 0.5 | M3: =sumif(D:D,K3,F:F) -> 17100 | N3: 600 | O3: =L3*N3 -> 300
K4: ='Internal Summary'!B42 -> 56g Moringa Tea (12x) | L4: =sumif(D:D,K4,E:E) -> 0 | M4: =sumif(D:D,K4,F:F) -> 0 | N4: 600 | O4: =L4*N4 -> 0
K5: ='Internal Summary'!B43 -> 56g Soursop Tea (12x) | L5: =sumif(D:D,K5,E:E) -> 1 | M5: =sumif(D:D,K5,F:F) -> 34200 | N5: 600 | O5: =L5*N5 -> 600
K6: ='Internal Summary'!B44 | L6: =sumif(D:D,K6,E:E) -> 0 | M6: =sumif(D:D,K6,F:F) -> 0
K7: ='Internal Summary'!B45 | L7: =sumif(D:D,K7,E:E) -> 0 | M7: =sumif(D:D,K7,F:F) -> 0 | N7: TOTAL | O7: =sum(O2:O5) -> 9025
K8: ='Internal Summary'!B46 | L8: =sumif(D:D,K8,E:E) -> 0 | M8: =sumif(D:D,K8,F:F) -> 0
K9: ='Internal Summary'!B47 | L9: =sumif(D:D,K9,E:E) -> 0 | M9: =sumif(D:D,K9,F:F) -> 0
K10: ='Internal Summary'!B48 | L10: =sumif(D:D,K10,E:E) -> 0 | M10: =sumif(D:D,K10,F:F) -> 0
K11: ='Internal Summary'!B49 | L11: =sumif(D:D,K11,E:E) -> 0 | M11: =sumif(D:D,K11,F:F) -> 0
K12: ='Internal Summary'!B50 | L12: =sumif(D:D,K12,E:E) -> 0 | M12: =sumif(D:D,K12,F:F) -> 0
K13: ='Internal Summary'!B51 | L13: =sumif(D:D,K13,E:E) -> 0 | M13: =sumif(D:D,K13,F:F) -> 0

Sheet Forwarding From Client
H1: Total Invoices Delivered | I1: =countifs(B:B,"<>",F:F,"<>")-1 -> 0 | K1: Sku Performance | L1: Units | M1: Value
H2: Unique Locations Supplied | I2: {=(COUNTA(UNIQUE(C:C))-1)} -> 0 | K2: ='Internal Summary'!B40 -> 500g Toddler Protein (12x) | L2: =sumif(D:D,K2,E:E) -> 0 | M2: =sumif(D:D,K2,F:F) -> 0
H3: Total Value of orders | I3: =sum(F:F) -> 0 | K3: ='Internal Summary'!B41 -> 56g Lemongrass Tea (12x) | L3: =sumif(D:D,K3,E:E) -> 0 | M3: =sumif(D:D,K3,F:F) -> 0
K4: ='Internal Summary'!B42 -> 56g Moringa Tea (12x) | L4: =sumif(D:D,K4,E:E) -> 0 | M4: =sumif(D:D,K4,F:F) -> 0
K5: ='Internal Summary'!B43 -> 56g Soursop Tea (12x) | L5: =sumif(D:D,K5,E:E) -> 0 | M5: =sumif(D:D,K5,F:F) -> 0
K6: ='Internal Summary'!B44 | L6: =sumif(D:D,K6,E:E) -> 0 | M6: =sumif(D:D,K6,F:F) -> 0
K7: ='Internal Summary'!B45 | L7: =sumif(D:D,K7,E:E) -> 0 | M7: =sumif(D:D,K7,F:F) -> 0
K8: ='Internal Summary'!B46 | L8: =sumif(D:D,K8,E:E) -> 0 | M8: =sumif(D:D,K8,F:F) -> 0
K9: ='Internal Summary'!B47 | L9: =sumif(D:D,K9,E:E) -> 0 | M9: =sumif(D:D,K9,F:F) -> 0
K10: ='Internal Summary'!B48 | L10: =sumif(D:D,K10,E:E) -> 0 | M10: =sumif(D:D,K10,F:F) -> 0
K11: ='Internal Summary'!B49 | L11: =sumif(D:D,K11,E:E) -> 0 | M11: =sumif(D:D,K11,F:F) -> 0
K12: ='Internal Summary'!B50 | L12: =sumif(D:D,K12,E:E) -> 0 | M12: =sumif(D:D,K12,F:F) -> 0
K13: ='Internal Summary'!B51 | L13: =sumif(D:D,K13,E:E) -> 0 | M13: =sumif(D:D,K13,F:F) -> 0

Sheet Dala Restocking
H1: Total Invoices Delivered | I1: =countifs(B:B,"<>",F:F,"<>")-1 -> 0 | K1: Sku Performance | L1: Units
H2: Unique Locations Supplied | I2: {=(COUNTA(UNIQUE(C:C,,0))-1)} -> 0 | K2: ='Internal Summary'!B40 -> 500g Toddler Protein (12x) | L2: =sumif(D:D,K2,E:E) -> 0
H3: Total Value of orders | I3: =sum(F:F) -> 0 | K3: ='Internal Summary'!B41 -> 56g Lemongrass Tea (12x) | L3: =sumif(D:D,K3,E:E) -> 0
K4: ='Internal Summary'!B42 -> 56g Moringa Tea (12x) | L4: =sumif(D:D,K4,E:E) -> 0
K5: ='Internal Summary'!B43 -> 56g Soursop Tea (12x) | L5: =sumif(D:D,K5,E:E) -> 0
K6: ='Internal Summary'!B44 | L6: =sumif(D:D,K6,E:E) -> 0
K7: ='Internal Summary'!B45 | L7: =sumif(D:D,K7,E:E) -> 0
K8: ='Internal Summary'!B46 | L8: =sumif(D:D,K8,E:E) -> 0
K9: ='Internal Summary'!B47 | L9: =sumif(D:D,K9,E:E) -> 0
K10: ='Internal Summary'!B48 | L10: =sumif(D:D,K10,E:E) -> 0
K11: ='Internal Summary'!B49 | L11: =sumif(D:D,K11,E:E) -> 0
K12: ='Internal Summary'!B50 | L12: =sumif(D:D,K12,E:E) -> 0
K13: ='Internal Summary'!B51 | L13: =sumif(D:D,K13,E:E) -> 0

Sheet Client Restocking
H1: Total Invoices Delivered | I1: =countifs(B:B,"<>",F:F,"<>")-1 -> 0 | K1: Sku Performance | L1: Units
H2: Unique Locations Supplied | I2: {=(COUNTA(UNIQUE(C:C,,0))-1)} -> 0 | K2: ='Internal Summary'!B40 -> 500g Toddler Protein (12x) | L2: =sumif(D:D,K2,E:E) -> 0
H3: Total Value of orders | I3: =sum(F:F) -> 0 | K3: ='Internal Summary'!B41 -> 56g Lemongrass Tea (12x) | L3: =sumif(D:D,K3,E:E) -> 0
K4: ='Internal Summary'!B42 -> 56g Moringa Tea (12x) | L4: =sumif(D:D,K4,E:E) -> 0
K5: ='Internal Summary'!B43 -> 56g Soursop Tea (12x) | L5: =sumif(D:D,K5,E:E) -> 0
K6: ='Internal Summary'!B44 | L6: =sumif(D:D,K6,E:E) -> 0
K7: ='Internal Summary'!B45 | L7: =sumif(D:D,K7,E:E) -> 0
K8: ='Internal Summary'!B46 | L8: =sumif(D:D,K8,E:E) -> 0
K9: ='Internal Summary'!B47 | L9: =sumif(D:D,K9,E:E) -> 0
K10: ='Internal Summary'!B48 | L10: =sumif(D:D,K10,E:E) -> 0
K11: ='Internal Summary'!B49 | L11: =sumif(D:D,K11,E:E) -> 0
K12: ='Internal Summary'!B50 | L12: =sumif(D:D,K12,E:E) -> 0
K13: ='Internal Summary'!B51 | L13: =sumif(D:D,K13,E:E) -> 0

Sheet Internal Summary
B1: Description | C1: Units | D1: measurements | E1: total
A2: SALES | B2: Total Invoices Delivered | E2: ='Dala Sales & Deliveries'!I1+'External Delivery Fulfillment'!I1 -> 8
B3: Unique Locations Delivered To | E3: ='Raw Data'!AX2 -> 7
B4: Value of Dala Deliveries | E4: ='Dala Sales & Deliveries'!I3 -> 173400
B5: Value of External Deliveries | E5: ='External Delivery Fulfillment'!I3 -> 324300
B6: VAT on sales
B7: Total Value of Deliveries | E7: =sum(E4:E6) -> 497700
A8: Remittance & Deductions | B8: Total Remitted to Partner
B9: Collection Fees | C9: 0.09 | E9: =E8*(C9+100%)-E8 -> 0
A10: Invoice Value Due | B10: Outstanding Paymets For Sales | E10: =E7-E8-E9 -> 497700
A11: Debts | B11: Unpaid Subscription | C11: 1 | D11: 250000 | E11: =C11*D11 -> 250000
B12: Collection Fees | E12: =E10*C9 -> 44793
B13: Delivery Fees | D13: Table 1 | E13: =C22+C26 -> 4325
B14: Reimbursements Due To DALA | E14: 0
B15: Retailer Deductions | E15: =C30 -> 0
B16: Total Deductions | E16: =sum(E11:E15) -> 299118
A17: Remmittance Due | B17: Total Balance to Remitt | E17: =E10-E16+C36 -> 198582
A20: Inventory and Operational Fees
B21: Dala Pickup for Warehouse | C21: =U69 -> 0
B22: Warehouse Delivery Fee | C22: =V69 -> 0
B23: Forwarding to Retail | C23: =S69 -> 0
B24: Forwarding Delivery Fee | C24: =T69 -> 0
B25: Dala Sales | C25: =67 -> 67
B26: Dala Delivery Fees | C26: =P69 -> 4325
B27: Exteranl Deliveries | C27: =Q69 -> 8
B28: External Delivery Fees | C28: =R69 -> 9025
B29: Product Defects and Expirey Issues | C29: =F69 -> 0
B30: Deductions From Retailer | C30: =G69 -> 0
B31: Samples used | C31: =I69 -> 0
B32: Produce Replacements | C32: =J69 -> 0
B33: Expected Closing Inventory | C33: 0
B34: Physical Stock count | C34: =K69 -> 38.5
B35: Inventory Shortages | C35: 0
B36: Inventory Shortage Costs | C36: 0
B39: SKUs | C39: Retail Value | D39: Inbound Delivery Fee | E39: Outbound Delivery Fee | F39: Defects/Expirey | G39: Deductions | H39: Opening Inventory | I39: Samples Used | J39: Product Replacements | K39: Physical Closing Stock Count | L39: Expected Closing Inventory | M39: Inventory Shortages | N39: Shortages Costs | O39: Dala Deliveries | P39: Retail Sales Fee | Q39: External Delivery | R39: External Delivery Fee | S39: Forwarding from Client | T39: Forwarding Delivery Fee | U39: Dala Restocking | V39: Dala Restocking Fee | W39: Client Restocking
B40: 500g Toddler Protein (12x) | C40: 42000 | D40: 600 | E40: 1250 | G40: =F40*C40 -> 0 | H40: 25 | K40: 6 | L40: =H40+U40+W40-O40-Q40-I40-J40 -> 16 | M40: =K40-L40 -> -10 | N40: =M40*C40 -> -420000 | O40: ='Dala Sales & Deliveries'!L2 -> 2.5 | P40: =O40*E40 -> 3125 | Q40: ='External Delivery Fulfillment'!L2 -> 6.5 | R40: =Q40*E40 -> 8125 | S40: ='Forwarding From Client'!L2 -> 0 | T40: =S40*E40 -> 0 | U40: ='Dala Restocking'!L2 -> 0 | V40: =U40*D40 -> 0 | W40: ='Client Restocking'!L2 -> 0
B41: 56g Lemongrass Tea (12x) | C41: 34200 | D41: 350 | E41: 600 | G41: =F41*C41 -> 0 | H41: 25 | K41: 13.5 | L41: =H41+U41+W41-O41-Q41-I41-J41 -> 23.5 | M41: =K41-L41 -> -10 | N41: =M41*C41 -> -342000 | O41: ='Dala Sales & Deliveries'!L3 -> 1 | P41: =O41*E41 -> 600 | Q41: ='External Delivery Fulfillment'!L3 -> 0.5 | R41: =Q41*E41 -> 300 | S41: ='Forwarding From Client'!L3 -> 0 | T41: =S41*E41 -> 0 | U41: ='Dala Restocking'!L3 -> 0 | V41: =U41*D41 -> 0 | W41: ='Client Restocking'!L3 -> 0
B42: 56g Moringa Tea (12x) | C42: 34200 | D42: 350 | E42: 600 | G42: =F42*C42 -> 0 | H42: 25 | K42: 9 | L42: =H42+U42+W42-O42-Q42-I42-J42 -> 24 | M42: =K42-L42 -> -15 | N42: =M42*C42 -> -513000 | O42: ='Dala Sales & Deliveries'!L4 -> 1 | P42: =O42*E42 -> 600 | Q42: ='External Delivery Fulfillment'!L4 -> 0 | R42: =Q42*E42 -> 0 | S42: ='Forwarding From Client'!L4 -> 0 | T42: =S42*E42 -> 0 | U42: ='Dala Restocking'!L4 -> 0 | V42: =U42*D42 -> 0 | W42: ='Client Restocking'!L4 -> 0
B43: 56g Soursop Tea (12x) | C43: 34200 | D43: 350 | E43: 600 | G43: =F43*C43 -> 0 | H43: 25 | K43: 10 | L43: =H43+U43+W43-O43-Q43-I43-J43 -> 24 | M43: =K43-L43 -> -14 | N43: =M43*C43 -> -478800 | O43: ='Dala Sales & Deliveries'!L5 -> 0 | P43: =O43*E43 -> 0 | Q43: ='External Delivery Fulfillment'!L5 -> 1 | R43: =Q43*E43 -> 600 | S43: ='Forwarding From Client'!L5 -> 0 | T43: =S43*E43 -> 0 | U43: ='Dala Restocking'!L5 -> 0 | V43: =U43*D43 -> 0 | W43: ='Client Restocking'!L5 -> 0
G44: =F44*C44 -> 0 | L44: =H44+U44+W44-O44-Q44-I44-J44 -> 0 | M44: =K44-L44 -> 0 | N44: =M44*C44 -> 0 | O44: ='Dala Sales & Deliveries'!L6 -> 0 | P44: =O44*E44 -> 0 | Q44: ='External Delivery Fulfillment'!L6 -> 0 | R44: =Q44*E44 -> 0 | S44: ='Forwarding From Client'!L6 -> 0 | T44: =S44*E44 -> 0 | U44: ='Dala Restocking'!L6 -> 0 | V44: =U44*D44 -> 0 | W44: ='Client Restocking'!L6 -> 0
...

Sheet External Summary
B1: Description | C1: Units | D1: measurements | E1: total
A2: SALES | B2: Total Invoices Delivered | E2: ='Dala Sales & Deliveries'!I1+'External Delivery Fulfillment'!I1+'Forwarding From Client'!I1 -> 8
B3: Unique Locations Delivered To | E3: ='Raw Data'!AX2 -> 7
B4: Value of Dala Deliveries | E4: ='Dala Sales & Deliveries'!I3 -> 173400
B5: Value of External Deliveries | E5: ='External Delivery Fulfillment'!I3 -> 324300
B6: Total Value of Deliveries | E6: =sum(E4:E5) -> 497700
A7: Remittance & Deductions | B7: Total Remitted to Partner
B8: Delivery Fees | C8: 0.07 | E8: =E7*(C8+100%)-E7 -> 0
B9: Collection Fees | C9: 0.13 | E9: =E7*(C9+100%)-E7 -> 0
A10: Debts | B10: Unpaid Subscription | C10: 2 | D10: 250000 | E10: =C10*D10 -> 500000
B11: Restocking Fees | E11: =V67 -> 0
B12: External Delivery Fees | E12: =R67 -> 9025
B13: Reimbursements Due To DALA | E13: 0
B14: Retailer Deductions | E14: =C28 -> 0
B15: Total Owed to Dala | E15: =sum(E10:E14) -> 509025
A18: Inventory and Operational Fees
B19: Dala Pickup for Warehouse | C19: =U67 -> 0
B20: Warehouse Delivery Fee | C20: =V67 -> 0
B21: Forwarding to Retail | C21: =S67 -> 0
B22: Forwarding Delivery Fee | C22: =T67 -> 0
B23: Dala Sales | C23: =O67 -> 4.5
B24: Dala Delivery Fees | C24: =P67 -> 4325
B25: Exteranl Deliveries | C25: =Q67 -> 8
B26: External Delivery Fees | C26: =R67 -> 9025
B27: Product Defects and Expirey Issues | C27: =F67 -> 0
B28: Deductions From Retailer | C28: =G67 -> 0
B29: Samples used | C29: =I67 -> 0
B30: Returns/Replacements | C30: =J67 -> 0
B31: Expected Closing Inventory | C31: =L67 -> -12.5
B32: Physical Stock count | C32: =K67 -> 17
B33: Inventory Shortages | C33: =M67 -> 29.5
B34: Inventory Shortage Costs | C34: =-N67 -> -1086900
B37: SKUs | C37: Retail Value | D37: Inbound Delivery Fee | E37: Outbound Delivery Fee | F37: Defects/Expirey | G37: Deductions | H37: Opening Inventory | I37: Samples Used | J37: Product Replacements | K37: Physical Closing Stock Count | L37: Expected Closing Inventory | M37: Inventory Shortages | N37: Shortages Costs | O37: Dala Sales | P37: Retail Sales Fee | Q37: External Delivery | R37: External Delivery Fee | S37: Forwarding from Client | T37: Forwarding Delivery Fee | U37: Dala Restocking | V37: Dala Restocking Fee | W37: Client Restocking
B38: ='Internal Summary'!B40 -> 500g Toddler Protein (12x) | C38: ='Internal Summary'!C40 -> 42000 | D38: ='Internal Summary'!D40 -> 600 | E38: ='Internal Summary'!E40 -> 1250 | G38: =F38*C38 -> 0 | K38: 1 | L38: =H38+U38+W38-O38-Q38-I38-J38 -> -9 | M38: =K38-L38 -> 10 | N38: =M38*C38 -> 420000 | O38: ='Dala Sales & Deliveries'!L2 -> 2.5 | P38: =O38*E38 -> 3125 | Q38: ='External Delivery Fulfillment'!L2 -> 6.5 | R38: =Q38*E38 -> 8125 | S38: ='Forwarding From Client'!L2 -> 0 | T38: =S38*E38 -> 0 | U38: ='Dala Restocking'!L2 -> 0 | V38: =U38*D38 -> 0 | W38: ='Client Restocking'!L2 -> 0
B39: ='Internal Summary'!B41 -> 56g Lemongrass Tea (12x) | C39: ='Internal Summary'!C41 -> 34200 | D39: ='Internal Summary'!D41 -> 350 | E39: ='Internal Summary'!E41 -> 600 | G39: =F39*C39 -> 0 | K39: 9.5 | L39: =H39+U39+W39-O39-Q39-I39-J39 -> -1.5 | M39: =K39-L39 -> 11 | N39: =M39*C39 -> 376200 | O39: ='Dala Sales & Deliveries'!L3 -> 1 | P39: =O39*E39 -> 600 | Q39: ='External Delivery Fulfillment'!L3 -> 0.5 | R39: =Q39*E39 -> 300 | S39: ='Forwarding From Client'!L3 -> 0 | T39: =S39*E39 -> 0 | U39: ='Dala Restocking'!L3 -> 0 | V39: =U39*D39 -> 0 | W39: ='Client Restocking'!L3 -> 0
B40: ='Internal Summary'!B42 -> 56g Moringa Tea (12x) | C40: ='Internal Summary'!C42 -> 34200 | D40: ='Internal Summary'!D42 -> 350 | E40: ='Internal Summary'!E42 -> 600 | G40: =F40*C40 -> 0 | K40: 4 | L40: =H40+U40+W40-O40-Q40-I40-J40 -> -1 | M40: =K40-L40 -> 5 | N40: =M40*C40 -> 171000 | O40: ='Dala Sales & Deliveries'!L4 -> 1 | P40: =O40*E40 -> 600 | Q40: ='External Delivery Fulfillment'!L4 -> 0 | R40: =Q40*E40 -> 0 | S40: ='Forwarding From Client'!L4 -> 0 | T40: =S40*E40 -> 0 | U40: ='Dala Restocking'!L4 -> 0 | V40: =U40*D40 -> 0 | W40: ='Client Restocking'!L4 -> 0
B41: ='Internal Summary'!B43 -> 56g Soursop Tea (12x) | C41: ='Internal Summary'!C43 -> 34200 | D41: ='Internal Summary'!D43 -> 350 | E41: ='Internal Summary'!E43 -> 600 | G41: =F41*C41 -> 0 | K41: 2.5 | L41: =H41+U41+W41-O41-Q41-I41-J41 -> -1 | M41: =K41-L41 -> 3.5 | N41: =M41*C41 -> 119700 | O41: ='Dala Sales & Deliveries'!L5 -> 0 | P41: =O41*E41 -> 0 | Q41: ='External Delivery Fulfillment'!L5 -> 1 | R41: =Q41*E41 -> 600 | S41: ='Forwarding From Client'!L5 -> 0 | T41: =S41*E41 -> 0 | U41: ='Dala Restocking'!L5 -> 0 | V41: =U41*D41 -> 0 | W41: ='Client Restocking'!L5 -> 0
B42: ='Internal Summary'!B44 | C42: ='Internal Summary'!C44 | D42: ='Internal Summary'!D44 | E42: ='Internal Summary'!E44 | G42: =F42*C42 -> 0 | L42: =H42+U42+W42-O42-Q42-I42-J42 -> 0 | M42: =K42-L42 -> 0 | N42: =M42*C42 -> 0 | O42: ='Dala Sales & Deliveries'!L6 -> 0 | P42: =O42*E42 -> 0 | Q42: ='External Delivery Fulfillment'!L6 -> 0 | R42: =Q42*E42 -> 0 | S42: ='Forwarding From Client'!L6 -> 0 | T42: =S42*E42 -> 0 | U42: ='Dala Restocking'!L6 -> 0 | V42: =U42*D42 -> 0 | W42: ='Client Restocking'!L6 -> 0
B43: ='Internal Summary'!B45 | C43: ='Internal Summary'!C45 | D43: ='Internal Summary'!D45 | E43: ='Internal Summary'!E45 | G43: =F43*C43 -> 0 | L43: =H43+U43+W43-O43-Q43-I43-J43 -> 0 | M43: =K43-L43 -> 0 | N43: =M43*C43 -> 0 | O43: ='Dala Sales & Deliveries'!L7 -> 0 | P43: =O43*E43 -> 0 | Q43: ='External Delivery Fulfillment'!L7 -> 0 | R43: =Q43*E43 -> 0 | S43: ='Forwarding From Client'!L7 -> 0 | T43: =S43*E43 -> 0 | U43: ='Dala Restocking'!L7 -> 0 | V43: =U43*D43 -> 0 | W43: ='Client Restocking'!L7 -> 0
B44: ='Internal Summary'!B46 | C44: ='Internal Summary'!C46 | D44: ='Internal Summary'!D46 | E44: ='Internal Summary'!E46 | G44: =F44*C44 -> 0 | L44: =H44+U44+W44-O44-Q44-I44-J44 -> 0 | M44: =K44-L44 -> 0 | N44: =M44*C44 -> 0 | O44: ='Dala Sales & Deliveries'!L8 -> 0 | P44: =O44*E44 -> 0 | Q44: ='External Delivery Fulfillment'!L8 -> 0 | R44: =Q44*E44 -> 0 | S44: ='Forwarding From Client'!L8 -> 0 | T44: =S44*E44 -> 0 | U44: ='Dala Restocking'!L8 -> 0 | V44: =U44*D44 -> 0 | W44: ='Client Restocking'!L8 -> 0
...

Sheet Sheet11
B1: A. DALA TECHNOLOGIES LTD (RC 7128226)
A2: S/N | B2: Date | C2: Customer Name | D2: Invoice Number | E2: Amount | F2: Overdue Days
A3: 1 | B3: 45867 | C3: 234 Stores, IKORODU | D3: DT:001964 | E3: 79000.01 | F3: 0
A4: 2 | B4: 45582 | C4: Able Supermarket | D4: DT:000282 | E4: 16000.3 | F4: 274
A5: 3 | B5: 45671 | C5: Addas Mall, IKEJA | D5: DT:000067 | E5: 119200.01 | F5: 185
A6: 4 | B6: 45862 | C6: Addas Mall, IKEJA | D6: DT:001896 | E6: 158792.52 | F6: 0
A7: 5 | B7: 45624 | C7: Addide Store, CENTRAL WAREHOUSE | D7: DT:000482 | E7: 245000.03 | F7: 232
A8: 6 | B8: 45728 | C8: Addide Store, CENTRAL WAREHOUSE | D8: DT:000519 | E8: 297500.02 | F8: 128
A9: 7 | B9: 45702 | C9: Addide Store, CENTRAL WAREHOUSE | D9: DT:000766 | E9: 107640.47 | F9: 154
A10: 8 | B10: 45813 | C10: Addide Store, CENTRAL WAREHOUSE | D10: DT:001369 | E10: 350000.01 | F10: 43
A11: 9 | B11: 45861 | C11: Addide Store, CENTRAL WAREHOUSE | D11: DT:001908 | E11: 349570.01 | F11: 0
A12: 10 | B12: 45543 | C12: Adeleke Store, Ajah | D12: DT:000120 | E12: 32000.6 | F12: 313
A13: 11 | B13: 45586 | C13: Adeleke Store, Ajah | D13: DT:000297 | E13: 84264.55 | F13: 270
A14: 12 | B14: 45657 | C14: Adeleke Store, Ajah | D14: DT:000652 | E14: 44400 | F14: 199
... A671: 669 | B671: 45842 | C671: Moneyworth Supermarket | D671: DT:001746 | E671: 110200.36 | F671: 14
A672: 670 | B672: 45782 | C672: Monifee Supermarket Ejigbo | D672: 233 | E672: 204500 | F672: 67
A673: 671 | B673: 45743 | C673: Monifee Supermarket Ejigbo | D673: DT:000659 | E673: 25700 | F673: 106
A674: 672 | B674: 45701 | C674: Monifee Supermarket Ejigbo | D674: DT:000762 | E674: 51400.01 | F674: 148
A675: 673 | B675: 45633 | C675: Monnaspark Superstore | D675: DT:000531 | E675: 52500 | F675: 223
A676: 674 | B676: 45848 | C676: Monnaspark Superstore | D676: DT:001781 | E676: 52500 | F676: 8
A677: 675 | B677: 45868 | C677: Monnaspark Superstore | D677: DT:001980 | E677: 33926.26 | F677: 0
A678: 676 | B678: 45675 | C678: MQ Supermarket | D678: DT:000096 | E678: 53700 | F678: 188
A679: 677 | B679: 45679 | C679: MQ Supermarket | D679: DT:000128 | E679: 54000 | F679: 177
A680: 678 | B680: 45684 | C680: MQ Supermarket | D680: DT:000152 | E680: 50050 | F680: 172
A681: 679 | B681: 45687 | C681: MQ Supermarket | D681: DT:000180 | E681: 54000 | F681: 169
A682: 680 | B682: 45568 | C682: MQ Supermarket | D682: DT:000195 | E682: 32000.6 | F682: 288
A683: 681 | B683: 45631 | C683: MQ Supermarket | D683: DT:000515 | E683: 74200 | F683: 225
A684: 682 | B684: 45652 | C684: MQ Supermarket | D684: DT:000642 | E684: 45500 | F684: 204
... A811: 809 | B811: 45853 | C811: Prime Mart Superstores, IYANA ISASHI | D811: DT:001809 | E811: 166500 | F811: 3
A812: 810 | B812: 45793 | C812: Prime Mart Superstores, OKOKOMAIKO | D812: 1 | E812: 2100 | F812: 63
A813: 811 | B813: 45672 | C813: Prime Mart Superstores, OKOKOMAIKO | D813: DT:000073 | E813: 147100.01 | F813: 177
A814: 812 | B814: 45544 | C814: Prime Mart Superstores, OKOKOMAIKO | D814: DT:000124 | E814: 342326.78 | F814: 312
A815: 813 | B815: 45680 | C815: Prime Mart Superstores, OKOKOMAIKO | D815: DT:000134 | E815: 50400 | F815: 176
A816: 814 | B816: 45548 | C816: Prime Mart Superstores, OKOKOMAIKO | D816: DT:000148 | E816: 88236 | F816: 308
A817: 815 | B817: 45583 | C817: Prime Mart Superstores, OKOKOMAIKO | D817: DT:000292 | E817: 132000.02 | F817: 273
A818: 816 | B818: 45590 | C818: Prime Mart Superstores, OKOKOMAIKO | D818: DT:000332 | E818: 96400 | F818: 266
A819: 817 | B819: 45636 | C819: Prime Mart Superstores, OKOKOMAIKO | D819: DT:000546 | E819: 169599.99 | F819: 220
A820: 818 | B820: 45749 | C820: Prime Mart Superstores, OKOKOMAIKO | D820: DT:000729 | E820: 85200 | F820: 107
A821: 819 | B821: 45772 | C821: Prime Mart Superstores, OKOKOMAIKO | D821: DT:000939 | E821: 88200 | F821: 84
A822: 820 | B822: 45813 | C822: Prime Mart Superstores, OKOKOMAIKO | D822: DT:001393 | E822: 124700.01 | F822: 43
...

Sheet Pivot Table 4
