Workbook

Sheet Raw Data
A1: Exported from Tally | I1: Dala Sales & Deliveries | Q1: External Deliveries | Y1: Forwarding From Client | AG1: Client Restock | AO1: Dala Restock | AW1: Unique Locations
A2: item name | B2: Date | C2: Particulars | D2: Vch Type | E2: Vch No. | F2: Quantity | G2: Value | I2: item name | J2: Date | K2: Particulars | L2: Vch Type | M2: Vch No. | N2: Quantity | O2: Value | P2: Total Value | Q2: item name | R2: Date | S2: Particulars | T2: Vch Type | U2: Vch No. | V2: Quantity | W2: Value | Y2: item name | Z2: Date | AA2: Particulars | AB2: Vch Type | AC2: Vch No. | AD2: Quantity | AE2: Value | AG2: item name | AH2: Date | AI2: Particulars | AJ2: Vch Type | AK2: Vch No. | AL2: Quantity | AM2: Value | AO2: item name | AP2: Date | AQ2: Particulars | AR2: Vch Type | AS2: Vch No. | AT2: Quantity | AU2: Value | AW2: {=counta(unique(C:C))-2} -> 20
A3: Atun 120g Peppersoup Spice (12x) | B3: 45920 | C3: Atun Foods | D3: Purchase Inv-Dala | E3: 2132 | F3: 20 | G3: 669767.4 | I3: =IFERROR(__xludf.DUMMYFUNCTION("IFERROR( FILTER($A$3:$G1844, LEN($A$3:$A1844), LOWER(TRIM($D$3:$D1844))=""sales""), )"),"Atun 120g Peppersoup Spice (12x)") -> Atun 120g Peppersoup Spice (12x) | J3: =IFERROR(__xludf.DUMMYFUNCTION("""COMPUTED_VALUE"""),45901.0) -> 45901 | K3: =IFERROR(__xludf.DUMMYFUNCTION("""COMPUTED_VALUE"""),"K & P Supermarket") -> K & P Supermarket | L3: =IFERROR(__xludf.DUMMYFUNCTION("""COMPUTED_VALUE"""),"Sales") -> Sales | M3: =IFERROR(__xludf.DUMMYFUNCTION("""COMPUTED_VALUE"""),"DT:002377") -> DT:002377 | N3: =IFERROR(__xludf.DUMMYFUNCTION("""COMPUTED_VALUE"""),1.0) -> 1 | O3: =IFERROR(__xludf.DUMMYFUNCTION("""COMPUTED_VALUE"""),33488.37) -> 33488.37 | P3: =sumif(M:M,M3,O:O) -> 33488.37 | Q3: =IFERROR(__xludf.DUMMYFUNCTION("IFERROR( FILTER($A$3:$G1844, LEN($A$3:$A1844), REGEXMATCH(LOWER(TRIM($D$3:$D1844)), ""\bjournal\b"")), ) "),"") | AG3: =IFERROR(__xludf.DUMMYFUNCTION("IFERROR( FILTER($A$3:$G1844, LEN($A$3:$A1844), LOWER(TRIM($D$3:$D1844))=""purchase inv-brand partner""), ) "),"") | AO3: =IFERROR(__xludf.DUMMYFUNCTION("IFERROR( FILTER($A$3:$G1844, LEN($A$3:$A1844), LOWER(TRIM($D$3:$D1844))=""purchase inv-dala""), )"),"Atun 120g Peppersoup Spice (12x)") -> Atun 120g Peppersoup Spice (12x) | AP3: =IFERROR(__xludf.DUMMYFUNCTION("""COMPUTED_VALUE"""),45920.0) -> 45920 | AQ3: =IFERROR(__xludf.DUMMYFUNCTION("""COMPUTED_VALUE"""),"Atun Foods") -> Atun Foods | AR3: =IFERROR(__xludf.DUMMYFUNCTION("""COMPUTED_VALUE"""),"Purchase Inv-Dala") -> Purchase Inv-Dala | AS3: =IFERROR(__xludf.DUMMYFUNCTION("""COMPUTED_VALUE"""),2132.0) -> 2132 | AT3: =IFERROR(__xludf.DUMMYFUNCTION("""COMPUTED_VALUE"""),20.0) -> 20 | AU3: =IFERROR(__xludf.DUMMYFUNCTION("""COMPUTED_VALUE"""),669767.4) -> 669767.4
A4: Atun 120g Peppersoup Spice (12x) | B4: 45901 | C4: K & P Supermarket | D4: Sales | E4: DT:002377 | F4: 1 | G4: 33488.37 | I4: =IFERROR(__xludf.DUMMYFUNCTION("""COMPUTED_VALUE"""),"Atun 120g Peppersoup Spice (12x)") -> Atun 120g Peppersoup Spice (12x) | J4: =IFERROR(__xludf.DUMMYFUNCTION("""COMPUTED_VALUE"""),45902.0) -> 45902 | K4: =IFERROR(__xludf.DUMMYFUNCTION("""COMPUTED_VALUE"""),"Ozzy Supermarket, VICTORY PARK EST.") -> Ozzy Supermarket, VICTORY PARK EST. | L4: =IFERROR(__xludf.DUMMYFUNCTION("""COMPUTED_VALUE"""),"Sales") -> Sales | M4: =IFERROR(__xludf.DUMMYFUNCTION("""COMPUTED_VALUE"""),"DT:002387") -> DT:002387 | N4: =IFERROR(__xludf.DUMMYFUNCTION("""COMPUTED_VALUE"""),1.0) -> 1 | O4: =IFERROR(__xludf.DUMMYFUNCTION("""COMPUTED_VALUE"""),33488.37) -> 33488.37 | P4: =sumif(M:M,M4,O:O) -> 83720.93
A5: Atun 120g Peppersoup Spice (12x) | B5: 45902 | C5: Ozzy Supermarket, VICTORY PARK EST. | D5: Sales | E5: DT:002387 | F5: 1 | G5: 33488.37 | I5: =IFERROR(__xludf.DUMMYFUNCTION("""COMPUTED_VALUE"""),"Atun 120g Peppersoup Spice (12x)") -> Atun 120g Peppersoup Spice (12x) | J5: =IFERROR(__xludf.DUMMYFUNCTION("""COMPUTED_VALUE"""),45903.0) -> 45903 | K5: =IFERROR(__xludf.DUMMYFUNCTION("""COMPUTED_VALUE"""),"Jendol Supermarket, ALAKUKO") -> Jendol Supermarket, ALAKUKO | L5: =IFERROR(__xludf.DUMMYFUNCTION("""COMPUTED_VALUE"""),"Sales") -> Sales | M5: =IFERROR(__xludf.DUMMYFUNCTION("""COMPUTED_VALUE"""),"DT:002407") -> DT:002407 | N5: =IFERROR(__xludf.DUMMYFUNCTION("""COMPUTED_VALUE"""),0.5) -> 0.5 | O5: =IFERROR(__xludf.DUMMYFUNCTION("""COMPUTED_VALUE"""),16744.19) -> 16744.19 | P5: =sumif(M:M,M5,O:O) -> 16744.19
A6: Atun 120g Peppersoup Spice (12x) | B6: 45903 | C6: Jendol Supermarket, ALAKUKO | D6: Sales | E6: DT:002407 | F6: 0.5 | G6: 16744.19 | I6: =IFERROR(__xludf.DUMMYFUNCTION("""COMPUTED_VALUE"""),"Atun 120g Peppersoup Spice (12x)") -> Atun 120g Peppersoup Spice (12x) | J6: =IFERROR(__xludf.DUMMYFUNCTION("""COMPUTED_VALUE"""),45904.0) -> 45904 | K6: =IFERROR(__xludf.DUMMYFUNCTION("""COMPUTED_VALUE"""),"Limitless Mart, LEKKI") -> Limitless Mart, LEKKI | L6: =IFERROR(__xludf.DUMMYFUNCTION("""COMPUTED_VALUE"""),"Sales") -> Sales | M6: =IFERROR(__xludf.DUMMYFUNCTION("""COMPUTED_VALUE"""),"DT:002415") -> DT:002415 | N6: =IFERROR(__xludf.DUMMYFUNCTION("""COMPUTED_VALUE"""),1.0) -> 1 | O6: =IFERROR(__xludf.DUMMYFUNCTION("""COMPUTED_VALUE"""),33488.37) -> 33488.37 | P6: =sumif(M:M,M6,O:O) -> 33488.37
A7: Atun 120g Peppersoup Spice (12x) | B7: 45904 | C7: Limitless Mart, LEKKI | D7: Sales | E7: DT:002415 | F7: 1 | G7: 33488.37 | I7: =IFERROR(__xludf.DUMMYFUNCTION("""COMPUTED_VALUE"""),"Atun 120g Peppersoup Spice (12x)") -> Atun 120g Peppersoup Spice (12x) | J7: =IFERROR(__xludf.DUMMYFUNCTION("""COMPUTED_VALUE"""),45905.0) -> 45905 | K7: =IFERROR(__xludf.DUMMYFUNCTION("""COMPUTED_VALUE"""),"Jendol Supermarket, EGBEDA") -> Jendol Supermarket, EGBEDA | L7: =IFERROR(__xludf.DUMMYFUNCTION("""COMPUTED_VALUE"""),"Sales") -> Sales | M7: =IFERROR(__xludf.DUMMYFUNCTION("""COMPUTED_VALUE"""),"DT:002438") -> DT:002438 | N7: =IFERROR(__xludf.DUMMYFUNCTION("""COMPUTED_VALUE"""),0.5) -> 0.5 | O7: =IFERROR(__xludf.DUMMYFUNCTION("""COMPUTED_VALUE"""),16744.19) -> 16744.19 | P7: =sumif(M:M,M7,O:O) -> 16744.19
A8: Atun 120g Peppersoup Spice (12x) | B8: 45905 | C8: Jendol Supermarket, EGBEDA | D8: Sales | E8: DT:002438 | F8: 0.5 | G8: 16744.19 | I8: =IFERROR(__xludf.DUMMYFUNCTION("""COMPUTED_VALUE"""),"Atun 120g Peppersoup Spice (12x)") -> Atun 120g Peppersoup Spice (12x) | J8: =IFERROR(__xludf.DUMMYFUNCTION("""COMPUTED_VALUE"""),45905.0) -> 45905 | K8: =IFERROR(__xludf.DUMMYFUNCTION("""COMPUTED_VALUE"""),"Zomain Supermarket, JAKANDE Gate") -> Zomain Supermarket, JAKANDE Gate | L8: =IFERROR(__xludf.DUMMYFUNCTION("""COMPUTED_VALUE"""),"Sales") -> Sales | M8: =IFERROR(__xludf.DUMMYFUNCTION("""COMPUTED_VALUE"""),"DT:002449") -> DT:002449 | N8: =IFERROR(__xludf.DUMMYFUNCTION("""COMPUTED_VALUE"""),0.5) -> 0.5 | O8: =IFERROR(__xludf.DUMMYFUNCTION("""COMPUTED_VALUE"""),16744.19) -> 16744.19 | P8: =sumif(M:M,M8,O:O) -> 30697.68
A9: Atun 120g Peppersoup Spice (12x) | B9: 45905 | C9: Zomain Supermarket, JAKANDE Gate | D9: Sales | E9: DT:002449 | F9: 0.5 | G9: 16744.19 | I9: =IFERROR(__xludf.DUMMYFUNCTION("""COMPUTED_VALUE"""),"Atun 120g Peppersoup Spice (12x)") -> Atun 120g Peppersoup Spice (12x) | J9: =IFERROR(__xludf.DUMMYFUNCTION("""COMPUTED_VALUE"""),45906.0) -> 45906 | K9: =IFERROR(__xludf.DUMMYFUNCTION("""COMPUTED_VALUE"""),"Pharm Affair") -> Pharm Affair | L9: =IFERROR(__xludf.DUMMYFUNCTION("""COMPUTED_VALUE"""),"Sales") -> Sales | M9: =IFERROR(__xludf.DUMMYFUNCTION("""COMPUTED_VALUE"""),"DT:002463") -> DT:002463 | N9: =IFERROR(__xludf.DUMMYFUNCTION("""COMPUTED_VALUE"""),0.5) -> 0.5 | O9: =IFERROR(__xludf.DUMMYFUNCTION("""COMPUTED_VALUE"""),16744.19) -> 16744.19 | P9: =sumif(M:M,M9,O:O) -> 33488.38
A10: Atun 120g Peppersoup Spice (12x) | B10: 45906 | C10: Pharm Affair | D10: Sales | E10: DT:002463 | F10: 0.5 | G10: 16744.19 | I10: =IFERROR(__xludf.DUMMYFUNCTION("""COMPUTED_VALUE"""),"Atun 120g Peppersoup Spice (12x)") -> Atun 120g Peppersoup Spice (12x) | J10: =IFERROR(__xludf.DUMMYFUNCTION("""COMPUTED_VALUE"""),45906.0) -> 45906 | K10: =IFERROR(__xludf.DUMMYFUNCTION("""COMPUTED_VALUE"""),"Teewell Superstore") -> Teewell Superstore | L10: =IFERROR(__xludf.DUMMYFUNCTION("""COMPUTED_VALUE"""),"Sales") -> Sales | M10: =IFERROR(__xludf.DUMMYFUNCTION("""COMPUTED_VALUE"""),"DT:002467") -> DT:002467 | N10: =IFERROR(__xludf.DUMMYFUNCTION("""COMPUTED_VALUE"""),0.5) -> 0.5 | O10: =IFERROR(__xludf.DUMMYFUNCTION("""COMPUTED_VALUE"""),16744.19) -> 16744.19 | P10: =sumif(M:M,M10,O:O) -> 41860.47
A11: Atun 120g Peppersoup Spice (12x) | B11: 45906 | C11: Teewell Superstore | D11: Sales | E11: DT:002467 | F11: 0.5 | G11: 16744.19 | I11: =IFERROR(__xludf.DUMMYFUNCTION("""COMPUTED_VALUE"""),"Atun 120g Peppersoup Spice (12x)") -> Atun 120g Peppersoup Spice (12x) | J11: =IFERROR(__xludf.DUMMYFUNCTION("""COMPUTED_VALUE"""),45911.0) -> 45911 | K11: =IFERROR(__xludf.DUMMYFUNCTION("""COMPUTED_VALUE"""),"Compramart Supermarket, MOBILE Rd.") -> Compramart Supermarket, MOBILE Rd. | L11: =IFERROR(__xludf.DUMMYFUNCTION("""COMPUTED_VALUE"""),"Sales") -> Sales | M11: =IFERROR(__xludf.DUMMYFUNCTION("""COMPUTED_VALUE"""),"DT:002492") -> DT:002492 | N11: =IFERROR(__xludf.DUMMYFUNCTION("""COMPUTED_VALUE"""),1.0) -> 1 | O11: =IFERROR(__xludf.DUMMYFUNCTION("""COMPUTED_VALUE"""),33488.37) -> 33488.37 | P11: =sumif(M:M,M11,O:O) -> 33488.37
A12: Atun 120g Peppersoup Spice (12x) | B12: 45911 | C12: Compramart Supermarket, MOBILE Rd. | D12: Sales | E12: DT:002492 | F12: 1 | G12: 33488.37 | I12: =IFERROR(__xludf.DUMMYFUNCTION("""COMPUTED_VALUE"""),"Atun 120g Peppersoup Spice (12x)") -> Atun 120g Peppersoup Spice (12x) | J12: =IFERROR(__xludf.DUMMYFUNCTION("""COMPUTED_VALUE"""),45911.0) -> 45911 | K12: =IFERROR(__xludf.DUMMYFUNCTION("""COMPUTED_VALUE"""),"Priviledge Superstore") -> Priviledge Superstore | L12: =IFERROR(__xludf.DUMMYFUNCTION("""COMPUTED_VALUE"""),"Sales") -> Sales | M12: =IFERROR(__xludf.DUMMYFUNCTION("""COMPUTED_VALUE"""),"DT:002502") -> DT:002502 | N12: =IFERROR(__xludf.DUMMYFUNCTION("""COMPUTED_VALUE"""),0.5) -> 0.5 | O12: =IFERROR(__xludf.DUMMYFUNCTION("""COMPUTED_VALUE"""),16744.19) -> 16744.19 | P12: =sumif(M:M,M12,O:O) -> 16744.19
A13: Atun 120g Peppersoup Spice (12x) | B13: 45911 | C13: Priviledge Superstore | D13: Sales | E13: DT:002502 | F13: 0.5 | G13: 16744.19 | I13: =IFERROR(__xludf.DUMMYFUNCTION("""COMPUTED_VALUE"""),"Atun 120g Peppersoup Spice (12x)") -> Atun 120g Peppersoup Spice (12x) | J13: =IFERROR(__xludf.DUMMYFUNCTION("""COMPUTED_VALUE"""),45911.0) -> 45911 | K13: =IFERROR(__xludf.DUMMYFUNCTION("""COMPUTED_VALUE"""),"Moneyworth Supermarket, IJUSHAGA") -> Moneyworth Supermarket, IJUSHAGA | L13: =IFERROR(__xludf.DUMMYFUNCTION("""COMPUTED_VALUE"""),"Sales") -> Sales | M13: =IFERROR(__xludf.DUMMYFUNCTION("""COMPUTED_VALUE"""),"DT:002505") -> DT:002505 | N13: =IFERROR(__xludf.DUMMYFUNCTION("""COMPUTED_VALUE"""),0.25) -> 0.25 | O13: =IFERROR(__xludf.DUMMYFUNCTION("""COMPUTED_VALUE"""),8372.09) -> 8372.09 | P13: =sumif(M:M,M13,O:O) -> 8372.09
A14: Atun 120g Peppersoup Spice (12x) | B14: 45911 | C14: Moneyworth Supermarket, IJUSHAGA | D14: Sales | E14: DT:002505 | F14: 0.25 | G14: 8372.09 | I14: =IFERROR(__xludf.DUMMYFUNCTION("""COMPUTED_VALUE"""),"Atun 120g Peppersoup Spice (12x)") -> Atun 120g Peppersoup Spice (12x) | J14: =IFERROR(__xludf.DUMMYFUNCTION("""COMPUTED_VALUE"""),45911.0) -> 45911 | K14: =IFERROR(__xludf.DUMMYFUNCTION("""COMPUTED_VALUE"""),"Ozzy Supermarket, mobile road") -> Ozzy Supermarket, mobile road | L14: =IFERROR(__xludf.DUMMYFUNCTION("""COMPUTED_VALUE"""),"Sales") -> Sales | M14: =IFERROR(__xludf.DUMMYFUNCTION("""COMPUTED_VALUE"""),"DT:002520") -> DT:002520 | N14: =IFERROR(__xludf.DUMMYFUNCTION("""COMPUTED_VALUE"""),1.0) -> 1 | O14: =IFERROR(__xludf.DUMMYFUNCTION("""COMPUTED_VALUE"""),33488.37) -> 33488.37 | P14: =sumif(M:M,M14,O:O) -> 61395.35
A15: Atun 120g Peppersoup Spice (12x) | B15: 45911 | C15: Ozzy Supermarket, mobile road | D15: Sales | E15: DT:002520 | F15: 1 | G15: 33488.37 | I15: =IFERROR(__xludf.DUMMYFUNCTION("""COMPUTED_VALUE"""),"Atun 120g Peppersoup Spice (12x)") -> Atun 120g Peppersoup Spice (12x) | J15: =IFERROR(__xludf.DUMMYFUNCTION("""COMPUTED_VALUE"""),45912.0) -> 45912 | K15: =IFERROR(__xludf.DUMMYFUNCTION("""COMPUTED_VALUE"""),"Renees Supermarket, IKOYI") -> Renees Supermarket, IKOYI | L15: =IFERROR(__xludf.DUMMYFUNCTION("""COMPUTED_VALUE"""),"Sales") -> Sales | M15: =IFERROR(__xludf.DUMMYFUNCTION("""COMPUTED_VALUE"""),"DT:002525") -> DT:002525 | N15: =IFERROR(__xludf.DUMMYFUNCTION("""COMPUTED_VALUE"""),1.0) -> 1 | O15: =IFERROR(__xludf.DUMMYFUNCTION("""COMPUTED_VALUE"""),33488.37) -> 33488.37 | P15: =sumif(M:M,M15,O:O) -> 33488.37
A16: Atun 120g Peppersoup Spice (12x) | B16: 45912 | C16: Renees Supermarket, IKOYI | D16: Sales | E16: DT:002525 | F16: 1 | G16: 33488.37 | I16: =IFERROR(__xludf.DUMMYFUNCTION("""COMPUTED_VALUE"""),"Atun 120g Peppersoup Spice (12x)") -> Atun 120g Peppersoup Spice (12x) | J16: =IFERROR(__xludf.DUMMYFUNCTION("""COMPUTED_VALUE"""),45912.0) -> 45912 | K16: =IFERROR(__xludf.DUMMYFUNCTION("""COMPUTED_VALUE"""),"Renees Supermarket, FREEDOM WAY") -> Renees Supermarket, FREEDOM WAY | L16: =IFERROR(__xludf.DUMMYFUNCTION("""COMPUTED_VALUE"""),"Sales") -> Sales | M16: =IFERROR(__xludf.DUMMYFUNCTION("""COMPUTED_VALUE"""),"DT:002536") -> DT:002536 | N16: =IFERROR(__xludf.DUMMYFUNCTION("""COMPUTED_VALUE"""),2.0) -> 2 | O16: =IFERROR(__xludf.DUMMYFUNCTION("""COMPUTED_VALUE"""),66976.74) -> 66976.74 | P16: =sumif(M:M,M16,O:O) -> 66976.74
A17: Atun 120g Peppersoup Spice (12x) | B17: 45912 | C17: Renees Supermarket, FREEDOM WAY | D17: Sales | E17: DT:002536 | F17: 2 | G17: 66976.74 | I17: =IFERROR(__xludf.DUMMYFUNCTION("""COMPUTED_VALUE"""),"Atun 120g Peppersoup Spice (12x)") -> Atun 120g Peppersoup Spice (12x) | J17: =IFERROR(__xludf.DUMMYFUNCTION("""COMPUTED_VALUE"""),45913.0) -> 45913 | K17: =IFERROR(__xludf.DUMMYFUNCTION("""COMPUTED_VALUE"""),"Jendol Supermarket, EGBEDA") -> Jendol Supermarket, EGBEDA | L17: =IFERROR(__xludf.DUMMYFUNCTION("""COMPUTED_VALUE"""),"Sales") -> Sales | M17: =IFERROR(__xludf.DUMMYFUNCTION("""COMPUTED_VALUE"""),"DT:002553") -> DT:002553 | N17: =IFERROR(__xludf.DUMMYFUNCTION("""COMPUTED_VALUE"""),0.5) -> 0.5 | O17: =IFERROR(__xludf.DUMMYFUNCTION("""COMPUTED_VALUE"""),16744.19) -> 16744.19 | P17: =sumif(M:M,M17,O:O) -> 16744.19
A18: Atun 120g Peppersoup Spice (12x) | B18: 45913 | C18: Jendol Supermarket, EGBEDA | D18: Sales | E18: DT:002553 | F18: 0.5 | G18: 16744.19 | I18: =IFERROR(__xludf.DUMMYFUNCTION("""COMPUTED_VALUE"""),"Atun 120g Peppersoup Spice (12x)") -> Atun 120g Peppersoup Spice (12x) | J18: =IFERROR(__xludf.DUMMYFUNCTION("""COMPUTED_VALUE"""),45924.0) -> 45924 | K18: =IFERROR(__xludf.DUMMYFUNCTION("""COMPUTED_VALUE"""),"Renees Supermarket, FREEDOM WAY") -> Renees Supermarket, FREEDOM WAY | L18: =IFERROR(__xludf.DUMMYFUNCTION("""COMPUTED_VALUE"""),"Sales") -> Sales | M18: =IFERROR(__xludf.DUMMYFUNCTION("""COMPUTED_VALUE"""),"DT:002665") -> DT:002665 | N18: =IFERROR(__xludf.DUMMYFUNCTION("""COMPUTED_VALUE"""),2.0) -> 2 | O18: =IFERROR(__xludf.DUMMYFUNCTION("""COMPUTED_VALUE"""),66976.74) -> 66976.74 | P18: =sumif(M:M,M18,O:O) -> 66976.74
A19: Atun 120g Peppersoup Spice (12x) | B19: 45924 | C19: Renees Supermarket, FREEDOM WAY | D19: Sales | E19: DT:002665 | F19: 2 | G19: 66976.74 | I19: =IFERROR(__xludf.DUMMYFUNCTION("""COMPUTED_VALUE"""),"Atun 120g Peppersoup Spice (12x)") -> Atun 120g Peppersoup Spice (12x) | J19: =IFERROR(__xludf.DUMMYFUNCTION("""COMPUTED_VALUE"""),45930.0) -> 45930 | K19: =IFERROR(__xludf.DUMMYFUNCTION("""COMPUTED_VALUE"""),"Jendol Supermarket, EGBEDA") -> Jendol Supermarket, EGBEDA | L19: =IFERROR(__xludf.DUMMYFUNCTION("""COMPUTED_VALUE"""),"Sales") -> Sales | M19: =IFERROR(__xludf.DUMMYFUNCTION("""COMPUTED_VALUE"""),"DT:002717") -> DT:002717 | N19: =IFERROR(__xludf.DUMMYFUNCTION("""COMPUTED_VALUE"""),0.5) -> 0.5 | O19: =IFERROR(__xludf.DUMMYFUNCTION("""COMPUTED_VALUE"""),16744.19) -> 16744.19 | P19: =sumif(M:M,M19,O:O) -> 16744.19
A20: Atun 120g Peppersoup Spice (12x) | B20: 45930 | C20: Jendol Supermarket, EGBEDA | D20: Sales | E20: DT:002717 | F20: 0.5 | G20: 16744.19 | I20: =IFERROR(__xludf.DUMMYFUNCTION("""COMPUTED_VALUE"""),"Atun 1.5litre Palm Oil (6x)") -> Atun 1.5litre Palm Oil (6x) | J20: =IFERROR(__xludf.DUMMYFUNCTION("""COMPUTED_VALUE"""),45902.0) -> 45902 | K20: =IFERROR(__xludf.DUMMYFUNCTION("""COMPUTED_VALUE"""),"Ozzy Supermarket, VICTORY PARK EST.") -> Ozzy Supermarket, VICTORY PARK EST. | L20: =IFERROR(__xludf.DUMMYFUNCTION("""COMPUTED_VALUE"""),"Sales") -> Sales | M20: =IFERROR(__xludf.DUMMYFUNCTION("""COMPUTED_VALUE"""),"DT:002387") -> DT:002387 | N20: =IFERROR(__xludf.DUMMYFUNCTION("""COMPUTED_VALUE"""),1.0) -> 1 | O20: =IFERROR(__xludf.DUMMYFUNCTION("""COMPUTED_VALUE"""),27906.98) -> 27906.98 | P20: =sumif(M:M,M20,O:O) -> 83720.93
A21: Atun 1.5litre Palm Oil (6x) | B21: 45902 | C21: Ozzy Supermarket, VICTORY PARK EST. | D21: Sales | E21: DT:002387 | F21: 1 | G21: 27906.98 | I21: =IFERROR(__xludf.DUMMYFUNCTION("""COMPUTED_VALUE"""),"Atun 1.5litre Palm Oil (6x)") -> Atun 1.5litre Palm Oil (6x) | J21: =IFERROR(__xludf.DUMMYFUNCTION("""COMPUTED_VALUE"""),45905.0) -> 45905 | K21: =IFERROR(__xludf.DUMMYFUNCTION("""COMPUTED_VALUE"""),"Zomain Supermarket, JAKANDE Gate") -> Zomain Supermarket, JAKANDE Gate | L21: =IFERROR(__xludf.DUMMYFUNCTION("""COMPUTED_VALUE"""),"Sales") -> Sales | M21: =IFERROR(__xludf.DUMMYFUNCTION("""COMPUTED_VALUE"""),"DT:002449") -> DT:002449 | N21: =IFERROR(__xludf.DUMMYFUNCTION("""COMPUTED_VALUE"""),0.5) -> 0.5 | O21: =IFERROR(__xludf.DUMMYFUNCTION("""COMPUTED_VALUE"""),13953.49) -> 13953.49 | P21: =sumif(M:M,M21,O:O) -> 30697.68
A22: Atun 1.5litre Palm Oil (6x) | B22: 45905 | C22: Zomain Supermarket, JAKANDE Gate | D22: Sales | E22: DT:002449 | F22: 0.5 | G22: 13953.49 | I22: =IFERROR(__xludf.DUMMYFUNCTION("""COMPUTED_VALUE"""),"Atun 1.5litre Palm Oil (6x)") -> Atun 1.5litre Palm Oil (6x) | J22: =IFERROR(__xludf.DUMMYFUNCTION("""COMPUTED_VALUE"""),45906.0) -> 45906 | K22: =IFERROR(__xludf.DUMMYFUNCTION("""COMPUTED_VALUE"""),"Teewell Superstore") -> Teewell Superstore | L22: =IFERROR(__xludf.DUMMYFUNCTION("""COMPUTED_VALUE"""),"Sales") -> Sales | M22: =IFERROR(__xludf.DUMMYFUNCTION("""COMPUTED_VALUE"""),"DT:002467") -> DT:002467 | N22: =IFERROR(__xludf.DUMMYFUNCTION("""COMPUTED_VALUE"""),0.5) -> 0.5 | O22: =IFERROR(__xludf.DUMMYFUNCTION("""COMPUTED_VALUE"""),13953.49) -> 13953.49 | P22: =sumif(M:M,M22,O:O) -> 41860.47
A23: Atun 1.5litre Palm Oil (6x) | B23: 45906 | C23: Teewell Superstore | D23: Sales | E23: DT:002467 | F23: 0.5 | G23: 13953.49 | I23: =IFERROR(__xludf.DUMMYFUNCTION("""COMPUTED_VALUE"""),"Atun 1.5litre Palm Oil (6x)") -> Atun 1.5litre Palm Oil (6x) | J23: =IFERROR(__xludf.DUMMYFUNCTION("""COMPUTED_VALUE"""),45906.0) -> 45906 | K23: =IFERROR(__xludf.DUMMYFUNCTION("""COMPUTED_VALUE"""),"Texon Supermarket, OGUDU") -> Texon Supermarket, OGUDU | L23: =IFERROR(__xludf.DUMMYFUNCTION("""COMPUTED_VALUE"""),"Sales") -> Sales | M23: =IFERROR(__xludf.DUMMYFUNCTION("""COMPUTED_VALUE"""),"DT:002471") -> DT:002471 | N23: =IFERROR(__xludf.DUMMYFUNCTION("""COMPUTED_VALUE"""),0.5) -> 0.5 | O23: =IFERROR(__xludf.DUMMYFUNCTION("""COMPUTED_VALUE"""),13953.49) -> 13953.49 | P23: =sumif(M:M,M23,O:O) -> 13953.49
A24: Atun 1.5litre Palm Oil (6x) | B24: 45906 | C24: Texon Supermarket, OGUDU | D24: Sales | E24: DT:002471 | F24: 0.5 | G24: 13953.49 | I24: =IFERROR(__xludf.DUMMYFUNCTION("""COMPUTED_VALUE"""),"Atun 1.5litre Palm Oil (6x)") -> Atun 1.5litre Palm Oil (6x) | J24: =IFERROR(__xludf.DUMMYFUNCTION("""COMPUTED_VALUE"""),45911.0) -> 45911 | K24: =IFERROR(__xludf.DUMMYFUNCTION("""COMPUTED_VALUE"""),"Ozzy Supermarket, mobile road") -> Ozzy Supermarket, mobile road | L24: =IFERROR(__xludf.DUMMYFUNCTION("""COMPUTED_VALUE"""),"Sales") -> Sales | M24: =IFERROR(__xludf.DUMMYFUNCTION("""COMPUTED_VALUE"""),"DT:002520") -> DT:002520 | N24: =IFERROR(__xludf.DUMMYFUNCTION("""COMPUTED_VALUE"""),1.0) -> 1 | O24: =IFERROR(__xludf.DUMMYFUNCTION("""COMPUTED_VALUE"""),27906.98) -> 27906.98 | P24: =sumif(M:M,M24,O:O) -> 61395.35
A25: Atun 1.5litre Palm Oil (6x) | B25: 45911 | C25: Ozzy Supermarket, mobile road | D25: Sales | E25: DT:002520 | F25: 1 | G25: 27906.98 | I25: =IFERROR(__xludf.DUMMYFUNCTION("""COMPUTED_VALUE"""),"Atun 1.5litre Palm Oil (6x)") -> Atun 1.5litre Palm Oil (6x) | J25: =IFERROR(__xludf.DUMMYFUNCTION("""COMPUTED_VALUE"""),45912.0) -> 45912 | K25: =IFERROR(__xludf.DUMMYFUNCTION("""COMPUTED_VALUE"""),"Renees Supermarket, LEKKI CENTRAL MOSQUE") -> Renees Supermarket, LEKKI CENTRAL MOSQUE | L25: =IFERROR(__xludf.DUMMYFUNCTION("""COMPUTED_VALUE"""),"Sales") -> Sales | M25: =IFERROR(__xludf.DUMMYFUNCTION("""COMPUTED_VALUE"""),"DT:002539") -> DT:002539 | N25: =IFERROR(__xludf.DUMMYFUNCTION("""COMPUTED_VALUE"""),1.0) -> 1 | O25: =IFERROR(__xludf.DUMMYFUNCTION("""COMPUTED_VALUE"""),27906.98) -> 27906.98 | P25: =sumif(M:M,M25,O:O) -> 27906.98
A26: Atun 1.5litre Palm Oil (6x) | B26: 45912 | C26: Renees Supermarket, LEKKI CENTRAL MOSQUE | D26: Sales | E26: DT:002539 | F26: 1 | G26: 27906.98 | I26: =IFERROR(__xludf.DUMMYFUNCTION("""COMPUTED_VALUE"""),"Atun 1.5litre Palm Oil (6x)") -> Atun 1.5litre Palm Oil (6x) | J26: =IFERROR(__xludf.DUMMYFUNCTION("""COMPUTED_VALUE"""),45916.0) -> 45916 | K26: =IFERROR(__xludf.DUMMYFUNCTION("""COMPUTED_VALUE"""),"Ozzy Supermarket, VICTORY PARK EST.") -> Ozzy Supermarket, VICTORY PARK EST. | L26: =IFERROR(__xludf.DUMMYFUNCTION("""COMPUTED_VALUE"""),"Sales") -> Sales | M26: =IFERROR(__xludf.DUMMYFUNCTION("""COMPUTED_VALUE"""),"DT:002570") -> DT:002570 | N26: =IFERROR(__xludf.DUMMYFUNCTION("""COMPUTED_VALUE"""),1.0) -> 1 | O26: =IFERROR(__xludf.DUMMYFUNCTION("""COMPUTED_VALUE"""),27906.98) -> 27906.98 | P26: =sumif(M:M,M26,O:O) -> 50232.56
A27: Atun 1.5litre Palm Oil (6x) | B27: 45916 | C27: Ozzy Supermarket, VICTORY PARK EST. | D27: Sales | E27: DT:002570 | F27: 1 | G27: 27906.98 | I27: =IFERROR(__xludf.DUMMYFUNCTION("""COMPUTED_VALUE"""),"Atun 1.5litre Palm Oil (6x)") -> Atun 1.5litre Palm Oil (6x) | J27: =IFERROR(__xludf.DUMMYFUNCTION("""COMPUTED_VALUE"""),45922.0) -> 45922 | K27: =IFERROR(__xludf.DUMMYFUNCTION("""COMPUTED_VALUE"""),"Skymart Supermarket, LANGBASA") -> Skymart Supermarket, LANGBASA | L27: =IFERROR(__xludf.DUMMYFUNCTION("""COMPUTED_VALUE"""),"Sales") -> Sales | M27: =IFERROR(__xludf.DUMMYFUNCTION("""COMPUTED_VALUE"""),"DT:002627") -> DT:002627 | N27: =IFERROR(__xludf.DUMMYFUNCTION("""COMPUTED_VALUE"""),1.0) -> 1 | O27: =IFERROR(__xludf.DUMMYFUNCTION("""COMPUTED_VALUE"""),27906.98) -> 27906.98 | P27: =sumif(M:M,M27,O:O) -> 27906.98
A28: Atun 1.5litre Palm Oil (6x) | B28: 45922 | C28: Skymart Supermarket, LANGBASA | D28: Sales | E28: DT:002627 | F28: 1 | G28: 27906.98 | I28: =IFERROR(__xludf.DUMMYFUNCTION("""COMPUTED_VALUE"""),"Atun 1.5litre Palm Oil (6x)") -> Atun 1.5litre Palm Oil (6x) | J28: =IFERROR(__xludf.DUMMYFUNCTION("""COMPUTED_VALUE"""),45926.0) -> 45926 | K28: =IFERROR(__xludf.DUMMYFUNCTION("""COMPUTED_VALUE"""),"Ozzy Supermarket, mobile road") -> Ozzy Supermarket, mobile road | L28: =IFERROR(__xludf.DUMMYFUNCTION("""COMPUTED_VALUE"""),"Sales") -> Sales | M28: =IFERROR(__xludf.DUMMYFUNCTION("""COMPUTED_VALUE"""),"DT:002689") -> DT:002689 | N28: =IFERROR(__xludf.DUMMYFUNCTION("""COMPUTED_VALUE"""),1.0) -> 1 | O28: =IFERROR(__xludf.DUMMYFUNCTION("""COMPUTED_VALUE"""),27906.98) -> 27906.98 | P28: =sumif(M:M,M28,O:O) -> 27906.98
A29: Atun 1.5litre Palm Oil (6x) | B29: 45926 | C29: Ozzy Supermarket, mobile road | D29: Sales | E29: DT:002689 | F29: 1 | G29: 27906.98 | I29: =IFERROR(__xludf.DUMMYFUNCTION("""COMPUTED_VALUE"""),"Atun 1.5litre Palm Oil (6x)") -> Atun 1.5litre Palm Oil (6x) | J29: =IFERROR(__xludf.DUMMYFUNCTION("""COMPUTED_VALUE"""),45926.0) -> 45926 | K29: =IFERROR(__xludf.DUMMYFUNCTION("""COMPUTED_VALUE"""),"Prestige Superstore, IPAJA") -> Prestige Superstore, IPAJA | L29: =IFERROR(__xludf.DUMMYFUNCTION("""COMPUTED_VALUE"""),"Sales") -> Sales | M29: =IFERROR(__xludf.DUMMYFUNCTION("""COMPUTED_VALUE"""),"DT:002694") -> DT:002694 | N29: =IFERROR(__xludf.DUMMYFUNCTION("""COMPUTED_VALUE"""),1.0) -> 1 | O29: =IFERROR(__xludf.DUMMYFUNCTION("""COMPUTED_VALUE"""),27906.98) -> 27906.98 | P29: =sumif(M:M,M29,O:O) -> 27906.98
A30: Atun 1.5litre Palm Oil (6x) | B30: 45926 | C30: Prestige Superstore, IPAJA | D30: Sales | E30: DT:002694 | F30: 1 | G30: 27906.98 | I30: =IFERROR(__xludf.DUMMYFUNCTION("""COMPUTED_VALUE"""),"Atun 1.5litre Palm Oil (6x)") -> Atun 1.5litre Palm Oil (6x) | J30: =IFERROR(__xludf.DUMMYFUNCTION("""COMPUTED_VALUE"""),45930.0) -> 45930 | K30: =IFERROR(__xludf.DUMMYFUNCTION("""COMPUTED_VALUE"""),"Prestige Superstore, IYANA ISHASHI") -> Prestige Superstore, IYANA ISHASHI | L30: =IFERROR(__xludf.DUMMYFUNCTION("""COMPUTED_VALUE"""),"Sales") -> Sales | M30: =IFERROR(__xludf.DUMMYFUNCTION("""COMPUTED_VALUE"""),"DT:002712") -> DT:002712 | N30: =IFERROR(__xludf.DUMMYFUNCTION("""COMPUTED_VALUE"""),1.0) -> 1 | O30: =IFERROR(__xludf.DUMMYFUNCTION("""COMPUTED_VALUE"""),27906.98) -> 27906.98 | P30: =sumif(M:M,M30,O:O) -> 27906.98
A31: Atun 1.5litre Palm Oil (6x) | B31: 45930 | C31: Prestige Superstore, IYANA ISHASHI | D31: Sales | E31: DT:002712 | F31: 1 | G31: 27906.98 | I31: =IFERROR(__xludf.DUMMYFUNCTION("""COMPUTED_VALUE"""),"Atun 1.5litre Palm Oil (6x)") -> Atun 1.5litre Palm Oil (6x) | J31: =IFERROR(__xludf.DUMMYFUNCTION("""COMPUTED_VALUE"""),45930.0) -> 45930 | K31: =IFERROR(__xludf.DUMMYFUNCTION("""COMPUTED_VALUE"""),"Prestige Superstore, IGANDO") -> Prestige Superstore, IGANDO | L31: =IFERROR(__xludf.DUMMYFUNCTION("""COMPUTED_VALUE"""),"Sales") -> Sales | M31: =IFERROR(__xludf.DUMMYFUNCTION("""COMPUTED_VALUE"""),"DT:002713") -> DT:002713 | N31: =IFERROR(__xludf.DUMMYFUNCTION("""COMPUTED_VALUE"""),1.0) -> 1 | O31: =IFERROR(__xludf.DUMMYFUNCTION("""COMPUTED_VALUE"""),27906.98) -> 27906.98 | P31: =sumif(M:M,M31,O:O) -> 27906.98
A32: Atun 1.5litre Palm Oil (6x) | B32: 45930 | C32: Prestige Superstore, IGANDO | D32: Sales | E32: DT:002713 | F32: 1 | G32: 27906.98 | I32: =IFERROR(__xludf.DUMMYFUNCTION("""COMPUTED_VALUE"""),"Atun 3kg Yellow Garri (4x)") -> Atun 3kg Yellow Garri (4x) | J32: =IFERROR(__xludf.DUMMYFUNCTION("""COMPUTED_VALUE"""),45902.0) -> 45902 | K32: =IFERROR(__xludf.DUMMYFUNCTION("""COMPUTED_VALUE"""),"Ozzy Supermarket, VICTORY PARK EST.") -> Ozzy Supermarket, VICTORY PARK EST. | L32: =IFERROR(__xludf.DUMMYFUNCTION("""COMPUTED_VALUE"""),"Sales") -> Sales | M32: =IFERROR(__xludf.DUMMYFUNCTION("""COMPUTED_VALUE"""),"DT:002387") -> DT:002387 | N32: =IFERROR(__xludf.DUMMYFUNCTION("""COMPUTED_VALUE"""),1.0) -> 1 | O32: =IFERROR(__xludf.DUMMYFUNCTION("""COMPUTED_VALUE"""),22325.58) -> 22325.58 | P32: =sumif(M:M,M32,O:O) -> 83720.93
A33: Atun 3kg Yellow Garri (4x) | B33: 45902 | C33: Ozzy Supermarket, VICTORY PARK EST. | D33: Sales | E33: DT:002387 | F33: 1 | G33: 22325.58 | I33: =IFERROR(__xludf.DUMMYFUNCTION("""COMPUTED_VALUE"""),"Atun 3kg Yellow Garri (4x)") -> Atun 3kg Yellow Garri (4x) | J33: =IFERROR(__xludf.DUMMYFUNCTION("""COMPUTED_VALUE"""),45906.0) -> 45906 | K33: =IFERROR(__xludf.DUMMYFUNCTION("""COMPUTED_VALUE"""),"Pharm Affair") -> Pharm Affair | L33: =IFERROR(__xludf.DUMMYFUNCTION("""COMPUTED_VALUE"""),"Sales") -> Sales | M33: =IFERROR(__xludf.DUMMYFUNCTION("""COMPUTED_VALUE"""),"DT:002463") -> DT:002463 | N33: =IFERROR(__xludf.DUMMYFUNCTION("""COMPUTED_VALUE"""),0.75) -> 0.75 | O33: =IFERROR(__xludf.DUMMYFUNCTION("""COMPUTED_VALUE"""),16744.19) -> 16744.19 | P33: =sumif(M:M,M33,O:O) -> 33488.38
A34: Atun 3kg Yellow Garri (4x) | B34: 45906 | C34: Pharm Affair | D34: Sales | E34: DT:002463 | F34: 0.75 | G34: 16744.19 | I34: =IFERROR(__xludf.DUMMYFUNCTION("""COMPUTED_VALUE"""),"Atun 3kg Yellow Garri (4x)") -> Atun 3kg Yellow Garri (4x) | J34: =IFERROR(__xludf.DUMMYFUNCTION("""COMPUTED_VALUE"""),45906.0) -> 45906 | K34: =IFERROR(__xludf.DUMMYFUNCTION("""COMPUTED_VALUE"""),"Teewell Superstore") -> Teewell Superstore | L34: =IFERROR(__xludf.DUMMYFUNCTION("""COMPUTED_VALUE"""),"Sales") -> Sales | M34: =IFERROR(__xludf.DUMMYFUNCTION("""COMPUTED_VALUE"""),"DT:002467") -> DT:002467 | N34: =IFERROR(__xludf.DUMMYFUNCTION("""COMPUTED_VALUE"""),0.5) -> 0.5 | O34: =IFERROR(__xludf.DUMMYFUNCTION("""COMPUTED_VALUE"""),11162.79) -> 11162.79 | P34: =sumif(M:M,M34,O:O) -> 41860.47
A35: Atun 3kg Yellow Garri (4x) | B35: 45906 | C35: Teewell Superstore | D35: Sales | E35: DT:002467 | F35: 0.5 | G35: 11162.79 | I35: =IFERROR(__xludf.DUMMYFUNCTION("""COMPUTED_VALUE"""),"Atun 3kg Yellow Garri (4x)") -> Atun 3kg Yellow Garri (4x) | J35: =IFERROR(__xludf.DUMMYFUNCTION("""COMPUTED_VALUE"""),45916.0) -> 45916 | K35: =IFERROR(__xludf.DUMMYFUNCTION("""COMPUTED_VALUE"""),"Ozzy Supermarket, VICTORY PARK EST.") -> Ozzy Supermarket, VICTORY PARK EST. | L35: =IFERROR(__xludf.DUMMYFUNCTION("""COMPUTED_VALUE"""),"Sales") -> Sales | M35: =IFERROR(__xludf.DUMMYFUNCTION("""COMPUTED_VALUE"""),"DT:002570") -> DT:002570 | N35: =IFERROR(__xludf.DUMMYFUNCTION("""COMPUTED_VALUE"""),1.0) -> 1 | O35: =IFERROR(__xludf.DUMMYFUNCTION("""COMPUTED_VALUE"""),22325.58) -> 22325.58 | P35: =sumif(M:M,M35,O:O) -> 50232.56
A36: Atun 3kg Yellow Garri (4x) | B36: 45916 | C36: Ozzy Supermarket, VICTORY PARK EST. | D36: Sales | E36: DT:002570 | F36: 1 | G36: 22325.58 | P36: =sumif(M:M,M36,O:O) -> 0
P37: =sumif(M:M,M37,O:O) -> 0
P38: =sumif(M:M,M38,O:O) -> 0
P39: =sumif(M:M,M39,O:O) -> 0
P40: =sumif(M:M,M40,O:O) -> 0
...

Sheet Payment Advice

Sheet Dala Sales & Deliveries
H1: Total Invoices Delivered | I1: =countifs(B:B,"<>",F:F,"<>")-1 -> 25 | K1: Sku Performance | L1: Units | M1: Value
H2: Unique Locations Supplied | I2: {=(COUNTA(UNIQUE(C:C))-1)} -> 20 | K2: ='Internal Summary'!B40 -> Atun 1.5litre Palm Oil (6x) | L2: =sumif(D:D,K2,E:E) -> 10.5 | M2: =sumif(D:D,K2,F:F) -> 293023.29
H3: Total Value of orders | I3: =sum(F:F) -> 842790.74 | K3: ='Internal Summary'!B41 -> Atun 120g Peppersoup Spice (12x) | L3: =sumif(D:D,K3,E:E) -> 14.25 | M3: =sumif(D:D,K3,F:F) -> 477209.31
K4: ='Internal Summary'!B42 -> Atun 3kg Yellow Garri (4x) | L4: =sumif(D:D,K4,E:E) -> 3.25 | M4: =sumif(D:D,K4,F:F) -> 72558.14
K5: ='Internal Summary'!B43 | L5: =sumif(D:D,K5,E:E) -> 0 | M5: =sumif(D:D,K5,F:F) -> 0
K6: ='Internal Summary'!B44 | L6: =sumif(D:D,K6,E:E) -> 0 | M6: =sumif(D:D,K6,F:F) -> 0
K7: ='Internal Summary'!B45 | L7: =sumif(D:D,K7,E:E) -> 0 | M7: =sumif(D:D,K7,F:F) -> 0
K8: ='Internal Summary'!B46 | L8: =sumif(D:D,K8,E:E) -> 0 | M8: =sumif(D:D,K8,F:F) -> 0
K9: ='Internal Summary'!B47 | L9: =sumif(D:D,K9,E:E) -> 0 | M9: =sumif(D:D,K9,F:F) -> 0
K10: ='Internal Summary'!B48 | L10: =sumif(D:D,K10,E:E) -> 0 | M10: =sumif(D:D,K10,F:F) -> 0
K11: ='Internal Summary'!B49 | L11: =sumif(D:D,K11,E:E) -> 0 | M11: =sumif(D:D,K11,F:F) -> 0
A12: 45758 | K12: ='Internal Summary'!B50 | L12: =sumif(D:D,K12,E:E) -> 0 | M12: =sumif(D:D,K12,F:F) -> 0
K13: ='Internal Summary'!B51 | L13: =sumif(D:D,K13,E:E) -> 0 | M13: =sumif(D:D,K13,F:F) -> 0

Sheet External Delivery Fulfillment
H1: Total Invoices Delivered | I1: =countifs(B:B,"<>",F:F,"<>")-1 -> 0 | K1: Sku Performance | L1: Units | M1: Value
H2: Unique Locations Supplied | I2: {=(COUNTA(UNIQUE(C:C))-1)} -> 0 | K2: ='Internal Summary'!B40 -> Atun 1.5litre Palm Oil (6x) | L2: =sumif(D:D,K2,E:E) -> 0 | M2: =sumif(D:D,K2,F:F) -> 0
H3: Total Value of orders | I3: =sum(F:F) -> 0 | K3: ='Internal Summary'!B41 -> Atun 120g Peppersoup Spice (12x) | L3: =sumif(D:D,K3,E:E) -> 0 | M3: =sumif(D:D,K3,F:F) -> 0
K4: ='Internal Summary'!B42 -> Atun 3kg Yellow Garri (4x) | L4: =sumif(D:D,K4,E:E) -> 0 | M4: =sumif(D:D,K4,F:F) -> 0
K5: ='Internal Summary'!B43 | L5: =sumif(D:D,K5,E:E) -> 0 | M5: =sumif(D:D,K5,F:F) -> 0
K6: ='Internal Summary'!B44 | L6: =sumif(D:D,K6,E:E) -> 0 | M6: =sumif(D:D,K6,F:F) -> 0
K7: ='Internal Summary'!B45 | L7: =sumif(D:D,K7,E:E) -> 0 | M7: =sumif(D:D,K7,F:F) -> 0
K8: ='Internal Summary'!B46 | L8: =sumif(D:D,K8,E:E) -> 0 | M8: =sumif(D:D,K8,F:F) -> 0
K9: ='Internal Summary'!B47 | L9: =sumif(D:D,K9,E:E) -> 0 | M9: =sumif(D:D,K9,F:F) -> 0
K10: ='Internal Summary'!B48 | L10: =sumif(D:D,K10,E:E) -> 0 | M10: =sumif(D:D,K10,F:F) -> 0
K11: ='Internal Summary'!B49 | L11: =sumif(D:D,K11,E:E) -> 0 | M11: =sumif(D:D,K11,F:F) -> 0
K12: ='Internal Summary'!B50 | L12: =sumif(D:D,K12,E:E) -> 0 | M12: =sumif(D:D,K12,F:F) -> 0
K13: ='Internal Summary'!B51 | L13: =sumif(D:D,K13,E:E) -> 0 | M13: =sumif(D:D,K13,F:F) -> 0

Sheet Forwarding From Client
H1: Total Invoices Delivered | I1: =countifs(B:B,"<>",F:F,"<>")-1 -> 0 | K1: Sku Performance | L1: Units | M1: Value
H2: Unique Locations Supplied | I2: {=(COUNTA(UNIQUE(C:C))-1)} -> 0 | K2: ='Internal Summary'!B40 -> Atun 1.5litre Palm Oil (6x) | L2: =sumif(D:D,K2,E:E) -> 0 | M2: =sumif(D:D,K2,F:F) -> 0
H3: Total Value of orders | I3: =sum(F:F) -> 0 | K3: ='Internal Summary'!B41 -> Atun 120g Peppersoup Spice (12x) | L3: =sumif(D:D,K3,E:E) -> 0 | M3: =sumif(D:D,K3,F:F) -> 0
K4: ='Internal Summary'!B42 -> Atun 3kg Yellow Garri (4x) | L4: =sumif(D:D,K4,E:E) -> 0 | M4: =sumif(D:D,K4,F:F) -> 0
K5: ='Internal Summary'!B43 | L5: =sumif(D:D,K5,E:E) -> 0 | M5: =sumif(D:D,K5,F:F) -> 0
K6: ='Internal Summary'!B44 | L6: =sumif(D:D,K6,E:E) -> 0 | M6: =sumif(D:D,K6,F:F) -> 0
K7: ='Internal Summary'!B45 | L7: =sumif(D:D,K7,E:E) -> 0 | M7: =sumif(D:D,K7,F:F) -> 0
K8: ='Internal Summary'!B46 | L8: =sumif(D:D,K8,E:E) -> 0 | M8: =sumif(D:D,K8,F:F) -> 0
K9: ='Internal Summary'!B47 | L9: =sumif(D:D,K9,E:E) -> 0 | M9: =sumif(D:D,K9,F:F) -> 0
K10: ='Internal Summary'!B48 | L10: =sumif(D:D,K10,E:E) -> 0 | M10: =sumif(D:D,K10,F:F) -> 0
K11: ='Internal Summary'!B49 | L11: =sumif(D:D,K11,E:E) -> 0 | M11: =sumif(D:D,K11,F:F) -> 0
K12: ='Internal Summary'!B50 | L12: =sumif(D:D,K12,E:E) -> 0 | M12: =sumif(D:D,K12,F:F) -> 0
K13: ='Internal Summary'!B51 | L13: =sumif(D:D,K13,E:E) -> 0 | M13: =sumif(D:D,K13,F:F) -> 0

Sheet Dala Restocking
H1: Total Invoices Delivered | I1: =countifs(B:B,"<>",F:F,"<>")-1 -> 1 | K1: Sku Performance | L1: Units
H2: Unique Locations Supplied | I2: {=(COUNTA(UNIQUE(C:C,,0))-1)} -> 1 | K2: ='Internal Summary'!B40 -> Atun 1.5litre Palm Oil (6x) | L2: =sumif(D:D,K2,E:E) -> 0
H3: Total Value of orders | I3: =sum(F:F) -> 669767.4 | K3: ='Internal Summary'!B41 -> Atun 120g Peppersoup Spice (12x) | L3: =sumif(D:D,K3,E:E) -> 20
K4: ='Internal Summary'!B42 -> Atun 3kg Yellow Garri (4x) | L4: =sumif(D:D,K4,E:E) -> 0
K5: ='Internal Summary'!B43 | L5: =sumif(D:D,K5,E:E) -> 0
K6: ='Internal Summary'!B44 | L6: =sumif(D:D,K6,E:E) -> 0
K7: ='Internal Summary'!B45 | L7: =sumif(D:D,K7,E:E) -> 0
K8: ='Internal Summary'!B46 | L8: =sumif(D:D,K8,E:E) -> 0
K9: ='Internal Summary'!B47 | L9: =sumif(D:D,K9,E:E) -> 0
K10: ='Internal Summary'!B48 | L10: =sumif(D:D,K10,E:E) -> 0
K11: ='Internal Summary'!B49 | L11: =sumif(D:D,K11,E:E) -> 0
K12: ='Internal Summary'!B50 | L12: =sumif(D:D,K12,E:E) -> 0
K13: ='Internal Summary'!B51 | L13: =sumif(D:D,K13,E:E) -> 0

Sheet Client Restocking
H1: Total Invoices Delivered | I1: =countifs(B:B,"<>",F:F,"<>")-1 -> 0 | K1: Sku Performance | L1: Units
H2: Unique Locations Supplied | I2: {=(COUNTA(UNIQUE(C:C,,0))-1)} -> 0 | K2: ='Internal Summary'!B40 -> Atun 1.5litre Palm Oil (6x) | L2: =sumif(D:D,K2,E:E) -> 0
H3: Total Value of orders | I3: =sum(F:F) -> 0 | K3: ='Internal Summary'!B41 -> Atun 120g Peppersoup Spice (12x) | L3: =sumif(D:D,K3,E:E) -> 0
K4: ='Internal Summary'!B42 -> Atun 3kg Yellow Garri (4x) | L4: =sumif(D:D,K4,E:E) -> 0
K5: ='Internal Summary'!B43 | L5: =sumif(D:D,K5,E:E) -> 0
K6: ='Internal Summary'!B44 | L6: =sumif(D:D,K6,E:E) -> 0
K7: ='Internal Summary'!B45 | L7: =sumif(D:D,K7,E:E) -> 0
K8: ='Internal Summary'!B46 | L8: =sumif(D:D,K8,E:E) -> 0
K9: ='Internal Summary'!B47 | L9: =sumif(D:D,K9,E:E) -> 0
K10: ='Internal Summary'!B48 | L10: =sumif(D:D,K10,E:E) -> 0
K11: ='Internal Summary'!B49 | L11: =sumif(D:D,K11,E:E) -> 0
K12: ='Internal Summary'!B50 | L12: =sumif(D:D,K12,E:E) -> 0
K13: ='Internal Summary'!B51 | L13: =sumif(D:D,K13,E:E) -> 0

Sheet Internal Summary
B1: Description | C1: Units | D1: measurements | E1: total
A2: SALES | B2: Total Invoices Delivered | E2: ='Dala Sales & Deliveries'!I1+'External Delivery Fulfillment'!I1 -> 25
B3: Unique Locations Delivered To | E3: ='Raw Data'!AW2 -> 20
B4: Value of Dala Deliveries | E4: ='Dala Sales & Deliveries'!I3 -> 842790.74
B5: Value of External Deliveries | E5: ='External Delivery Fulfillment'!I3 -> 0
B6: VAT on sales | E6: =E4*1.075-E4 -> 63209.306
B7: Total Value of Deliveries | E7: =sum(E4:E6) -> 906000.05
A8: Remittance & Deductions | B8: Total Remitted to Partner
B9: Collection Fees | C9: 0.22 | E9: =E8*(C9+100%)-E8 -> 0
A10: Invoice Value Due | B10: Outstanding Paymets For Sales | E10: =E7-E8-E9 -> 906000.05
A11: Debts | B11: Unpaid Subscription | E11: =C11*D11 -> 0
B12: Collection Fees | E12: =E10*C9 -> 199320.01
B13: Delivery Fees | D13: Table 1 | E13: =C22+C26 -> 87435
B14: Reimbursements Due To DALA | E14: 0
B15: Retailer Deductions | E15: =C30 -> 0
B16: Total Deductions | E16: =sum(E11:E15) -> 286755.01
A17: Remmittance Due | B17: Total Balance to Remitt | E17: =E10-E16+C36 -> 619245.04
A20: Inventory and Operational Fees
B21: Dala Pickup for Warehouse | C21: =U69 -> 20
B22: Warehouse Delivery Fee | C22: =V69 -> 30000
B23: Forwarding to Retail | C23: =S69 -> 0
B24: Forwarding Delivery Fee | C24: =T69 -> 0
B25: Dala Sales | C25: =67 -> 67
B26: Dala Delivery Fees | C26: =P69 -> 57435
B27: Exteranl Deliveries | C27: =Q69 -> 0
B28: External Delivery Fees | C28: =R69 -> 0
B29: Product Defects and Expirey Issues | C29: =F69 -> 0
B30: Deductions From Retailer | C30: 0
B31: Samples used | C31: =I69 -> 0
B32: Produce Replacements | C32: 0
B33: Expected Closing Inventory | C33: =L69 -> -8
B34: Physical Stock count | C34: =K69 -> 51.5
B35: Inventory Shortages | C35: 0
B36: Inventory Shortage Costs | C36: 0
B39: SKUs | C39: Retail Value | D39: Inbound Delivery Fee | E39: Outbound Delivery Fee | F39: Defects/Expirey | G39: Deductions | H39: Opening Inventory | I39: Samples Used | J39: Product Replacements | K39: Physical Closing Stock Count | L39: Expected Closing Inventory | M39: Inventory Shortages | N39: Shortages Costs | O39: Dala Deliveries | P39: Retail Sales Fee | Q39: External Delivery | R39: External Delivery Fee | S39: Forwarding from Client | T39: Forwarding Delivery Fee | U39: Dala Restocking | V39: Dala Restocking Fee | W39: Client Restocking
B40: Atun 1.5litre Palm Oil (6x) | C40: 30000 | D40: 2150 | E40: =C40*0.07 -> 2100 | G40: =F40*C40 -> 0 | K40: 14.5 | L40: =H40+U40+W40-O40-Q40-I40-J40 -> -10.5 | M40: =K40-L40 -> 25 | N40: =M40*C40 -> 750000 | O40: ='Dala Sales & Deliveries'!L2 -> 10.5 | P40: =O40*E40 -> 22050 | Q40: ='External Delivery Fulfillment'!L2 -> 0 | R40: =Q40*E40 -> 0 | S40: ='Forwarding From Client'!L2 -> 0 | T40: =S40*E40 -> 0 | U40: ='Dala Restocking'!L2 -> 0 | V40: =U40*D40 -> 0 | W40: ='Client Restocking'!L2 -> 0
B41: Atun 120g Peppersoup Spice (12x) | C41: 30000 | D41: 1500 | E41: =C41*0.07 -> 2100 | G41: =F41*C41 -> 0 | K41: 11 | L41: =H41+U41+W41-O41-Q41-I41-J41 -> 5.75 | M41: =K41-L41 -> 5.25 | N41: =M41*C41 -> 157500 | O41: ='Dala Sales & Deliveries'!L3 -> 14.25 | P41: =O41*E41 -> 29925 | Q41: ='External Delivery Fulfillment'!L3 -> 0 | R41: =Q41*E41 -> 0 | S41: ='Forwarding From Client'!L3 -> 0 | T41: =S41*E41 -> 0 | U41: ='Dala Restocking'!L3 -> 20 | V41: =U41*D41 -> 30000 | W41: ='Client Restocking'!L3 -> 0
B42: Atun 3kg Yellow Garri (4x) | C42: 24000 | D42: 1700 | E42: =C42*0.07 -> 1680 | G42: =F42*C42 -> 0 | K42: 26 | L42: =H42+U42+W42-O42-Q42-I42-J42 -> -3.25 | M42: =K42-L42 -> 29.25 | N42: =M42*C42 -> 702000 | O42: ='Dala Sales & Deliveries'!L4 -> 3.25 | P42: =O42*E42 -> 5460 | Q42: ='External Delivery Fulfillment'!L4 -> 0 | R42: =Q42*E42 -> 0 | S42: ='Forwarding From Client'!L4 -> 0 | T42: =S42*E42 -> 0 | U42: ='Dala Restocking'!L4 -> 0 | V42: =U42*D42 -> 0 | W42: ='Client Restocking'!L4 -> 0
G43: =F43*C43 -> 0 | L43: =H43+U43+W43-O43-Q43-I43-J43 -> 0 | M43: =K43-L43 -> 0 | N43: =M43*C43 -> 0 | O43: ='Dala Sales & Deliveries'!L5 -> 0 | P43: =O43*E43 -> 0 | Q43: ='External Delivery Fulfillment'!L5 -> 0 | R43: =Q43*E43 -> 0 | S43: ='Forwarding From Client'!L5 -> 0 | T43: =S43*E43 -> 0 | U43: ='Dala Restocking'!L5 -> 0 | V43: =U43*D43 -> 0 | W43: ='Client Restocking'!L5 -> 0
G44: =F44*C44 -> 0 | L44: =H44+U44+W44-O44-Q44-I44-J44 -> 0 | M44: =K44-L44 -> 0 | N44: =M44*C44 -> 0 | O44: ='Dala Sales & Deliveries'!L6 -> 0 | P44: =O44*E44 -> 0 | Q44: ='External Delivery Fulfillment'!L6 -> 0 | R44: =Q44*E44 -> 0 | S44: ='Forwarding From Client'!L6 -> 0 | T44: =S44*E44 -> 0 | U44: ='Dala Restocking'!L6 -> 0 | V44: =U44*D44 -> 0 | W44: ='Client Restocking'!L6 -> 0
...

Sheet External Summary
B1: Description | C1: Units | D1: measurements | E1: total
A2: SALES | B2: Total Invoices Delivered | E2: ='Dala Sales & Deliveries'!I1+'External Delivery Fulfillment'!I1+'Forwarding From Client'!I1 -> 25
B3: Unique Locations Delivered To | E3: ='Raw Data'!AW2 -> 20
B4: Value of Dala Deliveries | E4: ='Dala Sales & Deliveries'!I3 -> 842790.74
B5: VAT on sales | E5: =E4*1.075-E4 -> 63209.306
B6: Total Value of Deliveries | E6: =sum(E4:E5) -> 906000.05
A7: Remittance & Deductions | B7: Total Remitted to Partner
B8: Delivery Fees | E8: =E7*(C8+100%)-E7 -> 0
B9: Collection Fees | C9: 0.22 | E9: =E7*(C9+100%)-E7 -> 0
A10: Debts | B10: Unpaid Subscription | C10: 1 | E10: =C10*D10 -> 0
B11: Restocking Fees | E11: =V67 -> 30000
B12: External Delivery Fees | E12: =R67 -> 0
B13: Reimbursements Due To DALA | E13: 0
B14: Retailer Deductions | E14: =C28 -> 0
B15: Total Owed to Dala | E15: =sum(E10:E14) -> 30000
A18: Inventory and Operational Fees
B19: Dala Pickup for Warehouse | C19: =U67 -> 20
B20: Warehouse Delivery Fee | C20: =V67 -> 30000
B21: Forwarding to Retail | C21: =S67 -> 0
B22: Forwarding Delivery Fee | C22: =T67 -> 0
B23: Dala Sales | C23: =O67 -> 28
B24: Dala Delivery Fees | C24: =P67 -> 57435
B25: Exteranl Deliveries | C25: =Q67 -> 0
B26: External Delivery Fees | C26: =R67 -> 0
B27: Product Defects and Expirey Issues | C27: =F67 -> 0
B28: Deductions From Retailer | C28: =G67 -> 0
B29: Samples used | C29: =I67 -> 0
B30: Returns/Replacements | C30: =J67 -> 0
B31: Expected Closing Inventory | C31: =L67 -> -8
B32: Physical Stock count | C32: =K67 -> 54.25
B33: Inventory Shortages | C33: =M67 -> 62.25
B34: Inventory Shortage Costs | C34: 0
B37: SKUs | C37: Retail Value | D37: Inbound Delivery Fee | E37: Outbound Delivery Fee | F37: Defects/Expirey | G37: Deductions | H37: Opening Inventory | I37: Samples Used | J37: Product Replacements | K37: Physical Closing Stock Count | L37: Expected Closing Inventory | M37: Inventory Shortages | N37: Shortages Costs | O37: Dala Sales | P37: Retail Sales Fee | Q37: External Delivery | R37: External Delivery Fee | S37: Forwarding from Client | T37: Forwarding Delivery Fee | U37: Dala Restocking | V37: Dala Restocking Fee | W37: Client Restocking
B38: ='Internal Summary'!B40 -> Atun 1.5litre Palm Oil (6x) | C38: ='Internal Summary'!C40 -> 30000 | D38: ='Internal Summary'!D40 -> 2150 | E38: ='Internal Summary'!E40 -> 2100 | G38: =F38*C38 -> 0 | K38: 18.5 | L38: =H38+U38+W38-O38-Q38-I38-J38 -> -10.5 | M38: =K38-L38 -> 29 | N38: =M38*C38 -> 870000 | O38: ='Dala Sales & Deliveries'!L2 -> 10.5 | P38: =O38*E38 -> 22050 | Q38: ='External Delivery Fulfillment'!L2 -> 0 | R38: =Q38*E38 -> 0 | S38: ='Forwarding From Client'!L2 -> 0 | T38: =S38*E38 -> 0 | U38: ='Dala Restocking'!L2 -> 0 | V38: =U38*D38 -> 0 | W38: ='Client Restocking'!L2 -> 0
B39: ='Internal Summary'!B41 -> Atun 120g Peppersoup Spice (12x) | C39: ='Internal Summary'!C41 -> 30000 | D39: ='Internal Summary'!D41 -> 1500 | E39: ='Internal Summary'!E41 -> 2100 | G39: =F39*C39 -> 0 | K39: 6.5 | L39: =H39+U39+W39-O39-Q39-I39-J39 -> 5.75 | M39: =K39-L39 -> 0.75 | N39: =M39*C39 -> 22500 | O39: ='Dala Sales & Deliveries'!L3 -> 14.25 | P39: =O39*E39 -> 29925 | Q39: ='External Delivery Fulfillment'!L3 -> 0 | R39: =Q39*E39 -> 0 | S39: ='Forwarding From Client'!L3 -> 0 | T39: =S39*E39 -> 0 | U39: ='Dala Restocking'!L3 -> 20 | V39: =U39*D39 -> 30000 | W39: ='Client Restocking'!L3 -> 0
B40: ='Internal Summary'!B42 -> Atun 3kg Yellow Garri (4x) | C40: ='Internal Summary'!C42 -> 24000 | D40: ='Internal Summary'!D42 -> 1700 | E40: ='Internal Summary'!E42 -> 1680 | G40: =F40*C40 -> 0 | K40: 29.25 | L40: =H40+U40+W40-O40-Q40-I40-J40 -> -3.25 | M40: =K40-L40 -> 32.5 | N40: =M40*C40 -> 780000 | O40: ='Dala Sales & Deliveries'!L4 -> 3.25 | P40: =O40*E40 -> 5460 | Q40: ='External Delivery Fulfillment'!L4 -> 0 | R40: =Q40*E40 -> 0 | S40: ='Forwarding From Client'!L4 -> 0 | T40: =S40*E40 -> 0 | U40: ='Dala Restocking'!L4 -> 0 | V40: =U40*D40 -> 0 | W40: ='Client Restocking'!L4 -> 0
B41: ='Internal Summary'!B43 | C41: ='Internal Summary'!C43 | D41: ='Internal Summary'!D43 | E41: ='Internal Summary'!E43 | G41: =F41*C41 -> 0 | L41: =H41+U41+W41-O41-Q41-I41-J41 -> 0 | M41: =K41-L41 -> 0 | N41: =M41*C41 -> 0 | O41: ='Dala Sales & Deliveries'!L5 -> 0 | P41: =O41*E41 -> 0 | Q41: ='External Delivery Fulfillment'!L5 -> 0 | R41: =Q41*E41 -> 0 | S41: ='Forwarding From Client'!L5 -> 0 | T41: =S41*E41 -> 0 | U41: ='Dala Restocking'!L5 -> 0 | V41: =U41*D41 -> 0 | W41: ='Client Restocking'!L5 -> 0
B42: ='Internal Summary'!B44 | C42: ='Internal Summary'!C44 | D42: ='Internal Summary'!D44 | E42: ='Internal Summary'!E44 | G42: =F42*C42 -> 0 | L42: =H42+U42+W42-O42-Q42-I42-J42 -> 0 | M42: =K42-L42 -> 0 | N42: =M42*C42 -> 0 | O42: ='Dala Sales & Deliveries'!L6 -> 0 | P42: =O42*E42 -> 0 | Q42: ='External Delivery Fulfillment'!L6 -> 0 | R42: =Q42*E42 -> 0 | S42: ='Forwarding From Client'!L6 -> 0 | T42: =S42*E42 -> 0 | U42: ='Dala Restocking'!L6 -> 0 | V42: =U42*D42 -> 0 | W42: ='Client Restocking'!L6 -> 0
B43: ='Internal Summary'!B45 | C43: ='Internal Summary'!C45 | D43: ='Internal Summary'!D45 | E43: ='Internal Summary'!E45 | G43: =F43*C43 -> 0 | L43: =H43+U43+W43-O43-Q43-I43-J43 -> 0 | M43: =K43-L43 -> 0 | N43: =M43*C43 -> 0 | O43: ='Dala Sales & Deliveries'!L7 -> 0 | P43: =O43*E43 -> 0 | Q43: ='External Delivery Fulfillment'!L7 -> 0 | R43: =Q43*E43 -> 0 | S43: ='Forwarding From Client'!L7 -> 0 | T43: =S43*E43 -> 0 | U43: ='Dala Restocking'!L7 -> 0 | V43: =U43*D43 -> 0 | W43: ='Client Restocking'!L7 -> 0
B44: ='Internal Summary'!B46 | C44: ='Internal Summary'!C46 | D44: ='Internal Summary'!D46 | E44: ='Internal Summary'!E46 | G44: =F44*C44 -> 0 | L44: =H44+U44+W44-O44-Q44-I44-J44 -> 0 | M44: =K44-L44 -> 0 | N44: =M44*C44 -> 0 | O44: ='Dala Sales & Deliveries'!L8 -> 0 | P44: =O44*E44 -> 0 | Q44: ='External Delivery Fulfillment'!L8 -> 0 | R44: =Q44*E44 -> 0 | S44: ='Forwarding From Client'!L8 -> 0 | T44: =S44*E44 -> 0 | U44: ='Dala Restocking'!L8 -> 0 | V44: =U44*D44 -> 0 | W44: ='Client Restocking'!L8 -> 0
...
